Workbook

Sheet فروش كالا و خدمات
W1: شماره سریال:
W2: تاریخ :
A3: صورتحساب فروش کالا و خدمات
A4: مشخصات فروشنده
A5: نام شخص حقیقی / حقوقی : | D5: شرکت تکنیک | I5: شماره اقتصادی : | K5: 7 | L5: 5 | M5: 7 | N5: 7 | O5: 7 | P5: 6 | Q5: 1 | R5: 5 | S5: 1 | T5: 1 | U5: 1 | V5: 4 | W5: شماره ثبت / شماره ملی : | Y5: 0 | Z5: 2 | AA5: 0 | AB5: 3
A7: نشانی کامل : استان : تهران شهرستان : تهران شهر : تهران | I7: کدپستی 10 رقمی : | M7: 1 | N7: 1 | O7: 3 | P7: 4 | Q7: 8 | R7: 8 | S7: 8 | T7: 3 | U7: 4 | V7: 1 | W7: شماره تلفن / نمابر : 02188335750/02188335760
A8: نشانی : تهران - ابتدای مسیر جنوب به شمال اتوبان کردستان - نبش خیابان سی و سوم جهان ارا (شهید حسین پور) - پلاک 64 - شرکت تکنیک
A9: مشخصات خریدار
A10: نام شخص حقیقی / حقوقی : | D10: راه آهن جمهوری اسلامی ایران | I10: شماره اقتصادی : | K10: 7 | L10: 7 | M10: 1 | N10: 3 | O10: 1 | P10: 5 | Q10: 1 | R10: 1 | S10: 1 | T10: 1 | U10: 1 | V10: 4 | W10: شماره ثبت / شماره ملی : | Y10: 4 | Z10: 4 | AA10: 6 | AB10: 0 | AC10: 7
A12: نشانی کامل : استان : تهران شهرستان : تهران شهر : تهران | I12: کدپستی 10 رقمی : | M12: 1 | N12: 1 | O12: 1 | P12: 3 | Q12: 1 | R12: 7 | S12: 9 | T12: 1 | U12: 5 | V12: 1 | W12: شماره تلفن / نمابر : 55128159
A13: نشانی : میدان آرژانتین، ابتدای بلوار آفریقا ، ساختمان راه آهن جمهوری اسلامی ایران
A14: مشخصات کالا یا خدمات مورد معامله
A15: 1 | B15: 2 | C15: 3 | F15: 4 | G15: 5 | H15: 6 | I15: 7 | K15: 8 | Q15: 9 | W15: 10 | AA15: 11
A16: ردیف | B16: کد کالا | C16: شرح کالا و یا خدمات | F16: تعداد/ مقدار | G16: واحد اندازه گیری | H16: مبلغ واحد (ریال) | I16: مبلغ کل (ریال) | K16: مبلغ تخفیف | Q16: مبلغ کل پس از تخفیف (ریال) | W16: جمع مالیات و عوارض (ریال) | AA16: جمع مبلغ کل بعلاوه جمع مالیات و عوارض ( ریال)
A17: نحوه محاسبه براساس شماره ستون ← | I17: (4*6) | Q17: (7-8) | W17: (9*9%) | AA17: (9+10)
A18: 1 | B18: -- | C18: صورت وضعیت قطعی قرارداد طراحی، تأمین و اجرای دو خطه کردن راه‏آهن (زیرسازی، پل‏سازی، روسازی) محور مشك-سيستان ش قرارداد 400/6موقت 6891/ی مورخ 93/11/20 | F18: -- | G18: -- | H18: --
A19: 2
A20: جمع کل: | I20: =SUM(I18:J19) -> 0 | W20: =SUM(W18:Z19) -> 0 | AA20: =SUM(AA18:AH19) -> 0
A21: شرایط و نحوه فروش : نقدی : □ غیر نقدی : □ صورتحساب فصلی : □
A22: توضیحات:
A24: مهر و امضاء فروشنده: | I24: مهر و امضاء خریدار:

Sheet summary
E1: پروژه رفع گلوگاه هاي ظرفيتي در امور زيربنايي راه آهن ج.ا.ا
A8: « جدول خلاصه صورت وضعيت ها »
A10: شماره صورت وضعيت | D10: دوره کارکرد | G10: تجمعی صورت وضعیت شده پيمانکار (ریال) | K10: تجمعی تایید شده توسط مشاور(ریال) | O10: تجمعی تایید شده توسط کارفرما (ریال)
A11: ارسالي | B11: تاييد شده

Sheet summary-2
F1: پروژه رفع گلوگاه هاي ظرفيتي در امور زيربنايي راه آهن ج.ا.ا
A7: « خلاصه کارکرد صورت وضعیت موقت قطعی به تفکیک فصول مرتبط »
A9: کارفرما: | D9: شرکت راه آهن ج.ا.ا | H9: مشاور: | K9: مهندسین مشاور صحن بوستان | O9: پيمانکار: | R9: مشارکت تكنيك پل رود كنكاوان معدن شيراز
A10: عنوان قرارداد: | D10: پروژه احداث خط دوم راه آهن محور مشك - سيستان به روش EPC غيرصنعتي | H10: شماره قرارداد: | K10: 400/66891/ي | O10: تاریخ قرارداد: | R10: 1393/11/20
A11: فهرست بهای رشته: | D11: راه، راه آهن و باند فرودگاه | H11: صورت وضعیت از تاريخ: | K11: 1396/12/11 | O11: تا تاريخ: | R11: ='خلاصه مالي صورت وضعیت'!E5 -> 1399/06/02
A13: فصل | B13: شرح فصل | G13: مبلغ کارکرد (ريال) | P13: کارکرد | S13: ملاحظات
G14: تا دوره قبل -کارکرد 15 | J14: اين دوره قطعی | M14: تجمعي تاکنون
A15: مهندسي | B15: خدمات مهندسي و طراحي | G15: 5.2156117e+10 | J15: =IF(M15=0,0,M15-G15) -> 6.9393801e+09 | M15: ='خلاصه مالي صورت وضعیت'!$G$14 -> 5.9095497e+10 | P15: درخواست پیمانکار
G16: 3.8974588e+10 | J16: =IF(M16=0,0,M16-G16) -> 0 | M16: ='خلاصه مالي صورت وضعیت'!$H$14 -> 0 | P16: تأیید مشاور
J17: =IF(M17=0,0,M17-G17) -> 0 | P17: تأیید کارفرما
A18: بيمه | B18: بيمه نامه ها | G18: 7.1848629e+09 | J18: =IF(M18=0,0,M18-G18) -> 0 | M18: ='خلاصه مالي صورت وضعیت'!$G$11 -> 7.1848629e+09 | P18: درخواست پیمانکار
G19: 5295842703 | J19: =IF(M19=0,0,M19-G19) -> 0 | M19: ='خلاصه مالي صورت وضعیت'!$H$11 -> 0 | P19: تأیید مشاور
J20: =IF(M20=0,0,M20-G20) -> 0 | P20: تأیید کارفرما
A21: - | B21: کارهای اضافه | G21: 28486290919 | J21: =IF(M21=0,0,M21-G21) -> 18990860613 | M21: ='خلاصه مالي صورت وضعیت'!G29 -> 47477151532 | P21: درخواست پیمانکار
G22: 0 | J22: =IF(M22=0,0,M22-G22) -> 0 | M22: ='خلاصه مالي صورت وضعیت'!H29 -> 0 | P22: تأیید مشاور
J23: =IF(M23=0,0,M23-G23) -> 0 | M23: ='خلاصه مالي صورت وضعیت'!I29 -> 0 | P23: تأیید کارفرما
A24: - | B24: تجهیز و برچیدن کارگاه | G24: 4.5144889e+10 | J24: =IF(M24=0,0,M24-G24) -> 6.3466289e+09 | M24: ='خلاصه مالي صورت وضعیت'!G12+'خلاصه مالي صورت وضعیت'!G13+'خلاصه مالي صورت وضعیت'!G32 -> 5.1491518e+10 | P24: درخواست پیمانکار
G25: 3.4458004e+10 | J25: =IF(M25=0,0,M25-G25) -> 0 | M25: ='خلاصه مالي صورت وضعیت'!H12+'خلاصه مالي صورت وضعیت'!H13+'خلاصه مالي صورت وضعیت'!H32 -> 0 | P25: تأیید مشاور
J26: =IF(M26=0,0,M26-G26) -> 0 | P26: تأیید کارفرما
A27: - | B27: تحويل موقت و بيمه مهندسي سازه‌هاي تكميل شده | G27: 0 | M27: ='خلاصه مالي صورت وضعیت'!G31+'خلاصه مالي صورت وضعیت'!G33 -> 1.0777294e+10 | P27: درخواست پیمانکار
G28: 0 | M28: ='خلاصه مالي صورت وضعیت'!H31+'خلاصه مالي صورت وضعیت'!H33 -> 0 | P28: تأیید مشاور
P29: تأیید کارفرما
A30: - | B30: مقدمات لازم جهت فعاليتهاي اجرايي | G30: 5.9802009e+09 | J30: =IF(M30=0,0,M30-G30) -> 7184862.9 | M30: ='خلاصه مالي صورت وضعیت'!G10 -> 5987385758 | P30: درخواست پیمانکار
G31: 5.8796128e+09 | J31: =IF(M31=0,0,M31-G31) -> 0 | M31: ='خلاصه مالي صورت وضعیت'!H10 -> 0 | P31: تأیید مشاور
P32: تأیید کارفرما
A33: 1 | B33: عملیات تخریب | G33: 0 | J33: =IF(M33=0,0,M33-G33) -> 0 | M33: =SUMIF('خدمات اجرایی '!F:F,'summary-2'!A33,'خدمات اجرایی '!L:L) -> 0 | P33: درخواست پیمانکار
G34: 0 | J34: =IF(M34=0,0,M34-G34) -> 0 | M34: =SUMIF('خدمات اجرایی '!F:F,'summary-2'!A33,'خدمات اجرایی '!Q:Q) -> 0 | P34: تأیید مشاور
J35: =IF(M35=0,0,M35-G35) -> 0 | P35: تأیید کارفرما
A36: 2 | B36: عملیات خاکی با دست | G36: 0 | J36: =IF(M36=0,0,M36-G36) -> 0 | M36: =SUMIF('خدمات اجرایی '!F:F,'summary-2'!A36,'خدمات اجرایی '!L:L) -> 0 | P36: درخواست پیمانکار
G37: 0 | J37: =IF(M37=0,0,M37-G37) -> 0 | M37: =SUMIF('خدمات اجرایی '!F:F,'summary-2'!A36,'خدمات اجرایی '!Q:Q) -> 0 | P37: تأیید مشاور
J38: =IF(M38=0,0,M38-G38) -> 0 | P38: تأیید کارفرما
A39: 3 | B39: عملیات خاکی با ماشین | G39: 1.4008374e+11 | J39: =IF(M39=0,0,M39-G39) -> 1.4517075e+08 | M39: =SUMIF('خدمات اجرایی '!F:F,'summary-2'!A39,'خدمات اجرایی '!L:L) -> 1.4022891e+11 | P39: درخواست پیمانکار
G40: 1.3997263e+11 | J40: =IF(M40=0,0,M40-G40) -> 0 | M40: =SUMIF('خدمات اجرایی '!F:F,'summary-2'!A39,'خدمات اجرایی '!Q:Q) -> 0 | P40: تأیید مشاور
J41: =IF(M41=0,0,M41-G41) -> 0 | P41: تأیید کارفرما
A42: 6 | B42: عملیات بنایی با سنگ | G42: 2.54245e+09 | J42: =IF(M42=0,0,M42-G42) -> 0 | M42: =SUMIF('خدمات اجرایی '!F:F,'summary-2'!A42,'خدمات اجرایی '!L:L) -> 2.54245e+09 | P42: درخواست پیمانکار
G43: 2.4831261e+09 | J43: =IF(M43=0,0,M43-G43) -> 0 | M43: =SUMIF('خدمات اجرایی '!F:F,'summary-2'!A42,'خدمات اجرایی '!Q:Q) -> 0 | P43: تأیید مشاور
J44: =IF(M44=0,0,M44-G44) -> 0 | P44: تأیید کارفرما
A45: 8 | B45: قالب بندی و چوب بست | G45: 25424499588 | J45: =IF(M45=0,0,M45-G45) -> 0 | M45: =SUMIF('خدمات اجرایی '!F:F,'summary-2'!A45,'خدمات اجرایی '!L:L) -> 25424499588 | P45: درخواست پیمانکار
G46: 2.5255003e+10 | J46: =IF(M46=0,0,M46-G46) -> 0 | M46: =SUMIF('خدمات اجرایی '!F:F,'summary-2'!A45,'خدمات اجرایی '!Q:Q) -> 0 | P46: تأیید مشاور
J47: =IF(M47=0,0,M47-G47) -> 0 | P47: تأیید کارفرما
...

Sheet summary-Adjustment
F1: پروژه رفع گلوگاه هاي ظرفيتي در امور زيربنايي راه آهن ج.ا.ا
A4: Rev | D4: Volume | F4: Doc. No | I4: Doc. Type | K4: Stu. Gro | M4: Sub. Proj | O4: Proj | Q4: کد مدرک
A5: =[1]Cover!A5 -> 00 | D5: =[1]Cover!C5 -> 01 | F5: =[1]Cover!E5 -> 025 | I5: =[1]Cover!G5 -> ST | K5: =[1]Cover!I5 -> ECO | M5: =[1]Cover!K5 -> 18 | O5: =[1]Cover!M5 -> 95210 | Q5: ="صفحه 4 از "&[1]Cover!S5 -> صفحه 4 از 24
A7: « خلاصه کارکرد صورت وضعیت موقت قطعی به تفکیک فصول - مشمول تعديل »
A9: کارفرما: | D9: شرکت راه آهن ج.ا.ا | H9: مشاور: | K9: مهندسین مشاور صحن بوستان | O9: پيمانکار: | R9: مشارکت تكنيك پل رود كنكاوان معدن شيراز
A10: عنوان قرارداد: | D10: پروژه احداث خط دوم راه آهن محور مشك - سيستان به روش EPC غيرصنعتي | H10: شماره قرارداد: | K10: 400/66891/ي | O10: تاریخ قرارداد: | R10: 1393/11/20
A11: فهرست بهای رشته: | D11: راه، راه آهن و باند فرودگاه | H11: صورت وضعیت از تاريخ: | K11: 1396/12/11 | O11: تا تاريخ: | R11: ='خلاصه مالي صورت وضعیت'!E5 -> 1399/06/02
A13: فصل | B13: شرح فصل | G13: مبلغ کارکرد (ريال) | P13: کارکرد | S13: تعديل با استفاده از شاخص
G14: تا دوره قبل-کارکرد 15 | J14: اين دوره قطعی | M14: تجمعي تاکنون
A15: - | B15: مقدمات لازم جهت فعاليتهاي اجرايي +کارهای اضافه | G15: ='summary-2'!G30:I30 -> 5.9802009e+09 | J15: =IF(M15=0,0,M15-G15) -> 4.7484336e+10 | M15: ='خلاصه مالي صورت وضعیت'!G29+'خلاصه مالي صورت وضعیت'!G10 -> 53464537290 | P15: درخواست پیمانکار | S15: رشته اي فهرست بهاي راه، راه آهن و باند فرودگاه
G16: ='summary-2'!G31:I31 -> 5.8796128e+09 | J16: =IF(M16=0,0,M16-G16) -> 0 | M16: ='summary-2'!M31:O31 -> 0 | P16: تأیید مشاور
J17: =IF(M17=0,0,M17-G17) -> 0 | P17: تأیید کارفرما
A18: - | B18: تجهیز و برچیدن کارگاه | G18: ='summary-2'!G24:I24 -> 4.5144889e+10 | J18: =IF(M18=0,0,M18-G18) -> 1.2334015e+10 | M18: ='خلاصه مالي صورت وضعیت'!G12+'خلاصه مالي صورت وضعیت'!G13+'خلاصه مالي صورت وضعیت'!G31+'خلاصه مالي صورت وضعیت'!G32 -> 5.7478903e+10 | P18: درخواست پیمانکار | S18: ميانگين رشته اي فهرست بهاي راه، راه آهن و باند فرودگاه و فهرست بهاي ابنيه
G19: ='summary-2'!G25:I25 -> 3.4458004e+10 | J19: =IF(M19=0,0,M19-G19) -> 0 | M19: ='summary-2'!M25:O25 -> 0 | P19: تأیید مشاور
J20: =IF(M20=0,0,M20-G20) -> 0 | P20: تأیید کارفرما
A21: 1 | B21: عملیات تخریب | J21: =IF(M21=0,0,M21-G21) -> 0 | M21: ='summary-2'!M33 -> 0 | P21: درخواست پیمانکار | S21: فصل يك فهرست بهاي راه، راه آهن و باند فرودگاه
J22: =IF(M22=0,0,M22-G22) -> 0 | M22: ='summary-2'!M34 -> 0 | P22: تأیید مشاور
J23: =IF(M23=0,0,M23-G23) -> 0 | M23: ='summary-2'!M35 -> 0 | P23: تأیید کارفرما
A24: 2 | B24: عملیات خاکی با دست | J24: =IF(M24=0,0,M24-G24) -> 0 | M24: ='summary-2'!M36 -> 0 | P24: درخواست پیمانکار | S24: فصل دو فهرست بهاي راه، راه آهن و باند فرودگاه
J25: =IF(M25=0,0,M25-G25) -> 0 | M25: ='summary-2'!M37 -> 0 | P25: تأیید مشاور
J26: =IF(M26=0,0,M26-G26) -> 0 | M26: ='summary-2'!M38 -> 0 | P26: تأیید کارفرما
A27: 3 | B27: عملیات خاکی با ماشین | G27: ='summary-2'!G39:I39 -> 1.4008374e+11 | J27: =IF(M27=0,0,M27-G27) -> 1.4517075e+08 | M27: ='summary-2'!M39 -> 1.4022891e+11 | P27: درخواست پیمانکار | S27: فصل سه فهرست بهاي راه، راه آهن و باند فرودگاه
G28: ='summary-2'!G40:I40 -> 1.3997263e+11 | J28: =IF(M28=0,0,M28-G28) -> 0 | M28: ='summary-2'!M40 -> 0 | P28: تأیید مشاور
J29: =IF(M29=0,0,M29-G29) -> 0 | M29: ='summary-2'!M41 -> 0 | P29: تأیید کارفرما
A30: 6 | B30: عملیات بنایی با سنگ | G30: ='summary-2'!G42:I42 -> 2.54245e+09 | J30: =IF(M30=0,0,M30-G30) -> 0 | M30: ='summary-2'!M42 -> 2.54245e+09 | P30: درخواست پیمانکار | S30: فصل شش فهرست بهاي راه، راه آهن و باند فرودگاه
G31: ='summary-2'!G43:I43 -> 2.4831261e+09 | J31: =IF(M31=0,0,M31-G31) -> 0 | M31: ='summary-2'!M43 -> 0 | P31: تأیید مشاور
J32: =IF(M32=0,0,M32-G32) -> 0 | M32: ='summary-2'!M44 -> 0 | P32: تأیید کارفرما
A33: 8 | B33: قالب بندی و چوب بست | G33: ='summary-2'!G45:I45 -> 25424499588 | J33: =IF(M33=0,0,M33-G33) -> 0 | M33: ='summary-2'!M45 -> 25424499588 | P33: درخواست پیمانکار | S33: فصل هشت فهرست بهاي راه، راه آهن و باند فرودگاه
G34: ='summary-2'!G46:I46 -> 2.5255003e+10 | J34: =IF(M34=0,0,M34-G34) -> 0 | M34: ='summary-2'!M46 -> 0 | P34: تأیید مشاور
J35: =IF(M35=0,0,M35-G35) -> 0 | M35: ='summary-2'!M47 -> 0 | P35: تأیید کارفرما
A36: 9 | B36: کارهای فولادی با میلگرد | G36: ='summary-2'!G48:I48 -> 50848999176 | J36: =IF(M36=0,0,M36-G36) -> 0 | M36: ='summary-2'!M48 -> 50848999176 | P36: درخواست پیمانکار | S36: فصل نه فهرست بهاي راه، راه آهن و باند فرودگاه
A37: 9 | B37: کارهای فولادی با میلگرد | G37: ='summary-2'!G49:I49 -> 5.0510006e+10 | J37: =IF(M37=0,0,M37-G37) -> 0 | M37: ='summary-2'!M49 -> 0 | P37: تأیید مشاور
A38: 9 | B38: کارهای فولادی با میلگرد | J38: =IF(M38=0,0,M38-G38) -> 0 | M38: ='summary-2'!M50 -> 0 | P38: تأیید کارفرما
A39: 11 | B39: کارهای فولادی سبک | G39: ='summary-2'!G51:I51 -> 6.3278755e+09 | J39: =IF(M39=0,0,M39-G39) -> 1.5819689e+09 | M39: ='summary-2'!M51 -> 7.9098443e+09 | P39: درخواست پیمانکار | S39: فصل یازده فهرست بهاي راه، راه آهن و باند فرودگاه
A40: 12 | B40: کارهای فولادی با میلگرد | G40: ='summary-2'!G52:I52 -> 5.2732295e+08 | J40: =IF(M40=0,0,M40-G40) -> 0 | M40: ='summary-2'!M52 -> 0 | P40: تأیید مشاور
A41: 12 | B41: کارهای فولادی با میلگرد | J41: =IF(M41=0,0,M41-G41) -> 0 | M41: ='summary-2'!M53 -> 0 | P41: تأیید کارفرما
A42: 12 | B42: بتن درجا | G42: ='summary-2'!G54:I54 -> 1.6102183e+10 | J42: =IF(M42=0,0,M42-G42) -> 0 | M42: ='summary-2'!M54 -> 1.6102183e+10 | P42: درخواست پیمانکار | S42: فصل دوازده فهرست بهاي راه، راه آهن و باند فرودگاه
A43: 12 | B43: بتن درجا | G43: ='summary-2'!G55:I55 -> 1.6068284e+10 | J43: =IF(M43=0,0,M43-G43) -> 0 | M43: ='summary-2'!M55 -> 0 | P43: تأیید مشاور
A44: 12 | B44: بتن درجا | J44: =IF(M44=0,0,M44-G44) -> 0 | M44: ='summary-2'!M56 -> 0 | P44: تأیید کارفرما
A45: 13 | B45: بتن پیش ساخته | G45: ='summary-2'!G57:I57 -> 8.8591328e+10 | J45: =IF(M45=0,0,M45-G45) -> -4.3537841e+10 | M45: ='summary-2'!M57 -> 4.5053487e+10 | P45: درخواست پیمانکار | S45: فصل سيزده فهرست بهاي راه، راه آهن و باند فرودگاه
...

Sheet خلاصه متره کارکرد
D1: کارفرما: | E1: راه‏آهن جمهوری اسلامی ایران | K1: عنوان قرارداد: | L1: طراحی، تأمین و اجرای دو خطه کردن راه‏آهن (زیرسازی، پل‏سازی، روسازی) محور مشك-سيستان
D2: مشاور طرح: | E2: مهندسین مشاور صحن بوستان
D3: مشارکت: | E3: مشاركت تكنيك-پل‏رود-کنکاوان معدن شیراز | K3: شماره و تاریخ ابلاغ قرارداد: | L3: 400/66891/ی مورخ 93/11/20
D4: صورت‏وضعیت شماره: | E4: قطعی | J4: مبلغ قرارداد (ریال): | L4: 1197477151532
D5: تاریخ صورت‏وضعیت: | E5: 1399/06/02
A6: خلاصه متره کارکرد قطعی
A8: ردیف | B8: شرح | C8: کیلومتر شروع | D8: کیلومتر پایان | E8: طول(m) | F8: تعداد تراورس مورد نیاز | G8: بالاست مرحله اول اجراشده | H8: تعداد تراورس اجراشده | I8: طول ریل ریسه شده (m) | J8: درصد بالاست اجرا شده | K8: درصد تراورس اجرا شده | L8: درصد ریل ریسه شده | M8: توضیحات
A9: 1 | B9: بلاک خیر آباد-سیستان | C9: 509330 | D9: 524412 | E9: =D9-C9 -> 15082 | F9: =ROUND(E9/0.6,0) -> 25137 | G9: =E9-40-50-50-50-50-5635 -> 9207 | H9: 0 | J9: =G9/E9*100 -> 61.04628 | K9: =H9/F9*100 -> 0 | L9: =I9/E9*100 -> 0
A10: 2 | B10: ایستگاه خیر آباد | C10: =D9 -> 524412 | D10: 525828 | E10: =D10-C10 -> 1416 | F10: =ROUND(E10/0.6,0) -> 2360 | G10: =E10-20 -> 1396 | H10: 0 | J10: =G10/E10*100 -> 98.587571 | K10: =H10/F10*100 -> 0 | L10: =I10/E10*100 -> 0
A11: 3 | B11: بلاک هرند-خیر آباد | C11: =D10 -> 525828 | D11: 540260 | E11: =D11-C11 -> 14432 | F11: =ROUND(E11/0.6,0) -> 24053 | G11: =E11-15-140-30-45-25-20-70-20-25-30-20-25-30-50-20-30-20-15-25-15-20-20-20-10-10-5-10-10-12 -> 13645 | H11: 0 | J11: =G11/E11*100 -> 94.54684 | K11: =H11/F11*100 -> 0 | L11: =I11/E11*100 -> 0
A12: 4 | B12: ایستگاه هرند | C12: =D11 -> 540260 | D12: 541629 | E12: =D12-C12 -> 1369 | F12: =ROUND(E12/0.6,0) -> 2282 | G12: =E12 -> 1369 | H12: 0 | I12: =105*25 -> 2625 | J12: =G12/E12*100 -> 100 | K12: =H12/F12*100 -> 0 | L12: =I12/E12*100/2 -> 95.8729 | M12: یکصد پنج شاخه 25 متری در ایستگاه هرند دپو شده بود
A13: 5 | B13: بلاک مشک -هرند | C13: =D12 -> 541629 | D13: 556118 | E13: =D13-C13 -> 14489 | F13: =ROUND(E13/0.6,0) -> 24148 | G13: =E13-20 -> 14469 | H13: 10982 | I13: =6575*2 -> 13150 | J13: =G13/E13*100 -> 99.861964 | K13: =H13/F13*100 -> 45.477886 | L13: =I13/E13/2*100 -> 45.379253 | M13: چیدمان تراورس هرند به سمت مشک
A14: 6 | B14: ایستگاه مشک | C14: =D13 -> 556118 | D14: 557478 | E14: =D14-C14 -> 1360 | F14: =ROUND(E14/0.6,0) -> 2267 | G14: =E14 -> 1360 | H14: 0 | J14: =G14/E14*100 -> 100 | K14: =H14/F14*100 -> 0 | L14: =I14/E14*100 -> 0
B15: جمع | C15: =C9 -> 509330 | D15: 557478 | E15: =SUM(E9:E14) -> 48148 | F15: =ROUND(E15/0.6,0) -> 80247 | G15: =SUM(G9:G14) -> 41446 | H15: =SUM(H9:H14) -> 10982 | I15: =SUM(I9:I14) -> 15775 | J15: =G15/E15*100 -> 86.080419 | K15: =H15/F15*100 -> 13.685247 | L15: =I15/E15/2*100 -> 16.381781
A16: با توجه به تطویل مدت پیمان تا تاریخ 1399/06/02 (بیش از 3/5 سال مازاد بر مدت اولیه پیمان) هزینه خدمات مستمر قید شده در ساختار شکست چندین برابر هزینه پیش بینی شده صورت گرفته است لذا درصد منظور شده در کارکرد با توجه به ساختار شکست پروژه 100% منظور شده است بنابراین درصد اعمال خدمات سازمان دهی وبرنامه ریزی،بیمه نامه ها،تجهیز اولیه کارگاه، تجهیز مستمر کارگاه ،خدمات طراحی ومهندسی پیش از اجرا وحین اجرا واختتامیه پروژه 100% منظور شده است .در مورد خدمات اجرایی فعالیت زیرسازی پروژه به صورت 100% انجام شده در خصوص آیتم کار اضافه در ساختار شکست این ردیف تخفیفی بود که پیمانکار در زمان انعقاد قرارداد به کارفرما داده بود به این شکل در صورتی که کارفرما کار اضافه ای در چارچوب قرارداد به پیمانکار ابلاغ نماید پیمانکار مکلف است تا این سقف نسبت به انجام آن اقدام نماید (بدون دریافت هیچ مبلغی ) در غیر اینصورت مبلغ فوق باید به پیمانکار پرداخت گردد با توجه به عدم ابلاغ کار اضافه در زمان قرارداد لذا مبلغ فوق باید به پیمانکار پرداخت گردد ،فعالیت های مربوط به روسازی براساس متره فوق انجام گرفته است (بر اساس برداشت کارگاهی مورخ 99/06/20 ) در خصوص خدمات تامین درصد مربوطه با توجه به انجام فعالیت براساس ساختار شکست منظور شده است.مدارک مربوطه در پیوست مدارک پشتیبان ارائه شده است.

Sheet خلاصه مالي صورت وضعیت
D1: کارفرما: | E1: راه‏آهن جمهوری اسلامی ایران | G1: عنوان قرارداد: | H1: طراحی، تأمین و اجرای دو خطه کردن راه‏آهن (زیرسازی، پل‏سازی، روسازی) محور مشك-سيستان
D2: مشاور طرح: | E2: مهندسین مشاور صحن بوستان
D3: مشارکت: | E3: مشاركت تكنيك-پل‏رود-کنکاوان معدن شیراز | G3: شماره و تاریخ ابلاغ قرارداد: | H3: 400/66891/ی مورخ 93/11/20
D4: صورت‏وضعیت شماره: | E4: قطعی | G4: مبلغ قرارداد (ریال): | H4: 1197477151532
D5: تاریخ صورت‏وضعیت: | E5: 1399/06/02
A6: ردیف | B6: W.B.S | C6: عنوان فعالیت | F6: تایید شده قبلی (کارکرد 15) | G6: پیمانکار-قطعی | H6: مشاور کارفرما | I6: توضیحات
A8: 1 | B8: 1 | C8: پروژه طراحی، تامین و اجرای دو خطه کردن راه‏آهن محور مشک–سیستان | F8: =SUM(F9,F14,F17,F22,F30) -> 5.7076291e+11 | G8: =SUM(G9,G14,G17,G22,G30) -> 6.9794725e+11 | H8: =SUM(H9,H14,H17,H22,H30) -> 0
A9: 2 | B9: 1.3 | C9: فعالیت‌های مقدماتی، برنامه‏ریزی و تجهيز كارگاه | F9: =SUM(F10:F13) -> 4.5633459e+10 | G9: =SUM(G10:G13) -> 6.1071335e+10 | H9: =SUM(H10:H13) -> 0
A10: 3 | B10: 1.3.1 | C10: مقدمات لازم جهت فعاليت هاي اجرايي | F10: ='سازمان دهی و برنامه ریزی پروژه'!I8 -> 5.8796128e+09 | G10: ='سازمان دهی و برنامه ریزی پروژه'!L8 -> 5987385758 | H10: ='سازمان دهی و برنامه ریزی پروژه'!Q8 -> 0
A11: 4 | B11: 1.3.2 | C11: بيمه‌نامه‌ها | F11: ='بیمه نامه ها'!I8 -> 5295842703 | G11: ='بیمه نامه ها'!L8 -> 7.1848629e+09 | H11: ='بیمه نامه ها'!Q8 -> 0
A12: 5 | B12: 1.3.3 | C12: تجهیز اوليه کارگاه | F12: ='تجهیز کارگاه اولیه'!I8 -> 1.8759078e+10 | G12: ='تجهیز کارگاه اولیه'!L8 -> 20357111576 | H12: ='تجهیز کارگاه اولیه'!Q8 -> 0
A13: 6 | B13: 1.3.4 | C13: تجهيز مستمر كارگاه | F13: ='تجهیز کارگاه مستمر'!I8 -> 1.5698925e+10 | G13: ='تجهیز کارگاه مستمر'!L8 -> 2.7541974e+10 | H13: ='تجهیز کارگاه مستمر'!Q8 -> 0
A14: 7 | B14: 1.4 | C14: خدمات طراحي و مهندسی | F14: =SUM(F15:F16) -> 3.8974588e+10 | G14: =SUM(G15:G16) -> 5.9095497e+10 | H14: =SUM(H15:H16) -> 0
A15: 8 | B15: 1.4.1 | C15: خدمات طراحي و مهندسی پيش از اجرا | F15: ='خدمات طراحي مهندسي پیش از اجرا'!I8 -> 1.9214419e+10 | G15: ='خدمات طراحي مهندسي پیش از اجرا'!L8 -> 2.095585e+10 | H15: ='خدمات طراحي مهندسي پیش از اجرا'!Q8 -> 0
A16: 9 | B16: 1.4.2 | C16: خدمات مهندسی حین اجرا | F16: ='خدمات طراحي و مهندسي حین اجرا'!I8 -> 1.9760169e+10 | G16: ='خدمات طراحي و مهندسي حین اجرا'!L8 -> 3.8139647e+10 | H16: ='خدمات طراحي و مهندسي حین اجرا'!Q8 -> 0
A17: 10 | B17: 1.5 | C17: خدمات تامین | F17: =F18+F19+F20+F21 -> 1.2783398e+11 | G17: =G18+G19+G20+G21 -> 1.2554198e+11 | H17: =H18+H19+H20+H21 -> 0
A18: 11 | B18: 1.5.1 | C18: ريل | F18: ='خدمات تامین'!I9 -> 5.8196709e+10 | G18: ='خدمات تامین'!L9 -> 6.466301e+10 | H18: ='خدمات تامین'!Q9 -> 0
A19: 12 | B19: 1.5.2 | C19: سوزن | F19: ='خدمات تامین'!I16 -> 2.5147801e+10 | G19: ='خدمات تامین'!L16 -> 2.5147801e+10 | H19: ='خدمات تامین'!Q16 -> 0
A20: 13 | B20: 1.5.3 | C20: تراورس | F20: ='خدمات تامین'!I21 -> 4.1663448e+10 | G20: ='خدمات تامین'!L21 -> 3.5731171e+10 | H20: ='خدمات تامین'!Q21 -> 0
A21: 14 | B21: 1.5.4 | C21: ملحقات | F21: ='خدمات تامین'!I27 -> 2.8260202e+09 | G21: ='خدمات تامین'!L27 -> 0 | H21: ='خدمات تامین'!Q27 -> 0
A22: 15 | B22: 1.6 | C22: عملیات اجرایی | F22: =F23+F24+F25+F26+F27+F28+F29 -> 3.5832089e+11 | G22: =G23+G24+G25+G26+G27+G28+G29 -> 4.3786871e+11 | H22: =H23+H24+H25+H26+H27+H28+H29 -> 0
A23: 16 | B23: 1.6.1 | C23: بلوک مشک-هرند | F23: ='خدمات اجرایی '!I9 -> 1.0265534e+11 | G23: ='خدمات اجرایی '!L9 -> 1.1579914e+11 | H23: ='خدمات اجرایی '!Q9 -> 0
A24: 17 | B24: 1.6.2 | C24: ایستگاه مشک | F24: ='خدمات اجرایی '!I51 -> 1.5819677e+10 | G24: ='خدمات اجرایی '!L51 -> 1.7191313e+10 | H24: ='خدمات اجرایی '!Q51 -> 0
A25: 18 | B25: 1.6.3 | C25: بلوک هرند-خیرآباد | F25: ='خدمات اجرایی '!I78 -> 1.0433132e+11 | G25: ='خدمات اجرایی '!L78 -> 1.1247517e+11 | H25: ='خدمات اجرایی '!Q78 -> 0
A26: 19 | B26: 1.6.4 | C26: ایستگاه هرند | F26: ='خدمات اجرایی '!I120 -> 1.5847242e+10 | G26: ='خدمات اجرایی '!L120 -> 1.7649113e+10 | H26: ='خدمات اجرایی '!Q120 -> 0
A27: 20 | B27: 1.6.5 | C27: بلوک خیرآباد-سیستان | F27: ='خدمات اجرایی '!I147 -> 1.0380321e+11 | G27: ='خدمات اجرایی '!L147 -> 1.1006354e+11 | H27: ='خدمات اجرایی '!Q147 -> 0
A28: 21 | B28: 1.6.6 | C28: ایستگاه خیرآباد | F28: ='خدمات اجرایی '!I189 -> 1.5864102e+10 | G28: ='خدمات اجرایی '!L189 -> 1.7213265e+10 | H28: ='خدمات اجرایی '!Q189 -> 0
A29: 22 | B29: 1.6.7 | C29: کارهای اضافی | F29: ='خدمات اجرایی '!I216 -> 0 | G29: ='خدمات اجرایی '!L216 -> 47477151532 | H29: ='خدمات اجرایی '!Q216 -> 0
A30: 23 | B30: 1.7 | C30: اختتامیه پروژه | F30: =SUM(F31:F33) -> 0 | G30: =SUM(G31:G33) -> 1.4369726e+10 | H30: =SUM(H31:H33) -> 0
A31: 24 | B31: 1.7.1 | C31: تحويل موقت كل پروژه | F31: =اختتامیه!I9 -> 0 | G31: =اختتامیه!L9 -> 5.9873858e+09 | H31: =اختتامیه!Q9 -> 0
A32: 25 | B32: 1.7.2 | C32: برچيدن كارگاه | F32: =اختتامیه!I10 -> 0 | G32: =اختتامیه!L10 -> 3.5924315e+09 | H32: =اختتامیه!Q10 -> 0
A33: 26 | B33: 1.7.3 | C33: بيمه مهندسي سازه‌هاي تكميل شده | F33: =اختتامیه!I11 -> 0 | G33: =اختتامیه!L11 -> 4.7899086e+09 | H33: =اختتامیه!Q11 -> 0
F36: 1197477151532 | G36: 1197477151532 | H36: مبلغ پروژه
F37: 47477151532 | G37: 47477151532 | H37: کار اضافه
F38: =F36-F37 -> 1150000000000 | G38: =G36-G37 -> 1150000000000
F39: =F8/F38*F37 -> 2.356365e+10 | G39: =G8/G38*G37 -> 2.8814389e+10 | H39: مبلغ کار اضافه این کارکرد

Sheet جمع بندي صورت وضعیت
H1: کارفرما: | I1: راه آهن جمهوری اسلامی ایران | L1: عنوان قرارداد: | M1: طراحی،تامین و اجرای دوخطه کردن راه آهن(زیرسازی،پل سازی و روسازی)محور ساسان شبنم
H2: مشاور طرح: | I2: مهندسین مشاور صحن بوستان
H3: مشارکت: | I3: اهورامهرگستران-جهادنصرحمزه طرح نوانديشان-گمانه كاو | L3: شماره و تاریخ ابلاغ قرارداد: | M3: 400/71523/ي مورخ 93/12/10
H4: صورت وضعبت شماره: | I4: 2 | L4: مبلغ قرارداد: | M4: 768000000000
H5: تاریخ صورت وضعیت: | I5: 94/0.5/17
A6: ردیف | B6: W.B.S | C6: عنوان فعالیت | D6: هزینه کامل (ريال) | E6: وزن کامل (%) | F6: واحد | G6: گروه مشارکت | J6: مشاور زیر بنایی | M6: کارفرما
G7: درصد پیشرفت از (کل) | H7: درصد پیشرفت وزنی | I7: مبلغ(ریال) | J7: درصد پیشرفت از (کل) | K7: درصد پیشرفت وزنی | L7: مبلغ(ریال) | M7: درصد پیشرفت از (کل) | N7: درصد پیشرفت وزنی | O7: مبلغ(ریال)
A8: 1 | B8: 1 | C8: پروژه طراحی، تامین و اجرای دو خطه کردن راه آهن محور ساسان – شبنم | D8: =D11+D16+D19+D20+D21 -> 768000000000 | E8: =E11+E16+E19+E20+E21 -> 100 | I8: =SUM(I11,I16,I19,I20,I21) -> #REF! | L8: =SUM(L11,L16,L19,L20,L21) -> #REF! | O8: =SUM(O11,O16,O19,O20,O21) -> #REF!
A9: 2 | B9: 1.1 | C9: آغاز | D9: 0 | E9: 0
A10: 3 | B10: 1.2 | C10: تحویل زمین | D10: 0 | E10: 0
A11: 4 | B11: 1.3 | C11: فعالیت‌های مقدماتی، برنامه ریزی و تجهيز كارگاه | D11: =E11*$M$4/100 -> 3.6096e+10 | E11: =SUM(E12:E15) -> 4.7 | G11: =(G12*$E$12+G13*$E$13+G14*$E$14+G15*$E$15)/$E$11 -> 1 | H11: =G11*E11 -> 4.7 | I11: =G11*D11 -> 3.6096e+10 | J11: =(J12*$E$12+J13*$E$13+J14*$E$14+J15*$E$15)/$E$11 -> 0 | K11: =J11*E11 -> 0 | L11: =J11*D11 -> 0 | M11: =(M12*$E$12+M13*$E$13+M14*$E$14+M15*$E$15)/$E$11 -> #REF! | N11: =M11*E11 -> #REF! | O11: =M11*D11 -> #REF!
A12: 5 | B12: 1.3.1 | C12: سازماندهي و برنامه ریزی پروژه | D12: =E12*$M$4/100 -> 3840000000 | E12: 0.5 | G12: ='سازمان دهی و برنامه ریزی پروژه'!J8 -> 1 | H12: ='سازمان دهی و برنامه ریزی پروژه'!K8 -> 0.005 | I12: ='سازمان دهی و برنامه ریزی پروژه'!L8 -> 5987385758 | J12: ='سازمان دهی و برنامه ریزی پروژه'!O8 -> 0 | K12: ='سازمان دهی و برنامه ریزی پروژه'!P8 -> 0 | L12: ='سازمان دهی و برنامه ریزی پروژه'!Q8 -> 0 | M12: ='سازمان دهی و برنامه ریزی پروژه'!#REF! -> #REF! | N12: ='سازمان دهی و برنامه ریزی پروژه'!#REF! -> #REF! | O12: ='سازمان دهی و برنامه ریزی پروژه'!S8 -> 0
A13: 6 | B13: 1.3.2 | C13: بيمه‌نامه‌ها | D13: =E13*$M$4/100 -> 4608000000 | E13: 0.6 | G13: ='بیمه نامه ها'!J$8 -> 1 | H13: ='بیمه نامه ها'!K8 -> 0.006 | I13: ='بیمه نامه ها'!L8 -> 7.1848629e+09 | J13: ='بیمه نامه ها'!O$8 -> 0 | K13: ='بیمه نامه ها'!P$8 -> 0 | L13: ='بیمه نامه ها'!Q$8 -> 0 | M13: ='بیمه نامه ها'!#REF! -> #REF! | N13: ='بیمه نامه ها'!#REF! -> #REF! | O13: ='بیمه نامه ها'!S$8 -> 0
A14: 7 | B14: 1.3.3 | C14: تجهیز اوليه کارگاه | D14: =E14*$M$4/100 -> 9216000000 | E14: 1.2 | G14: ='تجهیز کارگاه اولیه'!J8 -> 1 | H14: ='تجهیز کارگاه اولیه'!K8 -> 0.017 | I14: ='تجهیز کارگاه اولیه'!L8 -> 20357111576 | J14: ='تجهیز کارگاه اولیه'!O8 -> 0 | K14: ='تجهیز کارگاه اولیه'!P8 -> 0 | L14: ='تجهیز کارگاه اولیه'!Q8 -> 0 | M14: ='تجهیز کارگاه اولیه'!#REF! -> #REF! | N14: ='تجهیز کارگاه اولیه'!#REF! -> #REF! | O14: ='تجهیز کارگاه اولیه'!S8 -> 0
A15: 8 | B15: 1.3.4 | C15: تجهيز مستمر كارگاه | D15: =E15*$M$4/100 -> 18432000000 | E15: 2.4 | G15: ='تجهیز کارگاه مستمر'!J8 -> 1 | H15: ='تجهیز کارگاه مستمر'!K8 -> 0.023 | I15: ='تجهیز کارگاه مستمر'!L8 -> 2.7541974e+10 | J15: ='تجهیز کارگاه مستمر'!O$8 -> 0 | K15: ='تجهیز کارگاه مستمر'!P$8 -> 0 | L15: ='تجهیز کارگاه مستمر'!Q$8 -> 0 | M15: ='تجهیز کارگاه مستمر'!#REF! -> #REF! | N15: ='تجهیز کارگاه مستمر'!#REF! -> #REF! | O15: ='تجهیز کارگاه مستمر'!S$8 -> 0
A16: 9 | B16: 1.4 | C16: خدمات طراحي و مهندسی | D16: =E16*$M$4/100 -> 8.1403491e+10 | E16: =E17+E18 -> 10.599413 | G16: =(G17*$E$17+G18*$E$18)/$E$16 -> 0.987 | H16: =G16*E16 -> 10.461621 | I16: =G16*D16 -> 8.0345246e+10 | J16: =(J17*$E$17+J18*$E$18)/$E$16 -> 0 | K16: =J16*E16 -> 0 | L16: =J16*D16 -> 0 | M16: =(M17*$E$17+M18*$E$18)/$E$16 -> #REF! | N16: =M16*E16 -> #REF! | O16: =M16*D16 -> #REF!
A17: 10 | B17: 1.4.1 | C17: خدمات طراحي و مهندسی پيش از اجرا | D17: =E17*$M$4/100 -> 2.8491222e+10 | E17: 3.7097945 | G17: ='خدمات طراحي مهندسي پیش از اجرا'!J8 -> 1 | H17: ='خدمات طراحي مهندسي پیش از اجرا'!K8 -> 0.0175 | I17: ='خدمات طراحي مهندسي پیش از اجرا'!L8 -> 2.095585e+10 | J17: ='خدمات طراحي مهندسي پیش از اجرا'!O8 -> 0 | K17: ='خدمات طراحي مهندسي پیش از اجرا'!P8 -> 0 | L17: ='خدمات طراحي مهندسي پیش از اجرا'!Q8 -> 0 | M17: ='خدمات طراحي مهندسي پیش از اجرا'!#REF! -> #REF! | N17: ='خدمات طراحي مهندسي پیش از اجرا'!#REF! -> #REF! | O17: ='خدمات طراحي مهندسي پیش از اجرا'!S8 -> 0
A18: 11 | B18: 1.4.2 | C18: خدمات مهندسی حین اجرا | D18: =E18*$M$4/100 -> 5.2912269e+10 | E18: 6.8896184 | G18: ='خدمات طراحي و مهندسي حین اجرا'!J$8 -> 0.98 | H18: ='خدمات طراحي و مهندسي حین اجرا'!K8 -> 0.03185 | I18: ='خدمات طراحي و مهندسي حین اجرا'!L8 -> 3.8139647e+10 | J18: ='خدمات طراحي و مهندسي حین اجرا'!O$8 -> 0 | K18: ='خدمات طراحي و مهندسي حین اجرا'!P$8 -> 0 | L18: ='خدمات طراحي و مهندسي حین اجرا'!Q$8 -> 0 | M18: ='خدمات طراحي و مهندسي حین اجرا'!#REF! -> #REF! | N18: ='خدمات طراحي و مهندسي حین اجرا'!#REF! -> #REF! | O18: ='خدمات طراحي و مهندسي حین اجرا'!S$8 -> 0
A19: 12 | B19: 1.5 | C19: خدمات تامین | D19: =E19*$M$4/100 -> 268804508978 | E19: 35.000587 | G19: ='خدمات تامین'!J$8 -> 0.27244992 | H19: ='خدمات تامین'!K8 -> 0.10483873 | I19: ='خدمات تامین'!L8 -> 1.2554198e+11 | J19: ='خدمات تامین'!O$8 -> 0 | K19: ='خدمات تامین'!P$8 -> 0 | L19: ='خدمات تامین'!Q$8 -> 0 | M19: ='خدمات تامین'!#REF! -> #REF! | N19: ='خدمات تامین'!#REF! -> #REF! | O19: ='خدمات تامین'!S$8 -> 0
A20: 13 | B20: 1.6 | C20: عملیات اجرایی | D20: =E20*$M$4/100 -> 369408000000 | E20: 48.1 | G20: =#REF! -> #REF! | H20: =#REF! -> #REF! | I20: =#REF! -> #REF! | J20: =#REF! -> #REF! | K20: =#REF! -> #REF! | L20: =#REF! -> #REF! | M20: =#REF! -> #REF! | N20: =#REF! -> #REF! | O20: =#REF! -> #REF!
A21: 14 | B21: 1.7 | C21: اختتامیه پروژه | D21: =E21*$M$4/100 -> 12288000000 | E21: =SUM(E22:E24) -> 1.6 | G21: =اختتامیه!J8 -> 1 | H21: =اختتامیه!K8 -> 0.012 | I21: =اختتامیه!L8 -> 1.4369726e+10 | J21: =اختتامیه!O8 -> 0 | K21: =اختتامیه!P8 -> 0 | L21: =اختتامیه!Q8 -> 0 | M21: =اختتامیه!#REF! -> #REF! | N21: =اختتامیه!#REF! -> #REF! | O21: =اختتامیه!S8 -> 0
A22: 15 | B22: 1.7.1 | C22: تحويل موقت كل پروژه | D22: =E22*$M$4/100 -> 6144000000 | E22: 0.8 | G22: =اختتامیه!J9 -> 1 | H22: =اختتامیه!K9 -> 0.005 | I22: =اختتامیه!L9 -> 5.9873858e+09 | J22: =اختتامیه!O9 -> 0 | K22: =اختتامیه!P9 -> 0 | L22: =اختتامیه!Q9 -> 0 | M22: =اختتامیه!#REF! -> #REF! | N22: =اختتامیه!#REF! -> #REF! | O22: =اختتامیه!S9 -> 0
A23: 16 | B23: 1.7.2 | C23: برچيدن كارگاه | D23: =E23*$M$4/100 -> 3072000000 | E23: 0.4 | G23: =اختتامیه!J10 -> 1 | H23: =اختتامیه!K10 -> 0.003 | I23: =اختتامیه!L10 -> 3.5924315e+09 | J23: =اختتامیه!O10 -> 0 | K23: =اختتامیه!P10 -> 0 | L23: =اختتامیه!Q10 -> 0 | M23: =اختتامیه!#REF! -> #REF! | N23: =اختتامیه!#REF! -> #REF! | O23: =اختتامیه!S10 -> 0
A24: 17 | B24: 1.7.3 | C24: بيمه مهندسي سازه‌هاي تكميل شده | D24: =E24*$M$4/100 -> 3072000000 | E24: 0.4 | G24: =اختتامیه!J11 -> 1 | H24: =اختتامیه!K11 -> 0.004 | I24: =اختتامیه!L11 -> 4.7899086e+09 | J24: =اختتامیه!O11 -> 0 | K24: =اختتامیه!P11 -> 0 | L24: =اختتامیه!Q11 -> 0 | M24: =اختتامیه!#REF! -> #REF! | N24: =اختتامیه!#REF! -> #REF! | O24: =اختتامیه!S11 -> 0
A25: 18 | B25: 1.8 | C25: پایان | D25: =E25*$M$4/100 -> 0 | E25: 0
G26: مهر و امضا گروه مشارکت اهورا مهر گستران | H26: مهر و امضا گروه مشارکت اهورا مهر گستران | I26: مهر و امضا گروه مشارکت اهورا مهر گستران | J26: مهر و امضا مشاور زیر بنایی مهندسین مشاور صحن بوستان | K26: مهر و امضا مشاور زیر بنایی مهندسین مشاور صحن بوستان | L26: مهر و امضا مشاور زیر بنایی مهندسین مشاور صحن بوستان | M26: تایید کارفرما | N26: تایید کارفرما | O26: تایید کارفرما

Sheet سازمان دهی و برنامه ریزی پروژه
D1: کارفرما: | E1: راه‏آهن جمهوری اسلامی ایران | O1: عنوان قرارداد: | Q1: طراحی، تأمین و اجرای دو خطه کردن راه‏آهن (زیرسازی، پل‏سازی، روسازی) محور مشك-سيستان
D2: مشاور طرح: | E2: مهندسین مشاور صحن بوستان
D3: مشارکت: | E3: مشاركت تكنيك-پل‏رود-کنکاوان معدن شیراز | O3: شماره و تاریخ ابلاغ قرارداد: | Q3: 400/66891/ی مورخ 93/11/20
D4: صورت‏وضعیت شماره: | E4: ='خلاصه مالي صورت وضعیت'!E4 -> قطعی | O4: مبلغ قرارداد (ریال): | Q4: ='خلاصه مالي صورت وضعیت'!H4:H5 -> 1197477151532
D5: تاریخ صورت‏وضعیت: | E5: ='خلاصه مالي صورت وضعیت'!E5 -> 1399/06/02
A6: ردیف | B6: W.B.S | C6: عنوان فعالیت | D6: هزینه کامل (ريال) | E6: وزن کامل (%) | F6: فصل مرتبط از فهرست بها | G6: تایید شده کارکرد قبلی (ص.و15) | J6: پیمانکار-قطعی | M6: توضیحات پیمانکار | O6: مشاور کارفرما | R6: توضیحات مشاور | T6: مدارك پشتيبان
D7: بر اساس ساختار شکست مصوب طی نامه شماره مورخ | G7: درصد پیشرفت از سرفصل (کل) | H7: درصد پیشرفت وزنی | I7: مبلغ (ریال) | J7: درصد پیشرفت از سرفصل (کل) | K7: درصد پیشرفت وزنی | L7: مبلغ (ریال) | O7: درصد پیشرفت از صد (کل) | P7: درصد پیشرفت وزنی | Q7: مبلغ (ریال)
A8: 1 | B8: 1.3.1 | C8: مقدمات لازم جهت فعاليت هاي اجرايي | D8: =SUM(D9:D17) -> 5987385758 | E8: =SUM(E9:E17) -> 0.005 | G8: =-I8/D8 -> -0.982 | H8: 0.00491 | I8: 5.8796128e+09 | J8: =L8/D8 -> 1 | K8: =SUM(K9:K17) -> 0.005 | L8: =SUM(L9:L17) -> 5987385758 | O8: =Q8/D8 -> 0 | P8: =Q8/Q4 -> 0 | Q8: =SUM(Q9:Q17) -> 0
A9: 2 | B9: 1.3.1.1 | C9: انتصاب و معرفی نماینده مشارکت (مدیر پروژه) | D9: =E9*$Q$4 -> 0 | E9: =CBS!D11 -> 0 | G9: 1 | H9: 0 | I9: 0 | J9: 1 | K9: =J9*E9 -> 0 | L9: =K9*$Q$4 -> 0 | P9: =O9*E9 -> 0 | Q9: =P9*$Q$4 -> 0
A10: 3 | B10: 1.3.1.2 | C10: تشکیل دفتر و سازمان کلیدی پروژه | D10: =E10*$Q$4 -> 4.19117e+08 | E10: =CBS!D12 -> 0.00035 | G10: 1 | H10: 0.00035 | I10: 4.19117e+08 | J10: 1 | K10: =J10*E10 -> 0.00035 | L10: =K10*$Q$4 -> 4.19117e+08 | P10: =O10*E10 -> 0 | Q10: =P10*$Q$4 -> 0
A11: 4 | B11: 1.3.1.3 | C11: تهیه و اعلام چارت سازمانی، شرح وظایف و حدود اختیارات و مسئولیت‏ها و شرایط احراز تیم پروژه | D11: =E11*$Q$4 -> 8.9810786e+08 | E11: =CBS!D13 -> 0.00075 | G11: 1 | H11: 0.00075 | I11: 8.9810786e+08 | J11: 1 | K11: =J11*E11 -> 0.00075 | L11: =K11*$Q$4 -> 8.9810786e+08 | P11: =O11*E11 -> 0 | Q11: =P11*$Q$4 -> 0
A12: 5 | B12: 1.3.1.4 | C12: تشکیل و تعریف نظام مدیریت پروژه، تهیه و ارسال ویرایش اول برنامه زمان‏بندی و ساختار شکست هزینه و سایر مدارک مرتبط برنامه‏ریزی | D12: =E12*$Q$4 -> 1.5567203e+09 | E12: =CBS!D14 -> 0.0013 | G12: 1 | H12: 0.0013 | I12: 1.5567203e+09 | J12: 1 | K12: =J12*E12 -> 0.0013 | L12: =K12*$Q$4 -> 1.5567203e+09 | P12: =O12*E12 -> 0 | Q12: =P12*$Q$4 -> 0
A13: 6 | B13: 1.3.1.5 | C13: برنامه‏ریزی و تعیین مشخصات و فهرست کامل اقدامات تجهیز کارگاه به همراه نقشه جانمایی | D13: =E13*$Q$4 -> 5.9873858e+08 | E13: =CBS!D15 -> 0.0005 | G13: 1 | H13: 0.0005 | I13: 5.9873858e+08 | J13: 1 | K13: =J13*E13 -> 0.0005 | L13: =K13*$Q$4 -> 5.9873858e+08 | P13: =O13*E13 -> 0 | Q13: =P13*$Q$4 -> 0
A14: 7 | B14: 1.3.1.6 | C14: تهیه و ارسال گردش فعالیتها و روابط بین مشارکت، مشاور و کارفرما (Coordination Procedure) | D14: =E14*$Q$4 -> 3.5924315e+08 | E14: =CBS!D16 -> 0.0003 | G14: 1 | H14: 0.0003 | I14: 3.5924315e+08 | J14: 1 | K14: =J14*E14 -> 0.0003 | L14: =K14*$Q$4 -> 3.5924315e+08 | P14: =O14*E14 -> 0 | Q14: =P14*$Q$4 -> 0
A15: 8 | B15: 1.3.1.7 | C15: تهیه و ارسال روش‏های اجرایی و دستورالعمل‏های کاری شامل: QA ،QC ،HSE ،5S و … | D15: =E15*$Q$4 -> 1.7962157e+09 | E15: =CBS!D17 -> 0.0015 | G15: 1 | H15: 0.0015 | I15: 1.7962157e+09 | J15: 1 | K15: =J15*E15 -> 0.0015 | L15: =K15*$Q$4 -> 1.7962157e+09 | P15: =O15*E15 -> 0 | Q15: =P15*$Q$4 -> 0
A16: 9 | B16: 1.3.1.8 | C16: تهیه و ارسال لیست کامل مدارک پیمانکار | D16: =E16*$Q$4 -> 3.5924315e+08 | E16: =CBS!D18 -> 0.0003 | G16: 0.7 | H16: 0.00021 | I16: 2.514702e+08 | J16: 1 | K16: =J16*E16 -> 0.0003 | L16: =K16*$Q$4 -> 3.5924315e+08 | M16: لیست مدارک به مشاور ارسال شده است | P16: =O16*E16 -> 0 | Q16: =P16*$Q$4 -> 0
A17: 10 | B17: 1.3.1.9 | C17: پایان سازمان‏دهی و برنامه‏ریزی مقدماتی پروژه | D17: =E17*$Q$4 -> 0 | E17: =CBS!D19 -> 0 | G17: 0 | H17: 0 | I17: 0 | K17: =J17*E17 -> 0 | L17: =K17*$Q$4 -> 0 | P17: =O17*E17 -> 0 | Q17: =P17*$Q$4 -> 0

Sheet بیمه نامه ها
D1: کارفرما: | E1: راه‏آهن جمهوری اسلامی ایران | O1: عنوان قرارداد: | Q1: طراحی، تأمین و اجرای دو خطه کردن راه‏آهن (زیرسازی، پل‏سازی، روسازی) محور مشك-سيستان
D2: مشاور طرح: | E2: مهندسین مشاور صحن بوستان
D3: مشارکت: | E3: مشاركت تكنيك-پل‏رود-کنکاوان معدن شیراز | O3: شماره و تاریخ ابلاغ قرارداد: | Q3: 400/66891/ی مورخ 93/11/20
D4: صورت‏وضعیت شماره: | E4: ='خلاصه مالي صورت وضعیت'!E4 -> قطعی | O4: مبلغ قرارداد (ریال): | Q4: ='خلاصه مالي صورت وضعیت'!H4:H5 -> 1197477151532
D5: تاریخ صورت‏وضعیت: | E5: ='خلاصه مالي صورت وضعیت'!E5 -> 1399/06/02
A6: ردیف | B6: W.B.S | C6: عنوان فعالیت | D6: هزینه کامل (ريال) | E6: وزن کامل (%) | F6: فصل مرتبط از فهرست بها | G6: تایید شده کارکرد قبلی (ص.و15) | J6: پیمانکار-قطعی | M6: توضیحات پیمانکار | O6: مشاور کارفرما | R6: توضیحات مشاور | T6: مدارك پشتيبان
D7: بر اساس ساختار شکست مصوب طی نامه شماره مورخ | G7: درصد پیشرفت از سرفصل (کل) | H7: درصد پیشرفت وزنی | I7: مبلغ (ریال) | J7: درصد پیشرفت از سرفصل (کل) | K7: درصد پیشرفت وزنی | L7: مبلغ (ریال) | O7: درصد پیشرفت از صد (کل) | P7: درصد پیشرفت وزنی | Q7: مبلغ (ریال)
A8: 1 | B8: 1.3.2 | C8: بيمه‌نامه‌ها | D8: =E8*$Q$4 -> 7.1848629e+09 | E8: =SUM(E9:E12) -> 0.006 | G8: ='[2]بیمه نامه ها'!J8 -> 0.73708333 | H8: ='[2]بیمه نامه ها'!K8 -> 0.0044225 | I8: ='[2]بیمه نامه ها'!L8 -> 5295842703 | J8: =L8/D8 -> 1 | K8: =SUM(K9:K12) -> 0.006 | L8: =SUM(L9:L12) -> 7.1848629e+09 | M8: کلیه بیمه نامه در طول مدت اولیه پروژه وچند سال بعد از آن ارائه شده است | O8: =(O9*$E$9+O10*$E$10+O11*$E$11+O12*$E$12)/E8 -> 0 | P8: =SUM(P9:P12) -> 0 | Q8: =SUM(Q9:Q12) -> 0
A9: 2 | B9: 1.3.2.1 | C9: ارائه بيمه تمام خطر پيمانكاري و اخذ تاييد مشاور | D9: =E9*$Q$4 -> 1.1974772e+09 | E9: =CBS!F21 -> 0.001 | G9: ='[2]بیمه نامه ها'!J9 -> 0.56 | H9: ='[2]بیمه نامه ها'!K9 -> 0.00056 | I9: ='[2]بیمه نامه ها'!L9 -> 6.705872e+08 | J9: 1 | K9: =J9*E9 -> 0.001 | L9: =K9*$Q$4 -> 1.1974772e+09 | P9: =O9*E9 -> 0 | Q9: =O9*D9 -> 0
A10: 3 | B10: 1.3.2.2 | C10: ارائه بيمه مسئوليت و اخذ تاييد مشاور | D10: =E10*$Q$4 -> 1.1974772e+09 | E10: =CBS!F22 -> 0.001 | G10: ='[2]بیمه نامه ها'!J10 -> 0.7 | H10: ='[2]بیمه نامه ها'!K10 -> 0.0007 | I10: ='[2]بیمه نامه ها'!L10 -> 8.3823401e+08 | J10: 1 | K10: =J10*E10 -> 0.001 | L10: =K10*$Q$4 -> 1.1974772e+09 | P10: =O10*E10 -> 0 | Q10: =O10*D10 -> 0
A11: 4 | B11: 1.3.2.3 | C11: تاييد بيمه‌هاي تمام خطر و مسئوليت توسط كارفرما | D11: =E11*$Q$4 -> 1.1974772e+09 | E11: =CBS!F23 -> 0.001 | G11: ='[2]بیمه نامه ها'!J11 -> 0.6125 | H11: ='[2]بیمه نامه ها'!K11 -> 0.0006125 | I11: ='[2]بیمه نامه ها'!L11 -> 7.3345476e+08 | J11: 1 | K11: =J11*E11 -> 0.001 | L11: =K11*$Q$4 -> 1.1974772e+09 | P11: =O11*E11 -> 0 | Q11: =O11*D11 -> 0
A12: 5 | B12: 1.3.2.4 | C12: پيگيري تا صدور بيمه‌نامه‌هاي فوق | D12: =E12*$Q$4 -> 3.5924315e+09 | E12: =CBS!F24 -> 0.003 | G12: ='[2]بیمه نامه ها'!J12 -> 0.85 | H12: ='[2]بیمه نامه ها'!K12 -> 0.00255 | I12: ='[2]بیمه نامه ها'!L12 -> 3.0535667e+09 | J12: 1 | K12: =J12*E12 -> 0.003 | L12: =K12*$Q$4 -> 3.5924315e+09 | P12: =O12*E12 -> 0 | Q12: =O12*D12 -> 0

Sheet تجهیز کارگاه اولیه
D1: کارفرما: | E1: راه‏آهن جمهوری اسلامی ایران | O1: عنوان قرارداد: | Q1: طراحی، تأمین و اجرای دو خطه کردن راه‏آهن (زیرسازی، پل‏سازی، روسازی) محور مشك-سيستان
D2: مشاور طرح: | E2: مهندسین مشاور صحن بوستان
D3: مشارکت: | E3: مشاركت تكنيك-پل‏رود-کنکاوان معدن شیراز | O3: شماره و تاریخ ابلاغ قرارداد: | Q3: 400/66891/ی مورخ 93/11/20
D4: صورت‏وضعیت شماره: | E4: ='خلاصه مالي صورت وضعیت'!E4 -> قطعی | O4: مبلغ قرارداد (ریال): | Q4: ='خلاصه مالي صورت وضعیت'!H4:H5 -> 1197477151532
D5: تاریخ صورت‏وضعیت: | E5: ='خلاصه مالي صورت وضعیت'!E5 -> 1399/06/02
A6: ردیف | B6: W.B.S | C6: عنوان فعالیت | D6: هزینه کامل (ريال) | E6: وزن کامل (%) | F6: فصل مرتبط از فهرست بها | G6: تایید شده کارکرد قبلی (ص.و15) | J6: پیمانکار-قطعی | M6: توضیحات پیمانکار | O6: مشاور کارفرما | R6: توضیحات مشاور | T6: مدارك پشتيبان
D7: بر اساس ساختار شکست مصوب طی نامه شماره مورخ | G7: درصد پیشرفت از سرفصل (کل) | H7: درصد پیشرفت وزنی | I7: مبلغ (ریال) | J7: درصد پیشرفت از سرفصل (کل) | K7: درصد پیشرفت وزنی | L7: مبلغ (ریال) | O7: درصد پیشرفت از صد (کل) | P7: درصد پیشرفت وزنی | Q7: مبلغ (ریال)
A8: 1 | B8: 1.3.3 | C8: تجهیز اوليه کارگاه | D8: =E8*$Q$4 -> 20357111576 | E8: =SUM(E9:E20) -> 0.017 | G8: 0.9215 | H8: 0.0156655 | I8: 1.8759078e+10 | J8: =L8/D8 -> 1 | K8: =SUM(K9:K20) -> 0.017 | L8: =SUM(L9:L20) -> 20357111576 | M8: تجهیز کارگاه همچنین تجهیز اولیه کارگاه بسیار فراتر از پروژه در همان ابتدای پروژه انجام گردیده است | O8: =Q8/D8 -> 0 | P8: =Q8/Q4 -> 0 | Q8: =SUM(Q9:Q20) -> 0
A9: 2 | B9: 1.3.3.1 | C9: آغاز عمليات تجهيز كارگاه | D9: =E9*$Q$4 -> 0 | E9: =CBS!F27 -> 0 | G9: 0 | H9: 0 | I9: 0 | J9: 1 | K9: =J9*E9 -> 0 | L9: =K9*$Q$4 -> 0 | P9: =O9*E9 -> 0 | Q9: =$Q$4*P9 -> 0
A10: 3 | B10: 1.3.3.2 | C10: تامين و تجهيز كامل محل سكونت عوامل پيمانكار، مشاور و كارفرما | D10: =E10*$Q$4 -> 3.0535667e+09 | E10: =CBS!F28 -> 0.00255 | G10: 1 | H10: 0.00255 | I10: 3.0535667e+09 | J10: 1 | K10: =J10*E10 -> 0.00255 | L10: =K10*$Q$4 -> 3.0535667e+09 | P10: =O10*E10 -> 0 | Q10: =$Q$4*P10 -> 0
A11: 4 | B11: 1.3.3.3 | C11: محوطه‌سازي و تامين راه‌هاي دسترسي، سرويس و ارتباطي | D11: =E11*$Q$4 -> 1.2214267e+09 | E11: =CBS!F29 -> 0.00102 | G11: 1 | H11: 0.00102 | I11: 1.2214267e+09 | J11: 1 | K11: =J11*E11 -> 0.00102 | L11: =K11*$Q$4 -> 1.2214267e+09 | P11: =O11*E11 -> 0 | Q11: =$Q$4*P11 -> 0
A12: 5 | B12: 1.3.3.4 | C12: تامين و تجهيز ساختمان‌هاي موقت اداري و دفاتر كار عوامل پيمانكار، مشاور و كارفرما و تجهيز آنها | D12: =E12*$Q$4 -> 3.0535667e+09 | E12: =CBS!F30 -> 0.00255 | G12: 1 | H12: 0.00255 | I12: 3.0535667e+09 | J12: 1 | K12: =J12*E12 -> 0.00255 | L12: =K12*$Q$4 -> 3.0535667e+09 | P12: =O12*E12 -> 0 | Q12: =$Q$4*P12 -> 0
A13: 6 | B13: 1.3.3.5 | C13: تامين آب، برق، سيستم مخابراتي، اينترنت و سوخت كارگاه | D13: =E13*$Q$4 -> 2.0357112e+09 | E13: =CBS!F31 -> 0.0017 | G13: 1 | H13: 0.0017 | I13: 2.0357112e+09 | J13: 1 | K13: =J13*E13 -> 0.0017 | L13: =K13*$Q$4 -> 2.0357112e+09 | P13: =O13*E13 -> 0 | Q13: =$Q$4*P13 -> 0
A14: 7 | B14: 1.3.3.6 | C14: اقدامات ايجاد و تامين و تجهيز ساختمان‌هاي پشتيباني، انبار و تعميرگاه | D14: =E14*$Q$4 -> 1.83214e+09 | E14: =CBS!F32 -> 0.00153 | G14: 1 | H14: 0.00153 | I14: 1.83214e+09 | J14: 1 | K14: =J14*E14 -> 0.00153 | L14: =K14*$Q$4 -> 1.83214e+09 | P14: =O14*E14 -> 0 | Q14: =$Q$4*P14 -> 0
A15: 8 | B15: 1.3.3.7 | C15: تامين و تجهيز آزمايشگاه | D15: =E15*$Q$4 -> 6.1071335e+08 | E15: =CBS!F33 -> 0.00051 | G15: 1 | H15: 0.00051 | I15: 6.1071335e+08 | J15: 1 | K15: =J15*E15 -> 0.00051 | L15: =K15*$Q$4 -> 6.1071335e+08 | P15: =O15*E15 -> 0 | Q15: =$Q$4*P15 -> 0
A16: 9 | B16: 1.3.3.8 | C16: محوطه‌سازي كارگاه عمومي و كارگاه روسازي | D16: =E16*$Q$4 -> 2.0357112e+09 | E16: =CBS!F34 -> 0.0017 | G16: 1 | H16: 0.0017 | I16: 2.0357112e+09 | J16: 1 | K16: =J16*E16 -> 0.0017 | L16: =K16*$Q$4 -> 2.0357112e+09 | P16: =O16*E16 -> 0 | Q16: =$Q$4*P16 -> 0
A17: 10 | B17: 1.3.3.9 | C17: اقدامات اجرايي براي تامين و نصب ماشين‌الات و تجهيزات و راه‌اندازي آنها | D17: =E17*$Q$4 -> 3.0535667e+09 | E17: =CBS!F35 -> 0.00255 | G17: 1 | H17: 0.00255 | I17: 3.0535667e+09 | J17: 1 | K17: =J17*E17 -> 0.00255 | L17: =K17*$Q$4 -> 3.0535667e+09 | P17: =O17*E17 -> 0 | Q17: =$Q$4*P17 -> 0
A18: 11 | B18: 1.3.3.10 | C18: اقدامات اوليه براي بهداشت، ايمني و حفاظت كار و محيط زيست | D18: =E18*$Q$4 -> 1.4249978e+09 | E18: =CBS!F36 -> 0.00119 | G18: 0.95 | H18: 0.0011305 | I18: 1.3537479e+09 | J18: 1 | K18: =J18*E18 -> 0.00119 | L18: =K18*$Q$4 -> 1.4249978e+09 | P18: =O18*E18 -> 0 | Q18: =$Q$4*P18 -> 0
A19: 12 | B19: 1.3.3.11 | C19: بيمه تجهيز كارگاه | D19: =E19*$Q$4 -> 2.0357112e+09 | E19: =CBS!F25 -> 0.0017 | G19: 0.25 | H19: 0.000425 | I19: 5.0892779e+08 | J19: 1 | K19: =J19*E19 -> 0.0017 | L19: =K19*$Q$4 -> 2.0357112e+09 | P19: =O19*E19 -> 0 | Q19: =$Q$4*P19 -> 0
A20: 13 | B20: 1.3.3.12 | C20: پايان تجهيز اوليه كارگاه | D20: =E20*$Q$4 -> 0 | E20: =CBS!F38 -> 0 | G20: 0 | H20: 0 | I20: 0 | K20: =J20*E20 -> 0 | L20: =K20*$Q$4 -> 0 | P20: =O20*E20 -> 0 | Q20: =$Q$4*P20 -> 0

Sheet تجهیز کارگاه مستمر
D1: کارفرما: | E1: راه‏آهن جمهوری اسلامی ایران | O1: عنوان قرارداد: | Q1: طراحی، تأمین و اجرای دو خطه کردن راه‏آهن (زیرسازی، پل‏سازی، روسازی) محور مشك-سيستان
D2: مشاور طرح: | E2: مهندسین مشاور صحن بوستان
D3: مشارکت: | E3: مشاركت تكنيك-پل‏رود-کنکاوان معدن شیراز | O3: شماره و تاریخ ابلاغ قرارداد: | Q3: 400/66891/ی مورخ 93/11/20
D4: صورت‏وضعیت شماره: | E4: ='خلاصه مالي صورت وضعیت'!E4 -> قطعی | O4: مبلغ قرارداد (ریال): | Q4: ='خلاصه مالي صورت وضعیت'!H4:H5 -> 1197477151532
D5: تاریخ صورت‏وضعیت: | E5: ='خلاصه مالي صورت وضعیت'!E5 -> 1399/06/02
A6: ردیف | B6: W.B.S | C6: عنوان فعالیت | D6: هزینه کامل (ريال) | E6: وزن کامل (%) | F6: فصل مرتبط از فهرست بها | G6: تایید شده کارکرد قبلی (ص.و15) | J6: پیمانکار-قطعی | M6: توضیحات پیمانکار | O6: مشاور کارفرما | R6: توضیحات مشاور | T6: مدارك پشتيبان
D7: بر اساس ساختار شکست مصوب طی نامه شماره مورخ | G7: درصد پیشرفت از سرفصل (کل) | H7: درصد پیشرفت وزنی | I7: مبلغ (ریال) | J7: درصد پیشرفت از سرفصل (کل) | K7: درصد پیشرفت وزنی | L7: مبلغ (ریال) | O7: درصد پیشرفت از صد (کل) | P7: درصد پیشرفت وزنی | Q7: مبلغ (ریال)
A8: 1 | B8: 1.3.4 | C8: تجهیز مستمر کارگاه | D8: =E8*$Q$4 -> 27541974485 | E8: =SUM(E9:E18) -> 0.023 | G8: 0.57 | H8: 0.01311 | I8: 1.5698925e+10 | J8: =L8/D8 -> 1 | K8: =SUM(K9:K18) -> 0.023 | L8: =SUM(L9:L18) -> 2.7541974e+10 | M8: تجهیز مستمر کارگاه در مدت اولیه پروژه و مدت تطویل یعنی حدود چهار سال بعد ازمدت اولیه پیمان انجام گردیده است لذا پیمانکار مستحق دریافت کل مبلغ تجهیز مستمرمی باشد | O8: =Q8/D8 -> 0 | P8: =SUM(P9:P18) -> 0 | Q8: =SUM(Q9:Q18) -> 0
A9: 2 | B9: 1.3.4.1 | C9: تداوم تامين و نگهداري اقامت‌گاه عوامل پيمانكار، مشاور و كارفرما | D9: =E9*$Q$4 -> 1.3770987e+09 | E9: =CBS!D39 -> 0.00115 | G9: 0.57 | H9: 0.0006555 | I9: 7.8494627e+08 | J9: 1 | K9: =J9*E9 -> 0.00115 | L9: =K9*$Q$4 -> 1.3770987e+09 | P9: =O9*E9 -> 0 | Q9: =$Q$4*P9 -> 0
A10: 3 | B10: 1.3.4.2 | C10: تامين و سرو خوراك عوامل پيمانكار، مشاور و كارفرما | D10: =E10*$Q$4 -> 8.2625923e+09 | E10: =CBS!D40 -> 0.0069 | G10: 0.57 | H10: 0.003933 | I10: 4.7096776e+09 | J10: 1 | K10: =J10*E10 -> 0.0069 | L10: =K10*$Q$4 -> 8.2625923e+09 | P10: =O10*E10 -> 0 | Q10: =$Q$4*P10 -> 0
A11: 4 | B11: 1.3.4.3 | C11: برقراري سرويس اياب و ذهاب كارگاه | D11: =E11*$Q$4 -> 6.8854936e+09 | E11: =CBS!D41 -> 0.00575 | G11: 0.57 | H11: 0.0032775 | I11: 3.9247314e+09 | J11: 1 | K11: =J11*E11 -> 0.00575 | L11: =K11*$Q$4 -> 6.8854936e+09 | P11: =O11*E11 -> 0 | Q11: =$Q$4*P11 -> 0
A12: 5 | B12: 1.3.4.4 | C12: بكاربستن مفاد نظام ايمني و حفاظت كار | D12: =E12*$Q$4 -> 2.7541974e+09 | E12: =CBS!D42 -> 0.0023 | G12: 0.57 | H12: 0.001311 | I12: 1.5698925e+09 | J12: 1 | K12: =J12*E12 -> 0.0023 | L12: =K12*$Q$4 -> 2.7541974e+09 | P12: =O12*E12 -> 0 | Q12: =$Q$4*P12 -> 0
A13: 6 | B13: 1.3.4.5 | C13: بكاربستن مفاد نظام بهداشت و حفظ محيط زيست | D13: =E13*$Q$4 -> 2.7541974e+09 | E13: =CBS!D43 -> 0.0023 | G13: 0.57 | H13: 0.001311 | I13: 1.5698925e+09 | J13: 1 | K13: =J13*E13 -> 0.0023 | L13: =K13*$Q$4 -> 2.7541974e+09 | P13: =O13*E13 -> 0 | Q13: =$Q$4*P13 -> 0
A14: 7 | B14: 1.3.4.6 | C14: تداوم بهره‌مندي كارگاه از آب، برق، گاز، سوخت، تلفن و اينترنت | D14: =E14*$Q$4 -> 4.1312962e+09 | E14: =CBS!D44 -> 0.00345 | G14: 0.57 | H14: 0.0019665 | I14: 2.3548388e+09 | J14: 1 | K14: =J14*E14 -> 0.00345 | L14: =K14*$Q$4 -> 4.1312962e+09 | P14: =O14*E14 -> 0 | Q14: =$Q$4*P14 -> 0
A15: 8 | B15: 1.3.4.7 | C15: رعايت نظم و انضباط در محوطه و محيط‌هاي اداري، كارگاهي و كارگري در انطباق با 5s | D15: =E15*$Q$4 -> 2.7541974e+08 | E15: =CBS!D45 -> 0.00023 | G15: 0.57 | H15: 0.0001311 | I15: 1.5698925e+08 | J15: 1 | K15: =J15*E15 -> 0.00023 | L15: =K15*$Q$4 -> 2.7541974e+08 | P15: =O15*E15 -> 0 | Q15: =$Q$4*P15 -> 0
A16: 9 | B16: 1.3.4.8 | C16: تداوم فعاليت‌هاي نت از طريق سنجش ميزان آماده بكار بودن ماشين‌آلات و تجهيزات | D16: =E16*$Q$4 -> 5.5083949e+08 | E16: =CBS!D46 -> 0.00046 | G16: 0.57 | H16: 0.0002622 | I16: 3.1397851e+08 | J16: 1 | K16: =J16*E16 -> 0.00046 | L16: =K16*$Q$4 -> 5.5083949e+08 | P16: =O16*E16 -> 0 | Q16: =$Q$4*P16 -> 0
A17: 10 | B17: 1.3.4.9 | C17: تداوم فعاليت‌هاي انبارداري و مديريت و حفاظت اقلام | D17: =E17*$Q$4 -> 2.7541974e+08 | E17: =CBS!D47 -> 0.00023 | G17: 0.57 | H17: 0.0001311 | I17: 1.5698925e+08 | J17: 1 | K17: =J17*E17 -> 0.00023 | L17: =K17*$Q$4 -> 2.7541974e+08 | P17: =O17*E17 -> 0 | Q17: =$Q$4*P17 -> 0
A18: 11 | B18: 1.3.4.10 | C18: تداوم حفظ و نگهداري دفاتر، محيط‌هاي اداري و پشتيباني در سطح استاندارد نور و تهويه و ... | D18: =E18*$Q$4 -> 2.7541974e+08 | E18: =CBS!D48 -> 0.00023 | G18: 0.57 | H18: 0.0001311 | I18: 1.5698925e+08 | J18: 1 | K18: =J18*E18 -> 0.00023 | L18: =K18*$Q$4 -> 2.7541974e+08 | P18: =O18*E18 -> 0 | Q18: =$Q$4*P18 -> 0

Sheet خدمات طراحي  مهندسي پیش از اجرا
D1: کارفرما: | E1: راه‏آهن جمهوری اسلامی ایران | O1: عنوان قرارداد: | Q1: طراحی، تأمین و اجرای دو خطه کردن راه‏آهن (زیرسازی، پل‏سازی، روسازی) محور مشك-سيستان
D2: مشاور طرح: | E2: مهندسین مشاور صحن بوستان
D3: مشارکت: | E3: مشاركت تكنيك-پل‏رود-کنکاوان معدن شیراز | O3: شماره و تاریخ ابلاغ قرارداد: | Q3: 400/66891/ی مورخ 93/11/20
D4: صورت‏وضعیت شماره: | E4: موقت 16 | O4: مبلغ قرارداد (ریال): | Q4: ='خلاصه مالي صورت وضعیت'!H4:H5 -> 1197477151532
D5: تاریخ صورت‏وضعیت: | E5: ='خلاصه مالي صورت وضعیت'!E5 -> 1399/06/02
A6: ردیف | B6: W.B.S | C6: عنوان فعالیت | D6: هزینه کامل (ريال) | E6: وزن کامل (%) | F6: فصل مرتبط از فهرست بها | G6: تایید شده کارکرد قبلی (ص.و15) | J6: پیمانکار-قطعی | M6: توضیحات پیمانکار | O6: مشاور کارفرما | R6: توضیحات مشاور | T6: مدارك پشتيبان
D7: بر اساس ساختار شکست مصوب طی نامه شماره مورخ | G7: درصد پیشرفت از سرفصل (کل) | H7: درصد پیشرفت وزنی | I7: مبلغ (ریال) | J7: درصد پیشرفت از سرفصل (کل) | K7: درصد پیشرفت وزنی | L7: مبلغ (ریال) | O7: درصد پیشرفت از صد (کل) | P7: درصد پیشرفت وزنی | Q7: مبلغ (ریال)
A8: 1 | B8: 1.4.1 | C8: خدمات طراحي و مهندسی پيش از اجرا | D8: =E8*$Q$4 -> 2.095585e+10 | E8: =SUM(E9:E15,E21,E27:E33,E39,E45:E51) -> 0.0175 | G8: 0.9169 | H8: 0.01604575 | I8: 1.9214419e+10 | J8: =L8/D8 -> 1 | K8: =SUM(K9:K15,K21,K27:K33,K39,K45:K51) -> 0.0175 | L8: =SUM(L9:L15,L21,L27:L33,L39,L45:L51) -> 2.095585e+10 | M8: کلیه خدمات مهندسی پیش از اجرا به اتمام رسیده است وکلیه مدارک مربوطه برای مشاور ارسال وتایید شده است | P8: =O8*E8 -> 0 | Q8: =P8*Q4 -> 0
A9: 2 | B9: 1.4.1.1 | C9: آغاز مطالعات مهندسي و طراحي | D9: =E9*$Q$4 -> 0 | E9: =CBS!D51 -> 0 | J9: 1 | K9: =J9*E9 -> 0 | L9: =K9*$Q$4 -> 0 | P9: =O9*E9 -> 0 | Q9: =P9*$Q$4 -> 0
A10: 3 | B10: 1.4.1.2 | C10: نقشه‌هاي توپوگرافی براساس برداشت مستقیم زمینی (1:2000 و1:500) | D10: =E10*$Q$4 -> 4.19117e+09 | E10: =CBS!D52 -> 0.0035 | J10: 1 | K10: =J10*E10 -> 0.0035 | L10: =K10*$Q$4 -> 4.19117e+09 | P10: =O10*E10 -> 0 | Q10: =P10*$Q$4 -> 0
A11: 4 | B11: 1.4.1.3 | C11: مطالعات اولیه شناخت و تحلیل وضع موجود | D11: =E11*$Q$4 -> 8.3823401e+08 | E11: =CBS!D53 -> 0.0007 | J11: 1 | K11: =J11*E11 -> 0.0007 | L11: =K11*$Q$4 -> 8.3823401e+08 | P11: =O11*E11 -> 0 | Q11: =P11*$Q$4 -> 0
A12: 5 | B12: 1.4.1.4 | C12: مطالعات طراحي رعايت سرعت طرح در طول محور و برآورد مقايسه‌اي مسير حركت در حريم | D12: =E12*$Q$4 -> 1.1974772e+09 | E12: =CBS!D54 -> 0.001 | J12: 1 | K12: =J12*E12 -> 0.001 | L12: =K12*$Q$4 -> 1.1974772e+09 | P12: =O12*E12 -> 0 | Q12: =P12*$Q$4 -> 0
A13: 6 | B13: 1.4.1.5 | C13: مطالعات اولیه ژئوتکنیک و برداشت وضع موجود | D13: =E13*$Q$4 -> 4.19117e+08 | E13: =CBS!D55 -> 0.00035 | J13: 1 | K13: =J13*E13 -> 0.00035 | L13: =K13*$Q$4 -> 4.19117e+08 | P13: =O13*E13 -> 0 | Q13: =P13*$Q$4 -> 0
A14: 7 | B14: 1.4.1.6 | C14: گزارش مطالعات تکمیلی ژئوتکنیک (صحرایی و آزمایشگاهی) | D14: =E14*$Q$4 -> 4.19117e+08 | E14: =CBS!D56 -> 0.00035 | J14: 1 | K14: =J14*E14 -> 0.00035 | L14: =K14*$Q$4 -> 4.19117e+08 | P14: =O14*E14 -> 0 | Q14: =P14*$Q$4 -> 0
A15: 8 | B15: 1.4.1.7 | C15: گزارش طراحی روسازی | D15: =E15*$Q$4 -> 1.1974772e+09 | E15: =SUM(E16:E20) -> 0.001 | K15: =SUM(K16:K20) -> 0.001 | L15: =SUM(L16:L20) -> 1.1974772e+09 | Q15: =SUM(Q16:Q20) -> 0
A16: 9 | B16: 1.4.1.7.1 | C16: بالاست | D16: =E16*$Q$4 -> 2.3949543e+08 | E16: =CBS!D58 -> 0.0002 | J16: 1 | K16: =J16*E16 -> 0.0002 | L16: =K16*$Q$4 -> 2.3949543e+08 | P16: =O16*E16 -> 0 | Q16: =P16*$Q$4 -> 0
A17: 10 | B17: 1.4.1.7.2 | C17: تراورس | D17: =E17*$Q$4 -> 2.3949543e+08 | E17: =CBS!D59 -> 0.0002 | J17: 1 | K17: =J17*E17 -> 0.0002 | L17: =K17*$Q$4 -> 2.3949543e+08 | P17: =O17*E17 -> 0 | Q17: =P17*$Q$4 -> 0
A18: 11 | B18: 1.4.1.7.3 | C18: پابند | D18: =E18*$Q$4 -> 2.3949543e+08 | E18: =CBS!D60 -> 0.0002 | J18: 1 | K18: =J18*E18 -> 0.0002 | L18: =K18*$Q$4 -> 2.3949543e+08 | P18: =O18*E18 -> 0 | Q18: =P18*$Q$4 -> 0
A19: 12 | B19: 1.4.1.7.4 | C19: ریل | D19: =E19*$Q$4 -> 2.3949543e+08 | E19: =CBS!D61 -> 0.0002 | J19: 1 | K19: =J19*E19 -> 0.0002 | L19: =K19*$Q$4 -> 2.3949543e+08 | P19: =O19*E19 -> 0 | Q19: =P19*$Q$4 -> 0
A20: 13 | B20: 1.4.1.7.5 | C20: سوزن | D20: =E20*$Q$4 -> 2.3949543e+08 | E20: =CBS!D62 -> 0.0002 | J20: 1 | K20: =J20*E20 -> 0.0002 | L20: =K20*$Q$4 -> 2.3949543e+08 | P20: =O20*E20 -> 0 | Q20: =P20*$Q$4 -> 0
A21: 14 | B21: 1.4.1.8 | C21: نقشه‏های اجرایی روسازی | D21: =E21*$Q$4 -> 1.1974772e+09 | E21: =SUM(E22:E26) -> 0.001 | K21: =SUM(K22:K26) -> 0.001 | L21: =SUM(L22:L26) -> 1.1974772e+09 | M21: کلیه خدمات مهندسی پیش از اجرا به اتمام رسیده است وکلیه مدارک مربوطه برای مشاور ارسال وتایید شده است | Q21: =SUM(Q22:Q26) -> 0
A22: 15 | B22: 1.4.1.8.1 | C22: بالاست | D22: =E22*$Q$4 -> 2.3949543e+08 | E22: =CBS!D64 -> 0.0002 | J22: 1 | K22: =J22*E22 -> 0.0002 | L22: =K22*$Q$4 -> 2.3949543e+08 | P22: =O22*E22 -> 0 | Q22: =P22*$Q$4 -> 0
A23: 16 | B23: 1.4.1.8.2 | C23: تراورس | D23: =E23*$Q$4 -> 2.3949543e+08 | E23: =CBS!D65 -> 0.0002 | J23: 1 | K23: =J23*E23 -> 0.0002 | L23: =K23*$Q$4 -> 2.3949543e+08 | P23: =O23*E23 -> 0 | Q23: =P23*$Q$4 -> 0
A24: 17 | B24: 1.4.1.8.3 | C24: پابند | D24: =E24*$Q$4 -> 2.3949543e+08 | E24: =CBS!D66 -> 0.0002 | J24: 1 | K24: =J24*E24 -> 0.0002 | L24: =K24*$Q$4 -> 2.3949543e+08 | P24: =O24*E24 -> 0 | Q24: =P24*$Q$4 -> 0
A25: 18 | B25: 1.4.1.8.4 | C25: ریل | D25: =E25*$Q$4 -> 2.3949543e+08 | E25: =CBS!D67 -> 0.0002 | J25: 1 | K25: =J25*E25 -> 0.0002 | L25: =K25*$Q$4 -> 2.3949543e+08 | P25: =O25*E25 -> 0 | Q25: =P25*$Q$4 -> 0
A26: 19 | B26: 1.4.1.8.5 | C26: سوزن | D26: =E26*$Q$4 -> 2.3949543e+08 | E26: =CBS!D68 -> 0.0002 | J26: 1 | K26: =J26*E26 -> 0.0002 | L26: =K26*$Q$4 -> 2.3949543e+08 | P26: =O26*E26 -> 0 | Q26: =P26*$Q$4 -> 0
A27: 20 | B27: 1.4.1.9 | C27: گزارش روش اجرای روسازی (خطوط و سوز‌ن‌ها) | D27: =E27*$Q$4 -> 1.1974772e+09 | E27: =CBS!D69 -> 0.001 | J27: 1 | K27: =J27*E27 -> 0.001 | L27: =K27*$Q$4 -> 1.1974772e+09 | P27: =O27*E27 -> 0 | Q27: =P27*$Q$4 -> 0
A28: 21 | B28: 1.4.1.10 | C28: گزارش طرح هندسی مسیر | D28: =E28*$Q$4 -> 5.9873858e+08 | E28: =CBS!D70 -> 0.0005 | J28: 1 | K28: =J28*E28 -> 0.0005 | L28: =K28*$Q$4 -> 5.9873858e+08 | P28: =O28*E28 -> 0 | Q28: =P28*$Q$4 -> 0
A29: 22 | B29: 1.4.1.11 | C29: نقشه‏های پلان طرح هندسی مسیر | D29: =E29*$Q$4 -> 2.3949543e+08 | E29: =CBS!D71 -> 0.0002 | J29: 1 | K29: =J29*E29 -> 0.0002 | L29: =K29*$Q$4 -> 2.3949543e+08 | P29: =O29*E29 -> 0 | Q29: =P29*$Q$4 -> 0
A30: 23 | B30: 1.4.1.12 | C30: نقشه‏های پروفیل طولی | D30: =E30*$Q$4 -> 2.3949543e+08 | E30: =CBS!D72 -> 0.0002 | J30: 1 | K30: =J30*E30 -> 0.0002 | L30: =K30*$Q$4 -> 2.3949543e+08 | P30: =O30*E30 -> 0 | Q30: =P30*$Q$4 -> 0
A31: 24 | B31: 1.4.1.13 | C31: نقشه‏های مقاطع عرضی | D31: =E31*$Q$4 -> 1.1974772e+09 | E31: =CBS!D73 -> 0.001 | J31: 1 | K31: =J31*E31 -> 0.001 | L31: =K31*$Q$4 -> 1.1974772e+09 | P31: =O31*E31 -> 0 | Q31: =P31*$Q$4 -> 0
A32: 25 | B32: 1.4.1.14 | C32: ارائه احجام عملیات خاکی براساس میخکوبی | D32: =E32*$Q$4 -> 3.5924315e+08 | E32: =CBS!D74 -> 0.0003 | J32: 1 | K32: =J32*E32 -> 0.0003 | L32: =K32*$Q$4 -> 3.5924315e+08 | P32: =O32*E32 -> 0 | Q32: =P32*$Q$4 -> 0
A33: 26 | B33: 1.4.1.15 | C33: گزارش محاسباتی پل‌های مسیر | D33: =E33*$Q$4 -> 1.1974772e+09 | E33: =CBS!D75 -> 0.001 | K33: =SUM(K34:K38) -> 0.001 | L33: =SUM(L34:L38) -> 1.1974772e+09 | Q33: =SUM(Q34:Q38) -> 0
A34: 27 | B34: 1.4.1.15.1 | C34: پلهای با دهانه 1 متر | D34: =E34*$Q$4 -> 2.3949543e+08 | E34: =CBS!D76 -> 0.0002 | J34: 1 | K34: =J34*E34 -> 0.0002 | L34: =K34*$Q$4 -> 2.3949543e+08 | P34: =O34*E34 -> 0 | Q34: =P34*$Q$4 -> 0
A35: 28 | B35: 1.4.1.15.2 | C35: پلهای با دهانه 2 متر | D35: =E35*$Q$4 -> 2.3949543e+08 | E35: =CBS!D77 -> 0.0002 | J35: 1 | K35: =J35*E35 -> 0.0002 | L35: =K35*$Q$4 -> 2.3949543e+08 | P35: =O35*E35 -> 0 | Q35: =P35*$Q$4 -> 0
A36: 29 | B36: 1.4.1.15.3 | C36: پلهای با دهانه 3 متر | D36: =E36*$Q$4 -> 2.3949543e+08 | E36: =CBS!D78 -> 0.0002 | J36: 1 | K36: =J36*E36 -> 0.0002 | L36: =K36*$Q$4 -> 2.3949543e+08 | P36: =O36*E36 -> 0 | Q36: =P36*$Q$4 -> 0
A37: 30 | B37: 1.4.1.15.4 | C37: پلهای با دهانه بیش از 3 متر | D37: =E37*$Q$4 -> 2.3949543e+08 | E37: =CBS!D79 -> 0.0002 | J37: 1 | K37: =J37*E37 -> 0.0002 | L37: =K37*$Q$4 -> 2.3949543e+08 | M37: کلیه خدمات مهندسی پیش از اجرا به اتمام رسیده است وکلیه مدارک مربوطه برای مشاور ارسال وتایید شده است | P37: =O37*E37 -> 0 | Q37: =P37*$Q$4 -> 0
A38: 31 | B38: 1.4.1.15.5 | C38: قطعات پیش‏ساخته دیوار برگشتی | D38: =E38*$Q$4 -> 2.3949543e+08 | E38: =CBS!D80 -> 0.0002 | J38: 1 | K38: =J38*E38 -> 0.0002 | L38: =K38*$Q$4 -> 2.3949543e+08 | P38: =O38*E38 -> 0 | Q38: =P38*$Q$4 -> 0
A39: 32 | B39: 1.4.1.16 | C39: نقشه‌های اجرایی پل‌های مسیر | D39: =E39*$Q$4 -> 2.9936929e+09 | E39: =CBS!D81 -> 0.0025 | K39: =SUM(K40:K44) -> 0.0025 | L39: =SUM(L40:L44) -> 2.9936929e+09 | Q39: =SUM(Q40:Q44) -> 0
A40: 33 | B40: 1.4.1.16.1 | C40: پلهای با دهانه 1 متر | D40: =E40*$Q$4 -> 5.9873858e+08 | E40: =CBS!D82 -> 0.0005 | J40: 1 | K40: =J40*E40 -> 0.0005 | L40: =K40*$Q$4 -> 5.9873858e+08 | P40: =O40*E40 -> 0 | Q40: =P40*$Q$4 -> 0
...

Sheet خدمات طراحي و مهندسي حین اجرا
D1: کارفرما: | E1: راه‏آهن جمهوری اسلامی ایران | O1: عنوان قرارداد: | Q1: طراحی، تأمین و اجرای دو خطه کردن راه‏آهن (زیرسازی، پل‏سازی، روسازی) محور مشك-سيستان
D2: مشاور طرح: | E2: مهندسین مشاور صحن بوستان
D3: مشارکت: | E3: مشاركت تكنيك-پل‏رود-کنکاوان معدن شیراز | O3: شماره و تاریخ ابلاغ قرارداد: | Q3: 400/66891/ی مورخ 93/11/20
D4: صورت‏وضعیت شماره: | E4: موقت 16 | O4: مبلغ قرارداد (ریال): | Q4: ='خلاصه مالي صورت وضعیت'!H4:H5 -> 1197477151532
D5: تاریخ صورت‏وضعیت: | E5: ='خلاصه مالي صورت وضعیت'!E5 -> 1399/06/02
A6: ردیف | B6: W.B.S | C6: عنوان فعالیت | D6: هزینه کامل (ريال) | E6: وزن کامل (%) | F6: فصل مرتبط از فهرست بها | G6: تایید شده کارکرد قبلی (ص.و15) | J6: پیمانکار-قطعی | M6: توضیحات پیمانکار | O6: مشاور کارفرما | R6: توضیحات مشاور | T6: مدارك پشتيبان
D7: بر اساس ساختار شکست مصوب طی نامه شماره مورخ | G7: درصد پیشرفت از سرفصل (کل) | H7: درصد پیشرفت وزنی | I7: مبلغ (ریال) | J7: درصد پیشرفت از سرفصل (کل) | K7: درصد پیشرفت وزنی | L7: مبلغ (ریال) | O7: درصد پیشرفت از صد (کل) | P7: درصد پیشرفت وزنی | Q7: مبلغ (ریال)
A8: 1 | B8: 1.4.2 | C8: خدمات مهندسی حین اجرا | D8: =E8*$Q$4 -> 3.8918007e+10 | E8: =SUM(E9:E15) -> 0.0325 | G8: 0.50773846 | H8: 0.0165015 | I8: 1.9760169e+10 | J8: =L8/D8 -> 0.98 | K8: =SUM(K9:K15) -> 0.03185 | L8: =SUM(L9:L15) -> 3.8139647e+10 | M8: با توجه به اینکه خدمات مهندسی حین اجرا در مدت اولیه پیمان ومدت تطویل ارائه شده است لذا از نظر این پیمانکار به جز ردیف 8 کلیه ردیف های مربوطه انجام شده است | O8: =(O9*$E$9+O10*$E$10+O11*$E$11+O12*$E$12+O13*$E$13+O14*$E$14+O15*$E$15)/$E$8 -> 0 | P8: =SUM(P9:P15) -> 0 | Q8: =SUM(Q9:Q15) -> 0
A9: 2 | B9: 1.4.2.1 | C9: استقرار عوامل نظارت كيفي كارگاه در انطباق با بند 2-3 پيوست شماره 1 قرارداد | D9: =E9*$Q$4 -> 1.365124e+10 | E9: =CBS!D95 -> 0.0114 | G9: 0.57 | H9: 0.006498 | I9: 7.7812065e+09 | J9: 1 | K9: =J9*E9 -> 0.0114 | L9: =K9*$Q$4 -> 1.365124e+10 | P9: =O9*$E9 -> 0 | Q9: =O9*$D9 -> 0
A10: 3 | B10: 1.4.2.2 | C10: انجام آزمايشات مورد لزوم حين اجرا و ارائه نتايج و گزارشات تحليلي | D10: =E10*$Q$4 -> 8.9810786e+09 | E10: =CBS!D96 -> 0.0075 | G10: 0.57 | H10: 0.004275 | I10: 5.1192148e+09 | J10: 1 | K10: =J10*E10 -> 0.0075 | L10: =K10*$Q$4 -> 8.9810786e+09 | P10: =O10*$E10 -> 0 | Q10: =O10*$D10 -> 0
A11: 4 | B11: 1.4.2.3 | C11: كاليبراسيون ادواري تجهيزات پايش و اندازه‌ گيري | D11: =E11*$Q$4 -> 7.7836015e+08 | E11: =CBS!D97 -> 0.00065 | G11: 0.57 | H11: 0.0003705 | I11: 4.4366528e+08 | J11: 1 | K11: =J11*E11 -> 0.00065 | L11: =K11*$Q$4 -> 7.7836015e+08 | P11: =O11*$E11 -> 0 | Q11: =O11*$D11 -> 0
A12: 5 | B12: 1.4.2.4 | C12: تهيه دستورالعمل‌ها و نقشه‌هاي فني كارگاهي | D12: =E12*$Q$4 -> 3.4726837e+09 | E12: =CBS!D98 -> 0.0029 | G12: 0.57 | H12: 0.001653 | I12: 1.9794297e+09 | J12: 1 | K12: =J12*E12 -> 0.0029 | L12: =K12*$Q$4 -> 3.4726837e+09 | P12: =O12*$E12 -> 0 | Q12: =O12*$D12 -> 0
A13: 6 | B13: 1.4.2.5 | C13: انجام تعهدات برنامه‌ريزي و مديريت محدوده، زمان و هزينه براساس نظام مديريت پروژه، ارائه گزارشات عملكرد پروژه، برپايي و شركت در جلسات كنترل پروژه و پيگيري مصوبات جلسه | D13: =E13*$Q$4 -> 7.7836015e+09 | E13: =CBS!D99 -> 0.0065 | G13: 0.57 | H13: 0.003705 | I13: 4.4366528e+09 | J13: 1 | K13: =J13*E13 -> 0.0065 | L13: =K13*$Q$4 -> 7.7836015e+09 | P13: =O13*$E13 -> 0 | Q13: =O13*$D13 -> 0
A14: 7 | B14: 1.4.2.6 | C14: تهيه نقشه‏هاي چون ساخت | D14: =E14*$Q$4 -> 3.4726837e+09 | E14: =CBS!D100 -> 0.0029 | G14: 0 | H14: 0 | I14: 0 | J14: 1 | K14: =J14*E14 -> 0.0029 | L14: =K14*$Q$4 -> 3.4726837e+09 | P14: =O14*$E14 -> 0 | Q14: =O14*$D14 -> 0
A15: 8 | B15: 1.4.2.7 | C15: تهيه كتابچه‌هاي بهره‌برداري، نگهداري و تعميرات | D15: =E15*$Q$4 -> 7.7836015e+08 | E15: =CBS!D101 -> 0.00065 | G15: 0 | H15: 0 | I15: 0 | J15: 0 | K15: =J15*E15 -> 0 | L15: =K15*$Q$4 -> 0 | P15: =O15*$E15 -> 0 | Q15: =O15*$D15 -> 0

Sheet خدمات مهندسي حين اجرا
D1: کارفرما: | E1: راه آهن جمهوری اسلامی ایران | K1: صورت وضعبت شماره: | M1: تاریخ صورت وضعیت:
D2: مشاور طرح: | E2: مهندسین مشاور صحن بوستان | K2: عنوان قرارداد:
D3: پیمانکار: | K3: تاریخ قرارداد: | M3: شماره قرارداد:
K4: مبلغ قرارداد: | L4: 768000000000
A5: ردیف | B5: W.B.S | C5: عنوان فعالیت | D5: هزینه کامل (ريال) | E5: وزن کامل (%) | F5: فصل فهرست بها | G5: گروه مشارکت | J5: مشاور زیر بنایی | M5: کارفرما | P5: مدارك پشتيبان
