Workbook

Sheet summary
E1: پروژه رفع گلوگاه هاي ظرفيتي در امور زيربنايي راه آهن ج.ا.ا
A8: « جدول خلاصه صورت وضعيت ها »
A10: شماره صورت وضعيت | D10: دوره کارکرد | G10: تجمعی صورت وضعیت شده پيمانکار (ریال) | K10: تجمعی تایید شده توسط مشاور(ریال) | O10: تجمعی تایید شده توسط کارفرما (ریال)
A11: ارسالي | B11: تاييد شده

Sheet summary-2
A7: « خلاصه کارکرد صورت وضعیت موقت شماره 16 به تفکیک فصول مرتبط »
A9: کارفرما: | D9: شرکت راه آهن ج.ا.ا | H9: مشاور: | K9: مهندسین مشاور صحن بوستان | O9: پيمانکار: | R9: مشارکت تكنيك پل رود كنكاوان معدن شيراز
A10: عنوان قرارداد: | D10: پروژه احداث خط دوم راه آهن محور مشك - سيستان به روش EPC غيرصنعتي | H10: شماره قرارداد: | K10: 400/66891/ي | O10: تاریخ قرارداد: | R10: 1393/11/20
A11: فهرست بهای رشته: | D11: راه، راه آهن و باند فرودگاه | H11: صورت وضعیت از تاريخ: | K11: 1396/12/11 | O11: تا تاريخ: | R11: ='خلاصه مالي صورت وضعیت'!E5 -> 1403/06/10
A13: فصل | B13: شرح فصل | G13: مبلغ کارکرد (ريال) | P13: کارکرد | S13: ملاحظات
G14: تا دوره قبل | J14: اين دوره | M14: تجمعي تاکنون
A15: مهندسي | B15: خدمات مهندسي و طراحي | G15: 5.2156117e+10 | J15: =IF(M15=0,0,M15-G15) -> 3.4666964e+09 | M15: ='خلاصه مالي صورت وضعیت'!$F$14 -> 5.5622814e+10 | P15: درخواست پیمانکار
G16: 3.8974588e+10 | J16: =IF(M16=0,0,M16-G16) -> -4.741291e+09 | M16: ='خلاصه مالي صورت وضعیت'!$G$14 -> 3.4233297e+10 | P16: تأیید مشاور
J17: =IF(M17=0,0,M17-G17) -> 0 | P17: تأیید کارفرما
A18: بيمه | B18: بيمه نامه ها و بيمه مهندسي سازه‌هاي تكميل شده | G18: 7.1848629e+09 | J18: =IF(M18=0,0,M18-G18) -> 0 | M18: ='خلاصه مالي صورت وضعیت'!$F$11++'خلاصه مالي صورت وضعیت'!F33 -> 7.1848629e+09 | P18: درخواست پیمانکار
G19: 5295842703 | J19: =IF(M19=0,0,M19-G19) -> 0 | M19: ='خلاصه مالي صورت وضعیت'!$G$11+'خلاصه مالي صورت وضعیت'!G33 -> 5295842703 | P19: تأیید مشاور
J20: =IF(M20=0,0,M20-G20) -> 0 | P20: تأیید کارفرما
A21: - | B21: تجهیز و برچیدن کارگاه | G21: 4.5144889e+10 | J21: =IF(M21=0,0,M21-G21) -> 2.7541974e+09 | M21: ='خلاصه مالي صورت وضعیت'!F12+'خلاصه مالي صورت وضعیت'!F13+'خلاصه مالي صورت وضعیت'!F32 -> 4.7899086e+10 | P21: درخواست پیمانکار
G22: 3.4458004e+10 | J22: =IF(M22=0,0,M22-G22) -> -5.0790993e+09 | M22: ='خلاصه مالي صورت وضعیت'!G12+'خلاصه مالي صورت وضعیت'!G13+'خلاصه مالي صورت وضعیت'!G32 -> 2.9378904e+10 | P22: تأیید مشاور
J23: =IF(M23=0,0,M23-G23) -> 0 | P23: تأیید کارفرما
A24: - | B24: تحويل موقت | G24: 0 | M24: ='خلاصه مالي صورت وضعیت'!F31 -> 0 | P24: درخواست پیمانکار
G25: 0 | M25: ='خلاصه مالي صورت وضعیت'!G31 -> 0 | P25: تأیید مشاور
P26: تأیید کارفرما
A27: - | B27: مقدمات لازم جهت فعاليتهاي اجرايي | G27: 5.9802009e+09 | J27: =IF(M27=0,0,M27-G27) -> 0 | M27: ='خلاصه مالي صورت وضعیت'!F10 -> 5.9802009e+09 | P27: درخواست پیمانکار
G28: 5.8796128e+09 | J28: =IF(M28=0,0,M28-G28) -> 1.0777294e+08 | M28: ='خلاصه مالي صورت وضعیت'!G10 -> 5987385758 | P28: تأیید مشاور
P29: تأیید کارفرما
A30: 1 | B30: عملیات تخریب | G30: 0 | J30: =IF(M30=0,0,M30-G30) -> 0 | M30: =SUMIF('خدمات اجرایی '!F:F,'summary-2'!A30,'خدمات اجرایی '!I:I) -> 0 | P30: درخواست پیمانکار
G31: 0 | J31: =IF(M31=0,0,M31-G31) -> 0 | M31: =SUMIF('خدمات اجرایی '!F:F,'summary-2'!A30,'خدمات اجرایی '!L:L) -> 0 | P31: تأیید مشاور
J32: =IF(M32=0,0,M32-G32) -> 0 | P32: تأیید کارفرما
A33: 2 | B33: عملیات خاکی با دست | G33: 0 | J33: =IF(M33=0,0,M33-G33) -> 0 | M33: =SUMIF('خدمات اجرایی '!F:F,'summary-2'!A33,'خدمات اجرایی '!I:I) -> 0 | P33: درخواست پیمانکار
G34: 0 | J34: =IF(M34=0,0,M34-G34) -> 0 | M34: =SUMIF('خدمات اجرایی '!F:F,'summary-2'!A33,'خدمات اجرایی '!L:L) -> 0 | P34: تأیید مشاور
J35: =IF(M35=0,0,M35-G35) -> 0 | P35: تأیید کارفرما
A36: 3 | B36: عملیات خاکی با ماشین | G36: 1.4008374e+11 | J36: =IF(M36=0,0,M36-G36) -> 1.4517075e+08 | M36: =SUMIF('خدمات اجرایی '!F:F,'summary-2'!A36,'خدمات اجرایی '!I:I) -> 1.4022891e+11 | P36: درخواست پیمانکار
G37: 1.3997263e+11 | J37: =IF(M37=0,0,M37-G37) -> -4.8666903e+09 | M37: =SUMIF('خدمات اجرایی '!F:F,'summary-2'!A36,'خدمات اجرایی '!L:L) -> 1.3510594e+11 | P37: تأیید مشاور
J38: =IF(M38=0,0,M38-G38) -> 0 | P38: تأیید کارفرما
A39: 6 | B39: عملیات بنایی با سنگ | G39: 2.54245e+09 | J39: =IF(M39=0,0,M39-G39) -> 0 | M39: =SUMIF('خدمات اجرایی '!F:F,'summary-2'!A39,'خدمات اجرایی '!I:I) -> 2.54245e+09 | P39: درخواست پیمانکار
G40: 2.4831261e+09 | J40: =IF(M40=0,0,M40-G40) -> -3.5001061e+08 | M40: =SUMIF('خدمات اجرایی '!F:F,'summary-2'!A39,'خدمات اجرایی '!L:L) -> 2.1331155e+09 | P40: تأیید مشاور
J41: =IF(M41=0,0,M41-G41) -> 0 | P41: تأیید کارفرما
A42: 8 | B42: قالب بندی و چوب بست | G42: 25424499588 | J42: =IF(M42=0,0,M42-G42) -> 0 | M42: =SUMIF('خدمات اجرایی '!F:F,'summary-2'!A42,'خدمات اجرایی '!I:I) -> 25424499588 | P42: درخواست پیمانکار
G43: 2.5255003e+10 | J43: =IF(M43=0,0,M43-G43) -> -3.9238478e+09 | M43: =SUMIF('خدمات اجرایی '!F:F,'summary-2'!A42,'خدمات اجرایی '!L:L) -> 2.1331155e+10 | P43: تأیید مشاور
J44: =IF(M44=0,0,M44-G44) -> 0 | P44: تأیید کارفرما
A45: 9 | B45: کارهای فولادی با میلگرد | G45: 50848999176 | J45: =IF(M45=0,0,M45-G45) -> 0 | M45: =SUMIF('خدمات اجرایی '!F:F,'summary-2'!A45,'خدمات اجرایی '!I:I) -> 50848999176 | P45: درخواست پیمانکار
B46: کارهای فولادی با میلگرد | G46: 5.0510006e+10 | J46: =IF(M46=0,0,M46-G46) -> -7.8476955e+09 | M46: =SUMIF('خدمات اجرایی '!F:F,'summary-2'!A45,'خدمات اجرایی '!L:L) -> 4.266231e+10 | P46: تأیید مشاور
B47: کارهای فولادی با میلگرد | J47: =IF(M47=0,0,M47-G47) -> 0 | P47: تأیید کارفرما
A48: 11 | B48: کارهای فولادی سبک | G48: 6.3278755e+09 | J48: =IF(M48=0,0,M48-G48) -> 0 | M48: =SUMIF('خدمات اجرایی '!F:F,'summary-2'!A48,'خدمات اجرایی '!I:I) -> 6.3278755e+09 | P48: درخواست پیمانکار
...

Sheet summary-Adjustment
A4: Rev | D4: Volume | F4: Doc. No | I4: Doc. Type | K4: Stu. Gro | M4: Sub. Proj | O4: Proj | Q4: کد مدرک
A5: =[1]Cover!A5 -> 00 | D5: =[1]Cover!C5 -> 01 | F5: =[1]Cover!E5 -> 025 | I5: =[1]Cover!G5 -> ST | K5: =[1]Cover!I5 -> ECO | M5: =[1]Cover!K5 -> 18 | O5: =[1]Cover!M5 -> 95210 | Q5: ="صفحه 4 از "&[1]Cover!S5 -> صفحه 4 از 24
A7: « خلاصه کارکرد صورت وضعیت موقت شماره 16 به تفکیک فصول - مشمول تعديل »
A9: کارفرما: | D9: شرکت راه آهن ج.ا.ا | H9: مشاور: | K9: مهندسین مشاور صحن بوستان | O9: پيمانکار: | R9: مشارکت تكنيك پل رود كنكاوان معدن شيراز
A10: عنوان قرارداد: | D10: پروژه احداث خط دوم راه آهن محور مشك - سيستان به روش EPC غيرصنعتي | H10: شماره قرارداد: | K10: 400/66891/ي | O10: تاریخ قرارداد: | R10: 1393/11/20
A11: فهرست بهای رشته: | D11: راه، راه آهن و باند فرودگاه | H11: صورت وضعیت از تاريخ: | K11: 1396/12/11 | O11: تا تاريخ: | R11: ='خلاصه مالي صورت وضعیت'!E5 -> 1403/06/10
A13: فصل | B13: شرح فصل | G13: مبلغ کارکرد (ريال) | P13: کارکرد | S13: تعديل با استفاده از شاخص
G14: تا دوره قبل | J14: اين دوره | M14: تجمعي تاکنون
A15: - | B15: مقدمات لازم جهت فعاليتهاي اجرايي | G15: ='summary-2'!G27:I27 -> 5.9802009e+09 | J15: =IF(M15=0,0,M15-G15) -> 0 | M15: ='summary-2'!M27:O27 -> 5.9802009e+09 | P15: درخواست پیمانکار | S15: رشته اي فهرست بهاي راه، راه آهن و باند فرودگاه
G16: ='summary-2'!G28:I28 -> 5.8796128e+09 | J16: =IF(M16=0,0,M16-G16) -> 1.0777294e+08 | M16: ='summary-2'!M28:O28 -> 5987385758 | P16: تأیید مشاور
J17: =IF(M17=0,0,M17-G17) -> 0 | P17: تأیید کارفرما
A18: - | B18: تجهیز و برچیدن کارگاه | G18: ='summary-2'!G21:I21 -> 4.5144889e+10 | J18: =IF(M18=0,0,M18-G18) -> 2.7541974e+09 | M18: ='summary-2'!M21:O21 -> 4.7899086e+10 | P18: درخواست پیمانکار | S18: ميانگين رشته اي فهرست بهاي راه، راه آهن و باند فرودگاه و فهرست بهاي ابنيه
G19: ='summary-2'!G22:I22 -> 3.4458004e+10 | J19: =IF(M19=0,0,M19-G19) -> -5.0790993e+09 | M19: ='summary-2'!M22:O22 -> 2.9378904e+10 | P19: تأیید مشاور
J20: =IF(M20=0,0,M20-G20) -> 0 | P20: تأیید کارفرما
A21: 1 | B21: عملیات تخریب | J21: =IF(M21=0,0,M21-G21) -> 0 | M21: ='summary-2'!M30 -> 0 | P21: درخواست پیمانکار | S21: فصل يك فهرست بهاي راه، راه آهن و باند فرودگاه
J22: =IF(M22=0,0,M22-G22) -> 0 | M22: ='summary-2'!M31 -> 0 | P22: تأیید مشاور
J23: =IF(M23=0,0,M23-G23) -> 0 | M23: ='summary-2'!M32 -> 0 | P23: تأیید کارفرما
A24: 2 | B24: عملیات خاکی با دست | J24: =IF(M24=0,0,M24-G24) -> 0 | M24: ='summary-2'!M33 -> 0 | P24: درخواست پیمانکار | S24: فصل دو فهرست بهاي راه، راه آهن و باند فرودگاه
J25: =IF(M25=0,0,M25-G25) -> 0 | M25: ='summary-2'!M34 -> 0 | P25: تأیید مشاور
J26: =IF(M26=0,0,M26-G26) -> 0 | M26: ='summary-2'!M35 -> 0 | P26: تأیید کارفرما
A27: 3 | B27: عملیات خاکی با ماشین | G27: ='summary-2'!G36:I36 -> 1.4008374e+11 | J27: =IF(M27=0,0,M27-G27) -> 1.4517075e+08 | M27: ='summary-2'!M36 -> 1.4022891e+11 | P27: درخواست پیمانکار | S27: فصل سه فهرست بهاي راه، راه آهن و باند فرودگاه
G28: ='summary-2'!G37:I37 -> 1.3997263e+11 | J28: =IF(M28=0,0,M28-G28) -> -4.8666903e+09 | M28: ='summary-2'!M37 -> 1.3510594e+11 | P28: تأیید مشاور
J29: =IF(M29=0,0,M29-G29) -> 0 | M29: ='summary-2'!M38 -> 0 | P29: تأیید کارفرما
A30: 6 | B30: عملیات بنایی با سنگ | G30: ='summary-2'!G39:I39 -> 2.54245e+09 | J30: =IF(M30=0,0,M30-G30) -> 0 | M30: ='summary-2'!M39 -> 2.54245e+09 | P30: درخواست پیمانکار | S30: فصل شش فهرست بهاي راه، راه آهن و باند فرودگاه
G31: ='summary-2'!G40:I40 -> 2.4831261e+09 | J31: =IF(M31=0,0,M31-G31) -> -3.5001061e+08 | M31: ='summary-2'!M40 -> 2.1331155e+09 | P31: تأیید مشاور
J32: =IF(M32=0,0,M32-G32) -> 0 | M32: ='summary-2'!M41 -> 0 | P32: تأیید کارفرما
A33: 8 | B33: قالب بندی و چوب بست | G33: ='summary-2'!G42:I42 -> 25424499588 | J33: =IF(M33=0,0,M33-G33) -> 0 | M33: ='summary-2'!M42 -> 25424499588 | P33: درخواست پیمانکار | S33: فصل هشت فهرست بهاي راه، راه آهن و باند فرودگاه
G34: ='summary-2'!G43:I43 -> 2.5255003e+10 | J34: =IF(M34=0,0,M34-G34) -> -3.9238478e+09 | M34: ='summary-2'!M43 -> 2.1331155e+10 | P34: تأیید مشاور
J35: =IF(M35=0,0,M35-G35) -> 0 | M35: ='summary-2'!M44 -> 0 | P35: تأیید کارفرما
A36: 9 | B36: کارهای فولادی با میلگرد | G36: ='summary-2'!G45:I45 -> 50848999176 | J36: =IF(M36=0,0,M36-G36) -> 0 | M36: ='summary-2'!M45 -> 50848999176 | P36: درخواست پیمانکار | S36: فصل نه فهرست بهاي راه، راه آهن و باند فرودگاه
A37: 9 | B37: کارهای فولادی با میلگرد | G37: ='summary-2'!G46:I46 -> 5.0510006e+10 | J37: =IF(M37=0,0,M37-G37) -> -7.8476955e+09 | M37: ='summary-2'!M46 -> 4.266231e+10 | P37: تأیید مشاور
A38: 9 | B38: کارهای فولادی با میلگرد | J38: =IF(M38=0,0,M38-G38) -> 0 | M38: ='summary-2'!M47 -> 0 | P38: تأیید کارفرما
A39: 11 | B39: کارهای فولادی سبک | G39: ='summary-2'!G48:I48 -> 6.3278755e+09 | J39: =IF(M39=0,0,M39-G39) -> 0 | M39: ='summary-2'!M48 -> 6.3278755e+09 | P39: درخواست پیمانکار | S39: فصل یازده فهرست بهاي راه، راه آهن و باند فرودگاه
A40: 12 | B40: کارهای فولادی با میلگرد | G40: ='summary-2'!G49:I49 -> 5.2732295e+08 | J40: =IF(M40=0,0,M40-G40) -> 6.1090364e+09 | M40: ='summary-2'!M49 -> 6.6363594e+09 | P40: تأیید مشاور
A41: 12 | B41: کارهای فولادی با میلگرد | J41: =IF(M41=0,0,M41-G41) -> 0 | M41: ='summary-2'!M50 -> 0 | P41: تأیید کارفرما
A42: 12 | B42: بتن درجا | G42: ='summary-2'!G51:I51 -> 1.6102183e+10 | J42: =IF(M42=0,0,M42-G42) -> 0 | M42: ='summary-2'!M51 -> 1.6102183e+10 | P42: درخواست پیمانکار | S42: فصل دوازده فهرست بهاي راه، راه آهن و باند فرودگاه
A43: 12 | B43: بتن درجا | G43: ='summary-2'!G52:I52 -> 1.6068284e+10 | J43: =IF(M43=0,0,M43-G43) -> -2.3874453e+09 | M43: ='summary-2'!M52 -> 1.3680838e+10 | P43: تأیید مشاور
A44: 12 | B44: بتن درجا | J44: =IF(M44=0,0,M44-G44) -> 0 | M44: ='summary-2'!M53 -> 0 | P44: تأیید کارفرما
A45: 13 | B45: بتن پیش ساخته | G45: ='summary-2'!G54:I54 -> 8.8591328e+10 | J45: =IF(M45=0,0,M45-G45) -> 0 | M45: ='summary-2'!M54 -> 8.8591328e+10 | P45: درخواست پیمانکار | S45: فصل سيزده فهرست بهاي راه، راه آهن و باند فرودگاه
A46: 13 | B46: بتن پیش ساخته | G46: ='summary-2'!G55:I55 -> 5.0850168e+10 | J46: =IF(M46=0,0,M46-G46) -> -2.8269882e+10 | M46: ='summary-2'!M55 -> 2.2580285e+10 | P46: تأیید مشاور
...

Sheet خلاصه مالي صورت وضعیت
D1: کارفرما: | E1: راه‏آهن جمهوری اسلامی ایران | F1: عنوان قرارداد: | G1: طراحی، تأمین و اجرای دو خطه کردن راه‏آهن (زیرسازی، پل‏سازی، روسازی) محور مشك-سيستان
D2: مشاور طرح: | E2: مهندسین مشاور صحن بوستان
D3: مشارکت: | E3: مشاركت تكنيك-پل‏رود-کنکاوان معدن شیراز | F3: شماره و تاریخ ابلاغ قرارداد: | G3: 400/66891/ی مورخ 93/11/20
D4: صورت‏وضعیت شماره: | E4: موقت 16 | F4: مبلغ قرارداد (ریال): | G4: 1197477151532
D5: تاریخ صورت‏وضعیت: | E5: 1403/06/10
A6: ردیف | B6: W.B.S | C6: عنوان فعالیت | F6: گروه مشارکت
G7: مشاور زیر بنایی | H7: کارفرما
A8: 1 | B8: 1 | C8: پروژه طراحی، تامین و اجرای دو خطه کردن راه‏آهن محور مشک–سیستان | F8: =SUM(F9,F14,F17,F22,F30) -> 8.4912616e+11 | G8: =SUM(G9,G14,G17,G22,G30) -> 4.4781204e+11 | I8: =G8-'summary-2'!M79 -> 0
A9: 2 | B9: 1.3 | C9: فعالیت‌های مقدماتی، برنامه‏ریزی و تجهيز كارگاه | F9: =SUM(F10:F13) -> 6.106415e+10 | G9: =SUM(G10:G13) -> 4.0662133e+10
A10: 3 | B10: 1.3.1 | C10: مقدمات لازم جهت فعاليت هاي اجرايي | F10: ='سازمان دهی و برنامه ریزی پروژه'!I8 -> 5.9802009e+09 | G10: ='سازمان دهی و برنامه ریزی پروژه'!L8 -> 5987385758
A11: 4 | B11: 1.3.2 | C11: بيمه‌نامه‌ها | F11: ='بیمه نامه ها'!I8 -> 7.1848629e+09 | G11: ='بیمه نامه ها'!L8 -> 5295842703
A12: 5 | B12: 1.3.3 | C12: تجهیز اوليه کارگاه | F12: ='تجهیز کارگاه اولیه'!I8 -> 20357111576 | G12: ='تجهیز کارگاه اولیه'!L8 -> 1.8830328e+10
A13: 6 | B13: 1.3.4 | C13: تجهيز مستمر كارگاه | F13: ='تجهیز کارگاه مستمر'!I8 -> 2.7541974e+10 | G13: ='تجهیز کارگاه مستمر'!L8 -> 1.0548576e+10
A14: 7 | B14: 1.4 | C14: خدمات طراحي و مهندسی | F14: =SUM(F15:F16) -> 5.5622814e+10 | G14: =SUM(G15:G16) -> 3.4233297e+10
A15: 8 | B15: 1.4.1 | C15: خدمات طراحي و مهندسی پيش از اجرا | F15: ='خدمات طراحي مهندسي پیش از اجرا'!I8 -> 2.095585e+10 | G15: ='خدمات طراحي مهندسي پیش از اجرا'!L8 -> 2.095585e+10
A16: 9 | B16: 1.4.2 | C16: خدمات مهندسی حین اجرا | F16: ='خدمات طراحي و مهندسي حین اجرا'!I8 -> 3.4666964e+10 | G16: ='خدمات طراحي و مهندسي حین اجرا'!L8 -> 1.3277447e+10
A17: 10 | B17: 1.5 | C17: خدمات تامین | F17: =F18+F19+F20+F21 -> 2.6789607e+11 | G17: =G18+G19+G20+G21 -> 1.4929969e+10
A18: 11 | B18: 1.5.1 | C18: ريل | F18: ='خدمات تامین'!I9 -> 1.0777168e+11 | G18: ='خدمات تامین'!L9+فصل13ریل!J5 -> 0
A19: 12 | B19: 1.5.2 | C19: سوزن | F19: ='خدمات تامین'!I16 -> 6.1073232e+10 | G19: ='خدمات تامین'!L16 -> 0
A20: 13 | B20: 1.5.3 | C20: تراورس | F20: ='خدمات تامین'!I21 -> 7.9269012e+10 | G20: ='خدمات تامین'!L21 -> 1.4929969e+10
A21: 14 | B21: 1.5.4 | C21: ملحقات | F21: ='خدمات تامین'!I27 -> 1.9782141e+10 | G21: ='خدمات تامین'!L27 -> 0
A22: 15 | B22: 1.6 | C22: عملیات اجرایی | F22: =F23+F24+F25+F26+F27+F28+F29 -> 4.6454313e+11 | G22: =G23+G24+G25+G26+G27+G28+G29 -> 3.5798664e+11
A23: 16 | B23: 1.6.1 | C23: بلوک مشک-هرند | F23: ='خدمات اجرایی '!I9 -> 1.3190058e+11 | G23: ='خدمات اجرایی '!L9 -> 1.0557092e+11
A24: 17 | B24: 1.6.2 | C24: ایستگاه مشک | F24: ='خدمات اجرایی '!I51 -> 2.0019606e+10 | G24: ='خدمات اجرایی '!L51 -> 1.6315827e+10
A25: 18 | B25: 1.6.3 | C25: بلوک هرند-خیرآباد | F25: ='خدمات اجرایی '!I78 -> 1.2710523e+11 | G25: ='خدمات اجرایی '!L78 -> 1.0181762e+11
A26: 19 | B26: 1.6.4 | C26: ایستگاه هرند | F26: ='خدمات اجرایی '!I120 -> 2.0055378e+10 | G26: ='خدمات اجرایی '!L120 -> 1.4424119e+10
A27: 20 | B27: 1.6.5 | C27: بلوک خیرآباد-سیستان | F27: ='خدمات اجرایی '!I147 -> 1.1690022e+11 | G27: ='خدمات اجرایی '!L147 -> 1.0457723e+11
A28: 21 | B28: 1.6.6 | C28: ایستگاه خیرآباد | F28: ='خدمات اجرایی '!I189 -> 2.0075825e+10 | G28: ='خدمات اجرایی '!L189 -> 1.5280919e+10
A29: 22 | B29: 1.6.7 | C29: کارهای اضافی | F29: ='خدمات اجرایی '!I216 -> 2.8486291e+10 | G29: 0
A30: 23 | B30: 1.7 | C30: اختتامیه پروژه | F30: =SUM(F31:F33) -> 0 | G30: =SUM(G31:G33) -> 0
A31: 24 | B31: 1.7.1 | C31: تحويل موقت كل پروژه | F31: =اختتامیه!I9 -> 0 | G31: =اختتامیه!L9 -> 0
A32: 25 | B32: 1.7.2 | C32: برچيدن كارگاه | F32: =اختتامیه!I10 -> 0 | G32: =اختتامیه!L10 -> 0
A33: 26 | B33: 1.7.3 | C33: بيمه مهندسي سازه‌هاي تكميل شده | F33: =اختتامیه!I11 -> 0 | G33: =اختتامیه!L11 -> 0
F36: 1197477151532 | G36: مبلغ پروژه
F37: 47477151532 | G37: کار اضافه
F38: =F36-F37 -> 1150000000000
F39: =F8/F38*F37 -> 3.5055732e+10 | G39: مبلغ کار اضافه این کارکرد

Sheet جمع بندي صورت وضعیت
H1: کارفرما: | I1: راه آهن جمهوری اسلامی ایران | L1: عنوان قرارداد: | M1: طراحی،تامین و اجرای دوخطه کردن راه آهن(زیرسازی،پل سازی و روسازی)محور ساسان شبنم
H2: مشاور طرح: | I2: مهندسین مشاور صحن بوستان
H3: مشارکت: | I3: اهورامهرگستران-جهادنصرحمزه طرح نوانديشان-گمانه كاو | L3: شماره و تاریخ ابلاغ قرارداد: | M3: 400/71523/ي مورخ 93/12/10
H4: صورت وضعبت شماره: | I4: 2 | L4: مبلغ قرارداد: | M4: 768000000000
H5: تاریخ صورت وضعیت: | I5: 94/0.5/17
A6: ردیف | B6: W.B.S | C6: عنوان فعالیت | D6: هزینه کامل (ريال) | E6: وزن کامل (%) | F6: واحد | G6: گروه مشارکت | J6: مشاور زیر بنایی | M6: کارفرما
G7: درصد پیشرفت از (کل) | H7: درصد پیشرفت وزنی | I7: مبلغ(ریال) | J7: درصد پیشرفت از (کل) | K7: درصد پیشرفت وزنی | L7: مبلغ(ریال) | M7: درصد پیشرفت از (کل) | N7: درصد پیشرفت وزنی | O7: مبلغ(ریال)
A8: 1 | B8: 1 | C8: پروژه طراحی، تامین و اجرای دو خطه کردن راه آهن محور ساسان – شبنم | D8: =D11+D16+D19+D20+D21 -> 768000000000 | E8: =E11+E16+E19+E20+E21 -> 100 | I8: =SUM(I11,I16,I19,I20,I21) -> #REF! | L8: =SUM(L11,L16,L19,L20,L21) -> #REF! | O8: =SUM(O11,O16,O19,O20,O21) -> #REF!
A9: 2 | B9: 1.1 | C9: آغاز | D9: 0 | E9: 0
A10: 3 | B10: 1.2 | C10: تحویل زمین | D10: 0 | E10: 0
A11: 4 | B11: 1.3 | C11: فعالیت‌های مقدماتی، برنامه ریزی و تجهيز كارگاه | D11: =E11*$M$4/100 -> 3.6096e+10 | E11: =SUM(E12:E15) -> 4.7 | G11: =(G12*$E$12+G13*$E$13+G14*$E$14+G15*$E$15)/$E$11 -> 0 | H11: =G11*E11 -> 0 | I11: =G11*D11 -> 0 | J11: =(J12*$E$12+J13*$E$13+J14*$E$14+J15*$E$15)/$E$11 -> 0.6322234 | K11: =J11*E11 -> 2.97145 | L11: =J11*D11 -> 2.2820736e+10 | M11: =(M12*$E$12+M13*$E$13+M14*$E$14+M15*$E$15)/$E$11 -> 0 | N11: =M11*E11 -> 0 | O11: =M11*D11 -> 0
A12: 5 | B12: 1.3.1 | C12: سازماندهي و برنامه ریزی پروژه | D12: =E12*$M$4/100 -> 3840000000 | E12: 0.5 | G12: ='سازمان دهی و برنامه ریزی پروژه'!G8 -> 0 | H12: ='سازمان دهی و برنامه ریزی پروژه'!H8 -> 0.004994 | I12: ='سازمان دهی و برنامه ریزی پروژه'!I8 -> 5.9802009e+09 | J12: ='سازمان دهی و برنامه ریزی پروژه'!J8 -> 1 | K12: ='سازمان دهی و برنامه ریزی پروژه'!K8 -> 0.005 | L12: ='سازمان دهی و برنامه ریزی پروژه'!L8 -> 5987385758 | M12: ='سازمان دهی و برنامه ریزی پروژه'!M8 -> 0 | N12: ='سازمان دهی و برنامه ریزی پروژه'!N8 -> 0 | O12: ='سازمان دهی و برنامه ریزی پروژه'!O8 -> 0
A13: 6 | B13: 1.3.2 | C13: بيمه‌نامه‌ها | D13: =E13*$M$4/100 -> 4608000000 | E13: 0.6 | G13: ='بیمه نامه ها'!G$8 -> 0 | H13: ='بیمه نامه ها'!H8 -> 0.006 | I13: ='بیمه نامه ها'!I8 -> 7.1848629e+09 | J13: ='بیمه نامه ها'!J$8 -> 0.73708333 | K13: ='بیمه نامه ها'!K$8 -> 0.0044225 | L13: ='بیمه نامه ها'!L$8 -> 5295842703 | M13: ='بیمه نامه ها'!M$8 -> 0 | N13: ='بیمه نامه ها'!N$8 -> 0 | O13: ='بیمه نامه ها'!O$8 -> 0
A14: 7 | B14: 1.3.3 | C14: تجهیز اوليه کارگاه | D14: =E14*$M$4/100 -> 9216000000 | E14: 1.2 | G14: ='تجهیز کارگاه اولیه'!G8 -> 0 | H14: ='تجهیز کارگاه اولیه'!H8 -> 0.017 | I14: ='تجهیز کارگاه اولیه'!I8 -> 20357111576 | J14: ='تجهیز کارگاه اولیه'!J8 -> 0.925 | K14: ='تجهیز کارگاه اولیه'!K8 -> 0.015725 | L14: ='تجهیز کارگاه اولیه'!L8 -> 1.8830328e+10 | M14: ='تجهیز کارگاه اولیه'!M8 -> 0 | N14: ='تجهیز کارگاه اولیه'!N8 -> 0 | O14: ='تجهیز کارگاه اولیه'!O8 -> 0
A15: 8 | B15: 1.3.4 | C15: تجهيز مستمر كارگاه | D15: =E15*$M$4/100 -> 18432000000 | E15: 2.4 | G15: ='تجهیز کارگاه مستمر'!G8 -> 0 | H15: ='تجهیز کارگاه مستمر'!H8 -> 0.023 | I15: ='تجهیز کارگاه مستمر'!I8 -> 2.7541974e+10 | J15: ='تجهیز کارگاه مستمر'!J$8 -> 0.383 | K15: ='تجهیز کارگاه مستمر'!K$8 -> 0.008809 | L15: ='تجهیز کارگاه مستمر'!L$8 -> 1.0548576e+10 | M15: ='تجهیز کارگاه مستمر'!M$8 -> 0 | N15: ='تجهیز کارگاه مستمر'!N$8 -> 0 | O15: ='تجهیز کارگاه مستمر'!O$8 -> 0
A16: 9 | B16: 1.4 | C16: خدمات طراحي و مهندسی | D16: =E16*$M$4/100 -> 8.1403491e+10 | E16: =E17+E18 -> 10.599413 | G16: =(G17*$E$17+G18*$E$18)/$E$16 -> 0 | H16: =G16*E16 -> 0 | I16: =G16*D16 -> 0 | J16: =(J17*$E$17+J18*$E$18)/$E$16 -> 0.571757 | K16: =J16*E16 -> 6.0602885 | L16: =J16*D16 -> 4.6543016e+10 | M16: =(M17*$E$17+M18*$E$18)/$E$16 -> #REF! | N16: =M16*E16 -> #REF! | O16: =M16*D16 -> #REF!
A17: 10 | B17: 1.4.1 | C17: خدمات طراحي و مهندسی پيش از اجرا | D17: =E17*$M$4/100 -> 2.8491222e+10 | E17: 3.7097945 | G17: ='خدمات طراحي مهندسي پیش از اجرا'!G8 -> 0 | H17: ='خدمات طراحي مهندسي پیش از اجرا'!H8 -> 0.0175 | I17: ='خدمات طراحي مهندسي پیش از اجرا'!I8 -> 2.095585e+10 | J17: ='خدمات طراحي مهندسي پیش از اجرا'!J8 -> 1 | K17: ='خدمات طراحي مهندسي پیش از اجرا'!K8 -> 0.0175 | L17: ='خدمات طراحي مهندسي پیش از اجرا'!L8 -> 2.095585e+10 | M17: ='خدمات طراحي مهندسي پیش از اجرا'!#REF! -> #REF! | N17: ='خدمات طراحي مهندسي پیش از اجرا'!#REF! -> #REF! | O17: ='خدمات طراحي مهندسي پیش از اجرا'!#REF! -> #REF!
A18: 11 | B18: 1.4.2 | C18: خدمات مهندسی حین اجرا | D18: =E18*$M$4/100 -> 5.2912269e+10 | E18: 6.8896184 | G18: ='خدمات طراحي و مهندسي حین اجرا'!G$8 -> 0 | H18: ='خدمات طراحي و مهندسي حین اجرا'!H8 -> 0.02895 | I18: ='خدمات طراحي و مهندسي حین اجرا'!I8 -> 3.4666964e+10 | J18: ='خدمات طراحي و مهندسي حین اجرا'!J$8 -> 0.34116462 | K18: ='خدمات طراحي و مهندسي حین اجرا'!K$8 -> 0.01108785 | L18: ='خدمات طراحي و مهندسي حین اجرا'!L$8 -> 1.3277447e+10 | M18: ='خدمات طراحي و مهندسي حین اجرا'!M$8 -> 0 | N18: ='خدمات طراحي و مهندسي حین اجرا'!N$8 -> 0 | O18: ='خدمات طراحي و مهندسي حین اجرا'!O$8 -> 0
A19: 12 | B19: 1.5 | C19: خدمات تامین | D19: =E19*$M$4/100 -> 268804508978 | E19: 35.000587 | G19: ='خدمات تامین'!G$8 -> 0.58138529 | H19: ='خدمات تامین'!H8 -> 0.22371706 | I19: ='خدمات تامین'!I8 -> 2.6789607e+11 | J19: ='خدمات تامین'!J$8 -> 0.032400864 | K19: ='خدمات تامین'!K$8 -> 0.012467853 | L19: ='خدمات تامین'!L$8 -> 1.4929969e+10 | M19: ='خدمات تامین'!#REF! -> #REF! | N19: ='خدمات تامین'!N$8 -> 0 | O19: ='خدمات تامین'!O$8 -> 0
A20: 13 | B20: 1.6 | C20: عملیات اجرایی | D20: =E20*$M$4/100 -> 369408000000 | E20: 48.1 | G20: =#REF! -> #REF! | H20: =#REF! -> #REF! | I20: =#REF! -> #REF! | J20: =#REF! -> #REF! | K20: =#REF! -> #REF! | L20: =#REF! -> #REF! | M20: =#REF! -> #REF! | N20: =#REF! -> #REF! | O20: =#REF! -> #REF!
A21: 14 | B21: 1.7 | C21: اختتامیه پروژه | D21: =E21*$M$4/100 -> 12288000000 | E21: =SUM(E22:E24) -> 1.6 | G21: =اختتامیه!G8 -> 0 | H21: =اختتامیه!H8 -> 0 | I21: =اختتامیه!I8 -> 0 | J21: =اختتامیه!J8 -> 0 | K21: =اختتامیه!K8 -> 0 | L21: =اختتامیه!L8 -> 0 | M21: =اختتامیه!M8 -> 0 | N21: =اختتامیه!N8 -> 0 | O21: =اختتامیه!O8 -> 0
A22: 15 | B22: 1.7.1 | C22: تحويل موقت كل پروژه | D22: =E22*$M$4/100 -> 6144000000 | E22: 0.8 | G22: =اختتامیه!G9 -> 0 | H22: =اختتامیه!H9 -> 0 | I22: =اختتامیه!I9 -> 0 | J22: =اختتامیه!J9 -> 0 | K22: =اختتامیه!K9 -> 0 | L22: =اختتامیه!L9 -> 0 | M22: =اختتامیه!M9 -> 0 | N22: =اختتامیه!N9 -> 0 | O22: =اختتامیه!O9 -> 0
A23: 16 | B23: 1.7.2 | C23: برچيدن كارگاه | D23: =E23*$M$4/100 -> 3072000000 | E23: 0.4 | G23: =اختتامیه!G10 -> 0 | H23: =اختتامیه!H10 -> 0 | I23: =اختتامیه!I10 -> 0 | J23: =اختتامیه!J10 -> 0 | K23: =اختتامیه!K10 -> 0 | L23: =اختتامیه!L10 -> 0 | M23: =اختتامیه!M10 -> 0 | N23: =اختتامیه!N10 -> 0 | O23: =اختتامیه!O10 -> 0
A24: 17 | B24: 1.7.3 | C24: بيمه مهندسي سازه‌هاي تكميل شده | D24: =E24*$M$4/100 -> 3072000000 | E24: 0.4 | G24: =اختتامیه!G11 -> 0 | H24: =اختتامیه!H11 -> 0 | I24: =اختتامیه!I11 -> 0 | J24: =اختتامیه!J11 -> 0 | K24: =اختتامیه!K11 -> 0 | L24: =اختتامیه!L11 -> 0 | M24: =اختتامیه!M11 -> 0 | N24: =اختتامیه!N11 -> 0 | O24: =اختتامیه!O11 -> 0
A25: 18 | B25: 1.8 | C25: پایان | D25: =E25*$M$4/100 -> 0 | E25: 0
G26: مهر و امضا گروه مشارکت اهورا مهر گستران | H26: مهر و امضا گروه مشارکت اهورا مهر گستران | I26: مهر و امضا گروه مشارکت اهورا مهر گستران | J26: مهر و امضا مشاور زیر بنایی مهندسین مشاور صحن بوستان | K26: مهر و امضا مشاور زیر بنایی مهندسین مشاور صحن بوستان | L26: مهر و امضا مشاور زیر بنایی مهندسین مشاور صحن بوستان | M26: تایید کارفرما | N26: تایید کارفرما | O26: تایید کارفرما

Sheet سازمان دهی و برنامه ریزی پروژه
D1: کارفرما: | E1: راه‏آهن جمهوری اسلامی ایران | J1: عنوان قرارداد: | L1: طراحی، تأمین و اجرای دو خطه کردن راه‏آهن (زیرسازی، پل‏سازی، روسازی) محور مشك-سيستان
D2: مشاور طرح: | E2: مهندسین مشاور صحن بوستان
D3: مشارکت: | E3: مشاركت تكنيك-پل‏رود-کنکاوان معدن شیراز | J3: شماره و تاریخ ابلاغ قرارداد: | L3: 400/66891/ی مورخ 93/11/20
D4: صورت‏وضعیت شماره: | E4: ='خلاصه مالي صورت وضعیت'!E4 -> موقت 16 | J4: مبلغ قرارداد (ریال): | L4: ='خلاصه مالي صورت وضعیت'!G4:G5 -> 1197477151532
D5: تاریخ صورت‏وضعیت: | E5: ='خلاصه مالي صورت وضعیت'!E5 -> 1403/06/10
A6: ردیف | B6: W.B.S | C6: عنوان فعالیت | D6: هزینه کامل (ريال) | E6: وزن کامل (%) | F6: فصل مرتبط از فهرست بها | G6: گروه مشارکت | J6: مشاور زیربنایی | M6: کارفرما | P6: مدارك پشتيبان
G7: درصد پیشرفت از سرفصل (کل) | H7: درصد پیشرفت وزنی | I7: مبلغ (ریال) | J7: درصد پیشرفت از صد (کل) | K7: درصد پیشرفت وزنی | L7: مبلغ (ریال) | M7: درصد پیشرفت از صد (کل) | N7: درصد پیشرفت وزنی | O7: مبلغ (ریال)
A8: 1 | B8: 1.3.1 | C8: مقدمات لازم جهت فعاليت هاي اجرايي | D8: =SUM(D9:D17) -> 5987385758 | E8: =SUM(E9:E17) -> 0.005 | H8: =SUM(H9:H17) -> 0.004994 | I8: =SUM(I9:I17) -> 5.9802009e+09 | J8: =L8/D8 -> 1 | K8: =L8/L4 -> 0.005 | L8: =SUM(L9:L17) -> 5987385758
A9: 2 | B9: 1.3.1.1 | C9: انتصاب و معرفی نماینده مشارکت (مدیر پروژه) | D9: =E9*$L$4 -> 0 | E9: =CBS!D11 -> 0 | G9: 1 | H9: =G9*E9 -> 0 | I9: =H9*$L$4 -> 0 | J9: 1 | K9: =J9*E9 -> 0 | L9: =K9*$L$4 -> 0
A10: 3 | B10: 1.3.1.2 | C10: تشکیل دفتر و سازمان کلیدی پروژه | D10: =E10*$L$4 -> 4.19117e+08 | E10: =CBS!D12 -> 0.00035 | G10: 1 | H10: =G10*E10 -> 0.00035 | I10: =H10*$L$4 -> 4.19117e+08 | J10: 1 | K10: =J10*E10 -> 0.00035 | L10: =K10*$L$4 -> 4.19117e+08
A11: 4 | B11: 1.3.1.3 | C11: تهیه و اعلام چارت سازمانی، شرح وظایف و حدود اختیارات و مسئولیت‏ها و شرایط احراز تیم پروژه | D11: =E11*$L$4 -> 8.9810786e+08 | E11: =CBS!D13 -> 0.00075 | G11: 1 | H11: =G11*E11 -> 0.00075 | I11: =H11*$L$4 -> 8.9810786e+08 | J11: 1 | K11: =J11*E11 -> 0.00075 | L11: =K11*$L$4 -> 8.9810786e+08
A12: 5 | B12: 1.3.1.4 | C12: تشکیل و تعریف نظام مدیریت پروژه، تهیه و ارسال ویرایش اول برنامه زمان‏بندی و ساختار شکست هزینه و سایر مدارک مرتبط برنامه‏ریزی | D12: =E12*$L$4 -> 1.5567203e+09 | E12: =CBS!D14 -> 0.0013 | G12: 1 | H12: =G12*E12 -> 0.0013 | I12: =H12*$L$4 -> 1.5567203e+09 | J12: 1 | K12: =J12*E12 -> 0.0013 | L12: =K12*$L$4 -> 1.5567203e+09
A13: 6 | B13: 1.3.1.5 | C13: برنامه‏ریزی و تعیین مشخصات و فهرست کامل اقدامات تجهیز کارگاه به همراه نقشه جانمایی | D13: =E13*$L$4 -> 5.9873858e+08 | E13: =CBS!D15 -> 0.0005 | G13: 1 | H13: =G13*E13 -> 0.0005 | I13: =H13*$L$4 -> 5.9873858e+08 | J13: 1 | K13: =J13*E13 -> 0.0005 | L13: =K13*$L$4 -> 5.9873858e+08
A14: 7 | B14: 1.3.1.6 | C14: تهیه و ارسال گردش فعالیتها و روابط بین مشارکت، مشاور و کارفرما (Coordination Procedure) | D14: =E14*$L$4 -> 3.5924315e+08 | E14: =CBS!D16 -> 0.0003 | G14: 1 | H14: =G14*E14 -> 0.0003 | I14: =H14*$L$4 -> 3.5924315e+08 | J14: 1 | K14: =J14*E14 -> 0.0003 | L14: =K14*$L$4 -> 3.5924315e+08
A15: 8 | B15: 1.3.1.7 | C15: تهیه و ارسال روش‏های اجرایی و دستورالعمل‏های کاری شامل: QA ،QC ،HSE ،5S و … | D15: =E15*$L$4 -> 1.7962157e+09 | E15: =CBS!D17 -> 0.0015 | G15: 1 | H15: =G15*E15 -> 0.0015 | I15: =H15*$L$4 -> 1.7962157e+09 | J15: 1 | K15: =J15*E15 -> 0.0015 | L15: =K15*$L$4 -> 1.7962157e+09
A16: 9 | B16: 1.3.1.8 | C16: تهیه و ارسال لیست کامل مدارک پیمانکار | D16: =E16*$L$4 -> 3.5924315e+08 | E16: =CBS!D18 -> 0.0003 | G16: 0.98 | H16: =G16*E16 -> 0.000294 | I16: =H16*$L$4 -> 3.5205828e+08 | J16: 1 | K16: =J16*E16 -> 0.0003 | L16: =K16*$L$4 -> 3.5924315e+08
A17: 10 | B17: 1.3.1.9 | C17: پایان سازمان‏دهی و برنامه‏ریزی مقدماتی پروژه | D17: =E17*$L$4 -> 0 | E17: =CBS!D19 -> 0 | H17: =G17*E17 -> 0 | I17: =H17*$L$4 -> 0 | K17: =J17*E17 -> 0 | L17: =K17*$L$4 -> 0

Sheet بیمه نامه ها
D1: کارفرما: | E1: راه‏آهن جمهوری اسلامی ایران | J1: عنوان قرارداد: | L1: طراحی، تأمین و اجرای دو خطه کردن راه‏آهن (زیرسازی، پل‏سازی، روسازی) محور مشك-سيستان
D2: مشاور طرح: | E2: مهندسین مشاور صحن بوستان
D3: مشارکت: | E3: مشاركت تكنيك-پل‏رود-کنکاوان معدن شیراز | J3: شماره و تاریخ ابلاغ قرارداد: | L3: 400/66891/ی مورخ 93/11/20
D4: صورت‏وضعیت شماره: | E4: ='خلاصه مالي صورت وضعیت'!E4 -> موقت 16 | J4: مبلغ قرارداد (ریال): | L4: ='خلاصه مالي صورت وضعیت'!G4:G5 -> 1197477151532
D5: تاریخ صورت‏وضعیت: | E5: ='خلاصه مالي صورت وضعیت'!E5 -> 1403/06/10
A6: ردیف | B6: W.B.S | C6: عنوان فعالیت | D6: هزینه کامل (ريال) | E6: وزن کامل (%) | F6: فصل مرتبط از فهرست بها | G6: گروه مشارکت | J6: مشاور زیربنایی | M6: کارفرما | P6: مدارك پشتيبان
G7: درصد پیشرفت از سرفصل (کل) | H7: درصد پیشرفت وزنی | I7: مبلغ (ریال) | J7: درصد پیشرفت از صد (کل) | K7: درصد پیشرفت وزنی | L7: مبلغ (ریال) | M7: درصد پیشرفت از صد (کل) | N7: درصد پیشرفت وزنی | O7: مبلغ (ریال)
A8: 1 | B8: 1.3.2 | C8: بيمه‌نامه‌ها | D8: =E8*$L$4 -> 7.1848629e+09 | E8: =SUM(E9:E12) -> 0.006 | H8: =SUM(H9:H12) -> 0.006 | I8: =SUM(I9:I12) -> 7.1848629e+09 | J8: =(J9*$E$9+J10*$E$10+J11*$E$11+J12*$E$12)/E8 -> 0.73708333 | K8: =SUM(K9:K12) -> 0.0044225 | L8: =SUM(L9:L12) -> 5295842703
A9: 2 | B9: 1.3.2.1 | C9: ارائه بيمه تمام خطر پيمانكاري و اخذ تاييد مشاور | D9: =E9*$L$4 -> 1.1974772e+09 | E9: =CBS!F21 -> 0.001 | G9: 1 | H9: =G9*E9 -> 0.001 | I9: =H9*$L$4 -> 1.1974772e+09 | J9: 0.56 | K9: =J9*E9 -> 0.00056 | L9: =J9*D9 -> 6.705872e+08 | M9: طبق آخرین مبالغ تائیدشده در ص و 15
A10: 3 | B10: 1.3.2.2 | C10: ارائه بيمه مسئوليت و اخذ تاييد مشاور | D10: =E10*$L$4 -> 1.1974772e+09 | E10: =CBS!F22 -> 0.001 | G10: 1 | H10: =G10*E10 -> 0.001 | I10: =H10*$L$4 -> 1.1974772e+09 | J10: 0.7 | K10: =J10*E10 -> 0.0007 | L10: =J10*D10 -> 8.3823401e+08
A11: 4 | B11: 1.3.2.3 | C11: تاييد بيمه‌هاي تمام خطر و مسئوليت توسط كارفرما | D11: =E11*$L$4 -> 1.1974772e+09 | E11: =CBS!F23 -> 0.001 | G11: 1 | H11: =G11*E11 -> 0.001 | I11: =H11*$L$4 -> 1.1974772e+09 | J11: 0.6125 | K11: =J11*E11 -> 0.0006125 | L11: =J11*D11 -> 7.3345476e+08
A12: 5 | B12: 1.3.2.4 | C12: پيگيري تا صدور بيمه‌نامه‌هاي فوق | D12: =E12*$L$4 -> 3.5924315e+09 | E12: =CBS!F24 -> 0.003 | G12: 1 | H12: =G12*E12 -> 0.003 | I12: =H12*$L$4 -> 3.5924315e+09 | J12: 0.85 | K12: =J12*E12 -> 0.00255 | L12: =J12*D12 -> 3.0535667e+09

Sheet تجهیز کارگاه اولیه
D1: کارفرما: | E1: راه‏آهن جمهوری اسلامی ایران | J1: عنوان قرارداد: | L1: طراحی، تأمین و اجرای دو خطه کردن راه‏آهن (زیرسازی، پل‏سازی، روسازی) محور مشك-سيستان
D2: مشاور طرح: | E2: مهندسین مشاور صحن بوستان
D3: مشارکت: | E3: مشاركت تكنيك-پل‏رود-کنکاوان معدن شیراز | J3: شماره و تاریخ ابلاغ قرارداد: | L3: 400/66891/ی مورخ 93/11/20
D4: صورت‏وضعیت شماره: | E4: ='خلاصه مالي صورت وضعیت'!E4 -> موقت 16 | J4: مبلغ قرارداد (ریال): | L4: ='خلاصه مالي صورت وضعیت'!G4:G5 -> 1197477151532
D5: تاریخ صورت‏وضعیت: | E5: ='خلاصه مالي صورت وضعیت'!E5 -> 1403/06/10
A6: ردیف | B6: W.B.S | C6: عنوان فعالیت | D6: هزینه کامل (ريال) | E6: وزن کامل (%) | F6: فصل مرتبط از فهرست بها | G6: گروه مشارکت | J6: مشاور زیربنایی | M6: کارفرما | P6: مدارك پشتيبان
G7: درصد پیشرفت از سرفصل (کل) | H7: درصد پیشرفت وزنی | I7: مبلغ (ریال) | J7: درصد پیشرفت از صد (کل) | K7: درصد پیشرفت وزنی | L7: مبلغ (ریال) | M7: درصد پیشرفت از صد (کل) | N7: درصد پیشرفت وزنی | O7: مبلغ (ریال)
A8: 1 | B8: 1.3.3 | C8: تجهیز اوليه کارگاه | D8: =E8*$L$4 -> 20357111576 | E8: =SUM(E9:E20) -> 0.017 | H8: =SUM(H9:H20) -> 0.017 | I8: =SUM(I9:I20) -> 20357111576 | J8: =L8/D8 -> 0.925 | K8: =L8/L4 -> 0.015725 | L8: =SUM(L9:L20) -> 1.8830328e+10
A9: 2 | B9: 1.3.3.1 | C9: آغاز عمليات تجهيز كارگاه | D9: =E9*$L$4 -> 0 | E9: =CBS!F27 -> 0 | G9: 1 | H9: =G9*E9 -> 0 | I9: =H9*$L$4 -> 0 | K9: =J9*E9 -> 0 | L9: =$L$4*K9 -> 0
A10: 3 | B10: 1.3.3.2 | C10: تامين و تجهيز كامل محل سكونت عوامل پيمانكار، مشاور و كارفرما | D10: =E10*$L$4 -> 3.0535667e+09 | E10: =CBS!F28 -> 0.00255 | G10: 1 | H10: =G10*E10 -> 0.00255 | I10: =H10*$L$4 -> 3.0535667e+09 | J10: 1 | K10: =J10*E10 -> 0.00255 | L10: =$L$4*K10 -> 3.0535667e+09
A11: 4 | B11: 1.3.3.3 | C11: محوطه‌سازي و تامين راه‌هاي دسترسي، سرويس و ارتباطي | D11: =E11*$L$4 -> 1.2214267e+09 | E11: =CBS!F29 -> 0.00102 | G11: 1 | H11: =G11*E11 -> 0.00102 | I11: =H11*$L$4 -> 1.2214267e+09 | J11: 1 | K11: =J11*E11 -> 0.00102 | L11: =$L$4*K11 -> 1.2214267e+09
A12: 5 | B12: 1.3.3.4 | C12: تامين و تجهيز ساختمان‌هاي موقت اداري و دفاتر كار عوامل پيمانكار، مشاور و كارفرما و تجهيز آنها | D12: =E12*$L$4 -> 3.0535667e+09 | E12: =CBS!F30 -> 0.00255 | G12: 1 | H12: =G12*E12 -> 0.00255 | I12: =H12*$L$4 -> 3.0535667e+09 | J12: 1 | K12: =J12*E12 -> 0.00255 | L12: =$L$4*K12 -> 3.0535667e+09
A13: 6 | B13: 1.3.3.5 | C13: تامين آب، برق، سيستم مخابراتي، اينترنت و سوخت كارگاه | D13: =E13*$L$4 -> 2.0357112e+09 | E13: =CBS!F31 -> 0.0017 | G13: 1 | H13: =G13*E13 -> 0.0017 | I13: =H13*$L$4 -> 2.0357112e+09 | J13: 1 | K13: =J13*E13 -> 0.0017 | L13: =$L$4*K13 -> 2.0357112e+09
A14: 7 | B14: 1.3.3.6 | C14: اقدامات ايجاد و تامين و تجهيز ساختمان‌هاي پشتيباني، انبار و تعميرگاه | D14: =E14*$L$4 -> 1.83214e+09 | E14: =CBS!F32 -> 0.00153 | G14: 1 | H14: =G14*E14 -> 0.00153 | I14: =H14*$L$4 -> 1.83214e+09 | J14: 1 | K14: =J14*E14 -> 0.00153 | L14: =$L$4*K14 -> 1.83214e+09
A15: 8 | B15: 1.3.3.7 | C15: تامين و تجهيز آزمايشگاه | D15: =E15*$L$4 -> 6.1071335e+08 | E15: =CBS!F33 -> 0.00051 | G15: 1 | H15: =G15*E15 -> 0.00051 | I15: =H15*$L$4 -> 6.1071335e+08 | J15: 1 | K15: =J15*E15 -> 0.00051 | L15: =$L$4*K15 -> 6.1071335e+08
A16: 9 | B16: 1.3.3.8 | C16: محوطه‌سازي كارگاه عمومي و كارگاه روسازي | D16: =E16*$L$4 -> 2.0357112e+09 | E16: =CBS!F34 -> 0.0017 | G16: 1 | H16: =G16*E16 -> 0.0017 | I16: =H16*$L$4 -> 2.0357112e+09 | J16: 1 | K16: =J16*E16 -> 0.0017 | L16: =$L$4*K16 -> 2.0357112e+09
A17: 10 | B17: 1.3.3.9 | C17: اقدامات اجرايي براي تامين و نصب ماشين‌الات و تجهيزات و راه‌اندازي آنها | D17: =E17*$L$4 -> 3.0535667e+09 | E17: =CBS!F35 -> 0.00255 | G17: 1 | H17: =G17*E17 -> 0.00255 | I17: =H17*$L$4 -> 3.0535667e+09 | J17: 1 | K17: =J17*E17 -> 0.00255 | L17: =$L$4*K17 -> 3.0535667e+09
A18: 11 | B18: 1.3.3.10 | C18: اقدامات اوليه براي بهداشت، ايمني و حفاظت كار و محيط زيست | D18: =E18*$L$4 -> 1.4249978e+09 | E18: =CBS!F36 -> 0.00119 | G18: 1 | H18: =G18*E18 -> 0.00119 | I18: =H18*$L$4 -> 1.4249978e+09 | J18: 1 | K18: =J18*E18 -> 0.00119 | L18: =$L$4*K18 -> 1.4249978e+09
A19: 12 | B19: 1.3.3.11 | C19: بيمه تجهيز كارگاه | D19: =E19*$L$4 -> 2.0357112e+09 | E19: =CBS!F25 -> 0.0017 | G19: 1 | H19: =G19*E19 -> 0.0017 | I19: =H19*$L$4 -> 2.0357112e+09 | J19: 0.25 | K19: =J19*E19 -> 0.000425 | L19: =$L$4*K19 -> 5.0892779e+08 | M19: طبق آخرین مبالغ تائیدشده در ص و 15
A20: 13 | B20: 1.3.3.12 | C20: پايان تجهيز اوليه كارگاه | D20: =E20*$L$4 -> 0 | E20: =CBS!F38 -> 0 | G20: 1 | H20: =G20*E20 -> 0 | I20: =H20*$L$4 -> 0 | K20: =J20*E20 -> 0 | L20: =$L$4*K20 -> 0

Sheet تجهیز کارگاه مستمر
D1: کارفرما: | E1: راه‏آهن جمهوری اسلامی ایران | J1: عنوان قرارداد: | L1: طراحی، تأمین و اجرای دو خطه کردن راه‏آهن (زیرسازی، پل‏سازی، روسازی) محور مشك-سيستان
D2: مشاور طرح: | E2: مهندسین مشاور صحن بوستان
D3: مشارکت: | E3: مشاركت تكنيك-پل‏رود-کنکاوان معدن شیراز | J3: شماره و تاریخ ابلاغ قرارداد: | L3: 400/66891/ی مورخ 93/11/20
D4: صورت‏وضعیت شماره: | E4: ='خلاصه مالي صورت وضعیت'!E4 -> موقت 16 | J4: مبلغ قرارداد (ریال): | L4: ='خلاصه مالي صورت وضعیت'!G4:G5 -> 1197477151532
D5: تاریخ صورت‏وضعیت: | E5: ='خلاصه مالي صورت وضعیت'!E5 -> 1403/06/10
A6: ردیف | B6: W.B.S | C6: عنوان فعالیت | D6: هزینه کامل (ريال) | E6: وزن کامل (%) | F6: فصل مرتبط از فهرست بها | G6: گروه مشارکت | J6: مشاور زیربنایی | M6: کارفرما | P6: مدارك پشتيبان
G7: درصد پیشرفت از سرفصل (کل) | H7: درصد پیشرفت وزنی | I7: مبلغ (ریال) | J7: درصد پیشرفت از صد (کل) | K7: درصد پیشرفت وزنی | L7: مبلغ (ریال) | M7: درصد پیشرفت از صد (کل) | N7: درصد پیشرفت وزنی | O7: مبلغ (ریال)
A8: 1 | B8: 1.3.4 | C8: تجهیز مستمر کارگاه | D8: =E8*$L$4 -> 27541974485 | E8: =SUM(E9:E18) -> 0.023 | H8: =SUM(H9:H18) -> 0.023 | I8: =SUM(I9:I18) -> 2.7541974e+10 | J8: =L8/D8 -> 0.383 | K8: =SUM(K9:K18) -> 0.008809 | L8: =SUM(L9:L18) -> 1.0548576e+10
A9: 2 | B9: 1.3.4.1 | C9: تداوم تامين و نگهداري اقامت‌گاه عوامل پيمانكار، مشاور و كارفرما | D9: =E9*$L$4 -> 1.3770987e+09 | E9: =CBS!D39 -> 0.00115 | G9: 1 | H9: =G9*E9 -> 0.00115 | I9: =H9*$L$4 -> 1.3770987e+09 | J9: 0.383 | K9: =J9*E9 -> 0.00044045 | L9: =$L$4*K9 -> 5.2742881e+08 | M9: به نسبت پیشرفت فیزیکی پروژه (باتوجه به عدم پذیرش کیفیت بخشی از ابنیه فنی اجرا شده مسیر) دلیل اختلاف: درصد پیشرفت فیزیکی
A10: 3 | B10: 1.3.4.2 | C10: تامين و سرو خوراك عوامل پيمانكار، مشاور و كارفرما | D10: =E10*$L$4 -> 8.2625923e+09 | E10: =CBS!D40 -> 0.0069 | G10: 1 | H10: =G10*E10 -> 0.0069 | I10: =H10*$L$4 -> 8.2625923e+09 | J10: =J9 -> 0.383 | K10: =J10*E10 -> 0.0026427 | L10: =$L$4*K10 -> 3.1645729e+09
A11: 4 | B11: 1.3.4.3 | C11: برقراري سرويس اياب و ذهاب كارگاه | D11: =E11*$L$4 -> 6.8854936e+09 | E11: =CBS!D41 -> 0.00575 | G11: 1 | H11: =G11*E11 -> 0.00575 | I11: =H11*$L$4 -> 6.8854936e+09 | J11: =J10 -> 0.383 | K11: =J11*E11 -> 0.00220225 | L11: =$L$4*K11 -> 2.6371441e+09
A12: 5 | B12: 1.3.4.4 | C12: بكاربستن مفاد نظام ايمني و حفاظت كار | D12: =E12*$L$4 -> 2.7541974e+09 | E12: =CBS!D42 -> 0.0023 | G12: 1 | H12: =G12*E12 -> 0.0023 | I12: =H12*$L$4 -> 2.7541974e+09 | J12: =J11 -> 0.383 | K12: =J12*E12 -> 0.0008809 | L12: =$L$4*K12 -> 1.0548576e+09
A13: 6 | B13: 1.3.4.5 | C13: بكاربستن مفاد نظام بهداشت و حفظ محيط زيست | D13: =E13*$L$4 -> 2.7541974e+09 | E13: =CBS!D43 -> 0.0023 | G13: 1 | H13: =G13*E13 -> 0.0023 | I13: =H13*$L$4 -> 2.7541974e+09 | J13: =J12 -> 0.383 | K13: =J13*E13 -> 0.0008809 | L13: =$L$4*K13 -> 1.0548576e+09
A14: 7 | B14: 1.3.4.6 | C14: تداوم بهره‌مندي كارگاه از آب، برق، گاز، سوخت، تلفن و اينترنت | D14: =E14*$L$4 -> 4.1312962e+09 | E14: =CBS!D44 -> 0.00345 | G14: 1 | H14: =G14*E14 -> 0.00345 | I14: =H14*$L$4 -> 4.1312962e+09 | J14: =J13 -> 0.383 | K14: =J14*E14 -> 0.00132135 | L14: =$L$4*K14 -> 1.5822864e+09
A15: 8 | B15: 1.3.4.7 | C15: رعايت نظم و انضباط در محوطه و محيط‌هاي اداري، كارگاهي و كارگري در انطباق با 5s | D15: =E15*$L$4 -> 2.7541974e+08 | E15: =CBS!D45 -> 0.00023 | G15: 1 | H15: =G15*E15 -> 0.00023 | I15: =H15*$L$4 -> 2.7541974e+08 | J15: =J14 -> 0.383 | K15: =J15*E15 -> 8.809e-05 | L15: =$L$4*K15 -> 1.0548576e+08
A16: 9 | B16: 1.3.4.8 | C16: تداوم فعاليت‌هاي نت از طريق سنجش ميزان آماده بكار بودن ماشين‌آلات و تجهيزات | D16: =E16*$L$4 -> 5.5083949e+08 | E16: =CBS!D46 -> 0.00046 | G16: 1 | H16: =G16*E16 -> 0.00046 | I16: =H16*$L$4 -> 5.5083949e+08 | J16: =J15 -> 0.383 | K16: =J16*E16 -> 0.00017618 | L16: =$L$4*K16 -> 2.1097152e+08
A17: 10 | B17: 1.3.4.9 | C17: تداوم فعاليت‌هاي انبارداري و مديريت و حفاظت اقلام | D17: =E17*$L$4 -> 2.7541974e+08 | E17: =CBS!D47 -> 0.00023 | G17: 1 | H17: =G17*E17 -> 0.00023 | I17: =H17*$L$4 -> 2.7541974e+08 | J17: =J16 -> 0.383 | K17: =J17*E17 -> 8.809e-05 | L17: =$L$4*K17 -> 1.0548576e+08
A18: 11 | B18: 1.3.4.10 | C18: تداوم حفظ و نگهداري دفاتر، محيط‌هاي اداري و پشتيباني در سطح استاندارد نور و تهويه و ... | D18: =E18*$L$4 -> 2.7541974e+08 | E18: =CBS!D48 -> 0.00023 | G18: 1 | H18: =G18*E18 -> 0.00023 | I18: =H18*$L$4 -> 2.7541974e+08 | J18: =J17 -> 0.383 | K18: =J18*E18 -> 8.809e-05 | L18: =$L$4*K18 -> 1.0548576e+08

Sheet خدمات طراحي  مهندسي پیش از اجرا
D1: کارفرما: | E1: راه‏آهن جمهوری اسلامی ایران | J1: عنوان قرارداد: | L1: طراحی، تأمین و اجرای دو خطه کردن راه‏آهن (زیرسازی، پل‏سازی، روسازی) محور مشك-سيستان
D2: مشاور طرح: | E2: مهندسین مشاور صحن بوستان
D3: مشارکت: | E3: مشاركت تكنيك-پل‏رود-کنکاوان معدن شیراز | J3: شماره و تاریخ ابلاغ قرارداد: | L3: 400/66891/ی مورخ 93/11/20
D4: صورت‏وضعیت شماره: | E4: موقت 16 | J4: مبلغ قرارداد (ریال): | L4: ='خلاصه مالي صورت وضعیت'!G4:G5 -> 1197477151532
D5: تاریخ صورت‏وضعیت: | E5: ='خلاصه مالي صورت وضعیت'!E5 -> 1403/06/10
A6: ردیف | B6: W.B.S | C6: عنوان فعالیت | D6: هزینه کامل (ريال) | E6: وزن کامل (%) | F6: فصل مرتبط از فهرست بها | G6: گروه مشارکت | J6: مشاور زیربنایی | M6: کارفرما | P6: مدارك پشتيبان
G7: درصد پیشرفت از سرفصل (کل) | H7: درصد پیشرفت وزنی | I7: مبلغ (ریال) | J7: درصد پیشرفت از صد (کل) | K7: درصد پیشرفت وزنی | L7: مبلغ (ریال) | M7: درصد پیشرفت از صد (کل) | N7: درصد پیشرفت وزنی | O7: مبلغ (ریال)
A8: 1 | B8: 1.4.1 | C8: خدمات طراحي و مهندسی پيش از اجرا | D8: =E8*$L$4 -> 2.095585e+10 | E8: =SUM(E9:E15,E21,E27:E33,E39,E45:E51) -> 0.0175 | H8: =SUM(H9:H15,H21,H27:H33,H39,H45:H51) -> 0.0175 | I8: =SUM(I9:I15,I21,I27:I33,I39,I45:I51) -> 2.095585e+10 | J8: =L8/D8 -> 1 | K8: =J8*E8 -> 0.0175 | L8: =L9+L10+L11+L12+L13+L14+L15+L21+L28+L29+L30+L31+L32+L33+L39+L45+L46+L47+L48+L49+L50+L51+L27 -> 2.095585e+10
A9: 2 | B9: 1.4.1.1 | C9: آغاز مطالعات مهندسي و طراحي | D9: =E9*$L$4 -> 0 | E9: =CBS!D51 -> 0 | G9: 1 | H9: =G9*E9 -> 0 | I9: =H9*$L$4 -> 0 | K9: =J9*E9 -> 0 | L9: =J9*D9 -> 0
A10: 3 | B10: 1.4.1.2 | C10: نقشه‌هاي توپوگرافی براساس برداشت مستقیم زمینی (1:2000 و1:500) | D10: =E10*$L$4 -> 4.19117e+09 | E10: =CBS!D52 -> 0.0035 | G10: 1 | H10: =G10*E10 -> 0.0035 | I10: =H10*$L$4 -> 4.19117e+09 | J10: 1 | K10: =J10*E10 -> 0.0035 | L10: =J10*D10 -> 4.19117e+09
A11: 4 | B11: 1.4.1.3 | C11: مطالعات اولیه شناخت و تحلیل وضع موجود | D11: =E11*$L$4 -> 8.3823401e+08 | E11: =CBS!D53 -> 0.0007 | G11: 1 | H11: =G11*E11 -> 0.0007 | I11: =H11*$L$4 -> 8.3823401e+08 | J11: 1 | K11: =J11*E11 -> 0.0007 | L11: =J11*D11 -> 8.3823401e+08
A12: 5 | B12: 1.4.1.4 | C12: مطالعات طراحي رعايت سرعت طرح در طول محور و برآورد مقايسه‌اي مسير حركت در حريم | D12: =E12*$L$4 -> 1.1974772e+09 | E12: =CBS!D54 -> 0.001 | G12: 1 | H12: =G12*E12 -> 0.001 | I12: =H12*$L$4 -> 1.1974772e+09 | J12: 1 | K12: =J12*E12 -> 0.001 | L12: =J12*D12 -> 1.1974772e+09
A13: 6 | B13: 1.4.1.5 | C13: مطالعات اولیه ژئوتکنیک و برداشت وضع موجود | D13: =E13*$L$4 -> 4.19117e+08 | E13: =CBS!D55 -> 0.00035 | G13: 1 | H13: =G13*E13 -> 0.00035 | I13: =H13*$L$4 -> 4.19117e+08 | J13: 1 | K13: =J13*E13 -> 0.00035 | L13: =J13*D13 -> 4.19117e+08
A14: 7 | B14: 1.4.1.6 | C14: گزارش مطالعات تکمیلی ژئوتکنیک (صحرایی و آزمایشگاهی) | D14: =E14*$L$4 -> 4.19117e+08 | E14: =CBS!D56 -> 0.00035 | G14: 1 | H14: =G14*E14 -> 0.00035 | I14: =H14*$L$4 -> 4.19117e+08 | J14: 1 | K14: =J14*E14 -> 0.00035 | L14: =J14*D14 -> 4.19117e+08
A15: 8 | B15: 1.4.1.7 | C15: گزارش طراحی روسازی | D15: =E15*$L$4 -> 1.1974772e+09 | E15: =SUM(E16:E20) -> 0.001 | H15: =SUM(H16:H20) -> 0.001 | I15: =SUM(I16:I20) -> 1.1974772e+09 | J15: 1 | K15: =J15*E15 -> 0.001 | L15: =J15*D15 -> 1.1974772e+09
A16: 9 | B16: 1.4.1.7.1 | C16: بالاست | D16: =E16*$L$4 -> 2.3949543e+08 | E16: =CBS!D58 -> 0.0002 | G16: 1 | H16: =G16*E16 -> 0.0002 | I16: =H16*$L$4 -> 2.3949543e+08 | K16: =J16*E16 -> 0 | L16: =J16*D16 -> 0
A17: 10 | B17: 1.4.1.7.2 | C17: تراورس | D17: =E17*$L$4 -> 2.3949543e+08 | E17: =CBS!D59 -> 0.0002 | G17: 1 | H17: =G17*E17 -> 0.0002 | I17: =H17*$L$4 -> 2.3949543e+08 | K17: =J17*E17 -> 0 | L17: =J17*D17 -> 0
A18: 11 | B18: 1.4.1.7.3 | C18: پابند | D18: =E18*$L$4 -> 2.3949543e+08 | E18: =CBS!D60 -> 0.0002 | G18: 1 | H18: =G18*E18 -> 0.0002 | I18: =H18*$L$4 -> 2.3949543e+08 | K18: =J18*E18 -> 0 | L18: =J18*D18 -> 0
A19: 12 | B19: 1.4.1.7.4 | C19: ریل | D19: =E19*$L$4 -> 2.3949543e+08 | E19: =CBS!D61 -> 0.0002 | G19: 1 | H19: =G19*E19 -> 0.0002 | I19: =H19*$L$4 -> 2.3949543e+08 | K19: =J19*E19 -> 0 | L19: =J19*D19 -> 0
A20: 13 | B20: 1.4.1.7.5 | C20: سوزن | D20: =E20*$L$4 -> 2.3949543e+08 | E20: =CBS!D62 -> 0.0002 | G20: 1 | H20: =G20*E20 -> 0.0002 | I20: =H20*$L$4 -> 2.3949543e+08 | K20: =J20*E20 -> 0 | L20: =J20*D20 -> 0
A21: 14 | B21: 1.4.1.8 | C21: نقشه‏های اجرایی روسازی | D21: =E21*$L$4 -> 1.1974772e+09 | E21: =SUM(E22:E26) -> 0.001 | H21: =SUM(H22:H26) -> 0.001 | I21: =SUM(I22:I26) -> 1.1974772e+09 | J21: 1 | L21: =J21*D21 -> 1.1974772e+09
A22: 15 | B22: 1.4.1.8.1 | C22: بالاست | D22: =E22*$L$4 -> 2.3949543e+08 | E22: =CBS!D64 -> 0.0002 | G22: 1 | H22: =G22*E22 -> 0.0002 | I22: =H22*$L$4 -> 2.3949543e+08 | K22: =J22*E22 -> 0 | L22: =J22*D22 -> 0
A23: 16 | B23: 1.4.1.8.2 | C23: تراورس | D23: =E23*$L$4 -> 2.3949543e+08 | E23: =CBS!D65 -> 0.0002 | G23: 1 | H23: =G23*E23 -> 0.0002 | I23: =H23*$L$4 -> 2.3949543e+08 | K23: =J23*E23 -> 0 | L23: =J23*D23 -> 0
A24: 17 | B24: 1.4.1.8.3 | C24: پابند | D24: =E24*$L$4 -> 2.3949543e+08 | E24: =CBS!D66 -> 0.0002 | G24: 1 | H24: =G24*E24 -> 0.0002 | I24: =H24*$L$4 -> 2.3949543e+08 | K24: =J24*E24 -> 0 | L24: =J24*D24 -> 0
A25: 18 | B25: 1.4.1.8.4 | C25: ریل | D25: =E25*$L$4 -> 2.3949543e+08 | E25: =CBS!D67 -> 0.0002 | G25: 1 | H25: =G25*E25 -> 0.0002 | I25: =H25*$L$4 -> 2.3949543e+08 | K25: =J25*E25 -> 0 | L25: =J25*D25 -> 0
A26: 19 | B26: 1.4.1.8.5 | C26: سوزن | D26: =E26*$L$4 -> 2.3949543e+08 | E26: =CBS!D68 -> 0.0002 | G26: 1 | H26: =G26*E26 -> 0.0002 | I26: =H26*$L$4 -> 2.3949543e+08 | K26: =J26*E26 -> 0 | L26: =J26*D26 -> 0
A27: 20 | B27: 1.4.1.9 | C27: گزارش روش اجرای روسازی (خطوط و سوز‌ن‌ها) | D27: =E27*$L$4 -> 1.1974772e+09 | E27: =CBS!D69 -> 0.001 | G27: 1 | H27: =G27*E27 -> 0.001 | I27: =H27*$L$4 -> 1.1974772e+09 | J27: 1 | K27: =J27*E27 -> 0.001 | L27: =J27*D27 -> 1.1974772e+09
A28: 21 | B28: 1.4.1.10 | C28: گزارش طرح هندسی مسیر | D28: =E28*$L$4 -> 5.9873858e+08 | E28: =CBS!D70 -> 0.0005 | G28: 1 | H28: =G28*E28 -> 0.0005 | I28: =H28*$L$4 -> 5.9873858e+08 | J28: 1 | K28: =J28*E28 -> 0.0005 | L28: =J28*D28 -> 5.9873858e+08
A29: 22 | B29: 1.4.1.11 | C29: نقشه‏های پلان طرح هندسی مسیر | D29: =E29*$L$4 -> 2.3949543e+08 | E29: =CBS!D71 -> 0.0002 | G29: 1 | H29: =G29*E29 -> 0.0002 | I29: =H29*$L$4 -> 2.3949543e+08 | J29: 1 | K29: =J29*E29 -> 0.0002 | L29: =J29*D29 -> 2.3949543e+08
A30: 23 | B30: 1.4.1.12 | C30: نقشه‏های پروفیل طولی | D30: =E30*$L$4 -> 2.3949543e+08 | E30: =CBS!D72 -> 0.0002 | G30: 1 | H30: =G30*E30 -> 0.0002 | I30: =H30*$L$4 -> 2.3949543e+08 | J30: 1 | K30: =J30*E30 -> 0.0002 | L30: =J30*D30 -> 2.3949543e+08
A31: 24 | B31: 1.4.1.13 | C31: نقشه‏های مقاطع عرضی | D31: =E31*$L$4 -> 1.1974772e+09 | E31: =CBS!D73 -> 0.001 | G31: 1 | H31: =G31*E31 -> 0.001 | I31: =H31*$L$4 -> 1.1974772e+09 | J31: 1 | K31: =J31*E31 -> 0.001 | L31: =J31*D31 -> 1.1974772e+09
A32: 25 | B32: 1.4.1.14 | C32: ارائه احجام عملیات خاکی براساس میخکوبی | D32: =E32*$L$4 -> 3.5924315e+08 | E32: =CBS!D74 -> 0.0003 | G32: 1 | H32: =G32*E32 -> 0.0003 | I32: =H32*$L$4 -> 3.5924315e+08 | J32: 1 | K32: =J32*E32 -> 0.0003 | L32: =J32*D32 -> 3.5924315e+08
A33: 26 | B33: 1.4.1.15 | C33: گزارش محاسباتی پل‌های مسیر | D33: =E33*$L$4 -> 1.1974772e+09 | E33: =CBS!D75 -> 0.001 | H33: =SUM(H34:H38) -> 0.001 | I33: =SUM(I34:I38) -> 1.1974772e+09 | J33: 1 | K33: =J33*E33 -> 0.001 | L33: =J33*D33 -> 1.1974772e+09
A34: 27 | B34: 1.4.1.15.1 | C34: پلهای با دهانه 1 متر | D34: =E34*$L$4 -> 2.3949543e+08 | E34: =CBS!D76 -> 0.0002 | G34: 1 | H34: =G34*E34 -> 0.0002 | I34: =H34*$L$4 -> 2.3949543e+08 | K34: =J34*E34 -> 0 | L34: =J34*D34 -> 0
A35: 28 | B35: 1.4.1.15.2 | C35: پلهای با دهانه 2 متر | D35: =E35*$L$4 -> 2.3949543e+08 | E35: =CBS!D77 -> 0.0002 | G35: 1 | H35: =G35*E35 -> 0.0002 | I35: =H35*$L$4 -> 2.3949543e+08 | K35: =J35*E35 -> 0 | L35: =J35*D35 -> 0
A36: 29 | B36: 1.4.1.15.3 | C36: پلهای با دهانه 3 متر | D36: =E36*$L$4 -> 2.3949543e+08 | E36: =CBS!D78 -> 0.0002 | G36: 1 | H36: =G36*E36 -> 0.0002 | I36: =H36*$L$4 -> 2.3949543e+08 | K36: =J36*E36 -> 0 | L36: =J36*D36 -> 0
A37: 30 | B37: 1.4.1.15.4 | C37: پلهای با دهانه بیش از 3 متر | D37: =E37*$L$4 -> 2.3949543e+08 | E37: =CBS!D79 -> 0.0002 | G37: 1 | H37: =G37*E37 -> 0.0002 | I37: =H37*$L$4 -> 2.3949543e+08 | K37: =J37*E37 -> 0 | L37: =J37*D37 -> 0
A38: 31 | B38: 1.4.1.15.5 | C38: قطعات پیش‏ساخته دیوار برگشتی | D38: =E38*$L$4 -> 2.3949543e+08 | E38: =CBS!D80 -> 0.0002 | G38: 1 | H38: =G38*E38 -> 0.0002 | I38: =H38*$L$4 -> 2.3949543e+08 | K38: =J38*E38 -> 0 | L38: =J38*D38 -> 0
A39: 32 | B39: 1.4.1.16 | C39: نقشه‌های اجرایی پل‌های مسیر | D39: =E39*$L$4 -> 2.9936929e+09 | E39: =CBS!D81 -> 0.0025 | H39: =SUM(H40:H44) -> 0.0025 | I39: =SUM(I40:I44) -> 2.9936929e+09 | J39: 1 | L39: =J39*D39 -> 2.9936929e+09
A40: 33 | B40: 1.4.1.16.1 | C40: پلهای با دهانه 1 متر | D40: =E40*$L$4 -> 5.9873858e+08 | E40: =CBS!D82 -> 0.0005 | G40: 1 | H40: =G40*E40 -> 0.0005 | I40: =H40*$L$4 -> 5.9873858e+08 | K40: =J40*E40 -> 0 | L40: =J40*D40 -> 0
...

Sheet خدمات طراحي و مهندسي حین اجرا
D1: کارفرما: | E1: راه‏آهن جمهوری اسلامی ایران | J1: عنوان قرارداد: | L1: طراحی، تأمین و اجرای دو خطه کردن راه‏آهن (زیرسازی، پل‏سازی، روسازی) محور مشك-سيستان
D2: مشاور طرح: | E2: مهندسین مشاور صحن بوستان
D3: مشارکت: | E3: مشاركت تكنيك-پل‏رود-کنکاوان معدن شیراز | J3: شماره و تاریخ ابلاغ قرارداد: | L3: 400/66891/ی مورخ 93/11/20
D4: صورت‏وضعیت شماره: | E4: موقت 16 | J4: مبلغ قرارداد (ریال): | L4: ='خلاصه مالي صورت وضعیت'!G4:G5 -> 1197477151532
D5: تاریخ صورت‏وضعیت: | E5: ='خلاصه مالي صورت وضعیت'!E5 -> 1403/06/10
A6: ردیف | B6: W.B.S | C6: عنوان فعالیت | D6: هزینه کامل (ريال) | E6: وزن کامل (%) | F6: فصل مرتبط از فهرست بها | G6: گروه مشارکت | J6: مشاور زیربنایی | M6: کارفرما | P6: مدارك پشتيبان
G7: درصد پیشرفت از سرفصل (کل) | H7: درصد پیشرفت وزنی | I7: مبلغ (ریال) | J7: درصد پیشرفت از صد (کل) | K7: درصد پیشرفت وزنی | L7: مبلغ (ریال) | M7: درصد پیشرفت از صد (کل) | N7: درصد پیشرفت وزنی | O7: مبلغ (ریال)
A8: 1 | B8: 1.4.2 | C8: خدمات مهندسی حین اجرا | D8: =E8*$L$4 -> 3.8918007e+10 | E8: =SUM(E9:E15) -> 0.0325 | H8: =SUM(H9:H15) -> 0.02895 | I8: =SUM(I9:I15) -> 3.4666964e+10 | J8: =(J9*$E$9+J10*$E$10+J11*$E$11+J12*$E$12+J13*$E$13+J14*$E$14+J15*$E$15)/$E$8 -> 0.34116462 | K8: =SUM(K9:K15) -> 0.01108785 | L8: =SUM(L9:L15) -> 1.3277447e+10
A9: 2 | B9: 1.4.2.1 | C9: استقرار عوامل نظارت كيفي كارگاه در انطباق با بند 2-3 پيوست شماره 1 قرارداد | D9: =E9*$L$4 -> 1.365124e+10 | E9: =CBS!D95 -> 0.0114 | G9: 1 | H9: =G9*E9 -> 0.0114 | I9: =H9*$L$4 -> 1.365124e+10 | J9: 0.383 | K9: =J9*$E9 -> 0.0043662 | L9: =J9*D9 -> 5.2284247e+09 | M9: به میزان پیشرفت فیزیکی پروژه (نظارت بر تامین و اجرای روسازی توسط پیمانکار انجام نگردید) ضمن اینکه طبق مکاتبات موجود عوامل نظارت و کیفیت نظارت نیز مورد تائید نبوده است. نقشه های چون ساخت و كتابچه‌هاي بهره‌برداري، نگهداري و تعميرات، توسط پیمانکار تهیه و ارائه نشده است دلیل اختلاف: درصد پیشرفت در این بخش
A10: 3 | B10: 1.4.2.2 | C10: انجام آزمايشات مورد لزوم حين اجرا و ارائه نتايج و گزارشات تحليلي | D10: =E10*$L$4 -> 8.9810786e+09 | E10: =CBS!D96 -> 0.0075 | G10: 1 | H10: =G10*E10 -> 0.0075 | I10: =H10*$L$4 -> 8.9810786e+09 | J10: =J9 -> 0.383 | K10: =J10*$E10 -> 0.0028725 | L10: =J10*D10 -> 3.4397531e+09
A11: 4 | B11: 1.4.2.3 | C11: كاليبراسيون ادواري تجهيزات پايش و اندازه‌ گيري | D11: =E11*$L$4 -> 7.7836015e+08 | E11: =CBS!D97 -> 0.00065 | G11: 1 | H11: =G11*E11 -> 0.00065 | I11: =H11*$L$4 -> 7.7836015e+08 | J11: =J10 -> 0.383 | K11: =J11*$E11 -> 0.00024895 | L11: =J11*D11 -> 2.9811194e+08
A12: 5 | B12: 1.4.2.4 | C12: تهيه دستورالعمل‌ها و نقشه‌هاي فني كارگاهي | D12: =E12*$L$4 -> 3.4726837e+09 | E12: =CBS!D98 -> 0.0029 | G12: 1 | H12: =G12*E12 -> 0.0029 | I12: =H12*$L$4 -> 3.4726837e+09 | J12: =J11 -> 0.383 | K12: =J12*$E12 -> 0.0011107 | L12: =J12*D12 -> 1.3300379e+09
A13: 6 | B13: 1.4.2.5 | C13: انجام تعهدات برنامه‌ريزي و مديريت محدوده، زمان و هزينه براساس نظام مديريت پروژه، ارائه گزارشات عملكرد پروژه، برپايي و شركت در جلسات كنترل پروژه و پيگيري مصوبات جلسه | D13: =E13*$L$4 -> 7.7836015e+09 | E13: =CBS!D99 -> 0.0065 | G13: 1 | H13: =G13*E13 -> 0.0065 | I13: =H13*$L$4 -> 7.7836015e+09 | J13: =J12 -> 0.383 | K13: =J13*$E13 -> 0.0024895 | L13: =J13*D13 -> 2.9811194e+09
A14: 7 | B14: 1.4.2.6 | C14: تهيه نقشه‏هاي چون ساخت | D14: =E14*$L$4 -> 3.4726837e+09 | E14: =CBS!D100 -> 0.0029 | G14: 0 | H14: =G14*E14 -> 0 | I14: =H14*$L$4 -> 0 | J14: 0 | K14: =J14*$E14 -> 0 | L14: =J14*D14 -> 0
A15: 8 | B15: 1.4.2.7 | C15: تهيه كتابچه‌هاي بهره‌برداري، نگهداري و تعميرات | D15: =E15*$L$4 -> 7.7836015e+08 | E15: =CBS!D101 -> 0.00065 | G15: 0 | H15: =G15*E15 -> 0 | I15: =H15*$L$4 -> 0 | J15: 0 | K15: =J15*$E15 -> 0 | L15: =J15*D15 -> 0

Sheet خدمات مهندسي حين اجرا
D1: کارفرما: | E1: راه آهن جمهوری اسلامی ایران | K1: صورت وضعبت شماره: | M1: تاریخ صورت وضعیت:
D2: مشاور طرح: | E2: مهندسین مشاور صحن بوستان | K2: عنوان قرارداد:
D3: پیمانکار: | K3: تاریخ قرارداد: | M3: شماره قرارداد:
K4: مبلغ قرارداد: | L4: 768000000000
A5: ردیف | B5: W.B.S | C5: عنوان فعالیت | D5: هزینه کامل (ريال) | E5: وزن کامل (%) | F5: فصل فهرست بها | G5: گروه مشارکت | J5: مشاور زیر بنایی | M5: کارفرما | P5: مدارك پشتيبان
G6: درصد پیشرفت (از 100) | H6: درصد پیشرفت وزنی | I6: مبلغ (ریال) | J6: درصد پیشرفت (از 100) | K6: درصد پیشرفت وزنی | L6: مبلغ (ریال) | M6: درصد پیشرفت (از 100) | N6: درصد پیشرفت وزنی | O6: مبلغ (ریال)
A7: 1 | B7: 1.4.1.2 | C7: خدمات مهندسی حین اجرا | D7: =E7*$L$4/100 -> 5.2912269e+10 | E7: ='جمع بندي صورت وضعیت'!E18 -> 6.8896184 | G7: =(G8*$E$8+G9*$E$9+G10*$E$10+G11*$E$11+G12*$E$12+G13*$E$13+G14*$E$14)/$E$7 -> 0 | H7: =SUM(H8:H14) -> 0 | I7: =SUM(I8:I14) -> 0 | J7: =(J8*$E$8+J9*$E$9+J10*$E$10+J11*$E$11+J12*$E$12+J13*$E$13+J14*$E$14)/$E$7 -> 0 | K7: =SUM(K8:K14) -> 0 | L7: =SUM(L8:L14) -> 0 | M7: =(M8*$E$8+M9*$E$9+M10*$E$10+M11*$E$11+M12*$E$12+M13*$E$13+M14*$E$14)/$E$7 -> 0 | N7: =SUM(N8:N14) -> 0 | O7: =SUM(O8:O14) -> 0
A8: 2 | B8: 1.4.1.2.1 | C8: استقرار عوامل نظارت كيفي كارگاه در انطباق با بند 2-3 پيوست شماره 1 قرارداد | D8: =E8*$L$4/100 -> 1.8519294e+10 | E8: 2.4113664 | H8: =G8*$E8 -> 0 | I8: =G8*$D8 -> 0 | K8: =J8*$E8 -> 0 | L8: =J8*$D8 -> 0 | N8: =M8*$E8 -> 0 | O8: =M8*$D8 -> 0
A9: 3 | B9: 1.4.1.2.2 | C9: انجام آزمايشات مورد لزوم حين اجرا و ارائه نتايج و گزارشات تحليلي | D9: =E9*$L$4/100 -> 1.2169822e+10 | E9: 1.5846122 | H9: =G9*E9 -> 0 | I9: =G9*D9 -> 0 | K9: =J9*$E9 -> 0 | L9: =J9*$D9 -> 0 | N9: =M9*$E9 -> 0 | O9: =M9*$D9 -> 0
A10: 4 | B10: 1.4.1.2.3 | C10: كاليبراسيون ادواري تجهيزات پايش و اندازه‌ گيري | D10: =E10*$L$4/100 -> 1.0582454e+09 | E10: 0.13779237 | H10: =G10*E10 -> 0 | I10: =G10*D10 -> 0 | K10: =J10*$E10 -> 0 | L10: =J10*$D10 -> 0 | N10: =M10*$E10 -> 0 | O10: =M10*$D10 -> 0
A11: 5 | B11: 1.4.1.2.4 | C11: تهيه دستورالعمل‌ها و نقشه‌هاي فني كارگاهي | D11: =E11*$L$4/100 -> 4.7621042e+09 | E11: 0.62006565 | H11: =G11*E11 -> 0 | I11: =G11*D11 -> 0 | K11: =J11*$E11 -> 0 | L11: =J11*$D11 -> 0 | N11: =M11*$E11 -> 0 | O11: =M11*$D11 -> 0
A12: 6 | B12: 1.4.1.2.5 | C12: انجام تعهدات برنامه‌ريزي و مديريت محدوده، زمان و هزينه براساس نظام مديريت پروژه، ارائه گزارشات عملكرد پروژه، برپايي و شركت در جلسات كنترل پروژه و پيگيري مصوبات جلسه | D12: =E12*$L$4/100 -> 1.0582454e+10 | E12: 1.3779237 | H12: =G12*E12 -> 0 | I12: =G12*D12 -> 0 | K12: =J12*$E12 -> 0 | L12: =J12*$D12 -> 0 | N12: =M12*$E12 -> 0 | O12: =M12*$D12 -> 0
A13: 7 | B13: 1.4.1.2.6 | C13: تهيه نقشه هاي چون ساخت | D13: =E13*$L$4/100 -> 4.7621042e+09 | E13: 0.62006565 | H13: =G13*E13 -> 0 | I13: =G13*D13 -> 0 | K13: =J13*$E13 -> 0 | L13: =J13*$D13 -> 0 | N13: =M13*$E13 -> 0 | O13: =M13*$D13 -> 0
A14: 8 | B14: 1.4.1.2.7 | C14: تهيه كتابچه‌هاي بهره‌برداري، نگهداري و تعميرات | D14: =E14*$L$4/100 -> 1.0582454e+09 | E14: 0.13779237 | H14: =G14*E14 -> 0 | I14: =G14*D14 -> 0 | K14: =J14*$E14 -> 0 | L14: =J14*$D14 -> 0 | N14: =M14*$E14 -> 0 | O14: =M14*$D14 -> 0
A15: 11 | B15: 1.4.1.2.11 | H15: =G15*E15 -> 0 | I15: =G15*D15 -> 0 | K15: =J15*E15 -> 0 | L15: =J15*D15 -> 0 | N15: =M15*E15 -> 0 | O15: =M15*D15 -> 0
A16: 12 | B16: 1.4.1.2.12 | H16: =G16*E16 -> 0 | I16: =G16*D16 -> 0 | K16: =J16*E16 -> 0 | L16: =J16*D16 -> 0 | N16: =M16*E16 -> 0 | O16: =M16*D16 -> 0
A17: 13 | B17: 1.4.1.2.13 | H17: =G17*E17 -> 0 | I17: =G17*D17 -> 0 | K17: =J17*E17 -> 0 | L17: =J17*D17 -> 0 | N17: =M17*E17 -> 0 | O17: =M17*D17 -> 0
A18: 14 | B18: 1.4.1.2.14 | H18: =G18*E18 -> 0 | I18: =G18*D18 -> 0 | K18: =J18*E18 -> 0 | L18: =J18*D18 -> 0 | N18: =M18*E18 -> 0 | O18: =M18*D18 -> 0
A19: 15 | B19: 1.4.1.2.15 | H19: =G19*E19 -> 0 | I19: =G19*D19 -> 0 | K19: =J19*E19 -> 0 | L19: =J19*D19 -> 0 | N19: =M19*E19 -> 0 | O19: =M19*D19 -> 0
A20: 16 | B20: 1.4.1.2.16 | H20: =G20*E20 -> 0 | I20: =G20*D20 -> 0 | K20: =J20*E20 -> 0 | L20: =J20*D20 -> 0 | N20: =M20*E20 -> 0 | O20: =M20*D20 -> 0
A21: 17 | B21: 1.4.1.2.17 | H21: =G21*E21 -> 0 | I21: =G21*D21 -> 0 | K21: =J21*E21 -> 0 | L21: =J21*D21 -> 0 | N21: =M21*E21 -> 0 | O21: =M21*D21 -> 0
A22: 18 | B22: 1.4.1.2.18 | H22: =G22*E22 -> 0 | I22: =G22*D22 -> 0 | K22: =J22*E22 -> 0 | L22: =J22*D22 -> 0 | N22: =M22*E22 -> 0 | O22: =M22*D22 -> 0
A23: 19 | B23: 1.4.1.2.19 | H23: =G23*E23 -> 0 | I23: =G23*D23 -> 0 | K23: =J23*E23 -> 0 | L23: =J23*D23 -> 0 | N23: =M23*E23 -> 0 | O23: =M23*D23 -> 0
A24: 20 | B24: 1.4.1.2.20 | H24: =G24*E24 -> 0 | I24: =G24*D24 -> 0 | K24: =J24*E24 -> 0 | L24: =J24*D24 -> 0 | N24: =M24*E24 -> 0 | O24: =M24*D24 -> 0
A25: 21 | B25: 1.4.1.2.21 | H25: =G25*E25 -> 0 | I25: =G25*D25 -> 0 | K25: =J25*E25 -> 0 | L25: =J25*D25 -> 0 | N25: =M25*E25 -> 0 | O25: =M25*D25 -> 0
A26: 22 | B26: 1.4.1.2.22 | H26: =G26*E26 -> 0 | I26: =G26*D26 -> 0 | K26: =J26*E26 -> 0 | L26: =J26*D26 -> 0 | N26: =M26*E26 -> 0 | O26: =M26*D26 -> 0
... A29: 25 | B29: 1.4.1.2.25 | H29: =G29*E29 -> 0 | I29: =G29*D29 -> 0 | K29: =J29*E29 -> 0 | L29: =J29*D29 -> 0 | N29: =M29*E29 -> 0 | O29: =M29*D29 -> 0
A30: مهر و امضإ گروه مشارکت شرکت مشاور مشاور | G30: مهر و امضا مشاور زیر بنایی مهندسین مشاور صحن بوستان | L30: کارفرما

Sheet خدمات تامین
D1: کارفرما: | E1: راه‏آهن جمهوری اسلامی ایران | J1: عنوان قرارداد: | L1: طراحی، تأمین و اجرای دو خطه کردن راه‏آهن (زیرسازی، پل‏سازی، روسازی) محور مشك-سيستان
D2: مشاور طرح: | E2: مهندسین مشاور صحن بوستان
D3: مشارکت: | E3: مشاركت تكنيك-پل‏رود-کنکاوان معدن شیراز | J3: شماره و تاریخ ابلاغ قرارداد: | L3: 400/66891/ی مورخ 93/11/20
D4: صورت‏وضعیت شماره: | E4: ='خلاصه مالي صورت وضعیت'!E4 -> موقت 16 | J4: مبلغ قرارداد (ریال): | L4: ='خلاصه مالي صورت وضعیت'!G4:G5 -> 1197477151532
D5: تاریخ صورت‏وضعیت: | E5: ='خلاصه مالي صورت وضعیت'!E5 -> 1403/06/10
A6: ردیف | B6: W.B.S | C6: عنوان فعالیت | D6: هزینه کامل (ريال) | E6: وزن کامل (%) | F6: فصل مرتبط از فهرست بها | G6: گروه مشارکت | J6: مشاور زیربنایی | M6: کارفرما | P6: مدارك پشتيبان
G7: درصد پیشرفت از سرفصل (کل) | H7: درصد پیشرفت وزنی | I7: مبلغ (ریال) | J7: درصد پیشرفت از صد (کل) | K7: درصد پیشرفت وزنی | L7: مبلغ (ریال) | M7: درصد پیشرفت از صد (کل) | N7: درصد پیشرفت وزنی | O7: مبلغ (ریال)
A8: 1 | B8: 1.5 | C8: خدمات تامین | D8: =D9+D16+D21+D27 -> 460789207909 | E8: =E9+E16+E21+E27 -> 0.3848 | G8: =I8/D8 -> 0.58138529 | H8: =H9+H16+H21+H27 -> 0.22371706 | I8: =I9+I16+I21+I27 -> 2.6789607e+11 | J8: =L8/D8 -> 0.032400864 | K8: =K9+K16+K21+K27 -> 0.012467853 | L8: =L9+L16+L21+L27 -> 1.4929969e+10
A9: 2 | B9: 1.5.1 | C9: ريل (هر 170 تن 0.494%) | D9: =D10+D13 -> 2.1554337e+11 | E9: =E10+E13 -> 0.1799979 | F9: 22 | H9: =H10+H13 -> 0.089998948 | I9: =I10+I13 -> 1.0777168e+11 | J9: =L9/D9 -> 0 | K9: =K10+K13 -> 0 | L9: =L10+L13 -> 0 | M9: 1-اعتبار مدارک ارائه شده ساقط گردیده و قرارداد مجددا جاری و فعال نگردید. 2- ریل پروژه توسط کارفرما تامین و دراختیار پیمانکار قرار گرفت. 3- بهای ردیفها، بهای واقعی فعالیت نمی باشد
A10: 3 | B10: 1.5.1.1 | C10: تشریفات تامین ریل | D10: =SUM(D11:D12) -> 1.0777168e+11 | E10: =SUM(E11:E12) -> 0.089998948 | H10: =SUM(H11:H12) -> 0.089998948 | I10: =SUM(I11:I12) -> 1.0777168e+11 | K10: =SUM(K11:K15) -> 0 | L10: =SUM(L11:L12) -> 0
A11: 4 | B11: 1.5.1.1.۱ | C11: ارائه اصل عقد قرارداد خرید ریل | D11: =E11*$L$4 -> 6.466301e+10 | E11: =CBS!D105 -> 0.053999369 | G11: 1 | H11: =G11*E11 -> 0.053999369 | I11: =H11*$L$4 -> 6.466301e+10 | J11: 0 | K11: =J11*E11 -> 0 | L11: =K11*$L$4 -> 0
A12: 5 | B12: 1.5.1.1.۲ | C12: پرداخت پیش پرداخت | D12: =E12*$L$4 -> 4.3108674e+10 | E12: =CBS!D106 -> 0.035999579 | G12: 1 | H12: =G12*E12 -> 0.035999579 | I12: =H12*$L$4 -> 4.3108674e+10 | J12: 0 | K12: =J12*E12 -> 0 | L12: =K12*$L$4 -> 0
A13: 6 | B13: 1.5.1.2 | C13: حمل و تخلیه ریل در محل کارگاه | D13: =SUM(D14:D15) -> 107771683892 | E13: =SUM(E14:E15) -> 0.089998948 | H13: =SUM(H14:H15) -> 0 | I13: =SUM(I14:I15) -> 0 | L13: =L14+L15 -> 0
A14: 7 | B14: 1.5.1.2.1 | C14: ارائه اسناد حمل خارجی | D14: =E14*$L$4 -> 6.466301e+10 | E14: =CBS!D108 -> 0.053999369 | G14: 0 | H14: =G14*E14 -> 0 | I14: =H14*$L$4 -> 0 | J14: 0 | K14: =J14*E14 -> 0 | L14: =K14*$L$4 -> 0
A15: 8 | B15: 1.5.1.2.۲ | C15: تخلیه و دپوی ریل در کارگاه | D15: =E15*$L$4 -> 4.3108674e+10 | E15: =CBS!D109 -> 0.035999579 | G15: 0 | H15: =G15*E15 -> 0 | I15: =H15*$L$4 -> 0 | J15: 0 | K15: =J15*E15 -> 0 | L15: =K15*$L$4 -> 0
A16: 9 | B16: 1.5.2 | C16: سوزن (هر سوزن 0.222%) | D16: 71850861189 | E16: =D16/$L$4 -> 0.060001864 | F16: 22 | H16: =H17+H18+H19+H20 -> 0.051001584 | I16: =I17+I18+I19+I20 -> 6.1073232e+10 | J16: =L16/D16 -> 0 | K16: =K17+K18+K19+K20 -> 0 | L16: =L17+L18+L19+L20 -> 0 | M16: 1-قرارداد منعقده با فروشنده به دلیل شرط درج شده در بند7 قرارداد، ارزش حقوقی نداشته و قابل پذیرش نمی باشد. 2-علی رغم پرداخت پیش پرداخت توسط کارفرما در وجه فروشنده، هیچ سوزنی تامین نگردید. 3- ضمن اینکه بهای ردیفها، بهای واقعی فعالیت نمی باشد
A17: 10 | B17: 1.5.2.1 | C17: عقد قرارداد | D17: =15%*$D$16 -> 1.0777629e+10 | E17: =D17/$L$4 -> 0.0090002796 | G17: 1 | H17: =G17*E17 -> 0.0090002796 | I17: =G17*D17 -> 1.0777629e+10 | J17: 0 | K17: =J17*E17 -> 0 | L17: =J17*D17 -> 0
