Workbook

Sheet مقایسه پروژه‌ها
A1: نمودار مقایسه‌ای شاخص‌های تعدیل | Cross-Project Comparison
A2: Toggle TRUE/FALSE to select activities | برای انتخاب TRUE/FALSE را تغییر دهید
A4: No. | B4: Project|پروژه | C4: Select | D4: Activity|فعالیت | F4: 📊 Chart Data
A5: 1 | B5: ابنیه|Buildings | C5: {=_xlfn.SWITCH(LEFT(B5,FIND("|",B5)-1),"ابنیه",HLOOKUP(D5,'نمودار ابنیه'!$B$5:$AD$6,2,FALSE),"مکانیکی",HLOOKUP(D5,'نمودار مکانیکی'!$B$5:$AJ$6,2,FALSE),"برقی",HLOOKUP(D5,'نمودار تاسیسات برقی'!$B$5:$AK$6,2,FALSE),"خطوط",HLOOKUP(D5,'نمودار خطوط انتقال '!$B$5:$R$6,2,FALSE),"شبکه",HLOOKUP(D5,'نمودار شبکه توزیع آ'!$B$5:$O$6,2,FALSE),"سد",HLOOKUP(D5,'نمودار سدسازی'!$B$5:$P$6,2,FALSE),"فاضلاب",HLOOKUP(D5,'نمودار جمع‌آوری و ا'!$B$5:$S$6,2,FALSE),"تجهیزات",HLOOKUP(D5,'نمودار تجهیزات آب و'!$B$5:$AG$6,2,FALSE),"پست",HLOOKUP(D5,'نمودار پست های انتق'!$B$5:$AH$6,2,FALSE),"نیرو",HLOOKUP(D5,'نمودار توزیع نیرو ب'!$B$5:$AE$6,2,FALSE),FALSE)} -> FALSE | D5: عملیات تخریب و برچیدن | E5: RowIdx | F5: Activity | G5: 1390-اول | H5: 1390-دوم | I5: 1390-سوم | J5: 1390-چهارم | K5: 1391-اول | L5: 1391-دوم | M5: 1391-سوم | N5: 1391-چهارم | O5: 1392-اول | P5: 1392-دوم | Q5: 1392-سوم | R5: 1392-چهارم | S5: 1393-اول | T5: 1393-دوم | U5: 1393-سوم | V5: 1393-چهارم | W5: 1394-اول | X5: 1394-دوم | Y5: 1394-سوم | Z5: 1394-چهارم | AA5: 1395-اول | AB5: 1395-دوم | AC5: 1395-سوم | AD5: 1395-چهارم | AE5: 1396-اول | AF5: 1396-دوم | AG5: 1396-سوم | AH5: 1396-چهارم | AI5: 1397-اول | AJ5: 1397-تیر | AK5: 1397-مرداد | AL5: 1397-شهریور | AM5: 1397-سوم | AN5: 1397-چهارم | AO5: 1398-اول | AP5: 1398-دوم | AQ5: 1398-سوم | AR5: 1398-چهارم | AS5: 1399-اول | AT5: 1399-تیر | AU5: 1399-مرداد | AV5: 1399-شهریور | AW5: 1399-سوم | AX5: 1399-چهارم | AY5: 1400-اول | AZ5: 1400-دوم | BA5: 1400-سوم | BB5: 1400-چهارم | BC5: 1401-اول | BD5: 1401-دوم | BE5: 1401-سوم | BF5: 1401-دی | BG5: 1401-بهمن | BH5: 1401-اسفند | BI5: 1402-اول | BJ5: 1402-دوم | BK5: 1402-سوم | BL5: 1402-چهارم
A6: 2 | B6: ابنیه|Buildings | C6: {=_xlfn.SWITCH(LEFT(B6,FIND("|",B6)-1),"ابنیه",HLOOKUP(D6,'نمودار ابنیه'!$B$5:$AD$6,2,FALSE),"مکانیکی",HLOOKUP(D6,'نمودار مکانیکی'!$B$5:$AJ$6,2,FALSE),"برقی",HLOOKUP(D6,'نمودار تاسیسات برقی'!$B$5:$AK$6,2,FALSE),"خطوط",HLOOKUP(D6,'نمودار خطوط انتقال '!$B$5:$R$6,2,FALSE),"شبکه",HLOOKUP(D6,'نمودار شبکه توزیع آ'!$B$5:$O$6,2,FALSE),"سد",HLOOKUP(D6,'نمودار سدسازی'!$B$5:$P$6,2,FALSE),"فاضلاب",HLOOKUP(D6,'نمودار جمع‌آوری و ا'!$B$5:$S$6,2,FALSE),"تجهیزات",HLOOKUP(D6,'نمودار تجهیزات آب و'!$B$5:$AG$6,2,FALSE),"پست",HLOOKUP(D6,'نمودار پست های انتق'!$B$5:$AH$6,2,FALSE),"نیرو",HLOOKUP(D6,'نمودار توزیع نیرو ب'!$B$5:$AE$6,2,FALSE),FALSE)} -> FALSE | D6: عملیات خاکی با دست | E6: {=IFERROR(_xlfn.AGGREGATE(15,6,ROW($C$5:$C$261)/($C$5:$C$261=TRUE),1)-4,"")} -> 9 | F6: {=IF($E6="","",LEFT(INDEX($B$5:$B$261,$E6),FIND("|",INDEX($B$5:$B$261,$E6))-1)&":"&LEFT(INDEX($D$5:$D$261,$E6),20))} -> ابنیه:کارهای فولادی سنگین | G6: {=IF($E6="","",_xlfn.SWITCH(LEFT(INDEX($B$5:$B$261,$E6),FIND("|",INDEX($B$5:$B$261,$E6))-1),"ابنیه",VLOOKUP(INDEX($D$5:$D$261,$E6),'نمودار ابنیه'!$A$9:$BG$37,COLUMN()-5,FALSE),"مکانیکی",VLOOKUP(INDEX($D$5:$D$261,$E6),'نمودار مکانیکی'!$A$9:$BG$43,COLUMN()-5,FALSE),"برقی",VLOOKUP(INDEX($D$5:$D$261,$E6),'نمودار تاسیسات برقی'!$A$9:$BG$44,COLUMN()-5,FALSE),"خطوط",VLOOKUP(INDEX($D$5:$D$261,$E6),'نمودار خطوط انتقال '!$A$9:$BG$26,COLUMN()-5,FALSE),"شبکه",VLOOKUP(INDEX($D$5:$D$261,$E6),'نمودار شبکه توزیع آ'!$A$9:$BG$22,COLUMN()-5,FALSE),"سد",VLOOKUP(INDEX($D$5:$D$261,$E6),'نمودار سدسازی'!$A$9:$BG$23,COLUMN()-5,FALSE),"فاضلاب",VLOOKUP(INDEX($D$5:$D$261,$E6),'نمودار جمع‌آوری و ا'!$A$9:$BG$26,COLUMN()-5,FALSE),"تجهیزات",VLOOKUP(INDEX($D$5:$D$261,$E6),'نمودار تجهیزات آب و'!$A$9:$BG$42,COLUMN()-5,FALSE),"پست",VLOOKUP(INDEX($D$5:$D$261,$E6),'نمودار پست های انتق'!$A$9:$BG$41,COLUMN()-5,FALSE),"نیرو",VLOOKUP(INDEX($D$5:$D$261,$E6),'نمودار توزیع نیرو ب'!$A$9:$BG$38,COLUMN()-5,FALSE),""))} -> 275.2 | H6: {=IF($E6="","",_xlfn.SWITCH(LEFT(INDEX($B$5:$B$261,$E6),FIND("|",INDEX($B$5:$B$261,$E6))-1),"ابنیه",VLOOKUP(INDEX($D$5:$D$261,$E6),'نمودار ابنیه'!$A$9:$BG$37,COLUMN()-5,FALSE),"مکانیکی",VLOOKUP(INDEX($D$5:$D$261,$E6),'نمودار مکانیکی'!$A$9:$BG$43,COLUMN()-5,FALSE),"برقی",VLOOKUP(INDEX($D$5:$D$261,$E6),'نمودار تاسیسات برقی'!$A$9:$BG$44,COLUMN()-5,FALSE),"خطوط",VLOOKUP(INDEX($D$5:$D$261,$E6),'نمودار خطوط انتقال '!$A$9:$BG$26,COLUMN()-5,FALSE),"شبکه",VLOOKUP(INDEX($D$5:$D$261,$E6),'نمودار شبکه توزیع آ'!$A$9:$BG$22,COLUMN()-5,FALSE),"سد",VLOOKUP(INDEX($D$5:$D$261,$E6),'نمودار سدسازی'!$A$9:$BG$23,COLUMN()-5,FALSE),"فاضلاب",VLOOKUP(INDEX($D$5:$D$261,$E6),'نمودار جمع‌آوری و ا'!$A$9:$BG$26,COLUMN()-5,FALSE),"تجهیزات",VLOOKUP(INDEX($D$5:$D$261,$E6),'نمودار تجهیزات آب و'!$A$9:$BG$42,COLUMN()-5,FALSE),"پست",VLOOKUP(INDEX($D$5:$D$261,$E6),'نمودار پست های انتق'!$A$9:$BG$41,COLUMN()-5,FALSE),"نیرو",VLOOKUP(INDEX($D$5:$D$261,$E6),'نمودار توزیع نیرو ب'!$A$9:$BG$38,COLUMN()-5,FALSE),""))} -> 302.3 | I6: {=IF($E6="","",_xlfn.SWITCH(LEFT(INDEX($B$5:$B$261,$E6),FIND("|",INDEX($B$5:$B$261,$E6))-1),"ابنیه",VLOOKUP(INDEX($D$5:$D$261,$E6),'نمودار ابنیه'!$A$9:$BG$37,COLUMN()-5,FALSE),"مکانیکی",VLOOKUP(INDEX($D$5:$D$261,$E6),'نمودار مکانیکی'!$A$9:$BG$43,COLUMN()-5,FALSE),"برقی",VLOOKUP(INDEX($D$5:$D$261,$E6),'نمودار تاسیسات برقی'!$A$9:$BG$44,COLUMN()-5,FALSE),"خطوط",VLOOKUP(INDEX($D$5:$D$261,$E6),'نمودار خطوط انتقال '!$A$9:$BG$26,COLUMN()-5,FALSE),"شبکه",VLOOKUP(INDEX($D$5:$D$261,$E6),'نمودار شبکه توزیع آ'!$A$9:$BG$22,COLUMN()-5,FALSE),"سد",VLOOKUP(INDEX($D$5:$D$261,$E6),'نمودار سدسازی'!$A$9:$BG$23,COLUMN()-5,FALSE),"فاضلاب",VLOOKUP(INDEX($D$5:$D$261,$E6),'نمودار جمع‌آوری و ا'!$A$9:$BG$26,COLUMN()-5,FALSE),"تجهیزات",VLOOKUP(INDEX($D$5:$D$261,$E6),'نمودار تجهیزات آب و'!$A$9:$BG$42,COLUMN()-5,FALSE),"پست",VLOOKUP(INDEX($D$5:$D$261,$E6),'نمودار پست های انتق'!$A$9:$BG$41,COLUMN()-5,FALSE),"نیرو",VLOOKUP(INDEX($D$5:$D$261,$E6),'نمودار توزیع نیرو ب'!$A$9:$BG$38,COLUMN()-5,FALSE),""))} -> 318.9 | J6: {=IF($E6="","",_xlfn.SWITCH(LEFT(INDEX($B$5:$B$261,$E6),FIND("|",INDEX($B$5:$B$261,$E6))-1),"ابنیه",VLOOKUP(INDEX($D$5:$D$261,$E6),'نمودار ابنیه'!$A$9:$BG$37,COLUMN()-5,FALSE),"مکانیکی",VLOOKUP(INDEX($D$5:$D$261,$E6),'نمودار مکانیکی'!$A$9:$BG$43,COLUMN()-5,FALSE),"برقی",VLOOKUP(INDEX($D$5:$D$261,$E6),'نمودار تاسیسات برقی'!$A$9:$BG$44,COLUMN()-5,FALSE),"خطوط",VLOOKUP(INDEX($D$5:$D$261,$E6),'نمودار خطوط انتقال '!$A$9:$BG$26,COLUMN()-5,FALSE),"شبکه",VLOOKUP(INDEX($D$5:$D$261,$E6),'نمودار شبکه توزیع آ'!$A$9:$BG$22,COLUMN()-5,FALSE),"سد",VLOOKUP(INDEX($D$5:$D$261,$E6),'نمودار سدسازی'!$A$9:$BG$23,COLUMN()-5,FALSE),"فاضلاب",VLOOKUP(INDEX($D$5:$D$261,$E6),'نمودار جمع‌آوری و ا'!$A$9:$BG$26,COLUMN()-5,FALSE),"تجهیزات",VLOOKUP(INDEX($D$5:$D$261,$E6),'نمودار تجهیزات آب و'!$A$9:$BG$42,COLUMN()-5,FALSE),"پست",VLOOKUP(INDEX($D$5:$D$261,$E6),'نمودار پست های انتق'!$A$9:$BG$41,COLUMN()-5,FALSE),"نیرو",VLOOKUP(INDEX($D$5:$D$261,$E6),'نمودار توزیع نیرو ب'!$A$9:$BG$38,COLUMN()-5,FALSE),""))} -> 335.8 | K6: {=IF($E6="","",_xlfn.SWITCH(LEFT(INDEX($B$5:$B$261,$E6),FIND("|",INDEX($B$5:$B$261,$E6))-1),"ابنیه",VLOOKUP(INDEX($D$5:$D$261,$E6),'نمودار ابنیه'!$A$9:$BG$37,COLUMN()-5,FALSE),"مکانیکی",VLOOKUP(INDEX($D$5:$D$261,$E6),'نمودار مکانیکی'!$A$9:$BG$43,COLUMN()-5,FALSE),"برقی",VLOOKUP(INDEX($D$5:$D$261,$E6),'نمودار تاسیسات برقی'!$A$9:$BG$44,COLUMN()-5,FALSE),"خطوط",VLOOKUP(INDEX($D$5:$D$261,$E6),'نمودار خطوط انتقال '!$A$9:$BG$26,COLUMN()-5,FALSE),"شبکه",VLOOKUP(INDEX($D$5:$D$261,$E6),'نمودار شبکه توزیع آ'!$A$9:$BG$22,COLUMN()-5,FALSE),"سد",VLOOKUP(INDEX($D$5:$D$261,$E6),'نمودار سدسازی'!$A$9:$BG$23,COLUMN()-5,FALSE),"فاضلاب",VLOOKUP(INDEX($D$5:$D$261,$E6),'نمودار جمع‌آوری و ا'!$A$9:$BG$26,COLUMN()-5,FALSE),"تجهیزات",VLOOKUP(INDEX($D$5:$D$261,$E6),'نمودار تجهیزات آب و'!$A$9:$BG$42,COLUMN()-5,FALSE),"پست",VLOOKUP(INDEX($D$5:$D$261,$E6),'نمودار پست های انتق'!$A$9:$BG$41,COLUMN()-5,FALSE),"نیرو",VLOOKUP(INDEX($D$5:$D$261,$E6),'نمودار توزیع نیرو ب'!$A$9:$BG$38,COLUMN()-5,FALSE),""))} -> 352.4 | L6: {=IF($E6="","",_xlfn.SWITCH(LEFT(INDEX($B$5:$B$261,$E6),FIND("|",INDEX($B$5:$B$261,$E6))-1),"ابنیه",VLOOKUP(INDEX($D$5:$D$261,$E6),'نمودار ابنیه'!$A$9:$BG$37,COLUMN()-5,FALSE),"مکانیکی",VLOOKUP(INDEX($D$5:$D$261,$E6),'نمودار مکانیکی'!$A$9:$BG$43,COLUMN()-5,FALSE),"برقی",VLOOKUP(INDEX($D$5:$D$261,$E6),'نمودار تاسیسات برقی'!$A$9:$BG$44,COLUMN()-5,FALSE),"خطوط",VLOOKUP(INDEX($D$5:$D$261,$E6),'نمودار خطوط انتقال '!$A$9:$BG$26,COLUMN()-5,FALSE),"شبکه",VLOOKUP(INDEX($D$5:$D$261,$E6),'نمودار شبکه توزیع آ'!$A$9:$BG$22,COLUMN()-5,FALSE),"سد",VLOOKUP(INDEX($D$5:$D$261,$E6),'نمودار سدسازی'!$A$9:$BG$23,COLUMN()-5,FALSE),"فاضلاب",VLOOKUP(INDEX($D$5:$D$261,$E6),'نمودار جمع‌آوری و ا'!$A$9:$BG$26,COLUMN()-5,FALSE),"تجهیزات",VLOOKUP(INDEX($D$5:$D$261,$E6),'نمودار تجهیزات آب و'!$A$9:$BG$42,COLUMN()-5,FALSE),"پست",VLOOKUP(INDEX($D$5:$D$261,$E6),'نمودار پست های انتق'!$A$9:$BG$41,COLUMN()-5,FALSE),"نیرو",VLOOKUP(INDEX($D$5:$D$261,$E6),'نمودار توزیع نیرو ب'!$A$9:$BG$38,COLUMN()-5,FALSE),""))} -> 404.1 | M6: {=IF($E6="","",_xlfn.SWITCH(LEFT(INDEX($B$5:$B$261,$E6),FIND("|",INDEX($B$5:$B$261,$E6))-1),"ابنیه",VLOOKUP(INDEX($D$5:$D$261,$E6),'نمودار ابنیه'!$A$9:$BG$37,COLUMN()-5,FALSE),"مکانیکی",VLOOKUP(INDEX($D$5:$D$261,$E6),'نمودار مکانیکی'!$A$9:$BG$43,COLUMN()-5,FALSE),"برقی",VLOOKUP(INDEX($D$5:$D$261,$E6),'نمودار تاسیسات برقی'!$A$9:$BG$44,COLUMN()-5,FALSE),"خطوط",VLOOKUP(INDEX($D$5:$D$261,$E6),'نمودار خطوط انتقال '!$A$9:$BG$26,COLUMN()-5,FALSE),"شبکه",VLOOKUP(INDEX($D$5:$D$261,$E6),'نمودار شبکه توزیع آ'!$A$9:$BG$22,COLUMN()-5,FALSE),"سد",VLOOKUP(INDEX($D$5:$D$261,$E6),'نمودار سدسازی'!$A$9:$BG$23,COLUMN()-5,FALSE),"فاضلاب",VLOOKUP(INDEX($D$5:$D$261,$E6),'نمودار جمع‌آوری و ا'!$A$9:$BG$26,COLUMN()-5,FALSE),"تجهیزات",VLOOKUP(INDEX($D$5:$D$261,$E6),'نمودار تجهیزات آب و'!$A$9:$BG$42,COLUMN()-5,FALSE),"پست",VLOOKUP(INDEX($D$5:$D$261,$E6),'نمودار پست های انتق'!$A$9:$BG$41,COLUMN()-5,FALSE),"نیرو",VLOOKUP(INDEX($D$5:$D$261,$E6),'نمودار توزیع نیرو ب'!$A$9:$BG$38,COLUMN()-5,FALSE),""))} -> 498.1 | N6: {=IF($E6="","",_xlfn.SWITCH(LEFT(INDEX($B$5:$B$261,$E6),FIND("|",INDEX($B$5:$B$261,$E6))-1),"ابنیه",VLOOKUP(INDEX($D$5:$D$261,$E6),'نمودار ابنیه'!$A$9:$BG$37,COLUMN()-5,FALSE),"مکانیکی",VLOOKUP(INDEX($D$5:$D$261,$E6),'نمودار مکانیکی'!$A$9:$BG$43,COLUMN()-5,FALSE),"برقی",VLOOKUP(INDEX($D$5:$D$261,$E6),'نمودار تاسیسات برقی'!$A$9:$BG$44,COLUMN()-5,FALSE),"خطوط",VLOOKUP(INDEX($D$5:$D$261,$E6),'نمودار خطوط انتقال '!$A$9:$BG$26,COLUMN()-5,FALSE),"شبکه",VLOOKUP(INDEX($D$5:$D$261,$E6),'نمودار شبکه توزیع آ'!$A$9:$BG$22,COLUMN()-5,FALSE),"سد",VLOOKUP(INDEX($D$5:$D$261,$E6),'نمودار سدسازی'!$A$9:$BG$23,COLUMN()-5,FALSE),"فاضلاب",VLOOKUP(INDEX($D$5:$D$261,$E6),'نمودار جمع‌آوری و ا'!$A$9:$BG$26,COLUMN()-5,FALSE),"تجهیزات",VLOOKUP(INDEX($D$5:$D$261,$E6),'نمودار تجهیزات آب و'!$A$9:$BG$42,COLUMN()-5,FALSE),"پست",VLOOKUP(INDEX($D$5:$D$261,$E6),'نمودار پست های انتق'!$A$9:$BG$41,COLUMN()-5,FALSE),"نیرو",VLOOKUP(INDEX($D$5:$D$261,$E6),'نمودار توزیع نیرو ب'!$A$9:$BG$38,COLUMN()-5,FALSE),""))} -> 546.8 | ... BL6: {=IF($E6="","",_xlfn.SWITCH(LEFT(INDEX($B$5:$B$261,$E6),FIND("|",INDEX($B$5:$B$261,$E6))-1),"ابنیه",VLOOKUP(INDEX($D$5:$D$261,$E6),'نمودار ابنیه'!$A$9:$BG$37,COLUMN()-5,FALSE),"مکانیکی",VLOOKUP(INDEX($D$5:$D$261,$E6),'نمودار مکانیکی'!$A$9:$BG$43,COLUMN()-5,FALSE),"برقی",VLOOKUP(INDEX($D$5:$D$261,$E6),'نمودار تاسیسات برقی'!$A$9:$BG$44,COLUMN()-5,FALSE),"خطوط",VLOOKUP(INDEX($D$5:$D$261,$E6),'نمودار خطوط انتقال '!$A$9:$BG$26,COLUMN()-5,FALSE),"شبکه",VLOOKUP(INDEX($D$5:$D$261,$E6),'نمودار شبکه توزیع آ'!$A$9:$BG$22,COLUMN()-5,FALSE),"سد",VLOOKUP(INDEX($D$5:$D$261,$E6),'نمودار سدسازی'!$A$9:$BG$23,COLUMN()-5,FALSE),"فاضلاب",VLOOKUP(INDEX($D$5:$D$261,$E6),'نمودار جمع‌آوری و ا'!$A$9:$BG$26,COLUMN()-5,FALSE),"تجهیزات",VLOOKUP(INDEX($D$5:$D$261,$E6),'نمودار تجهیزات آب و'!$A$9:$BG$42,COLUMN()-5,FALSE),"پست",VLOOKUP(INDEX($D$5:$D$261,$E6),'نمودار پست های انتق'!$A$9:$BG$41,COLUMN()-5,FALSE),"نیرو",VLOOKUP(INDEX($D$5:$D$261,$E6),'نمودار توزیع نیرو ب'!$A$9:$BG$38,COLUMN()-5,FALSE),""))} -> 8776.9
A7: 3 | B7: ابنیه|Buildings | C7: {=_xlfn.SWITCH(LEFT(B7,FIND("|",B7)-1),"ابنیه",HLOOKUP(D7,'نمودار ابنیه'!$B$5:$AD$6,2,FALSE),"مکانیکی",HLOOKUP(D7,'نمودار مکانیکی'!$B$5:$AJ$6,2,FALSE),"برقی",HLOOKUP(D7,'نمودار تاسیسات برقی'!$B$5:$AK$6,2,FALSE),"خطوط",HLOOKUP(D7,'نمودار خطوط انتقال '!$B$5:$R$6,2,FALSE),"شبکه",HLOOKUP(D7,'نمودار شبکه توزیع آ'!$B$5:$O$6,2,FALSE),"سد",HLOOKUP(D7,'نمودار سدسازی'!$B$5:$P$6,2,FALSE),"فاضلاب",HLOOKUP(D7,'نمودار جمع‌آوری و ا'!$B$5:$S$6,2,FALSE),"تجهیزات",HLOOKUP(D7,'نمودار تجهیزات آب و'!$B$5:$AG$6,2,FALSE),"پست",HLOOKUP(D7,'نمودار پست های انتق'!$B$5:$AH$6,2,FALSE),"نیرو",HLOOKUP(D7,'نمودار توزیع نیرو ب'!$B$5:$AE$6,2,FALSE),FALSE)} -> FALSE | D7: عملیات خاکی با ماشین | E7: {=IFERROR(_xlfn.AGGREGATE(15,6,ROW($C$5:$C$261)/($C$5:$C$261=TRUE),2)-4,"")} -> 30 | F7: {=IF($E7="","",LEFT(INDEX($B$5:$B$261,$E7),FIND("|",INDEX($B$5:$B$261,$E7))-1)&":"&LEFT(INDEX($D$5:$D$261,$E7),20))} -> مکانیکی:لوله های فولادی | G7: {=IF($E7="","",_xlfn.SWITCH(LEFT(INDEX($B$5:$B$261,$E7),FIND("|",INDEX($B$5:$B$261,$E7))-1),"ابنیه",VLOOKUP(INDEX($D$5:$D$261,$E7),'نمودار ابنیه'!$A$9:$BG$37,COLUMN()-5,FALSE),"مکانیکی",VLOOKUP(INDEX($D$5:$D$261,$E7),'نمودار مکانیکی'!$A$9:$BG$43,COLUMN()-5,FALSE),"برقی",VLOOKUP(INDEX($D$5:$D$261,$E7),'نمودار تاسیسات برقی'!$A$9:$BG$44,COLUMN()-5,FALSE),"خطوط",VLOOKUP(INDEX($D$5:$D$261,$E7),'نمودار خطوط انتقال '!$A$9:$BG$26,COLUMN()-5,FALSE),"شبکه",VLOOKUP(INDEX($D$5:$D$261,$E7),'نمودار شبکه توزیع آ'!$A$9:$BG$22,COLUMN()-5,FALSE),"سد",VLOOKUP(INDEX($D$5:$D$261,$E7),'نمودار سدسازی'!$A$9:$BG$23,COLUMN()-5,FALSE),"فاضلاب",VLOOKUP(INDEX($D$5:$D$261,$E7),'نمودار جمع‌آوری و ا'!$A$9:$BG$26,COLUMN()-5,FALSE),"تجهیزات",VLOOKUP(INDEX($D$5:$D$261,$E7),'نمودار تجهیزات آب و'!$A$9:$BG$42,COLUMN()-5,FALSE),"پست",VLOOKUP(INDEX($D$5:$D$261,$E7),'نمودار پست های انتق'!$A$9:$BG$41,COLUMN()-5,FALSE),"نیرو",VLOOKUP(INDEX($D$5:$D$261,$E7),'نمودار توزیع نیرو ب'!$A$9:$BG$38,COLUMN()-5,FALSE),""))} -> 269.9 | H7: {=IF($E7="","",_xlfn.SWITCH(LEFT(INDEX($B$5:$B$261,$E7),FIND("|",INDEX($B$5:$B$261,$E7))-1),"ابنیه",VLOOKUP(INDEX($D$5:$D$261,$E7),'نمودار ابنیه'!$A$9:$BG$37,COLUMN()-5,FALSE),"مکانیکی",VLOOKUP(INDEX($D$5:$D$261,$E7),'نمودار مکانیکی'!$A$9:$BG$43,COLUMN()-5,FALSE),"برقی",VLOOKUP(INDEX($D$5:$D$261,$E7),'نمودار تاسیسات برقی'!$A$9:$BG$44,COLUMN()-5,FALSE),"خطوط",VLOOKUP(INDEX($D$5:$D$261,$E7),'نمودار خطوط انتقال '!$A$9:$BG$26,COLUMN()-5,FALSE),"شبکه",VLOOKUP(INDEX($D$5:$D$261,$E7),'نمودار شبکه توزیع آ'!$A$9:$BG$22,COLUMN()-5,FALSE),"سد",VLOOKUP(INDEX($D$5:$D$261,$E7),'نمودار سدسازی'!$A$9:$BG$23,COLUMN()-5,FALSE),"فاضلاب",VLOOKUP(INDEX($D$5:$D$261,$E7),'نمودار جمع‌آوری و ا'!$A$9:$BG$26,COLUMN()-5,FALSE),"تجهیزات",VLOOKUP(INDEX($D$5:$D$261,$E7),'نمودار تجهیزات آب و'!$A$9:$BG$42,COLUMN()-5,FALSE),"پست",VLOOKUP(INDEX($D$5:$D$261,$E7),'نمودار پست های انتق'!$A$9:$BG$41,COLUMN()-5,FALSE),"نیرو",VLOOKUP(INDEX($D$5:$D$261,$E7),'نمودار توزیع نیرو ب'!$A$9:$BG$38,COLUMN()-5,FALSE),""))} -> 283.3 | I7: {=IF($E7="","",_xlfn.SWITCH(LEFT(INDEX($B$5:$B$261,$E7),FIND("|",INDEX($B$5:$B$261,$E7))-1),"ابنیه",VLOOKUP(INDEX($D$5:$D$261,$E7),'نمودار ابنیه'!$A$9:$BG$37,COLUMN()-5,FALSE),"مکانیکی",VLOOKUP(INDEX($D$5:$D$261,$E7),'نمودار مکانیکی'!$A$9:$BG$43,COLUMN()-5,FALSE),"برقی",VLOOKUP(INDEX($D$5:$D$261,$E7),'نمودار تاسیسات برقی'!$A$9:$BG$44,COLUMN()-5,FALSE),"خطوط",VLOOKUP(INDEX($D$5:$D$261,$E7),'نمودار خطوط انتقال '!$A$9:$BG$26,COLUMN()-5,FALSE),"شبکه",VLOOKUP(INDEX($D$5:$D$261,$E7),'نمودار شبکه توزیع آ'!$A$9:$BG$22,COLUMN()-5,FALSE),"سد",VLOOKUP(INDEX($D$5:$D$261,$E7),'نمودار سدسازی'!$A$9:$BG$23,COLUMN()-5,FALSE),"فاضلاب",VLOOKUP(INDEX($D$5:$D$261,$E7),'نمودار جمع‌آوری و ا'!$A$9:$BG$26,COLUMN()-5,FALSE),"تجهیزات",VLOOKUP(INDEX($D$5:$D$261,$E7),'نمودار تجهیزات آب و'!$A$9:$BG$42,COLUMN()-5,FALSE),"پست",VLOOKUP(INDEX($D$5:$D$261,$E7),'نمودار پست های انتق'!$A$9:$BG$41,COLUMN()-5,FALSE),"نیرو",VLOOKUP(INDEX($D$5:$D$261,$E7),'نمودار توزیع نیرو ب'!$A$9:$BG$38,COLUMN()-5,FALSE),""))} -> 296.5 | J7: {=IF($E7="","",_xlfn.SWITCH(LEFT(INDEX($B$5:$B$261,$E7),FIND("|",INDEX($B$5:$B$261,$E7))-1),"ابنیه",VLOOKUP(INDEX($D$5:$D$261,$E7),'نمودار ابنیه'!$A$9:$BG$37,COLUMN()-5,FALSE),"مکانیکی",VLOOKUP(INDEX($D$5:$D$261,$E7),'نمودار مکانیکی'!$A$9:$BG$43,COLUMN()-5,FALSE),"برقی",VLOOKUP(INDEX($D$5:$D$261,$E7),'نمودار تاسیسات برقی'!$A$9:$BG$44,COLUMN()-5,FALSE),"خطوط",VLOOKUP(INDEX($D$5:$D$261,$E7),'نمودار خطوط انتقال '!$A$9:$BG$26,COLUMN()-5,FALSE),"شبکه",VLOOKUP(INDEX($D$5:$D$261,$E7),'نمودار شبکه توزیع آ'!$A$9:$BG$22,COLUMN()-5,FALSE),"سد",VLOOKUP(INDEX($D$5:$D$261,$E7),'نمودار سدسازی'!$A$9:$BG$23,COLUMN()-5,FALSE),"فاضلاب",VLOOKUP(INDEX($D$5:$D$261,$E7),'نمودار جمع‌آوری و ا'!$A$9:$BG$26,COLUMN()-5,FALSE),"تجهیزات",VLOOKUP(INDEX($D$5:$D$261,$E7),'نمودار تجهیزات آب و'!$A$9:$BG$42,COLUMN()-5,FALSE),"پست",VLOOKUP(INDEX($D$5:$D$261,$E7),'نمودار پست های انتق'!$A$9:$BG$41,COLUMN()-5,FALSE),"نیرو",VLOOKUP(INDEX($D$5:$D$261,$E7),'نمودار توزیع نیرو ب'!$A$9:$BG$38,COLUMN()-5,FALSE),""))} -> 305.2 | K7: {=IF($E7="","",_xlfn.SWITCH(LEFT(INDEX($B$5:$B$261,$E7),FIND("|",INDEX($B$5:$B$261,$E7))-1),"ابنیه",VLOOKUP(INDEX($D$5:$D$261,$E7),'نمودار ابنیه'!$A$9:$BG$37,COLUMN()-5,FALSE),"مکانیکی",VLOOKUP(INDEX($D$5:$D$261,$E7),'نمودار مکانیکی'!$A$9:$BG$43,COLUMN()-5,FALSE),"برقی",VLOOKUP(INDEX($D$5:$D$261,$E7),'نمودار تاسیسات برقی'!$A$9:$BG$44,COLUMN()-5,FALSE),"خطوط",VLOOKUP(INDEX($D$5:$D$261,$E7),'نمودار خطوط انتقال '!$A$9:$BG$26,COLUMN()-5,FALSE),"شبکه",VLOOKUP(INDEX($D$5:$D$261,$E7),'نمودار شبکه توزیع آ'!$A$9:$BG$22,COLUMN()-5,FALSE),"سد",VLOOKUP(INDEX($D$5:$D$261,$E7),'نمودار سدسازی'!$A$9:$BG$23,COLUMN()-5,FALSE),"فاضلاب",VLOOKUP(INDEX($D$5:$D$261,$E7),'نمودار جمع‌آوری و ا'!$A$9:$BG$26,COLUMN()-5,FALSE),"تجهیزات",VLOOKUP(INDEX($D$5:$D$261,$E7),'نمودار تجهیزات آب و'!$A$9:$BG$42,COLUMN()-5,FALSE),"پست",VLOOKUP(INDEX($D$5:$D$261,$E7),'نمودار پست های انتق'!$A$9:$BG$41,COLUMN()-5,FALSE),"نیرو",VLOOKUP(INDEX($D$5:$D$261,$E7),'نمودار توزیع نیرو ب'!$A$9:$BG$38,COLUMN()-5,FALSE),""))} -> 339.7 | L7: {=IF($E7="","",_xlfn.SWITCH(LEFT(INDEX($B$5:$B$261,$E7),FIND("|",INDEX($B$5:$B$261,$E7))-1),"ابنیه",VLOOKUP(INDEX($D$5:$D$261,$E7),'نمودار ابنیه'!$A$9:$BG$37,COLUMN()-5,FALSE),"مکانیکی",VLOOKUP(INDEX($D$5:$D$261,$E7),'نمودار مکانیکی'!$A$9:$BG$43,COLUMN()-5,FALSE),"برقی",VLOOKUP(INDEX($D$5:$D$261,$E7),'نمودار تاسیسات برقی'!$A$9:$BG$44,COLUMN()-5,FALSE),"خطوط",VLOOKUP(INDEX($D$5:$D$261,$E7),'نمودار خطوط انتقال '!$A$9:$BG$26,COLUMN()-5,FALSE),"شبکه",VLOOKUP(INDEX($D$5:$D$261,$E7),'نمودار شبکه توزیع آ'!$A$9:$BG$22,COLUMN()-5,FALSE),"سد",VLOOKUP(INDEX($D$5:$D$261,$E7),'نمودار سدسازی'!$A$9:$BG$23,COLUMN()-5,FALSE),"فاضلاب",VLOOKUP(INDEX($D$5:$D$261,$E7),'نمودار جمع‌آوری و ا'!$A$9:$BG$26,COLUMN()-5,FALSE),"تجهیزات",VLOOKUP(INDEX($D$5:$D$261,$E7),'نمودار تجهیزات آب و'!$A$9:$BG$42,COLUMN()-5,FALSE),"پست",VLOOKUP(INDEX($D$5:$D$261,$E7),'نمودار پست های انتق'!$A$9:$BG$41,COLUMN()-5,FALSE),"نیرو",VLOOKUP(INDEX($D$5:$D$261,$E7),'نمودار توزیع نیرو ب'!$A$9:$BG$38,COLUMN()-5,FALSE),""))} -> 379.3 | M7: {=IF($E7="","",_xlfn.SWITCH(LEFT(INDEX($B$5:$B$261,$E7),FIND("|",INDEX($B$5:$B$261,$E7))-1),"ابنیه",VLOOKUP(INDEX($D$5:$D$261,$E7),'نمودار ابنیه'!$A$9:$BG$37,COLUMN()-5,FALSE),"مکانیکی",VLOOKUP(INDEX($D$5:$D$261,$E7),'نمودار مکانیکی'!$A$9:$BG$43,COLUMN()-5,FALSE),"برقی",VLOOKUP(INDEX($D$5:$D$261,$E7),'نمودار تاسیسات برقی'!$A$9:$BG$44,COLUMN()-5,FALSE),"خطوط",VLOOKUP(INDEX($D$5:$D$261,$E7),'نمودار خطوط انتقال '!$A$9:$BG$26,COLUMN()-5,FALSE),"شبکه",VLOOKUP(INDEX($D$5:$D$261,$E7),'نمودار شبکه توزیع آ'!$A$9:$BG$22,COLUMN()-5,FALSE),"سد",VLOOKUP(INDEX($D$5:$D$261,$E7),'نمودار سدسازی'!$A$9:$BG$23,COLUMN()-5,FALSE),"فاضلاب",VLOOKUP(INDEX($D$5:$D$261,$E7),'نمودار جمع‌آوری و ا'!$A$9:$BG$26,COLUMN()-5,FALSE),"تجهیزات",VLOOKUP(INDEX($D$5:$D$261,$E7),'نمودار تجهیزات آب و'!$A$9:$BG$42,COLUMN()-5,FALSE),"پست",VLOOKUP(INDEX($D$5:$D$261,$E7),'نمودار پست های انتق'!$A$9:$BG$41,COLUMN()-5,FALSE),"نیرو",VLOOKUP(INDEX($D$5:$D$261,$E7),'نمودار توزیع نیرو ب'!$A$9:$BG$38,COLUMN()-5,FALSE),""))} -> 424.9 | N7: {=IF($E7="","",_xlfn.SWITCH(LEFT(INDEX($B$5:$B$261,$E7),FIND("|",INDEX($B$5:$B$261,$E7))-1),"ابنیه",VLOOKUP(INDEX($D$5:$D$261,$E7),'نمودار ابنیه'!$A$9:$BG$37,COLUMN()-5,FALSE),"مکانیکی",VLOOKUP(INDEX($D$5:$D$261,$E7),'نمودار مکانیکی'!$A$9:$BG$43,COLUMN()-5,FALSE),"برقی",VLOOKUP(INDEX($D$5:$D$261,$E7),'نمودار تاسیسات برقی'!$A$9:$BG$44,COLUMN()-5,FALSE),"خطوط",VLOOKUP(INDEX($D$5:$D$261,$E7),'نمودار خطوط انتقال '!$A$9:$BG$26,COLUMN()-5,FALSE),"شبکه",VLOOKUP(INDEX($D$5:$D$261,$E7),'نمودار شبکه توزیع آ'!$A$9:$BG$22,COLUMN()-5,FALSE),"سد",VLOOKUP(INDEX($D$5:$D$261,$E7),'نمودار سدسازی'!$A$9:$BG$23,COLUMN()-5,FALSE),"فاضلاب",VLOOKUP(INDEX($D$5:$D$261,$E7),'نمودار جمع‌آوری و ا'!$A$9:$BG$26,COLUMN()-5,FALSE),"تجهیزات",VLOOKUP(INDEX($D$5:$D$261,$E7),'نمودار تجهیزات آب و'!$A$9:$BG$42,COLUMN()-5,FALSE),"پست",VLOOKUP(INDEX($D$5:$D$261,$E7),'نمودار پست های انتق'!$A$9:$BG$41,COLUMN()-5,FALSE),"نیرو",VLOOKUP(INDEX($D$5:$D$261,$E7),'نمودار توزیع نیرو ب'!$A$9:$BG$38,COLUMN()-5,FALSE),""))} -> 533.7 | ... BL7: {=IF($E7="","",_xlfn.SWITCH(LEFT(INDEX($B$5:$B$261,$E7),FIND("|",INDEX($B$5:$B$261,$E7))-1),"ابنیه",VLOOKUP(INDEX($D$5:$D$261,$E7),'نمودار ابنیه'!$A$9:$BG$37,COLUMN()-5,FALSE),"مکانیکی",VLOOKUP(INDEX($D$5:$D$261,$E7),'نمودار مکانیکی'!$A$9:$BG$43,COLUMN()-5,FALSE),"برقی",VLOOKUP(INDEX($D$5:$D$261,$E7),'نمودار تاسیسات برقی'!$A$9:$BG$44,COLUMN()-5,FALSE),"خطوط",VLOOKUP(INDEX($D$5:$D$261,$E7),'نمودار خطوط انتقال '!$A$9:$BG$26,COLUMN()-5,FALSE),"شبکه",VLOOKUP(INDEX($D$5:$D$261,$E7),'نمودار شبکه توزیع آ'!$A$9:$BG$22,COLUMN()-5,FALSE),"سد",VLOOKUP(INDEX($D$5:$D$261,$E7),'نمودار سدسازی'!$A$9:$BG$23,COLUMN()-5,FALSE),"فاضلاب",VLOOKUP(INDEX($D$5:$D$261,$E7),'نمودار جمع‌آوری و ا'!$A$9:$BG$26,COLUMN()-5,FALSE),"تجهیزات",VLOOKUP(INDEX($D$5:$D$261,$E7),'نمودار تجهیزات آب و'!$A$9:$BG$42,COLUMN()-5,FALSE),"پست",VLOOKUP(INDEX($D$5:$D$261,$E7),'نمودار پست های انتق'!$A$9:$BG$41,COLUMN()-5,FALSE),"نیرو",VLOOKUP(INDEX($D$5:$D$261,$E7),'نمودار توزیع نیرو ب'!$A$9:$BG$38,COLUMN()-5,FALSE),""))} -> 7274.2
A8: 4 | B8: ابنیه|Buildings | C8: {=_xlfn.SWITCH(LEFT(B8,FIND("|",B8)-1),"ابنیه",HLOOKUP(D8,'نمودار ابنیه'!$B$5:$AD$6,2,FALSE),"مکانیکی",HLOOKUP(D8,'نمودار مکانیکی'!$B$5:$AJ$6,2,FALSE),"برقی",HLOOKUP(D8,'نمودار تاسیسات برقی'!$B$5:$AK$6,2,FALSE),"خطوط",HLOOKUP(D8,'نمودار خطوط انتقال '!$B$5:$R$6,2,FALSE),"شبکه",HLOOKUP(D8,'نمودار شبکه توزیع آ'!$B$5:$O$6,2,FALSE),"سد",HLOOKUP(D8,'نمودار سدسازی'!$B$5:$P$6,2,FALSE),"فاضلاب",HLOOKUP(D8,'نمودار جمع‌آوری و ا'!$B$5:$S$6,2,FALSE),"تجهیزات",HLOOKUP(D8,'نمودار تجهیزات آب و'!$B$5:$AG$6,2,FALSE),"پست",HLOOKUP(D8,'نمودار پست های انتق'!$B$5:$AH$6,2,FALSE),"نیرو",HLOOKUP(D8,'نمودار توزیع نیرو ب'!$B$5:$AE$6,2,FALSE),FALSE)} -> FALSE | D8: عملیات بنایی با سنگ | E8: {=IFERROR(_xlfn.AGGREGATE(15,6,ROW($C$5:$C$261)/($C$5:$C$261=TRUE),3)-4,"")} -> 31 | F8: {=IF($E8="","",LEFT(INDEX($B$5:$B$261,$E8),FIND("|",INDEX($B$5:$B$261,$E8))-1)&":"&LEFT(INDEX($D$5:$D$261,$E8),20))} -> مکانیکی:لوله های چدنی | G8: {=IF($E8="","",_xlfn.SWITCH(LEFT(INDEX($B$5:$B$261,$E8),FIND("|",INDEX($B$5:$B$261,$E8))-1),"ابنیه",VLOOKUP(INDEX($D$5:$D$261,$E8),'نمودار ابنیه'!$A$9:$BG$37,COLUMN()-5,FALSE),"مکانیکی",VLOOKUP(INDEX($D$5:$D$261,$E8),'نمودار مکانیکی'!$A$9:$BG$43,COLUMN()-5,FALSE),"برقی",VLOOKUP(INDEX($D$5:$D$261,$E8),'نمودار تاسیسات برقی'!$A$9:$BG$44,COLUMN()-5,FALSE),"خطوط",VLOOKUP(INDEX($D$5:$D$261,$E8),'نمودار خطوط انتقال '!$A$9:$BG$26,COLUMN()-5,FALSE),"شبکه",VLOOKUP(INDEX($D$5:$D$261,$E8),'نمودار شبکه توزیع آ'!$A$9:$BG$22,COLUMN()-5,FALSE),"سد",VLOOKUP(INDEX($D$5:$D$261,$E8),'نمودار سدسازی'!$A$9:$BG$23,COLUMN()-5,FALSE),"فاضلاب",VLOOKUP(INDEX($D$5:$D$261,$E8),'نمودار جمع‌آوری و ا'!$A$9:$BG$26,COLUMN()-5,FALSE),"تجهیزات",VLOOKUP(INDEX($D$5:$D$261,$E8),'نمودار تجهیزات آب و'!$A$9:$BG$42,COLUMN()-5,FALSE),"پست",VLOOKUP(INDEX($D$5:$D$261,$E8),'نمودار پست های انتق'!$A$9:$BG$41,COLUMN()-5,FALSE),"نیرو",VLOOKUP(INDEX($D$5:$D$261,$E8),'نمودار توزیع نیرو ب'!$A$9:$BG$38,COLUMN()-5,FALSE),""))} -> 559 | H8: {=IF($E8="","",_xlfn.SWITCH(LEFT(INDEX($B$5:$B$261,$E8),FIND("|",INDEX($B$5:$B$261,$E8))-1),"ابنیه",VLOOKUP(INDEX($D$5:$D$261,$E8),'نمودار ابنیه'!$A$9:$BG$37,COLUMN()-5,FALSE),"مکانیکی",VLOOKUP(INDEX($D$5:$D$261,$E8),'نمودار مکانیکی'!$A$9:$BG$43,COLUMN()-5,FALSE),"برقی",VLOOKUP(INDEX($D$5:$D$261,$E8),'نمودار تاسیسات برقی'!$A$9:$BG$44,COLUMN()-5,FALSE),"خطوط",VLOOKUP(INDEX($D$5:$D$261,$E8),'نمودار خطوط انتقال '!$A$9:$BG$26,COLUMN()-5,FALSE),"شبکه",VLOOKUP(INDEX($D$5:$D$261,$E8),'نمودار شبکه توزیع آ'!$A$9:$BG$22,COLUMN()-5,FALSE),"سد",VLOOKUP(INDEX($D$5:$D$261,$E8),'نمودار سدسازی'!$A$9:$BG$23,COLUMN()-5,FALSE),"فاضلاب",VLOOKUP(INDEX($D$5:$D$261,$E8),'نمودار جمع‌آوری و ا'!$A$9:$BG$26,COLUMN()-5,FALSE),"تجهیزات",VLOOKUP(INDEX($D$5:$D$261,$E8),'نمودار تجهیزات آب و'!$A$9:$BG$42,COLUMN()-5,FALSE),"پست",VLOOKUP(INDEX($D$5:$D$261,$E8),'نمودار پست های انتق'!$A$9:$BG$41,COLUMN()-5,FALSE),"نیرو",VLOOKUP(INDEX($D$5:$D$261,$E8),'نمودار توزیع نیرو ب'!$A$9:$BG$38,COLUMN()-5,FALSE),""))} -> 560.4 | I8: {=IF($E8="","",_xlfn.SWITCH(LEFT(INDEX($B$5:$B$261,$E8),FIND("|",INDEX($B$5:$B$261,$E8))-1),"ابنیه",VLOOKUP(INDEX($D$5:$D$261,$E8),'نمودار ابنیه'!$A$9:$BG$37,COLUMN()-5,FALSE),"مکانیکی",VLOOKUP(INDEX($D$5:$D$261,$E8),'نمودار مکانیکی'!$A$9:$BG$43,COLUMN()-5,FALSE),"برقی",VLOOKUP(INDEX($D$5:$D$261,$E8),'نمودار تاسیسات برقی'!$A$9:$BG$44,COLUMN()-5,FALSE),"خطوط",VLOOKUP(INDEX($D$5:$D$261,$E8),'نمودار خطوط انتقال '!$A$9:$BG$26,COLUMN()-5,FALSE),"شبکه",VLOOKUP(INDEX($D$5:$D$261,$E8),'نمودار شبکه توزیع آ'!$A$9:$BG$22,COLUMN()-5,FALSE),"سد",VLOOKUP(INDEX($D$5:$D$261,$E8),'نمودار سدسازی'!$A$9:$BG$23,COLUMN()-5,FALSE),"فاضلاب",VLOOKUP(INDEX($D$5:$D$261,$E8),'نمودار جمع‌آوری و ا'!$A$9:$BG$26,COLUMN()-5,FALSE),"تجهیزات",VLOOKUP(INDEX($D$5:$D$261,$E8),'نمودار تجهیزات آب و'!$A$9:$BG$42,COLUMN()-5,FALSE),"پست",VLOOKUP(INDEX($D$5:$D$261,$E8),'نمودار پست های انتق'!$A$9:$BG$41,COLUMN()-5,FALSE),"نیرو",VLOOKUP(INDEX($D$5:$D$261,$E8),'نمودار توزیع نیرو ب'!$A$9:$BG$38,COLUMN()-5,FALSE),""))} -> 581.8 | J8: {=IF($E8="","",_xlfn.SWITCH(LEFT(INDEX($B$5:$B$261,$E8),FIND("|",INDEX($B$5:$B$261,$E8))-1),"ابنیه",VLOOKUP(INDEX($D$5:$D$261,$E8),'نمودار ابنیه'!$A$9:$BG$37,COLUMN()-5,FALSE),"مکانیکی",VLOOKUP(INDEX($D$5:$D$261,$E8),'نمودار مکانیکی'!$A$9:$BG$43,COLUMN()-5,FALSE),"برقی",VLOOKUP(INDEX($D$5:$D$261,$E8),'نمودار تاسیسات برقی'!$A$9:$BG$44,COLUMN()-5,FALSE),"خطوط",VLOOKUP(INDEX($D$5:$D$261,$E8),'نمودار خطوط انتقال '!$A$9:$BG$26,COLUMN()-5,FALSE),"شبکه",VLOOKUP(INDEX($D$5:$D$261,$E8),'نمودار شبکه توزیع آ'!$A$9:$BG$22,COLUMN()-5,FALSE),"سد",VLOOKUP(INDEX($D$5:$D$261,$E8),'نمودار سدسازی'!$A$9:$BG$23,COLUMN()-5,FALSE),"فاضلاب",VLOOKUP(INDEX($D$5:$D$261,$E8),'نمودار جمع‌آوری و ا'!$A$9:$BG$26,COLUMN()-5,FALSE),"تجهیزات",VLOOKUP(INDEX($D$5:$D$261,$E8),'نمودار تجهیزات آب و'!$A$9:$BG$42,COLUMN()-5,FALSE),"پست",VLOOKUP(INDEX($D$5:$D$261,$E8),'نمودار پست های انتق'!$A$9:$BG$41,COLUMN()-5,FALSE),"نیرو",VLOOKUP(INDEX($D$5:$D$261,$E8),'نمودار توزیع نیرو ب'!$A$9:$BG$38,COLUMN()-5,FALSE),""))} -> 582.9 | K8: {=IF($E8="","",_xlfn.SWITCH(LEFT(INDEX($B$5:$B$261,$E8),FIND("|",INDEX($B$5:$B$261,$E8))-1),"ابنیه",VLOOKUP(INDEX($D$5:$D$261,$E8),'نمودار ابنیه'!$A$9:$BG$37,COLUMN()-5,FALSE),"مکانیکی",VLOOKUP(INDEX($D$5:$D$261,$E8),'نمودار مکانیکی'!$A$9:$BG$43,COLUMN()-5,FALSE),"برقی",VLOOKUP(INDEX($D$5:$D$261,$E8),'نمودار تاسیسات برقی'!$A$9:$BG$44,COLUMN()-5,FALSE),"خطوط",VLOOKUP(INDEX($D$5:$D$261,$E8),'نمودار خطوط انتقال '!$A$9:$BG$26,COLUMN()-5,FALSE),"شبکه",VLOOKUP(INDEX($D$5:$D$261,$E8),'نمودار شبکه توزیع آ'!$A$9:$BG$22,COLUMN()-5,FALSE),"سد",VLOOKUP(INDEX($D$5:$D$261,$E8),'نمودار سدسازی'!$A$9:$BG$23,COLUMN()-5,FALSE),"فاضلاب",VLOOKUP(INDEX($D$5:$D$261,$E8),'نمودار جمع‌آوری و ا'!$A$9:$BG$26,COLUMN()-5,FALSE),"تجهیزات",VLOOKUP(INDEX($D$5:$D$261,$E8),'نمودار تجهیزات آب و'!$A$9:$BG$42,COLUMN()-5,FALSE),"پست",VLOOKUP(INDEX($D$5:$D$261,$E8),'نمودار پست های انتق'!$A$9:$BG$41,COLUMN()-5,FALSE),"نیرو",VLOOKUP(INDEX($D$5:$D$261,$E8),'نمودار توزیع نیرو ب'!$A$9:$BG$38,COLUMN()-5,FALSE),""))} -> 588.7 | L8: {=IF($E8="","",_xlfn.SWITCH(LEFT(INDEX($B$5:$B$261,$E8),FIND("|",INDEX($B$5:$B$261,$E8))-1),"ابنیه",VLOOKUP(INDEX($D$5:$D$261,$E8),'نمودار ابنیه'!$A$9:$BG$37,COLUMN()-5,FALSE),"مکانیکی",VLOOKUP(INDEX($D$5:$D$261,$E8),'نمودار مکانیکی'!$A$9:$BG$43,COLUMN()-5,FALSE),"برقی",VLOOKUP(INDEX($D$5:$D$261,$E8),'نمودار تاسیسات برقی'!$A$9:$BG$44,COLUMN()-5,FALSE),"خطوط",VLOOKUP(INDEX($D$5:$D$261,$E8),'نمودار خطوط انتقال '!$A$9:$BG$26,COLUMN()-5,FALSE),"شبکه",VLOOKUP(INDEX($D$5:$D$261,$E8),'نمودار شبکه توزیع آ'!$A$9:$BG$22,COLUMN()-5,FALSE),"سد",VLOOKUP(INDEX($D$5:$D$261,$E8),'نمودار سدسازی'!$A$9:$BG$23,COLUMN()-5,FALSE),"فاضلاب",VLOOKUP(INDEX($D$5:$D$261,$E8),'نمودار جمع‌آوری و ا'!$A$9:$BG$26,COLUMN()-5,FALSE),"تجهیزات",VLOOKUP(INDEX($D$5:$D$261,$E8),'نمودار تجهیزات آب و'!$A$9:$BG$42,COLUMN()-5,FALSE),"پست",VLOOKUP(INDEX($D$5:$D$261,$E8),'نمودار پست های انتق'!$A$9:$BG$41,COLUMN()-5,FALSE),"نیرو",VLOOKUP(INDEX($D$5:$D$261,$E8),'نمودار توزیع نیرو ب'!$A$9:$BG$38,COLUMN()-5,FALSE),""))} -> 594 | M8: {=IF($E8="","",_xlfn.SWITCH(LEFT(INDEX($B$5:$B$261,$E8),FIND("|",INDEX($B$5:$B$261,$E8))-1),"ابنیه",VLOOKUP(INDEX($D$5:$D$261,$E8),'نمودار ابنیه'!$A$9:$BG$37,COLUMN()-5,FALSE),"مکانیکی",VLOOKUP(INDEX($D$5:$D$261,$E8),'نمودار مکانیکی'!$A$9:$BG$43,COLUMN()-5,FALSE),"برقی",VLOOKUP(INDEX($D$5:$D$261,$E8),'نمودار تاسیسات برقی'!$A$9:$BG$44,COLUMN()-5,FALSE),"خطوط",VLOOKUP(INDEX($D$5:$D$261,$E8),'نمودار خطوط انتقال '!$A$9:$BG$26,COLUMN()-5,FALSE),"شبکه",VLOOKUP(INDEX($D$5:$D$261,$E8),'نمودار شبکه توزیع آ'!$A$9:$BG$22,COLUMN()-5,FALSE),"سد",VLOOKUP(INDEX($D$5:$D$261,$E8),'نمودار سدسازی'!$A$9:$BG$23,COLUMN()-5,FALSE),"فاضلاب",VLOOKUP(INDEX($D$5:$D$261,$E8),'نمودار جمع‌آوری و ا'!$A$9:$BG$26,COLUMN()-5,FALSE),"تجهیزات",VLOOKUP(INDEX($D$5:$D$261,$E8),'نمودار تجهیزات آب و'!$A$9:$BG$42,COLUMN()-5,FALSE),"پست",VLOOKUP(INDEX($D$5:$D$261,$E8),'نمودار پست های انتق'!$A$9:$BG$41,COLUMN()-5,FALSE),"نیرو",VLOOKUP(INDEX($D$5:$D$261,$E8),'نمودار توزیع نیرو ب'!$A$9:$BG$38,COLUMN()-5,FALSE),""))} -> 626.2 | N8: {=IF($E8="","",_xlfn.SWITCH(LEFT(INDEX($B$5:$B$261,$E8),FIND("|",INDEX($B$5:$B$261,$E8))-1),"ابنیه",VLOOKUP(INDEX($D$5:$D$261,$E8),'نمودار ابنیه'!$A$9:$BG$37,COLUMN()-5,FALSE),"مکانیکی",VLOOKUP(INDEX($D$5:$D$261,$E8),'نمودار مکانیکی'!$A$9:$BG$43,COLUMN()-5,FALSE),"برقی",VLOOKUP(INDEX($D$5:$D$261,$E8),'نمودار تاسیسات برقی'!$A$9:$BG$44,COLUMN()-5,FALSE),"خطوط",VLOOKUP(INDEX($D$5:$D$261,$E8),'نمودار خطوط انتقال '!$A$9:$BG$26,COLUMN()-5,FALSE),"شبکه",VLOOKUP(INDEX($D$5:$D$261,$E8),'نمودار شبکه توزیع آ'!$A$9:$BG$22,COLUMN()-5,FALSE),"سد",VLOOKUP(INDEX($D$5:$D$261,$E8),'نمودار سدسازی'!$A$9:$BG$23,COLUMN()-5,FALSE),"فاضلاب",VLOOKUP(INDEX($D$5:$D$261,$E8),'نمودار جمع‌آوری و ا'!$A$9:$BG$26,COLUMN()-5,FALSE),"تجهیزات",VLOOKUP(INDEX($D$5:$D$261,$E8),'نمودار تجهیزات آب و'!$A$9:$BG$42,COLUMN()-5,FALSE),"پست",VLOOKUP(INDEX($D$5:$D$261,$E8),'نمودار پست های انتق'!$A$9:$BG$41,COLUMN()-5,FALSE),"نیرو",VLOOKUP(INDEX($D$5:$D$261,$E8),'نمودار توزیع نیرو ب'!$A$9:$BG$38,COLUMN()-5,FALSE),""))} -> 715.9 | ... BL8: {=IF($E8="","",_xlfn.SWITCH(LEFT(INDEX($B$5:$B$261,$E8),FIND("|",INDEX($B$5:$B$261,$E8))-1),"ابنیه",VLOOKUP(INDEX($D$5:$D$261,$E8),'نمودار ابنیه'!$A$9:$BG$37,COLUMN()-5,FALSE),"مکانیکی",VLOOKUP(INDEX($D$5:$D$261,$E8),'نمودار مکانیکی'!$A$9:$BG$43,COLUMN()-5,FALSE),"برقی",VLOOKUP(INDEX($D$5:$D$261,$E8),'نمودار تاسیسات برقی'!$A$9:$BG$44,COLUMN()-5,FALSE),"خطوط",VLOOKUP(INDEX($D$5:$D$261,$E8),'نمودار خطوط انتقال '!$A$9:$BG$26,COLUMN()-5,FALSE),"شبکه",VLOOKUP(INDEX($D$5:$D$261,$E8),'نمودار شبکه توزیع آ'!$A$9:$BG$22,COLUMN()-5,FALSE),"سد",VLOOKUP(INDEX($D$5:$D$261,$E8),'نمودار سدسازی'!$A$9:$BG$23,COLUMN()-5,FALSE),"فاضلاب",VLOOKUP(INDEX($D$5:$D$261,$E8),'نمودار جمع‌آوری و ا'!$A$9:$BG$26,COLUMN()-5,FALSE),"تجهیزات",VLOOKUP(INDEX($D$5:$D$261,$E8),'نمودار تجهیزات آب و'!$A$9:$BG$42,COLUMN()-5,FALSE),"پست",VLOOKUP(INDEX($D$5:$D$261,$E8),'نمودار پست های انتق'!$A$9:$BG$41,COLUMN()-5,FALSE),"نیرو",VLOOKUP(INDEX($D$5:$D$261,$E8),'نمودار توزیع نیرو ب'!$A$9:$BG$38,COLUMN()-5,FALSE),""))} -> 6279.9
A9: 5 | B9: ابنیه|Buildings | C9: {=_xlfn.SWITCH(LEFT(B9,FIND("|",B9)-1),"ابنیه",HLOOKUP(D9,'نمودار ابنیه'!$B$5:$AD$6,2,FALSE),"مکانیکی",HLOOKUP(D9,'نمودار مکانیکی'!$B$5:$AJ$6,2,FALSE),"برقی",HLOOKUP(D9,'نمودار تاسیسات برقی'!$B$5:$AK$6,2,FALSE),"خطوط",HLOOKUP(D9,'نمودار خطوط انتقال '!$B$5:$R$6,2,FALSE),"شبکه",HLOOKUP(D9,'نمودار شبکه توزیع آ'!$B$5:$O$6,2,FALSE),"سد",HLOOKUP(D9,'نمودار سدسازی'!$B$5:$P$6,2,FALSE),"فاضلاب",HLOOKUP(D9,'نمودار جمع‌آوری و ا'!$B$5:$S$6,2,FALSE),"تجهیزات",HLOOKUP(D9,'نمودار تجهیزات آب و'!$B$5:$AG$6,2,FALSE),"پست",HLOOKUP(D9,'نمودار پست های انتق'!$B$5:$AH$6,2,FALSE),"نیرو",HLOOKUP(D9,'نمودار توزیع نیرو ب'!$B$5:$AE$6,2,FALSE),FALSE)} -> FALSE | D9: قالب بندی چوبی | E9: {=IFERROR(_xlfn.AGGREGATE(15,6,ROW($C$5:$C$261)/($C$5:$C$261=TRUE),4)-4,"")} -> 32 | F9: {=IF($E9="","",LEFT(INDEX($B$5:$B$261,$E9),FIND("|",INDEX($B$5:$B$261,$E9))-1)&":"&LEFT(INDEX($D$5:$D$261,$E9),20))} -> مکانیکی:لوله های پی.وی.سی | G9: {=IF($E9="","",_xlfn.SWITCH(LEFT(INDEX($B$5:$B$261,$E9),FIND("|",INDEX($B$5:$B$261,$E9))-1),"ابنیه",VLOOKUP(INDEX($D$5:$D$261,$E9),'نمودار ابنیه'!$A$9:$BG$37,COLUMN()-5,FALSE),"مکانیکی",VLOOKUP(INDEX($D$5:$D$261,$E9),'نمودار مکانیکی'!$A$9:$BG$43,COLUMN()-5,FALSE),"برقی",VLOOKUP(INDEX($D$5:$D$261,$E9),'نمودار تاسیسات برقی'!$A$9:$BG$44,COLUMN()-5,FALSE),"خطوط",VLOOKUP(INDEX($D$5:$D$261,$E9),'نمودار خطوط انتقال '!$A$9:$BG$26,COLUMN()-5,FALSE),"شبکه",VLOOKUP(INDEX($D$5:$D$261,$E9),'نمودار شبکه توزیع آ'!$A$9:$BG$22,COLUMN()-5,FALSE),"سد",VLOOKUP(INDEX($D$5:$D$261,$E9),'نمودار سدسازی'!$A$9:$BG$23,COLUMN()-5,FALSE),"فاضلاب",VLOOKUP(INDEX($D$5:$D$261,$E9),'نمودار جمع‌آوری و ا'!$A$9:$BG$26,COLUMN()-5,FALSE),"تجهیزات",VLOOKUP(INDEX($D$5:$D$261,$E9),'نمودار تجهیزات آب و'!$A$9:$BG$42,COLUMN()-5,FALSE),"پست",VLOOKUP(INDEX($D$5:$D$261,$E9),'نمودار پست های انتق'!$A$9:$BG$41,COLUMN()-5,FALSE),"نیرو",VLOOKUP(INDEX($D$5:$D$261,$E9),'نمودار توزیع نیرو ب'!$A$9:$BG$38,COLUMN()-5,FALSE),""))} -> 346.5 | H9: {=IF($E9="","",_xlfn.SWITCH(LEFT(INDEX($B$5:$B$261,$E9),FIND("|",INDEX($B$5:$B$261,$E9))-1),"ابنیه",VLOOKUP(INDEX($D$5:$D$261,$E9),'نمودار ابنیه'!$A$9:$BG$37,COLUMN()-5,FALSE),"مکانیکی",VLOOKUP(INDEX($D$5:$D$261,$E9),'نمودار مکانیکی'!$A$9:$BG$43,COLUMN()-5,FALSE),"برقی",VLOOKUP(INDEX($D$5:$D$261,$E9),'نمودار تاسیسات برقی'!$A$9:$BG$44,COLUMN()-5,FALSE),"خطوط",VLOOKUP(INDEX($D$5:$D$261,$E9),'نمودار خطوط انتقال '!$A$9:$BG$26,COLUMN()-5,FALSE),"شبکه",VLOOKUP(INDEX($D$5:$D$261,$E9),'نمودار شبکه توزیع آ'!$A$9:$BG$22,COLUMN()-5,FALSE),"سد",VLOOKUP(INDEX($D$5:$D$261,$E9),'نمودار سدسازی'!$A$9:$BG$23,COLUMN()-5,FALSE),"فاضلاب",VLOOKUP(INDEX($D$5:$D$261,$E9),'نمودار جمع‌آوری و ا'!$A$9:$BG$26,COLUMN()-5,FALSE),"تجهیزات",VLOOKUP(INDEX($D$5:$D$261,$E9),'نمودار تجهیزات آب و'!$A$9:$BG$42,COLUMN()-5,FALSE),"پست",VLOOKUP(INDEX($D$5:$D$261,$E9),'نمودار پست های انتق'!$A$9:$BG$41,COLUMN()-5,FALSE),"نیرو",VLOOKUP(INDEX($D$5:$D$261,$E9),'نمودار توزیع نیرو ب'!$A$9:$BG$38,COLUMN()-5,FALSE),""))} -> 248.1 | I9: {=IF($E9="","",_xlfn.SWITCH(LEFT(INDEX($B$5:$B$261,$E9),FIND("|",INDEX($B$5:$B$261,$E9))-1),"ابنیه",VLOOKUP(INDEX($D$5:$D$261,$E9),'نمودار ابنیه'!$A$9:$BG$37,COLUMN()-5,FALSE),"مکانیکی",VLOOKUP(INDEX($D$5:$D$261,$E9),'نمودار مکانیکی'!$A$9:$BG$43,COLUMN()-5,FALSE),"برقی",VLOOKUP(INDEX($D$5:$D$261,$E9),'نمودار تاسیسات برقی'!$A$9:$BG$44,COLUMN()-5,FALSE),"خطوط",VLOOKUP(INDEX($D$5:$D$261,$E9),'نمودار خطوط انتقال '!$A$9:$BG$26,COLUMN()-5,FALSE),"شبکه",VLOOKUP(INDEX($D$5:$D$261,$E9),'نمودار شبکه توزیع آ'!$A$9:$BG$22,COLUMN()-5,FALSE),"سد",VLOOKUP(INDEX($D$5:$D$261,$E9),'نمودار سدسازی'!$A$9:$BG$23,COLUMN()-5,FALSE),"فاضلاب",VLOOKUP(INDEX($D$5:$D$261,$E9),'نمودار جمع‌آوری و ا'!$A$9:$BG$26,COLUMN()-5,FALSE),"تجهیزات",VLOOKUP(INDEX($D$5:$D$261,$E9),'نمودار تجهیزات آب و'!$A$9:$BG$42,COLUMN()-5,FALSE),"پست",VLOOKUP(INDEX($D$5:$D$261,$E9),'نمودار پست های انتق'!$A$9:$BG$41,COLUMN()-5,FALSE),"نیرو",VLOOKUP(INDEX($D$5:$D$261,$E9),'نمودار توزیع نیرو ب'!$A$9:$BG$38,COLUMN()-5,FALSE),""))} -> 263.7 | J9: {=IF($E9="","",_xlfn.SWITCH(LEFT(INDEX($B$5:$B$261,$E9),FIND("|",INDEX($B$5:$B$261,$E9))-1),"ابنیه",VLOOKUP(INDEX($D$5:$D$261,$E9),'نمودار ابنیه'!$A$9:$BG$37,COLUMN()-5,FALSE),"مکانیکی",VLOOKUP(INDEX($D$5:$D$261,$E9),'نمودار مکانیکی'!$A$9:$BG$43,COLUMN()-5,FALSE),"برقی",VLOOKUP(INDEX($D$5:$D$261,$E9),'نمودار تاسیسات برقی'!$A$9:$BG$44,COLUMN()-5,FALSE),"خطوط",VLOOKUP(INDEX($D$5:$D$261,$E9),'نمودار خطوط انتقال '!$A$9:$BG$26,COLUMN()-5,FALSE),"شبکه",VLOOKUP(INDEX($D$5:$D$261,$E9),'نمودار شبکه توزیع آ'!$A$9:$BG$22,COLUMN()-5,FALSE),"سد",VLOOKUP(INDEX($D$5:$D$261,$E9),'نمودار سدسازی'!$A$9:$BG$23,COLUMN()-5,FALSE),"فاضلاب",VLOOKUP(INDEX($D$5:$D$261,$E9),'نمودار جمع‌آوری و ا'!$A$9:$BG$26,COLUMN()-5,FALSE),"تجهیزات",VLOOKUP(INDEX($D$5:$D$261,$E9),'نمودار تجهیزات آب و'!$A$9:$BG$42,COLUMN()-5,FALSE),"پست",VLOOKUP(INDEX($D$5:$D$261,$E9),'نمودار پست های انتق'!$A$9:$BG$41,COLUMN()-5,FALSE),"نیرو",VLOOKUP(INDEX($D$5:$D$261,$E9),'نمودار توزیع نیرو ب'!$A$9:$BG$38,COLUMN()-5,FALSE),""))} -> 265.3 | K9: {=IF($E9="","",_xlfn.SWITCH(LEFT(INDEX($B$5:$B$261,$E9),FIND("|",INDEX($B$5:$B$261,$E9))-1),"ابنیه",VLOOKUP(INDEX($D$5:$D$261,$E9),'نمودار ابنیه'!$A$9:$BG$37,COLUMN()-5,FALSE),"مکانیکی",VLOOKUP(INDEX($D$5:$D$261,$E9),'نمودار مکانیکی'!$A$9:$BG$43,COLUMN()-5,FALSE),"برقی",VLOOKUP(INDEX($D$5:$D$261,$E9),'نمودار تاسیسات برقی'!$A$9:$BG$44,COLUMN()-5,FALSE),"خطوط",VLOOKUP(INDEX($D$5:$D$261,$E9),'نمودار خطوط انتقال '!$A$9:$BG$26,COLUMN()-5,FALSE),"شبکه",VLOOKUP(INDEX($D$5:$D$261,$E9),'نمودار شبکه توزیع آ'!$A$9:$BG$22,COLUMN()-5,FALSE),"سد",VLOOKUP(INDEX($D$5:$D$261,$E9),'نمودار سدسازی'!$A$9:$BG$23,COLUMN()-5,FALSE),"فاضلاب",VLOOKUP(INDEX($D$5:$D$261,$E9),'نمودار جمع‌آوری و ا'!$A$9:$BG$26,COLUMN()-5,FALSE),"تجهیزات",VLOOKUP(INDEX($D$5:$D$261,$E9),'نمودار تجهیزات آب و'!$A$9:$BG$42,COLUMN()-5,FALSE),"پست",VLOOKUP(INDEX($D$5:$D$261,$E9),'نمودار پست های انتق'!$A$9:$BG$41,COLUMN()-5,FALSE),"نیرو",VLOOKUP(INDEX($D$5:$D$261,$E9),'نمودار توزیع نیرو ب'!$A$9:$BG$38,COLUMN()-5,FALSE),""))} -> 302.6 | L9: {=IF($E9="","",_xlfn.SWITCH(LEFT(INDEX($B$5:$B$261,$E9),FIND("|",INDEX($B$5:$B$261,$E9))-1),"ابنیه",VLOOKUP(INDEX($D$5:$D$261,$E9),'نمودار ابنیه'!$A$9:$BG$37,COLUMN()-5,FALSE),"مکانیکی",VLOOKUP(INDEX($D$5:$D$261,$E9),'نمودار مکانیکی'!$A$9:$BG$43,COLUMN()-5,FALSE),"برقی",VLOOKUP(INDEX($D$5:$D$261,$E9),'نمودار تاسیسات برقی'!$A$9:$BG$44,COLUMN()-5,FALSE),"خطوط",VLOOKUP(INDEX($D$5:$D$261,$E9),'نمودار خطوط انتقال '!$A$9:$BG$26,COLUMN()-5,FALSE),"شبکه",VLOOKUP(INDEX($D$5:$D$261,$E9),'نمودار شبکه توزیع آ'!$A$9:$BG$22,COLUMN()-5,FALSE),"سد",VLOOKUP(INDEX($D$5:$D$261,$E9),'نمودار سدسازی'!$A$9:$BG$23,COLUMN()-5,FALSE),"فاضلاب",VLOOKUP(INDEX($D$5:$D$261,$E9),'نمودار جمع‌آوری و ا'!$A$9:$BG$26,COLUMN()-5,FALSE),"تجهیزات",VLOOKUP(INDEX($D$5:$D$261,$E9),'نمودار تجهیزات آب و'!$A$9:$BG$42,COLUMN()-5,FALSE),"پست",VLOOKUP(INDEX($D$5:$D$261,$E9),'نمودار پست های انتق'!$A$9:$BG$41,COLUMN()-5,FALSE),"نیرو",VLOOKUP(INDEX($D$5:$D$261,$E9),'نمودار توزیع نیرو ب'!$A$9:$BG$38,COLUMN()-5,FALSE),""))} -> 360.8 | M9: {=IF($E9="","",_xlfn.SWITCH(LEFT(INDEX($B$5:$B$261,$E9),FIND("|",INDEX($B$5:$B$261,$E9))-1),"ابنیه",VLOOKUP(INDEX($D$5:$D$261,$E9),'نمودار ابنیه'!$A$9:$BG$37,COLUMN()-5,FALSE),"مکانیکی",VLOOKUP(INDEX($D$5:$D$261,$E9),'نمودار مکانیکی'!$A$9:$BG$43,COLUMN()-5,FALSE),"برقی",VLOOKUP(INDEX($D$5:$D$261,$E9),'نمودار تاسیسات برقی'!$A$9:$BG$44,COLUMN()-5,FALSE),"خطوط",VLOOKUP(INDEX($D$5:$D$261,$E9),'نمودار خطوط انتقال '!$A$9:$BG$26,COLUMN()-5,FALSE),"شبکه",VLOOKUP(INDEX($D$5:$D$261,$E9),'نمودار شبکه توزیع آ'!$A$9:$BG$22,COLUMN()-5,FALSE),"سد",VLOOKUP(INDEX($D$5:$D$261,$E9),'نمودار سدسازی'!$A$9:$BG$23,COLUMN()-5,FALSE),"فاضلاب",VLOOKUP(INDEX($D$5:$D$261,$E9),'نمودار جمع‌آوری و ا'!$A$9:$BG$26,COLUMN()-5,FALSE),"تجهیزات",VLOOKUP(INDEX($D$5:$D$261,$E9),'نمودار تجهیزات آب و'!$A$9:$BG$42,COLUMN()-5,FALSE),"پست",VLOOKUP(INDEX($D$5:$D$261,$E9),'نمودار پست های انتق'!$A$9:$BG$41,COLUMN()-5,FALSE),"نیرو",VLOOKUP(INDEX($D$5:$D$261,$E9),'نمودار توزیع نیرو ب'!$A$9:$BG$38,COLUMN()-5,FALSE),""))} -> 505.6 | N9: {=IF($E9="","",_xlfn.SWITCH(LEFT(INDEX($B$5:$B$261,$E9),FIND("|",INDEX($B$5:$B$261,$E9))-1),"ابنیه",VLOOKUP(INDEX($D$5:$D$261,$E9),'نمودار ابنیه'!$A$9:$BG$37,COLUMN()-5,FALSE),"مکانیکی",VLOOKUP(INDEX($D$5:$D$261,$E9),'نمودار مکانیکی'!$A$9:$BG$43,COLUMN()-5,FALSE),"برقی",VLOOKUP(INDEX($D$5:$D$261,$E9),'نمودار تاسیسات برقی'!$A$9:$BG$44,COLUMN()-5,FALSE),"خطوط",VLOOKUP(INDEX($D$5:$D$261,$E9),'نمودار خطوط انتقال '!$A$9:$BG$26,COLUMN()-5,FALSE),"شبکه",VLOOKUP(INDEX($D$5:$D$261,$E9),'نمودار شبکه توزیع آ'!$A$9:$BG$22,COLUMN()-5,FALSE),"سد",VLOOKUP(INDEX($D$5:$D$261,$E9),'نمودار سدسازی'!$A$9:$BG$23,COLUMN()-5,FALSE),"فاضلاب",VLOOKUP(INDEX($D$5:$D$261,$E9),'نمودار جمع‌آوری و ا'!$A$9:$BG$26,COLUMN()-5,FALSE),"تجهیزات",VLOOKUP(INDEX($D$5:$D$261,$E9),'نمودار تجهیزات آب و'!$A$9:$BG$42,COLUMN()-5,FALSE),"پست",VLOOKUP(INDEX($D$5:$D$261,$E9),'نمودار پست های انتق'!$A$9:$BG$41,COLUMN()-5,FALSE),"نیرو",VLOOKUP(INDEX($D$5:$D$261,$E9),'نمودار توزیع نیرو ب'!$A$9:$BG$38,COLUMN()-5,FALSE),""))} -> 534.8 | ... BL9: {=IF($E9="","",_xlfn.SWITCH(LEFT(INDEX($B$5:$B$261,$E9),FIND("|",INDEX($B$5:$B$261,$E9))-1),"ابنیه",VLOOKUP(INDEX($D$5:$D$261,$E9),'نمودار ابنیه'!$A$9:$BG$37,COLUMN()-5,FALSE),"مکانیکی",VLOOKUP(INDEX($D$5:$D$261,$E9),'نمودار مکانیکی'!$A$9:$BG$43,COLUMN()-5,FALSE),"برقی",VLOOKUP(INDEX($D$5:$D$261,$E9),'نمودار تاسیسات برقی'!$A$9:$BG$44,COLUMN()-5,FALSE),"خطوط",VLOOKUP(INDEX($D$5:$D$261,$E9),'نمودار خطوط انتقال '!$A$9:$BG$26,COLUMN()-5,FALSE),"شبکه",VLOOKUP(INDEX($D$5:$D$261,$E9),'نمودار شبکه توزیع آ'!$A$9:$BG$22,COLUMN()-5,FALSE),"سد",VLOOKUP(INDEX($D$5:$D$261,$E9),'نمودار سدسازی'!$A$9:$BG$23,COLUMN()-5,FALSE),"فاضلاب",VLOOKUP(INDEX($D$5:$D$261,$E9),'نمودار جمع‌آوری و ا'!$A$9:$BG$26,COLUMN()-5,FALSE),"تجهیزات",VLOOKUP(INDEX($D$5:$D$261,$E9),'نمودار تجهیزات آب و'!$A$9:$BG$42,COLUMN()-5,FALSE),"پست",VLOOKUP(INDEX($D$5:$D$261,$E9),'نمودار پست های انتق'!$A$9:$BG$41,COLUMN()-5,FALSE),"نیرو",VLOOKUP(INDEX($D$5:$D$261,$E9),'نمودار توزیع نیرو ب'!$A$9:$BG$38,COLUMN()-5,FALSE),""))} -> 5504.8
A10: 6 | B10: ابنیه|Buildings | C10: {=_xlfn.SWITCH(LEFT(B10,FIND("|",B10)-1),"ابنیه",HLOOKUP(D10,'نمودار ابنیه'!$B$5:$AD$6,2,FALSE),"مکانیکی",HLOOKUP(D10,'نمودار مکانیکی'!$B$5:$AJ$6,2,FALSE),"برقی",HLOOKUP(D10,'نمودار تاسیسات برقی'!$B$5:$AK$6,2,FALSE),"خطوط",HLOOKUP(D10,'نمودار خطوط انتقال '!$B$5:$R$6,2,FALSE),"شبکه",HLOOKUP(D10,'نمودار شبکه توزیع آ'!$B$5:$O$6,2,FALSE),"سد",HLOOKUP(D10,'نمودار سدسازی'!$B$5:$P$6,2,FALSE),"فاضلاب",HLOOKUP(D10,'نمودار جمع‌آوری و ا'!$B$5:$S$6,2,FALSE),"تجهیزات",HLOOKUP(D10,'نمودار تجهیزات آب و'!$B$5:$AG$6,2,FALSE),"پست",HLOOKUP(D10,'نمودار پست های انتق'!$B$5:$AH$6,2,FALSE),"نیرو",HLOOKUP(D10,'نمودار توزیع نیرو ب'!$B$5:$AE$6,2,FALSE),FALSE)} -> FALSE | D10: قالب بندی فلزی | E10: {=IFERROR(_xlfn.AGGREGATE(15,6,ROW($C$5:$C$261)/($C$5:$C$261=TRUE),5)-4,"")} -> 33 | F10: {=IF($E10="","",LEFT(INDEX($B$5:$B$261,$E10),FIND("|",INDEX($B$5:$B$261,$E10))-1)&":"&LEFT(INDEX($D$5:$D$261,$E10),20))} -> مکانیکی:لوله های پلی اتیلن | G10: {=IF($E10="","",_xlfn.SWITCH(LEFT(INDEX($B$5:$B$261,$E10),FIND("|",INDEX($B$5:$B$261,$E10))-1),"ابنیه",VLOOKUP(INDEX($D$5:$D$261,$E10),'نمودار ابنیه'!$A$9:$BG$37,COLUMN()-5,FALSE),"مکانیکی",VLOOKUP(INDEX($D$5:$D$261,$E10),'نمودار مکانیکی'!$A$9:$BG$43,COLUMN()-5,FALSE),"برقی",VLOOKUP(INDEX($D$5:$D$261,$E10),'نمودار تاسیسات برقی'!$A$9:$BG$44,COLUMN()-5,FALSE),"خطوط",VLOOKUP(INDEX($D$5:$D$261,$E10),'نمودار خطوط انتقال '!$A$9:$BG$26,COLUMN()-5,FALSE),"شبکه",VLOOKUP(INDEX($D$5:$D$261,$E10),'نمودار شبکه توزیع آ'!$A$9:$BG$22,COLUMN()-5,FALSE),"سد",VLOOKUP(INDEX($D$5:$D$261,$E10),'نمودار سدسازی'!$A$9:$BG$23,COLUMN()-5,FALSE),"فاضلاب",VLOOKUP(INDEX($D$5:$D$261,$E10),'نمودار جمع‌آوری و ا'!$A$9:$BG$26,COLUMN()-5,FALSE),"تجهیزات",VLOOKUP(INDEX($D$5:$D$261,$E10),'نمودار تجهیزات آب و'!$A$9:$BG$42,COLUMN()-5,FALSE),"پست",VLOOKUP(INDEX($D$5:$D$261,$E10),'نمودار پست های انتق'!$A$9:$BG$41,COLUMN()-5,FALSE),"نیرو",VLOOKUP(INDEX($D$5:$D$261,$E10),'نمودار توزیع نیرو ب'!$A$9:$BG$38,COLUMN()-5,FALSE),""))} -> 153.8 | H10: {=IF($E10="","",_xlfn.SWITCH(LEFT(INDEX($B$5:$B$261,$E10),FIND("|",INDEX($B$5:$B$261,$E10))-1),"ابنیه",VLOOKUP(INDEX($D$5:$D$261,$E10),'نمودار ابنیه'!$A$9:$BG$37,COLUMN()-5,FALSE),"مکانیکی",VLOOKUP(INDEX($D$5:$D$261,$E10),'نمودار مکانیکی'!$A$9:$BG$43,COLUMN()-5,FALSE),"برقی",VLOOKUP(INDEX($D$5:$D$261,$E10),'نمودار تاسیسات برقی'!$A$9:$BG$44,COLUMN()-5,FALSE),"خطوط",VLOOKUP(INDEX($D$5:$D$261,$E10),'نمودار خطوط انتقال '!$A$9:$BG$26,COLUMN()-5,FALSE),"شبکه",VLOOKUP(INDEX($D$5:$D$261,$E10),'نمودار شبکه توزیع آ'!$A$9:$BG$22,COLUMN()-5,FALSE),"سد",VLOOKUP(INDEX($D$5:$D$261,$E10),'نمودار سدسازی'!$A$9:$BG$23,COLUMN()-5,FALSE),"فاضلاب",VLOOKUP(INDEX($D$5:$D$261,$E10),'نمودار جمع‌آوری و ا'!$A$9:$BG$26,COLUMN()-5,FALSE),"تجهیزات",VLOOKUP(INDEX($D$5:$D$261,$E10),'نمودار تجهیزات آب و'!$A$9:$BG$42,COLUMN()-5,FALSE),"پست",VLOOKUP(INDEX($D$5:$D$261,$E10),'نمودار پست های انتق'!$A$9:$BG$41,COLUMN()-5,FALSE),"نیرو",VLOOKUP(INDEX($D$5:$D$261,$E10),'نمودار توزیع نیرو ب'!$A$9:$BG$38,COLUMN()-5,FALSE),""))} -> 154.7 | I10: {=IF($E10="","",_xlfn.SWITCH(LEFT(INDEX($B$5:$B$261,$E10),FIND("|",INDEX($B$5:$B$261,$E10))-1),"ابنیه",VLOOKUP(INDEX($D$5:$D$261,$E10),'نمودار ابنیه'!$A$9:$BG$37,COLUMN()-5,FALSE),"مکانیکی",VLOOKUP(INDEX($D$5:$D$261,$E10),'نمودار مکانیکی'!$A$9:$BG$43,COLUMN()-5,FALSE),"برقی",VLOOKUP(INDEX($D$5:$D$261,$E10),'نمودار تاسیسات برقی'!$A$9:$BG$44,COLUMN()-5,FALSE),"خطوط",VLOOKUP(INDEX($D$5:$D$261,$E10),'نمودار خطوط انتقال '!$A$9:$BG$26,COLUMN()-5,FALSE),"شبکه",VLOOKUP(INDEX($D$5:$D$261,$E10),'نمودار شبکه توزیع آ'!$A$9:$BG$22,COLUMN()-5,FALSE),"سد",VLOOKUP(INDEX($D$5:$D$261,$E10),'نمودار سدسازی'!$A$9:$BG$23,COLUMN()-5,FALSE),"فاضلاب",VLOOKUP(INDEX($D$5:$D$261,$E10),'نمودار جمع‌آوری و ا'!$A$9:$BG$26,COLUMN()-5,FALSE),"تجهیزات",VLOOKUP(INDEX($D$5:$D$261,$E10),'نمودار تجهیزات آب و'!$A$9:$BG$42,COLUMN()-5,FALSE),"پست",VLOOKUP(INDEX($D$5:$D$261,$E10),'نمودار پست های انتق'!$A$9:$BG$41,COLUMN()-5,FALSE),"نیرو",VLOOKUP(INDEX($D$5:$D$261,$E10),'نمودار توزیع نیرو ب'!$A$9:$BG$38,COLUMN()-5,FALSE),""))} -> 144.5 | J10: {=IF($E10="","",_xlfn.SWITCH(LEFT(INDEX($B$5:$B$261,$E10),FIND("|",INDEX($B$5:$B$261,$E10))-1),"ابنیه",VLOOKUP(INDEX($D$5:$D$261,$E10),'نمودار ابنیه'!$A$9:$BG$37,COLUMN()-5,FALSE),"مکانیکی",VLOOKUP(INDEX($D$5:$D$261,$E10),'نمودار مکانیکی'!$A$9:$BG$43,COLUMN()-5,FALSE),"برقی",VLOOKUP(INDEX($D$5:$D$261,$E10),'نمودار تاسیسات برقی'!$A$9:$BG$44,COLUMN()-5,FALSE),"خطوط",VLOOKUP(INDEX($D$5:$D$261,$E10),'نمودار خطوط انتقال '!$A$9:$BG$26,COLUMN()-5,FALSE),"شبکه",VLOOKUP(INDEX($D$5:$D$261,$E10),'نمودار شبکه توزیع آ'!$A$9:$BG$22,COLUMN()-5,FALSE),"سد",VLOOKUP(INDEX($D$5:$D$261,$E10),'نمودار سدسازی'!$A$9:$BG$23,COLUMN()-5,FALSE),"فاضلاب",VLOOKUP(INDEX($D$5:$D$261,$E10),'نمودار جمع‌آوری و ا'!$A$9:$BG$26,COLUMN()-5,FALSE),"تجهیزات",VLOOKUP(INDEX($D$5:$D$261,$E10),'نمودار تجهیزات آب و'!$A$9:$BG$42,COLUMN()-5,FALSE),"پست",VLOOKUP(INDEX($D$5:$D$261,$E10),'نمودار پست های انتق'!$A$9:$BG$41,COLUMN()-5,FALSE),"نیرو",VLOOKUP(INDEX($D$5:$D$261,$E10),'نمودار توزیع نیرو ب'!$A$9:$BG$38,COLUMN()-5,FALSE),""))} -> 153.5 | K10: {=IF($E10="","",_xlfn.SWITCH(LEFT(INDEX($B$5:$B$261,$E10),FIND("|",INDEX($B$5:$B$261,$E10))-1),"ابنیه",VLOOKUP(INDEX($D$5:$D$261,$E10),'نمودار ابنیه'!$A$9:$BG$37,COLUMN()-5,FALSE),"مکانیکی",VLOOKUP(INDEX($D$5:$D$261,$E10),'نمودار مکانیکی'!$A$9:$BG$43,COLUMN()-5,FALSE),"برقی",VLOOKUP(INDEX($D$5:$D$261,$E10),'نمودار تاسیسات برقی'!$A$9:$BG$44,COLUMN()-5,FALSE),"خطوط",VLOOKUP(INDEX($D$5:$D$261,$E10),'نمودار خطوط انتقال '!$A$9:$BG$26,COLUMN()-5,FALSE),"شبکه",VLOOKUP(INDEX($D$5:$D$261,$E10),'نمودار شبکه توزیع آ'!$A$9:$BG$22,COLUMN()-5,FALSE),"سد",VLOOKUP(INDEX($D$5:$D$261,$E10),'نمودار سدسازی'!$A$9:$BG$23,COLUMN()-5,FALSE),"فاضلاب",VLOOKUP(INDEX($D$5:$D$261,$E10),'نمودار جمع‌آوری و ا'!$A$9:$BG$26,COLUMN()-5,FALSE),"تجهیزات",VLOOKUP(INDEX($D$5:$D$261,$E10),'نمودار تجهیزات آب و'!$A$9:$BG$42,COLUMN()-5,FALSE),"پست",VLOOKUP(INDEX($D$5:$D$261,$E10),'نمودار پست های انتق'!$A$9:$BG$41,COLUMN()-5,FALSE),"نیرو",VLOOKUP(INDEX($D$5:$D$261,$E10),'نمودار توزیع نیرو ب'!$A$9:$BG$38,COLUMN()-5,FALSE),""))} -> 175.2 | L10: {=IF($E10="","",_xlfn.SWITCH(LEFT(INDEX($B$5:$B$261,$E10),FIND("|",INDEX($B$5:$B$261,$E10))-1),"ابنیه",VLOOKUP(INDEX($D$5:$D$261,$E10),'نمودار ابنیه'!$A$9:$BG$37,COLUMN()-5,FALSE),"مکانیکی",VLOOKUP(INDEX($D$5:$D$261,$E10),'نمودار مکانیکی'!$A$9:$BG$43,COLUMN()-5,FALSE),"برقی",VLOOKUP(INDEX($D$5:$D$261,$E10),'نمودار تاسیسات برقی'!$A$9:$BG$44,COLUMN()-5,FALSE),"خطوط",VLOOKUP(INDEX($D$5:$D$261,$E10),'نمودار خطوط انتقال '!$A$9:$BG$26,COLUMN()-5,FALSE),"شبکه",VLOOKUP(INDEX($D$5:$D$261,$E10),'نمودار شبکه توزیع آ'!$A$9:$BG$22,COLUMN()-5,FALSE),"سد",VLOOKUP(INDEX($D$5:$D$261,$E10),'نمودار سدسازی'!$A$9:$BG$23,COLUMN()-5,FALSE),"فاضلاب",VLOOKUP(INDEX($D$5:$D$261,$E10),'نمودار جمع‌آوری و ا'!$A$9:$BG$26,COLUMN()-5,FALSE),"تجهیزات",VLOOKUP(INDEX($D$5:$D$261,$E10),'نمودار تجهیزات آب و'!$A$9:$BG$42,COLUMN()-5,FALSE),"پست",VLOOKUP(INDEX($D$5:$D$261,$E10),'نمودار پست های انتق'!$A$9:$BG$41,COLUMN()-5,FALSE),"نیرو",VLOOKUP(INDEX($D$5:$D$261,$E10),'نمودار توزیع نیرو ب'!$A$9:$BG$38,COLUMN()-5,FALSE),""))} -> 181.8 | M10: {=IF($E10="","",_xlfn.SWITCH(LEFT(INDEX($B$5:$B$261,$E10),FIND("|",INDEX($B$5:$B$261,$E10))-1),"ابنیه",VLOOKUP(INDEX($D$5:$D$261,$E10),'نمودار ابنیه'!$A$9:$BG$37,COLUMN()-5,FALSE),"مکانیکی",VLOOKUP(INDEX($D$5:$D$261,$E10),'نمودار مکانیکی'!$A$9:$BG$43,COLUMN()-5,FALSE),"برقی",VLOOKUP(INDEX($D$5:$D$261,$E10),'نمودار تاسیسات برقی'!$A$9:$BG$44,COLUMN()-5,FALSE),"خطوط",VLOOKUP(INDEX($D$5:$D$261,$E10),'نمودار خطوط انتقال '!$A$9:$BG$26,COLUMN()-5,FALSE),"شبکه",VLOOKUP(INDEX($D$5:$D$261,$E10),'نمودار شبکه توزیع آ'!$A$9:$BG$22,COLUMN()-5,FALSE),"سد",VLOOKUP(INDEX($D$5:$D$261,$E10),'نمودار سدسازی'!$A$9:$BG$23,COLUMN()-5,FALSE),"فاضلاب",VLOOKUP(INDEX($D$5:$D$261,$E10),'نمودار جمع‌آوری و ا'!$A$9:$BG$26,COLUMN()-5,FALSE),"تجهیزات",VLOOKUP(INDEX($D$5:$D$261,$E10),'نمودار تجهیزات آب و'!$A$9:$BG$42,COLUMN()-5,FALSE),"پست",VLOOKUP(INDEX($D$5:$D$261,$E10),'نمودار پست های انتق'!$A$9:$BG$41,COLUMN()-5,FALSE),"نیرو",VLOOKUP(INDEX($D$5:$D$261,$E10),'نمودار توزیع نیرو ب'!$A$9:$BG$38,COLUMN()-5,FALSE),""))} -> 244.6 | N10: {=IF($E10="","",_xlfn.SWITCH(LEFT(INDEX($B$5:$B$261,$E10),FIND("|",INDEX($B$5:$B$261,$E10))-1),"ابنیه",VLOOKUP(INDEX($D$5:$D$261,$E10),'نمودار ابنیه'!$A$9:$BG$37,COLUMN()-5,FALSE),"مکانیکی",VLOOKUP(INDEX($D$5:$D$261,$E10),'نمودار مکانیکی'!$A$9:$BG$43,COLUMN()-5,FALSE),"برقی",VLOOKUP(INDEX($D$5:$D$261,$E10),'نمودار تاسیسات برقی'!$A$9:$BG$44,COLUMN()-5,FALSE),"خطوط",VLOOKUP(INDEX($D$5:$D$261,$E10),'نمودار خطوط انتقال '!$A$9:$BG$26,COLUMN()-5,FALSE),"شبکه",VLOOKUP(INDEX($D$5:$D$261,$E10),'نمودار شبکه توزیع آ'!$A$9:$BG$22,COLUMN()-5,FALSE),"سد",VLOOKUP(INDEX($D$5:$D$261,$E10),'نمودار سدسازی'!$A$9:$BG$23,COLUMN()-5,FALSE),"فاضلاب",VLOOKUP(INDEX($D$5:$D$261,$E10),'نمودار جمع‌آوری و ا'!$A$9:$BG$26,COLUMN()-5,FALSE),"تجهیزات",VLOOKUP(INDEX($D$5:$D$261,$E10),'نمودار تجهیزات آب و'!$A$9:$BG$42,COLUMN()-5,FALSE),"پست",VLOOKUP(INDEX($D$5:$D$261,$E10),'نمودار پست های انتق'!$A$9:$BG$41,COLUMN()-5,FALSE),"نیرو",VLOOKUP(INDEX($D$5:$D$261,$E10),'نمودار توزیع نیرو ب'!$A$9:$BG$38,COLUMN()-5,FALSE),""))} -> 270.5 | ... BL10: {=IF($E10="","",_xlfn.SWITCH(LEFT(INDEX($B$5:$B$261,$E10),FIND("|",INDEX($B$5:$B$261,$E10))-1),"ابنیه",VLOOKUP(INDEX($D$5:$D$261,$E10),'نمودار ابنیه'!$A$9:$BG$37,COLUMN()-5,FALSE),"مکانیکی",VLOOKUP(INDEX($D$5:$D$261,$E10),'نمودار مکانیکی'!$A$9:$BG$43,COLUMN()-5,FALSE),"برقی",VLOOKUP(INDEX($D$5:$D$261,$E10),'نمودار تاسیسات برقی'!$A$9:$BG$44,COLUMN()-5,FALSE),"خطوط",VLOOKUP(INDEX($D$5:$D$261,$E10),'نمودار خطوط انتقال '!$A$9:$BG$26,COLUMN()-5,FALSE),"شبکه",VLOOKUP(INDEX($D$5:$D$261,$E10),'نمودار شبکه توزیع آ'!$A$9:$BG$22,COLUMN()-5,FALSE),"سد",VLOOKUP(INDEX($D$5:$D$261,$E10),'نمودار سدسازی'!$A$9:$BG$23,COLUMN()-5,FALSE),"فاضلاب",VLOOKUP(INDEX($D$5:$D$261,$E10),'نمودار جمع‌آوری و ا'!$A$9:$BG$26,COLUMN()-5,FALSE),"تجهیزات",VLOOKUP(INDEX($D$5:$D$261,$E10),'نمودار تجهیزات آب و'!$A$9:$BG$42,COLUMN()-5,FALSE),"پست",VLOOKUP(INDEX($D$5:$D$261,$E10),'نمودار پست های انتق'!$A$9:$BG$41,COLUMN()-5,FALSE),"نیرو",VLOOKUP(INDEX($D$5:$D$261,$E10),'نمودار توزیع نیرو ب'!$A$9:$BG$38,COLUMN()-5,FALSE),""))} -> 3195.5
