Workbook
Name \0: #REF!
Name \A: #REF!
Name \N: #REF!
Name \r: #N/A
Name \Y: #REF!
Name \z: #REF!
Name ___max1: #N/A
Name ___min1: #N/A
Name ___Rev1: #REF!
Name ___Rev2: #REF!
Name ___Rev3: #REF!
Name ___Rev4: #REF!
Name __max1: #N/A
Name __min1: #N/A
Name __NGd1: #REF!
Name __NGd10: #REF!
Name __NGd12: #REF!
Name __NGd13: #REF!
Name __NGd14: #REF!
Name __NGd15: #REF!
Name __NGd2: #REF!
Name __NGd3: #REF!
Name __NGd4: #REF!
Name __NGd5: #REF!
Name __NGd6: #REF!
Name __NGd7: #REF!
Name __NGd8: #REF!
Name __NGd9: #REF!
Name __NPa10: #REF!
Name __NPa2: #REF!
Name __NPa3: #REF!
Name __NPa4: #REF!
Name __NPa5: #REF!
Name __NPa7: #REF!
Name __NPa8: #REF!
Name __NPa9: #REF!
Name __NSp1: #REF!
Name __Rev1: #REF!
Name __Rev2: #REF!
Name __Rev3: #REF!
Name __Rev4: #REF!
Name _1_: #REF!
Name _2_??깛2_Click: [0]!_2_??깛2_Click
Name _2_??깛2_Click: '1-2'!_2_??깛2_Click
Name _3_??깛3_Click: [0]!_3_??깛3_Click
Name _3_??깛3_Click: '1-2'!_3_??깛3_Click
Name _max1: #N/A
Name _min1: #N/A
Name _NGd1: #REF!
Name _NGd10: #REF!
Name _NGd12: #REF!
Name _NGd13: #REF!
Name _NGd14: #REF!
Name _NGd15: #REF!
Name _NGd2: #REF!
Name _NGd3: #REF!
Name _NGd4: #REF!
Name _NGd5: #REF!
Name _NGd6: #REF!
Name _NGd7: #REF!

Sheet 1-2
G1: بخشنامه مابه التفاوت ارز نوبت : | H1: 4
G2: تاریخ مبنای محاسبه مابه التفاوت ارز: | H2: {=_xlfn.LET(_xlpm.x,VALUE(H1),IF(_xlpm.x=3,"اسفند ۱۳۹۸",IF(_xlpm.x=4,"1403/07/01","")))} -> 1403/07/01
B3: c | C3: ردیف قراردادی | G3: شرح ردیف | H3: نام بسته خرید | I3: تاریخ پیشنهاد قیمت در زمان مناقصه | J3: تاریخ مبنای محاسبات طبق بخشنامه | K3: تاریخ ورود به کارگاه/ حواله ارز | L3: ضریب ارزبری طبق استعلام | M3: ضریب ارزبری منظور شده بر اساس درصد ارزبری درخواستی | N3: ضریب F روش الف | O3: قیمت ارز در زمان خرید(Ci) | P3: قیمت ارز پایه بر اساس بخشنامه(C0) | Q3: محاسبات بر مبنای مقدار ارز حواله شده میباشد ؟ | R3: N | S3: درصد کاهش مقدار N بر اساس بخشنامه با توافق کارفرما | T3: تعداد ماه سپری شده(r) | U3: ستون محاسباتی | V3: ستون محاسباتی | W3: مبلغ قراردادی ردیف (ريال) | X3: مبلغ جبرانی بر اساس روش الف M=F[(Ci/Co)-y)]*(P/1.06*K) (ريال) | Y3: تحویل/ حواله ارز در تاخیرات خارج از قصور خریدار یا پیمانکار
N6: - | U6: (N*r)/z | V6: *(1+x)
B7: 1 | C7: 1 | D7: 1 | E7: 2 | F7: 1 | G7: پیش پرداخت | H7: پیش پرداخت | I7: ۱۴۰۲/۰۶/۲۹ | J7: {=_xlfn.LET(_xlpm.x, VALUE($H$1), IF(_xlpm.x=3, "اسفند ۱۳۹۸", IF(_xlpm.x=4, "1403/07/01", "")))} -> 1403/07/01 | K7: 1402/06/30 | L7: 0.8 | M7: 1 | N7: 1.2 | O7: 401204 | P7: {=_xlfn.LET(_xlpm.x, VALUE($H$1), IF(_xlpm.x=3, 405150, IF(_xlpm.x=4, 506978, "")))} -> 506978 | Q7: 1402 | R7: =IFERROR( IF( OR( VALUE(LEFT(J7, 4)) = 1402, VALUE(LEFT(J7, 4)) = 1403 ), 0.05, IFERROR(R2, "") ), "" ) -> 0.05 | S7: 1.5 | T7: - | U7: =IF(AND(OR(Y7="Yes",Y7="بله"),ISNUMBER(T7)),0,IF(ISNUMBER(T7),R7*T7/S7,"")) | V7: =1+U7 -> #VALUE! | W7: 1294891401579 | X7: =N7*((O7/P7)-(V7))*(W7/1.06*M7) -> #VALUE! | Y7: بله
B8: 2 | C8: 1 | D8: 2 | E8: 3 | F8: - | G8: DWDM | H8: صورتحساب 1 | I8: =$I$7 -> ۱۴۰۲/۰۶/۲۹ | J8: {=_xlfn.LET(_xlpm.x, VALUE($H$1), IF(_xlpm.x=3, "اسفند ۱۳۹۸", IF(_xlpm.x=4, "1403/07/01", "")))} -> 1403/07/01 | K8: 1402/08/20 | L8: 0.70666667 | M8: 1 | N8: 1.2 | O8: 401459 | P8: {=_xlfn.LET(_xlpm.x, VALUE($H$1), IF(_xlpm.x=3, 405150, IF(_xlpm.x=4, 506978, "")))} -> 506978 | Q8: 1402 | R8: =IFERROR( IF( OR( VALUE(LEFT(J8, 4)) = 1402, VALUE(LEFT(J8, 4)) = 1403 ), 0.05, IFERROR(R3, "") ), "" ) -> 0.05 | S8: 1.5 | T8: - | U8: =IF(AND(OR(Y8="Yes",Y8="بله"),ISNUMBER(T8)),0,IF(ISNUMBER(T8),R8*T8/S8,"")) | V8: =1+U8 -> #VALUE! | W8: 134592000000 | X8: =N8*((O8/P8)-(V8))*(W8/1.06*M8) -> #VALUE!
B9: 3 | C9: 1 | D9: 3 | E9: 2 | F9: 11 | G9: RINO | H9: صورتحساب-1 1 | I9: =$I$7 -> ۱۴۰۲/۰۶/۲۹ | J9: {=_xlfn.LET(_xlpm.x, VALUE($H$1), IF(_xlpm.x=3, "اسفند ۱۳۹۸", IF(_xlpm.x=4, "1403/07/01", "")))} -> 1403/07/01 | K9: 1402/11/02 | L9: #N/A | M9: 1 | N9: 1.2 | O9: 430169 | P9: {=_xlfn.LET(_xlpm.x, VALUE($H$1), IF(_xlpm.x=3, 405150, IF(_xlpm.x=4, 506978, "")))} -> 506978 | Q9: 1402 | R9: =IFERROR( IF( OR( VALUE(LEFT(J9, 4)) = 1402, VALUE(LEFT(J9, 4)) = 1403), 0.05, IFERROR(R4, "") ), "" ) -> 0.05 | S9: 1.5 | T9: - | U9: =IF(AND(OR(Y9="Yes",Y9="بله"),ISNUMBER(T9)),0,IF(ISNUMBER(T9),R9*T9/S9,"")) | V9: =1+U9 -> #VALUE! | W9: 158145600000 | X9: =N9*((O9/P9)-(V9))*(W9/1.06*M9) -> #VALUE!
B10: 4 | C10: 1 | D10: 3 | E10: 2 | F10: 12 | G10: 02 HPDS&SHARIF | H10: صورتحساب 2 | I10: =$I$7 -> ۱۴۰۲/۰۶/۲۹ | J10: {=_xlfn.LET(_xlpm.x, VALUE($H$1), IF(_xlpm.x=3, "اسفند ۱۳۹۸", IF(_xlpm.x=4, "1403/07/01", "")))} -> 1403/07/01 | K10: 1402/10/30 | L10: #N/A | M10: 1 | N10: 1.2 | O10: 430284 | P10: {=_xlfn.LET(_xlpm.x, VALUE($H$1), IF(_xlpm.x=3, 405150, IF(_xlpm.x=4, 506978, "")))} -> 506978 | Q10: 1402 | R10: =IFERROR( IF( OR( VALUE(LEFT(J10, 4)) = 1402, VALUE(LEFT(J10, 4)) = 1403), 0.05, IFERROR(R5, "") ), "" ) -> 0.05 | S10: 1.5 | T10: - | U10: =IF(AND(OR(Y10="Yes",Y10="بله"),ISNUMBER(T10)),0,IF(ISNUMBER(T10),R10*T10/S10,"")) | V10: =1+U10 -> #VALUE! | W10: 254042400000 | X10: =N10*((O10/P10)-(V10))*(W10/1.06*M10) -> #VALUE!
B11: 5 | C11: 1 | D11: 1 | E11: 5 | F11: 1 | G11: 03 Xfusion1 | H11: صورتحساب 3 | I11: =$I$7 -> ۱۴۰۲/۰۶/۲۹ | J11: {=_xlfn.LET(_xlpm.x, VALUE($H$1), IF(_xlpm.x=3, "اسفند ۱۳۹۸", IF(_xlpm.x=4, "1403/07/01", "")))} -> 1403/07/01 | K11: 1402/12/26 | L11: #N/A | M11: 1 | N11: 1.2 | O11: 440489 | P11: {=_xlfn.LET(_xlpm.x, VALUE($H$1), IF(_xlpm.x=3, 405150, IF(_xlpm.x=4, 506978, "")))} -> 506978 | Q11: 1402 | R11: =IFERROR( IF( OR( VALUE(LEFT(J11, 4)) = 1402, VALUE(LEFT(J11, 4)) = 1403), 0.05, IFERROR(R6, "") ), "" ) -> 0.05 | S11: 1.5 | T11: - | U11: =IF(AND(OR(Y11="Yes",Y11="بله"),ISNUMBER(T11)),0,IF(ISNUMBER(T11),R11*T11/S11,"")) | V11: =1+U11 -> #VALUE! | W11: 1175324640000 | X11: =N11*((O11/P11)-(V11))*(W11/1.06*M11) -> #VALUE!
B12: 6 | C12: 1 | D12: 1 | E12: 5 | F12: 5 | G12: 04 HPDS&FORTINET | H12: صورتحساب 4 | I12: =$I$7 -> ۱۴۰۲/۰۶/۲۹ | J12: {=_xlfn.LET(_xlpm.x, VALUE($H$1), IF(_xlpm.x=3, "اسفند ۱۳۹۸", IF(_xlpm.x=4, "1403/07/01", "")))} -> 1403/07/01 | K12: 1403/04/06 | L12: #N/A | M12: 1 | N12: 1.2 | O12: 459763 | P12: {=_xlfn.LET(_xlpm.x, VALUE($H$1), IF(_xlpm.x=3, 405150, IF(_xlpm.x=4, 506978, "")))} -> 506978 | Q12: 1402 | R12: =IFERROR( IF( OR( VALUE(LEFT(J12, 4)) = 1402, VALUE(LEFT(J12, 4)) = 1403), 0.05, IFERROR(R7, "") ), "" ) -> 0.05 | S12: 1.5 | T12: - | U12: =IF(AND(OR(Y12="Yes",Y12="بله"),ISNUMBER(T12)),0,IF(ISNUMBER(T12),R12*T12/S12,"")) | V12: =1+U12 -> #VALUE! | W12: 545173868800 | X12: =N12*((O12/P12)-(V12))*(W12/1.06*M12) -> #VALUE!
B13: 7 | C13: 1 | D13: 1 | E13: 5 | F13: 19 | G13: 05 Xfusion2 | H13: صورتحساب 5 | I13: =$I$7 -> ۱۴۰۲/۰۶/۲۹ | J13: {=_xlfn.LET(_xlpm.x, VALUE($H$1), IF(_xlpm.x=3, "اسفند ۱۳۹۸", IF(_xlpm.x=4, "1403/07/01", "")))} -> 1403/07/01 | K13: 1403/06/30 | L13: #N/A | M13: 1 | N13: 1.2 | O13: 0 | P13: {=_xlfn.LET(_xlpm.x, VALUE($H$1), IF(_xlpm.x=3, 405150, IF(_xlpm.x=4, 506978, "")))} -> 506978 | Q13: 1402 | R13: =IFERROR( IF( OR( VALUE(LEFT(J13, 4)) = 1402, VALUE(LEFT(J13, 4)) = 1403), 0.05, IFERROR(R8, "") ), "" ) -> 0.05 | S13: 1.5 | T13: - | U13: =IF(AND(OR(Y13="Yes",Y13="بله"),ISNUMBER(T13)),0,IF(ISNUMBER(T13),R13*T13/S13,"")) | V13: =1+U13 -> #VALUE! | W13: 1146989760000 | X13: =N13*((O13/P13)-(V13))*(W13/1.06*M13) -> #VALUE!
B14: 8 | C14: 1 | D14: 1 | E14: 5 | F14: 23 | H14: 20 درصد کسورات تست و تحویل صورتحساب 5 | I14: =$I$7 -> ۱۴۰۲/۰۶/۲۹ | J14: 1403/07/01 | K14: 1403/10/09 | L14: #N/A | M14: 1 | N14: 1.2 | O14: 672704 | P14: {=_xlfn.LET(_xlpm.x, VALUE($H$1), IF(_xlpm.x=3, 405150, IF(_xlpm.x=4, 506978, "")))} -> 506978 | Q14: 1402 | R14: =IFERROR( IF( OR( VALUE(LEFT(J14, 4)) = 1402, VALUE(LEFT(J14, 4)) = 1403), 0.05, IFERROR(R9, "") ), "" ) -> 0.05 | S14: 1.5 | T14: 3.2666667 | U14: =IF(AND(OR(Y14="Yes",Y14="بله"),ISNUMBER(T14)),0,IF(ISNUMBER(T14),R14*T14/S14,"")) -> 0 | V14: =1+U14 -> 1 | W14: 109034773760 | X14: =N14*((O14/P14)-(V14))*(W14/1.06*M14) -> 4.0349852e+10 | Y14: Yes
B15: 33 | C15: 1 | D15: 1 | E15: 5 | F15: 40 | H15: 20 درصد کسورات تست و تحویل صورتحساب 4 | I15: =$I$7 -> ۱۴۰۲/۰۶/۲۹ | J15: {=_xlfn.LET(_xlpm.x, VALUE($H$1), IF(_xlpm.x=3, "اسفند ۱۳۹۸", IF(_xlpm.x=4, "1403/07/01", "")))} -> 1403/07/01 | K15: 1404/02/09 | L15: #N/A | M15: 1 | N15: 1.2 | O15: 787331 | P15: {=_xlfn.LET(_xlpm.x, VALUE($H$1), IF(_xlpm.x=3, 405150, IF(_xlpm.x=4, 506978, "")))} -> 506978 | Q15: 1402 | R15: =IFERROR( IF( OR( VALUE(LEFT(J15, 4)) = 1402, VALUE(LEFT(J15, 4)) = 1403), 0.05, IFERROR(R10, "") ), "" ) -> 0.05 | S15: 1.5 | T15: 7.2666667 | U15: =IF(AND(OR(Y15="Yes",Y15="بله"),ISNUMBER(T15)),0,IF(ISNUMBER(T15),R15*T15/S15,"")) -> 0 | V15: =1+U15 -> 1 | W15: 229397952000 | X15: =N15*((O15/P15)-(V15))*(W15/1.06*M15) -> 1.4360879e+11 | Y15: بله
B16: 34 | C16: 1 | D16: 1 | E16: 7 | F16: 2 | G16: 06 F5 | H16: صورتحساب شماره 6 | I16: =$I$7 -> ۱۴۰۲/۰۶/۲۹ | J16: {=_xlfn.LET(_xlpm.x, VALUE($H$1), IF(_xlpm.x=3, "اسفند ۱۳۹۸", IF(_xlpm.x=4, "1403/07/01", "")))} -> 1403/07/01 | K16: 1403/12/18 | L16: #N/A | M16: 1 | N16: 1.2 | O16: 741620 | P16: {=_xlfn.LET(_xlpm.x, VALUE($H$1), IF(_xlpm.x=3, 405150, IF(_xlpm.x=4, 506978, "")))} -> 506978 | Q16: 1402 | R16: =IFERROR( IF( OR( VALUE(LEFT(J16, 4)) = 1402, VALUE(LEFT(J16, 4)) = 1403), 0.05, IFERROR(R11, "") ), "" ) -> 0.05 | S16: 1.5 | T16: 5.5666667 | U16: =IF(AND(OR(Y16="Yes",Y16="بله"),ISNUMBER(T16)),0,IF(ISNUMBER(T16),R16*T16/S16,"")) -> 0 | V16: =1+U16 -> 1 | W16: 70380400000 | X16: =N16*((O16/P16)-(V16))*(W16/1.06*M16) -> 3.6875995e+10 | Y16: بله
B17: 35 | C17: 1 | D17: 1 | E17: 7 | F17: 15 | G17: 07 Cisco | H17: صورتحساب شماره 7 | I17: =$I$7 -> ۱۴۰۲/۰۶/۲۹ | J17: {=_xlfn.LET(_xlpm.x, VALUE($H$1), IF(_xlpm.x=3, "اسفند ۱۳۹۸", IF(_xlpm.x=4, "1403/07/01", "")))} -> 1403/07/01 | K17: 1403/12/18 | L17: #N/A | M17: 1 | N17: 1.2 | O17: 741620 | P17: {=_xlfn.LET(_xlpm.x, VALUE($H$1), IF(_xlpm.x=3, 405150, IF(_xlpm.x=4, 506978, "")))} -> 506978 | Q17: 1402 | R17: =IFERROR( IF( OR( VALUE(LEFT(J17, 4)) = 1402, VALUE(LEFT(J17, 4)) = 1403), 0.05, IFERROR(R12, "") ), "" ) -> 0.05 | S17: 1.5 | T17: 5.5666667 | U17: =IF(AND(OR(Y17="Yes",Y17="بله"),ISNUMBER(T17)),0,IF(ISNUMBER(T17),R17*T17/S17,"")) -> 0 | V17: =1+U17 -> 1 | W17: 1097411574400 | X17: =N17*((O17/P17)-(V17))*(W17/1.06*M17) -> 5.7499167e+11 | Y17: بله
B18: 36 | C18: 1 | D18: 1 | E18: 8 | F18: 29 | G18: 08 Spare | H18: صورتحساب شماره 8 | I18: ۱۴۰۴/۰۳/۲۹ | J18: {=_xlfn.LET(_xlpm.x, VALUE($H$1), IF(_xlpm.x=3, "اسفند ۱۳۹۸", IF(_xlpm.x=4, "1403/07/01", "")))} -> 1403/07/01 | K18: 1404/02/13 | L18: #N/A | M18: 1 | N18: 1.2 | O18: 782169 | P18: {=_xlfn.LET(_xlpm.x, VALUE($H$1), IF(_xlpm.x=3, 405150, IF(_xlpm.x=4, 506978, "")))} -> 506978 | Q18: 1402 | R18: =IFERROR( IF( OR( VALUE(LEFT(J18, 4)) = 1402, VALUE(LEFT(J18, 4)) = 1403), 0.05, IFERROR(R13, "") ), "" ) -> 0.05 | S18: 1.5 | T18: #REF! | U18: =IF(AND(OR(Y18="Yes",Y18="بله"),ISNUMBER(T18)),0,IF(ISNUMBER(T18),R18*T18/S18,"")) | V18: =1+U18 -> #VALUE! | W18: 1682400000 | X18: =N18*((O18/P18)-(V18))*(W18/1.06*M18) -> #VALUE! | Y18: Yes
B19: جمع | G19: 09 Dell | H19: صورتحساب شماره 9 | I19: ۱۴۰۲/۰۶/۲۹ | J19: {=_xlfn.LET(_xlpm.x, VALUE($H$1), IF(_xlpm.x=3, "اسفند ۱۳۹۸", IF(_xlpm.x=4, "1403/07/01", "")))} -> 1403/07/01 | M19: 1 | N19: 1.2 | O19: 840000 | P19: {=_xlfn.LET(_xlpm.x, VALUE($H$1), IF(_xlpm.x=3, 405150, IF(_xlpm.x=4, 506978, "")))} -> 506978 | Q19: 1402 | R19: 0.05 | S19: 1.5 | T19: 7.4 | U19: =IF(AND(OR(Y19="Yes",Y19="بله"),ISNUMBER(T19)),0,IF(ISNUMBER(T19),R19*T19/S19,"")) -> 0 | V19: =1+U19 -> 1 | W19: 1646395694800 | X19: =N19*((O19/P19)-(V19))*(W19/1.06*M19) -> 1.2243157e+12 | Y19: Yes

Sheet درصد ارزیری
A1: جدول شماره یک | K1: جدول شماره یک | P1: آخرین مهلت پیشنهاد قیمت | Q1: نرخ تسعیر ارز | R1: مبنای شاخص (یک فصل قبل) | AA1: تنظیمات / Settings ⚙️
A2: ردیف | B2: شرح ردیف | C2: نام فهرست بهای پایه 1 | D2: شماره فصل | E2: 1-درصد | F2: شاخص مبنای فصلی فهرست ۱ | G2: نام فهرست بهای پایه 2 | H2: شماره فصل | I2: 2-درصد | J2: شاخص مبنای فصلی فهرست ۲ | K2: نرخ ارز در زمان پرداخت | L2: 422010.14 | M2: درصد ارزبری | N2: شاخص تعدیل ارزی | P2: 1403/07/07 | Q2: {=_xlfn.LET(_xlpm.d,SUBSTITUTE(SUBSTITUTE(SUBSTITUTE(SUBSTITUTE(SUBSTITUTE(SUBSTITUTE(SUBSTITUTE(SUBSTITUTE(SUBSTITUTE(SUBSTITUTE(P2,"۰","0"),"۱","1"),"۲","2"),"۳","3"),"۴","4"),"۵","5"),"۶","6"),"۷","7"),"۸","8"),"۹","9"),_xlpm.rowNum,MATCH(_xlpm.d,'Arz '!A:A,0),_xlpm.validRates,_xlfn._xlws.FILTER(INDEX('Arz '!B:B,_xlfn.SEQUENCE(14,1,_xlpm.rowNum-13)),ISNUMBER(INDEX('Arz '!B:B,_xlfn.SEQUENCE(14,1,_xlpm.rowNum-13)))),_xlpm.last7,IF(ROWS(_xlpm.validRates)>=7,INDEX(_xlpm.validRates,_xlfn.SEQUENCE(7,1,ROWS(_xlpm.validRates)-6)),_xlpm.validRates),IFERROR(AVERAGE(_xlpm.last7),"یافت نشد"))} -> 517551.86 | R2: {=_xlfn.LET(_xlpm.dateTxt,SUBSTITUTE(SUBSTITUTE(SUBSTITUTE(SUBSTITUTE(SUBSTITUTE(SUBSTITUTE(SUBSTITUTE(SUBSTITUTE(SUBSTITUTE(SUBSTITUTE(P2,"۰","0"),"۱","1"),"۲","2"),"۳","3"),"۴","4"),"۵","5"),"۶","6"),"۷","7"),"۸","8"),"۹","9"),_xlpm.yr,LEFT(_xlpm.dateTxt,4),_xlpm.mo,MID(_xlpm.dateTxt,6,2),_xlpm.prevQ,IF(_xlpm.mo<="03",4,IF(_xlpm.mo<="06",1,IF(_xlpm.mo<="09",2,3))),_xlpm.prevYr,IF(_xlpm.mo<="03",_xlpm.yr-1,_xlpm.yr),"سه ماهه "&IF(_xlpm.prevQ=1,"اول",IF(_xlpm.prevQ=2,"دوم",IF(_xlpm.prevQ=3,"سوم","چهارم")))&" "&_xlpm.prevYr)} -> سه ماهه دوم 1403 | AA2: Language / زبان | AB2: Persian | AC2: (Choose: Persian/English)
A3: 1 | B3: پمپ های سانتریفوژ | C3: تاسیسات برقی | D3: 24 | E3: 1 | F3: {=_xlfn.LET(_xlpm.yr,VALUE(RIGHT($R$2,4)),_xlpm.qName,TRIM(SUBSTITUTE(SUBSTITUTE($R$2,RIGHT($R$2,4),""),"سه ماهه","")),_xlpm.chapNum,D3,_xlpm.shName,C3,_xlpm.abnieYr,_xlfn.SCAN(0,ابنیه!$C$2:$AL$2,_xlfn.LAMBDA(_xlpm.a,_xlpm.b,IF(_xlpm.b<>"",_xlpm.b,_xlpm.a))),_xlpm.abnieCol,MATCH(1,(_xlpm.abnieYr=_xlpm.yr)*(ISNUMBER(SEARCH(_xlpm.qName,ابنیه!$C$3:$AL$3))),0),_xlpm.abnie,IF(_xlpm.shName="ابنیه",INDEX(ابنیه!$C$4:$AL$50,MATCH(_xlpm.chapNum,ابنیه!$A$4:$A$50,0),_xlpm.abnieCol),NA()),_xlpm.mechYr,_xlfn.SCAN(0,مکانیک!$C$2:$AL$2,_xlfn.LAMBDA(_xlpm.a,_xlpm.b,IF(_xlpm.b<>"",_xlpm.b,_xlpm.a))),_xlpm.mechCol,MATCH(1,(_xlpm.mechYr=_xlpm.yr)*(ISNUMBER(SEARCH(_xlpm.qName,مکانیک!$C$3:$AL$3))),0),_xlpm.mech,IF(_xlpm.shName="مکانیک",INDEX(مکانیک!$C$4:$AL$50,MATCH(_xlpm.chapNum,مکانیک!$A$4:$A$50,0),_xlpm.mechCol),NA()),_xlpm.elecYr,_xlfn.SCAN(0,'تاسیسات برقی'!$C$2:$AL$2,_xlfn.LAMBDA(_xlpm.a,_xlpm.b,IF(_xlpm.b<>"",_xlpm.b,_xlpm.a))),_xlpm.elecCol,MATCH(1,(_xlpm.elecYr=_xlpm.yr)*(ISNUMBER(SEARCH(_xlpm.qName,'تاسیسات برقی'!$C$3:$AL$3))),0),_xlpm.elec,IF(_xlpm.shName="تاسیسات برقی",INDEX('تاسیسات برقی'!$C$4:$AL$50,MATCH(_xlpm.chapNum,'تاسیسات برقی'!$A$4:$A$50,0),_xlpm.elecCol),NA()),_xlpm.rahYr,_xlfn.SCAN(0,'[1]راه, راه آهن و باند فرودگاه'!$C$2:$AL$2,_xlfn.LAMBDA(_xlpm.a,_xlpm.b,IF(_xlpm.b<>"",_xlpm.b,_xlpm.a))),_xlpm.rahCol,MATCH(1,(_xlpm.rahYr=_xlpm.yr)*(ISNUMBER(SEARCH(_xlpm.qName,'[1]راه, راه آهن و باند فرودگاه'!$C$3:$AL$3))),0),_xlpm.rah,IF(OR(_xlpm.shName="راه",_xlpm.shName="راه، راه آهن و باند فرودگاه"),INDEX('[1]راه, راه آهن و باند فرودگاه'!$C$4:$AL$50,MATCH(_xlpm.chapNum,'[1]راه, راه آهن و باند فرودگاه'!$A$4:$A$50,0),_xlpm.rahCol),NA()),_xlpm.abYr,_xlfn.SCAN(0,'تجهیزات آب و فاضلاب'!$C$2:$AL$2,_xlfn.LAMBDA(_xlpm.a,_xlpm.b,IF(_xlpm.b<>"",_xlpm.b,_xlpm.a))),_xlpm.abCol,MATCH(1,(_xlpm.abYr=_xlpm.yr)*(ISNUMBER(SEARCH(_xlpm.qName,'تجهیزات آب و فاضلاب'!$C$3:$AL$3))),0),_xlpm.ab,IF(OR(_xlpm.shName="تجهیزات آب و فاضلاب",_xlpm.shName="آب و فاضلاب"),INDEX('تجهیزات آب و فاضلاب'!$C$4:$AL$50,MATCH(_xlpm.chapNum,'تجهیزات آب و فاضلاب'!$A$4:$A$50,0),_xlpm.abCol),NA()),IFERROR(_xlpm.abnie,IFERROR(_xlpm.mech,IFERROR(_xlpm.elec,IFERROR(_xlpm.rah,IFERROR(_xlpm.ab,"یافت نشد"))))))} -> 5671.7 | J3: {=IF(G3="","",_xlfn.LET(_xlpm.yr,VALUE(RIGHT($R$2,4)),_xlpm.qName,TRIM(SUBSTITUTE(SUBSTITUTE($R$2,RIGHT($R$2,4),""),"سه ماهه","")),_xlpm.chapNum,H3,_xlpm.shName,G3,_xlpm.abnieYr,_xlfn.SCAN(0,ابنیه!$C$2:$AL$2,_xlfn.LAMBDA(_xlpm.a,_xlpm.b,IF(_xlpm.b<>"",_xlpm.b,_xlpm.a))),_xlpm.abnieCol,MATCH(1,(_xlpm.abnieYr=_xlpm.yr)*(ISNUMBER(SEARCH(_xlpm.qName,ابنیه!$C$3:$AL$3))),0),_xlpm.abnie,IF(_xlpm.shName="ابنیه",INDEX(ابنیه!$C$4:$AL$50,MATCH(_xlpm.chapNum,ابنیه!$A$4:$A$50,0),_xlpm.abnieCol),NA()),_xlpm.mechYr,_xlfn.SCAN(0,مکانیک!$C$2:$AL$2,_xlfn.LAMBDA(_xlpm.a,_xlpm.b,IF(_xlpm.b<>"",_xlpm.b,_xlpm.a))),_xlpm.mechCol,MATCH(1,(_xlpm.mechYr=_xlpm.yr)*(ISNUMBER(SEARCH(_xlpm.qName,مکانیک!$C$3:$AL$3))),0),_xlpm.mech,IF(_xlpm.shName="مکانیک",INDEX(مکانیک!$C$4:$AL$50,MATCH(_xlpm.chapNum,مکانیک!$A$4:$A$50,0),_xlpm.mechCol),NA()),_xlpm.elecYr,_xlfn.SCAN(0,'تاسیسات برقی'!$C$2:$AL$2,_xlfn.LAMBDA(_xlpm.a,_xlpm.b,IF(_xlpm.b<>"",_xlpm.b,_xlpm.a))),_xlpm.elecCol,MATCH(1,(_xlpm.elecYr=_xlpm.yr)*(ISNUMBER(SEARCH(_xlpm.qName,'تاسیسات برقی'!$C$3:$AL$3))),0),_xlpm.elec,IF(_xlpm.shName="تاسیسات برقی",INDEX('تاسیسات برقی'!$C$4:$AL$50,MATCH(_xlpm.chapNum,'تاسیسات برقی'!$A$4:$A$50,0),_xlpm.elecCol),NA()),_xlpm.rahYr,_xlfn.SCAN(0,'[1]راه, راه آهن و باند فرودگاه'!$C$2:$AL$2,_xlfn.LAMBDA(_xlpm.a,_xlpm.b,IF(_xlpm.b<>"",_xlpm.b,_xlpm.a))),_xlpm.rahCol,MATCH(1,(_xlpm.rahYr=_xlpm.yr)*(ISNUMBER(SEARCH(_xlpm.qName,'[1]راه, راه آهن و باند فرودگاه'!$C$3:$AL$3))),0),_xlpm.rah,IF(OR(_xlpm.shName="راه",_xlpm.shName="راه، راه آهن و باند فرودگاه"),INDEX('[1]راه, راه آهن و باند فرودگاه'!$C$4:$AL$50,MATCH(_xlpm.chapNum,'[1]راه, راه آهن و باند فرودگاه'!$A$4:$A$50,0),_xlpm.rahCol),NA()),_xlpm.abYr,_xlfn.SCAN(0,'تجهیزات آب و فاضلاب'!$C$2:$AL$2,_xlfn.LAMBDA(_xlpm.a,_xlpm.b,IF(_xlpm.b<>"",_xlpm.b,_xlpm.a))),_xlpm.abCol,MATCH(1,(_xlpm.abYr=_xlpm.yr)*(ISNUMBER(SEARCH(_xlpm.qName,'تجهیزات آب و فاضلاب'!$C$3:$AL$3))),0),_xlpm.ab,IF(OR(_xlpm.shName="تجهیزات آب و فاضلاب",_xlpm.shName="آب و فاضلاب"),INDEX('تجهیزات آب و فاضلاب'!$C$4:$AL$50,MATCH(_xlpm.chapNum,'تجهیزات آب و فاضلاب'!$A$4:$A$50,0),_xlpm.abCol),NA()),IFERROR(_xlpm.abnie,IFERROR(_xlpm.mech,IFERROR(_xlpm.elec,IFERROR(_xlpm.rah,IFERROR(_xlpm.ab,"یافت نشد")))))))} | K3: ۱۴۰۳/۰۳/۱۰ | L3: {=_xlfn.LET(_xlpm.dateTxt,SUBSTITUTE(SUBSTITUTE(SUBSTITUTE(SUBSTITUTE(SUBSTITUTE(SUBSTITUTE(SUBSTITUTE(SUBSTITUTE(SUBSTITUTE(SUBSTITUTE(K3,"۰","0"),"۱","1"),"۲","2"),"۳","3"),"۴","4"),"۵","5"),"۶","6"),"۷","7"),"۸","8"),"۹","9"),_xlpm.rate,VLOOKUP(_xlpm.dateTxt,'Arz '!A:B,2,FALSE),IFERROR(IF(_xlpm.rate=0,"تعطیل رسمی",IF(_xlpm.rate="","تعطیل رسمی",_xlpm.rate)),"یافت نشد"))} -> 455102 | M3: =1-(E3+I3) -> 0 | N3: =IFERROR(IF(ISNUMBER(L3),(L3/$Q$2)-1,L3),"یافت نشد") -> -0.12066396 | AA3: Direction / جهت | AB3: RTL | AC3: Auto from language
A4: 2 | B4: پمپ های مستغرق | C4: مکانیک | D4: 24 | E4: 0.8 | F4: {=_xlfn.LET(_xlpm.yr,VALUE(RIGHT($R$2,4)),_xlpm.qName,TRIM(SUBSTITUTE(SUBSTITUTE($R$2,RIGHT($R$2,4),""),"سه ماهه","")),_xlpm.chapNum,D4,_xlpm.shName,C4,_xlpm.abnieYr,_xlfn.SCAN(0,ابنیه!$C$2:$AL$2,_xlfn.LAMBDA(_xlpm.a,_xlpm.b,IF(_xlpm.b<>"",_xlpm.b,_xlpm.a))),_xlpm.abnieCol,MATCH(1,(_xlpm.abnieYr=_xlpm.yr)*(ISNUMBER(SEARCH(_xlpm.qName,ابنیه!$C$3:$AL$3))),0),_xlpm.abnie,IF(_xlpm.shName="ابنیه",INDEX(ابنیه!$C$4:$AL$50,MATCH(_xlpm.chapNum,ابنیه!$A$4:$A$50,0),_xlpm.abnieCol),NA()),_xlpm.mechYr,_xlfn.SCAN(0,مکانیک!$C$2:$AL$2,_xlfn.LAMBDA(_xlpm.a,_xlpm.b,IF(_xlpm.b<>"",_xlpm.b,_xlpm.a))),_xlpm.mechCol,MATCH(1,(_xlpm.mechYr=_xlpm.yr)*(ISNUMBER(SEARCH(_xlpm.qName,مکانیک!$C$3:$AL$3))),0),_xlpm.mech,IF(_xlpm.shName="مکانیک",INDEX(مکانیک!$C$4:$AL$50,MATCH(_xlpm.chapNum,مکانیک!$A$4:$A$50,0),_xlpm.mechCol),NA()),_xlpm.elecYr,_xlfn.SCAN(0,'تاسیسات برقی'!$C$2:$AL$2,_xlfn.LAMBDA(_xlpm.a,_xlpm.b,IF(_xlpm.b<>"",_xlpm.b,_xlpm.a))),_xlpm.elecCol,MATCH(1,(_xlpm.elecYr=_xlpm.yr)*(ISNUMBER(SEARCH(_xlpm.qName,'تاسیسات برقی'!$C$3:$AL$3))),0),_xlpm.elec,IF(_xlpm.shName="تاسیسات برقی",INDEX('تاسیسات برقی'!$C$4:$AL$50,MATCH(_xlpm.chapNum,'تاسیسات برقی'!$A$4:$A$50,0),_xlpm.elecCol),NA()),_xlpm.rahYr,_xlfn.SCAN(0,'[1]راه, راه آهن و باند فرودگاه'!$C$2:$AL$2,_xlfn.LAMBDA(_xlpm.a,_xlpm.b,IF(_xlpm.b<>"",_xlpm.b,_xlpm.a))),_xlpm.rahCol,MATCH(1,(_xlpm.rahYr=_xlpm.yr)*(ISNUMBER(SEARCH(_xlpm.qName,'[1]راه, راه آهن و باند فرودگاه'!$C$3:$AL$3))),0),_xlpm.rah,IF(OR(_xlpm.shName="راه",_xlpm.shName="راه، راه آهن و باند فرودگاه"),INDEX('[1]راه, راه آهن و باند فرودگاه'!$C$4:$AL$50,MATCH(_xlpm.chapNum,'[1]راه, راه آهن و باند فرودگاه'!$A$4:$A$50,0),_xlpm.rahCol),NA()),_xlpm.abYr,_xlfn.SCAN(0,'تجهیزات آب و فاضلاب'!$C$2:$AL$2,_xlfn.LAMBDA(_xlpm.a,_xlpm.b,IF(_xlpm.b<>"",_xlpm.b,_xlpm.a))),_xlpm.abCol,MATCH(1,(_xlpm.abYr=_xlpm.yr)*(ISNUMBER(SEARCH(_xlpm.qName,'تجهیزات آب و فاضلاب'!$C$3:$AL$3))),0),_xlpm.ab,IF(OR(_xlpm.shName="تجهیزات آب و فاضلاب",_xlpm.shName="آب و فاضلاب"),INDEX('تجهیزات آب و فاضلاب'!$C$4:$AL$50,MATCH(_xlpm.chapNum,'تجهیزات آب و فاضلاب'!$A$4:$A$50,0),_xlpm.abCol),NA()),IFERROR(_xlpm.abnie,IFERROR(_xlpm.mech,IFERROR(_xlpm.elec,IFERROR(_xlpm.rah,IFERROR(_xlpm.ab,"یافت نشد"))))))} -> 6186.2 | J4: {=IF(G4="","",_xlfn.LET(_xlpm.yr,VALUE(RIGHT($R$2,4)),_xlpm.qName,TRIM(SUBSTITUTE(SUBSTITUTE($R$2,RIGHT($R$2,4),""),"سه ماهه","")),_xlpm.chapNum,H4,_xlpm.shName,G4,_xlpm.abnieYr,_xlfn.SCAN(0,ابنیه!$C$2:$AL$2,_xlfn.LAMBDA(_xlpm.a,_xlpm.b,IF(_xlpm.b<>"",_xlpm.b,_xlpm.a))),_xlpm.abnieCol,MATCH(1,(_xlpm.abnieYr=_xlpm.yr)*(ISNUMBER(SEARCH(_xlpm.qName,ابنیه!$C$3:$AL$3))),0),_xlpm.abnie,IF(_xlpm.shName="ابنیه",INDEX(ابنیه!$C$4:$AL$50,MATCH(_xlpm.chapNum,ابنیه!$A$4:$A$50,0),_xlpm.abnieCol),NA()),_xlpm.mechYr,_xlfn.SCAN(0,مکانیک!$C$2:$AL$2,_xlfn.LAMBDA(_xlpm.a,_xlpm.b,IF(_xlpm.b<>"",_xlpm.b,_xlpm.a))),_xlpm.mechCol,MATCH(1,(_xlpm.mechYr=_xlpm.yr)*(ISNUMBER(SEARCH(_xlpm.qName,مکانیک!$C$3:$AL$3))),0),_xlpm.mech,IF(_xlpm.shName="مکانیک",INDEX(مکانیک!$C$4:$AL$50,MATCH(_xlpm.chapNum,مکانیک!$A$4:$A$50,0),_xlpm.mechCol),NA()),_xlpm.elecYr,_xlfn.SCAN(0,'تاسیسات برقی'!$C$2:$AL$2,_xlfn.LAMBDA(_xlpm.a,_xlpm.b,IF(_xlpm.b<>"",_xlpm.b,_xlpm.a))),_xlpm.elecCol,MATCH(1,(_xlpm.elecYr=_xlpm.yr)*(ISNUMBER(SEARCH(_xlpm.qName,'تاسیسات برقی'!$C$3:$AL$3))),0),_xlpm.elec,IF(_xlpm.shName="تاسیسات برقی",INDEX('تاسیسات برقی'!$C$4:$AL$50,MATCH(_xlpm.chapNum,'تاسیسات برقی'!$A$4:$A$50,0),_xlpm.elecCol),NA()),_xlpm.rahYr,_xlfn.SCAN(0,'[1]راه, راه آهن و باند فرودگاه'!$C$2:$AL$2,_xlfn.LAMBDA(_xlpm.a,_xlpm.b,IF(_xlpm.b<>"",_xlpm.b,_xlpm.a))),_xlpm.rahCol,MATCH(1,(_xlpm.rahYr=_xlpm.yr)*(ISNUMBER(SEARCH(_xlpm.qName,'[1]راه, راه آهن و باند فرودگاه'!$C$3:$AL$3))),0),_xlpm.rah,IF(OR(_xlpm.shName="راه",_xlpm.shName="راه، راه آهن و باند فرودگاه"),INDEX('[1]راه, راه آهن و باند فرودگاه'!$C$4:$AL$50,MATCH(_xlpm.chapNum,'[1]راه, راه آهن و باند فرودگاه'!$A$4:$A$50,0),_xlpm.rahCol),NA()),_xlpm.abYr,_xlfn.SCAN(0,'تجهیزات آب و فاضلاب'!$C$2:$AL$2,_xlfn.LAMBDA(_xlpm.a,_xlpm.b,IF(_xlpm.b<>"",_xlpm.b,_xlpm.a))),_xlpm.abCol,MATCH(1,(_xlpm.abYr=_xlpm.yr)*(ISNUMBER(SEARCH(_xlpm.qName,'تجهیزات آب و فاضلاب'!$C$3:$AL$3))),0),_xlpm.ab,IF(OR(_xlpm.shName="تجهیزات آب و فاضلاب",_xlpm.shName="آب و فاضلاب"),INDEX('تجهیزات آب و فاضلاب'!$C$4:$AL$50,MATCH(_xlpm.chapNum,'تجهیزات آب و فاضلاب'!$A$4:$A$50,0),_xlpm.abCol),NA()),IFERROR(_xlpm.abnie,IFERROR(_xlpm.mech,IFERROR(_xlpm.elec,IFERROR(_xlpm.rah,IFERROR(_xlpm.ab,"یافت نشد")))))))} | K4: ۱۴۰۲/۱۰/۱۹ | L4: {=_xlfn.LET(_xlpm.dateTxt,SUBSTITUTE(SUBSTITUTE(SUBSTITUTE(SUBSTITUTE(SUBSTITUTE(SUBSTITUTE(SUBSTITUTE(SUBSTITUTE(SUBSTITUTE(SUBSTITUTE(K4,"۰","0"),"۱","1"),"۲","2"),"۳","3"),"۴","4"),"۵","5"),"۶","6"),"۷","7"),"۸","8"),"۹","9"),_xlpm.rate,VLOOKUP(_xlpm.dateTxt,'Arz '!A:B,2,FALSE),IFERROR(IF(_xlpm.rate=0,"تعطیل رسمی",IF(_xlpm.rate="","تعطیل رسمی",_xlpm.rate)),"یافت نشد"))} -> 433832 | M4: =1-(E4+I4) -> 0.2 | N4: =IFERROR(IF(ISNUMBER(L4),(L4/$Q$2)-1,L4),"یافت نشد") -> -0.16176129 | AA4: Digits / ارقام | AB4: Persian | AC4: (Auto from language)
A5: 3 | B5: پمپ های ارشمیدس (اسکروپمپ) | C5: مکانیک | D5: 24 | E5: 0.2 | F5: {=_xlfn.LET(_xlpm.yr,VALUE(RIGHT($R$2,4)),_xlpm.qName,TRIM(SUBSTITUTE(SUBSTITUTE($R$2,RIGHT($R$2,4),""),"سه ماهه","")),_xlpm.chapNum,D5,_xlpm.shName,C5,_xlpm.abnieYr,_xlfn.SCAN(0,ابنیه!$C$2:$AL$2,_xlfn.LAMBDA(_xlpm.a,_xlpm.b,IF(_xlpm.b<>"",_xlpm.b,_xlpm.a))),_xlpm.abnieCol,MATCH(1,(_xlpm.abnieYr=_xlpm.yr)*(ISNUMBER(SEARCH(_xlpm.qName,ابنیه!$C$3:$AL$3))),0),_xlpm.abnie,IF(_xlpm.shName="ابنیه",INDEX(ابنیه!$C$4:$AL$50,MATCH(_xlpm.chapNum,ابنیه!$A$4:$A$50,0),_xlpm.abnieCol),NA()),_xlpm.mechYr,_xlfn.SCAN(0,مکانیک!$C$2:$AL$2,_xlfn.LAMBDA(_xlpm.a,_xlpm.b,IF(_xlpm.b<>"",_xlpm.b,_xlpm.a))),_xlpm.mechCol,MATCH(1,(_xlpm.mechYr=_xlpm.yr)*(ISNUMBER(SEARCH(_xlpm.qName,مکانیک!$C$3:$AL$3))),0),_xlpm.mech,IF(_xlpm.shName="مکانیک",INDEX(مکانیک!$C$4:$AL$50,MATCH(_xlpm.chapNum,مکانیک!$A$4:$A$50,0),_xlpm.mechCol),NA()),_xlpm.elecYr,_xlfn.SCAN(0,'تاسیسات برقی'!$C$2:$AL$2,_xlfn.LAMBDA(_xlpm.a,_xlpm.b,IF(_xlpm.b<>"",_xlpm.b,_xlpm.a))),_xlpm.elecCol,MATCH(1,(_xlpm.elecYr=_xlpm.yr)*(ISNUMBER(SEARCH(_xlpm.qName,'تاسیسات برقی'!$C$3:$AL$3))),0),_xlpm.elec,IF(_xlpm.shName="تاسیسات برقی",INDEX('تاسیسات برقی'!$C$4:$AL$50,MATCH(_xlpm.chapNum,'تاسیسات برقی'!$A$4:$A$50,0),_xlpm.elecCol),NA()),_xlpm.rahYr,_xlfn.SCAN(0,'[1]راه, راه آهن و باند فرودگاه'!$C$2:$AL$2,_xlfn.LAMBDA(_xlpm.a,_xlpm.b,IF(_xlpm.b<>"",_xlpm.b,_xlpm.a))),_xlpm.rahCol,MATCH(1,(_xlpm.rahYr=_xlpm.yr)*(ISNUMBER(SEARCH(_xlpm.qName,'[1]راه, راه آهن و باند فرودگاه'!$C$3:$AL$3))),0),_xlpm.rah,IF(OR(_xlpm.shName="راه",_xlpm.shName="راه، راه آهن و باند فرودگاه"),INDEX('[1]راه, راه آهن و باند فرودگاه'!$C$4:$AL$50,MATCH(_xlpm.chapNum,'[1]راه, راه آهن و باند فرودگاه'!$A$4:$A$50,0),_xlpm.rahCol),NA()),_xlpm.abYr,_xlfn.SCAN(0,'تجهیزات آب و فاضلاب'!$C$2:$AL$2,_xlfn.LAMBDA(_xlpm.a,_xlpm.b,IF(_xlpm.b<>"",_xlpm.b,_xlpm.a))),_xlpm.abCol,MATCH(1,(_xlpm.abYr=_xlpm.yr)*(ISNUMBER(SEARCH(_xlpm.qName,'تجهیزات آب و فاضلاب'!$C$3:$AL$3))),0),_xlpm.ab,IF(OR(_xlpm.shName="تجهیزات آب و فاضلاب",_xlpm.shName="آب و فاضلاب"),INDEX('تجهیزات آب و فاضلاب'!$C$4:$AL$50,MATCH(_xlpm.chapNum,'تجهیزات آب و فاضلاب'!$A$4:$A$50,0),_xlpm.abCol),NA()),IFERROR(_xlpm.abnie,IFERROR(_xlpm.mech,IFERROR(_xlpm.elec,IFERROR(_xlpm.rah,IFERROR(_xlpm.ab,"یافت نشد"))))))} -> 6186.2 | G5: ابنیه | H5: 16 | I5: 0.6 | J5: {=IF(G5="","",_xlfn.LET(_xlpm.yr,VALUE(RIGHT($R$2,4)),_xlpm.qName,TRIM(SUBSTITUTE(SUBSTITUTE($R$2,RIGHT($R$2,4),""),"سه ماهه","")),_xlpm.chapNum,H5,_xlpm.shName,G5,_xlpm.abnieYr,_xlfn.SCAN(0,ابنیه!$C$2:$AL$2,_xlfn.LAMBDA(_xlpm.a,_xlpm.b,IF(_xlpm.b<>"",_xlpm.b,_xlpm.a))),_xlpm.abnieCol,MATCH(1,(_xlpm.abnieYr=_xlpm.yr)*(ISNUMBER(SEARCH(_xlpm.qName,ابنیه!$C$3:$AL$3))),0),_xlpm.abnie,IF(_xlpm.shName="ابنیه",INDEX(ابنیه!$C$4:$AL$50,MATCH(_xlpm.chapNum,ابنیه!$A$4:$A$50,0),_xlpm.abnieCol),NA()),_xlpm.mechYr,_xlfn.SCAN(0,مکانیک!$C$2:$AL$2,_xlfn.LAMBDA(_xlpm.a,_xlpm.b,IF(_xlpm.b<>"",_xlpm.b,_xlpm.a))),_xlpm.mechCol,MATCH(1,(_xlpm.mechYr=_xlpm.yr)*(ISNUMBER(SEARCH(_xlpm.qName,مکانیک!$C$3:$AL$3))),0),_xlpm.mech,IF(_xlpm.shName="مکانیک",INDEX(مکانیک!$C$4:$AL$50,MATCH(_xlpm.chapNum,مکانیک!$A$4:$A$50,0),_xlpm.mechCol),NA()),_xlpm.elecYr,_xlfn.SCAN(0,'تاسیسات برقی'!$C$2:$AL$2,_xlfn.LAMBDA(_xlpm.a,_xlpm.b,IF(_xlpm.b<>"",_xlpm.b,_xlpm.a))),_xlpm.elecCol,MATCH(1,(_xlpm.elecYr=_xlpm.yr)*(ISNUMBER(SEARCH(_xlpm.qName,'تاسیسات برقی'!$C$3:$AL$3))),0),_xlpm.elec,IF(_xlpm.shName="تاسیسات برقی",INDEX('تاسیسات برقی'!$C$4:$AL$50,MATCH(_xlpm.chapNum,'تاسیسات برقی'!$A$4:$A$50,0),_xlpm.elecCol),NA()),_xlpm.rahYr,_xlfn.SCAN(0,'[1]راه, راه آهن و باند فرودگاه'!$C$2:$AL$2,_xlfn.LAMBDA(_xlpm.a,_xlpm.b,IF(_xlpm.b<>"",_xlpm.b,_xlpm.a))),_xlpm.rahCol,MATCH(1,(_xlpm.rahYr=_xlpm.yr)*(ISNUMBER(SEARCH(_xlpm.qName,'[1]راه, راه آهن و باند فرودگاه'!$C$3:$AL$3))),0),_xlpm.rah,IF(OR(_xlpm.shName="راه",_xlpm.shName="راه، راه آهن و باند فرودگاه"),INDEX('[1]راه, راه آهن و باند فرودگاه'!$C$4:$AL$50,MATCH(_xlpm.chapNum,'[1]راه, راه آهن و باند فرودگاه'!$A$4:$A$50,0),_xlpm.rahCol),NA()),_xlpm.abYr,_xlfn.SCAN(0,'تجهیزات آب و فاضلاب'!$C$2:$AL$2,_xlfn.LAMBDA(_xlpm.a,_xlpm.b,IF(_xlpm.b<>"",_xlpm.b,_xlpm.a))),_xlpm.abCol,MATCH(1,(_xlpm.abYr=_xlpm.yr)*(ISNUMBER(SEARCH(_xlpm.qName,'تجهیزات آب و فاضلاب'!$C$3:$AL$3))),0),_xlpm.ab,IF(OR(_xlpm.shName="تجهیزات آب و فاضلاب",_xlpm.shName="آب و فاضلاب"),INDEX('تجهیزات آب و فاضلاب'!$C$4:$AL$50,MATCH(_xlpm.chapNum,'تجهیزات آب و فاضلاب'!$A$4:$A$50,0),_xlpm.abCol),NA()),IFERROR(_xlpm.abnie,IFERROR(_xlpm.mech,IFERROR(_xlpm.elec,IFERROR(_xlpm.rah,IFERROR(_xlpm.ab,"یافت نشد")))))))} -> 7848.6 | K5: 1402/03/15 | L5: {=_xlfn.LET(_xlpm.dateTxt,SUBSTITUTE(SUBSTITUTE(SUBSTITUTE(SUBSTITUTE(SUBSTITUTE(SUBSTITUTE(SUBSTITUTE(SUBSTITUTE(SUBSTITUTE(SUBSTITUTE(K5,"۰","0"),"۱","1"),"۲","2"),"۳","3"),"۴","4"),"۵","5"),"۶","6"),"۷","7"),"۸","8"),"۹","9"),_xlpm.rate,VLOOKUP(_xlpm.dateTxt,'Arz '!A:B,2,FALSE),IFERROR(IF(_xlpm.rate=0,"تعطیل رسمی",IF(_xlpm.rate="","تعطیل رسمی",_xlpm.rate)),"یافت نشد"))} -> تعطیل رسمی | M5: =1-(E5+I5) -> 0.2 | N5: =IFERROR(IF(ISNUMBER(L5),(L5/$Q$2)-1,L5),"یافت نشد") -> تعطیل رسمی
A6: 4 | B6: دریچه دستی فولادی با پوشش | C6: ابنیه | D6: 16 | E6: 0.75 | F6: {=_xlfn.LET(_xlpm.yr,VALUE(RIGHT($R$2,4)),_xlpm.qName,TRIM(SUBSTITUTE(SUBSTITUTE($R$2,RIGHT($R$2,4),""),"سه ماهه","")),_xlpm.chapNum,D6,_xlpm.shName,C6,_xlpm.abnieYr,_xlfn.SCAN(0,ابنیه!$C$2:$AL$2,_xlfn.LAMBDA(_xlpm.a,_xlpm.b,IF(_xlpm.b<>"",_xlpm.b,_xlpm.a))),_xlpm.abnieCol,MATCH(1,(_xlpm.abnieYr=_xlpm.yr)*(ISNUMBER(SEARCH(_xlpm.qName,ابنیه!$C$3:$AL$3))),0),_xlpm.abnie,IF(_xlpm.shName="ابنیه",INDEX(ابنیه!$C$4:$AL$50,MATCH(_xlpm.chapNum,ابنیه!$A$4:$A$50,0),_xlpm.abnieCol),NA()),_xlpm.mechYr,_xlfn.SCAN(0,مکانیک!$C$2:$AL$2,_xlfn.LAMBDA(_xlpm.a,_xlpm.b,IF(_xlpm.b<>"",_xlpm.b,_xlpm.a))),_xlpm.mechCol,MATCH(1,(_xlpm.mechYr=_xlpm.yr)*(ISNUMBER(SEARCH(_xlpm.qName,مکانیک!$C$3:$AL$3))),0),_xlpm.mech,IF(_xlpm.shName="مکانیک",INDEX(مکانیک!$C$4:$AL$50,MATCH(_xlpm.chapNum,مکانیک!$A$4:$A$50,0),_xlpm.mechCol),NA()),_xlpm.elecYr,_xlfn.SCAN(0,'تاسیسات برقی'!$C$2:$AL$2,_xlfn.LAMBDA(_xlpm.a,_xlpm.b,IF(_xlpm.b<>"",_xlpm.b,_xlpm.a))),_xlpm.elecCol,MATCH(1,(_xlpm.elecYr=_xlpm.yr)*(ISNUMBER(SEARCH(_xlpm.qName,'تاسیسات برقی'!$C$3:$AL$3))),0),_xlpm.elec,IF(_xlpm.shName="تاسیسات برقی",INDEX('تاسیسات برقی'!$C$4:$AL$50,MATCH(_xlpm.chapNum,'تاسیسات برقی'!$A$4:$A$50,0),_xlpm.elecCol),NA()),_xlpm.rahYr,_xlfn.SCAN(0,'[1]راه, راه آهن و باند فرودگاه'!$C$2:$AL$2,_xlfn.LAMBDA(_xlpm.a,_xlpm.b,IF(_xlpm.b<>"",_xlpm.b,_xlpm.a))),_xlpm.rahCol,MATCH(1,(_xlpm.rahYr=_xlpm.yr)*(ISNUMBER(SEARCH(_xlpm.qName,'[1]راه, راه آهن و باند فرودگاه'!$C$3:$AL$3))),0),_xlpm.rah,IF(OR(_xlpm.shName="راه",_xlpm.shName="راه، راه آهن و باند فرودگاه"),INDEX('[1]راه, راه آهن و باند فرودگاه'!$C$4:$AL$50,MATCH(_xlpm.chapNum,'[1]راه, راه آهن و باند فرودگاه'!$A$4:$A$50,0),_xlpm.rahCol),NA()),_xlpm.abYr,_xlfn.SCAN(0,'تجهیزات آب و فاضلاب'!$C$2:$AL$2,_xlfn.LAMBDA(_xlpm.a,_xlpm.b,IF(_xlpm.b<>"",_xlpm.b,_xlpm.a))),_xlpm.abCol,MATCH(1,(_xlpm.abYr=_xlpm.yr)*(ISNUMBER(SEARCH(_xlpm.qName,'تجهیزات آب و فاضلاب'!$C$3:$AL$3))),0),_xlpm.ab,IF(OR(_xlpm.shName="تجهیزات آب و فاضلاب",_xlpm.shName="آب و فاضلاب"),INDEX('تجهیزات آب و فاضلاب'!$C$4:$AL$50,MATCH(_xlpm.chapNum,'تجهیزات آب و فاضلاب'!$A$4:$A$50,0),_xlpm.abCol),NA()),IFERROR(_xlpm.abnie,IFERROR(_xlpm.mech,IFERROR(_xlpm.elec,IFERROR(_xlpm.rah,IFERROR(_xlpm.ab,"یافت نشد"))))))} -> 7848.6 | G6: مکانیک | H6: 7 | I6: 0.25 | J6: {=IF(G6="","",_xlfn.LET(_xlpm.yr,VALUE(RIGHT($R$2,4)),_xlpm.qName,TRIM(SUBSTITUTE(SUBSTITUTE($R$2,RIGHT($R$2,4),""),"سه ماهه","")),_xlpm.chapNum,H6,_xlpm.shName,G6,_xlpm.abnieYr,_xlfn.SCAN(0,ابنیه!$C$2:$AL$2,_xlfn.LAMBDA(_xlpm.a,_xlpm.b,IF(_xlpm.b<>"",_xlpm.b,_xlpm.a))),_xlpm.abnieCol,MATCH(1,(_xlpm.abnieYr=_xlpm.yr)*(ISNUMBER(SEARCH(_xlpm.qName,ابنیه!$C$3:$AL$3))),0),_xlpm.abnie,IF(_xlpm.shName="ابنیه",INDEX(ابنیه!$C$4:$AL$50,MATCH(_xlpm.chapNum,ابنیه!$A$4:$A$50,0),_xlpm.abnieCol),NA()),_xlpm.mechYr,_xlfn.SCAN(0,مکانیک!$C$2:$AL$2,_xlfn.LAMBDA(_xlpm.a,_xlpm.b,IF(_xlpm.b<>"",_xlpm.b,_xlpm.a))),_xlpm.mechCol,MATCH(1,(_xlpm.mechYr=_xlpm.yr)*(ISNUMBER(SEARCH(_xlpm.qName,مکانیک!$C$3:$AL$3))),0),_xlpm.mech,IF(_xlpm.shName="مکانیک",INDEX(مکانیک!$C$4:$AL$50,MATCH(_xlpm.chapNum,مکانیک!$A$4:$A$50,0),_xlpm.mechCol),NA()),_xlpm.elecYr,_xlfn.SCAN(0,'تاسیسات برقی'!$C$2:$AL$2,_xlfn.LAMBDA(_xlpm.a,_xlpm.b,IF(_xlpm.b<>"",_xlpm.b,_xlpm.a))),_xlpm.elecCol,MATCH(1,(_xlpm.elecYr=_xlpm.yr)*(ISNUMBER(SEARCH(_xlpm.qName,'تاسیسات برقی'!$C$3:$AL$3))),0),_xlpm.elec,IF(_xlpm.shName="تاسیسات برقی",INDEX('تاسیسات برقی'!$C$4:$AL$50,MATCH(_xlpm.chapNum,'تاسیسات برقی'!$A$4:$A$50,0),_xlpm.elecCol),NA()),_xlpm.rahYr,_xlfn.SCAN(0,'[1]راه, راه آهن و باند فرودگاه'!$C$2:$AL$2,_xlfn.LAMBDA(_xlpm.a,_xlpm.b,IF(_xlpm.b<>"",_xlpm.b,_xlpm.a))),_xlpm.rahCol,MATCH(1,(_xlpm.rahYr=_xlpm.yr)*(ISNUMBER(SEARCH(_xlpm.qName,'[1]راه, راه آهن و باند فرودگاه'!$C$3:$AL$3))),0),_xlpm.rah,IF(OR(_xlpm.shName="راه",_xlpm.shName="راه، راه آهن و باند فرودگاه"),INDEX('[1]راه, راه آهن و باند فرودگاه'!$C$4:$AL$50,MATCH(_xlpm.chapNum,'[1]راه, راه آهن و باند فرودگاه'!$A$4:$A$50,0),_xlpm.rahCol),NA()),_xlpm.abYr,_xlfn.SCAN(0,'تجهیزات آب و فاضلاب'!$C$2:$AL$2,_xlfn.LAMBDA(_xlpm.a,_xlpm.b,IF(_xlpm.b<>"",_xlpm.b,_xlpm.a))),_xlpm.abCol,MATCH(1,(_xlpm.abYr=_xlpm.yr)*(ISNUMBER(SEARCH(_xlpm.qName,'تجهیزات آب و فاضلاب'!$C$3:$AL$3))),0),_xlpm.ab,IF(OR(_xlpm.shName="تجهیزات آب و فاضلاب",_xlpm.shName="آب و فاضلاب"),INDEX('تجهیزات آب و فاضلاب'!$C$4:$AL$50,MATCH(_xlpm.chapNum,'تجهیزات آب و فاضلاب'!$A$4:$A$50,0),_xlpm.abCol),NA()),IFERROR(_xlpm.abnie,IFERROR(_xlpm.mech,IFERROR(_xlpm.elec,IFERROR(_xlpm.rah,IFERROR(_xlpm.ab,"یافت نشد")))))))} -> 9705.5 | K6: ۱۴۰۳/۰۷/۰۱ | L6: {=_xlfn.LET(_xlpm.dateTxt,SUBSTITUTE(SUBSTITUTE(SUBSTITUTE(SUBSTITUTE(SUBSTITUTE(SUBSTITUTE(SUBSTITUTE(SUBSTITUTE(SUBSTITUTE(SUBSTITUTE(K6,"۰","0"),"۱","1"),"۲","2"),"۳","3"),"۴","4"),"۵","5"),"۶","6"),"۷","7"),"۸","8"),"۹","9"),_xlpm.rate,VLOOKUP(_xlpm.dateTxt,'Arz '!A:B,2,FALSE),IFERROR(IF(_xlpm.rate=0,"تعطیل رسمی",IF(_xlpm.rate="","تعطیل رسمی",_xlpm.rate)),"یافت نشد"))} -> 516581 | M6: =1-(E6+I6) -> 0 | N6: =IFERROR(IF(ISNUMBER(L6),(L6/$Q$2)-1,L6),"یافت نشد") -> -0.0018758645
A7: 5 | B7: دریچه فولادی با پوشش مجهز به محرک برقی و یا بادی | C7: ابنیه | D7: 16 | E7: 0.3 | F7: {=_xlfn.LET(_xlpm.yr,VALUE(RIGHT($R$2,4)),_xlpm.qName,TRIM(SUBSTITUTE(SUBSTITUTE($R$2,RIGHT($R$2,4),""),"سه ماهه","")),_xlpm.chapNum,D7,_xlpm.shName,C7,_xlpm.abnieYr,_xlfn.SCAN(0,ابنیه!$C$2:$AL$2,_xlfn.LAMBDA(_xlpm.a,_xlpm.b,IF(_xlpm.b<>"",_xlpm.b,_xlpm.a))),_xlpm.abnieCol,MATCH(1,(_xlpm.abnieYr=_xlpm.yr)*(ISNUMBER(SEARCH(_xlpm.qName,ابنیه!$C$3:$AL$3))),0),_xlpm.abnie,IF(_xlpm.shName="ابنیه",INDEX(ابنیه!$C$4:$AL$50,MATCH(_xlpm.chapNum,ابنیه!$A$4:$A$50,0),_xlpm.abnieCol),NA()),_xlpm.mechYr,_xlfn.SCAN(0,مکانیک!$C$2:$AL$2,_xlfn.LAMBDA(_xlpm.a,_xlpm.b,IF(_xlpm.b<>"",_xlpm.b,_xlpm.a))),_xlpm.mechCol,MATCH(1,(_xlpm.mechYr=_xlpm.yr)*(ISNUMBER(SEARCH(_xlpm.qName,مکانیک!$C$3:$AL$3))),0),_xlpm.mech,IF(_xlpm.shName="مکانیک",INDEX(مکانیک!$C$4:$AL$50,MATCH(_xlpm.chapNum,مکانیک!$A$4:$A$50,0),_xlpm.mechCol),NA()),_xlpm.elecYr,_xlfn.SCAN(0,'تاسیسات برقی'!$C$2:$AL$2,_xlfn.LAMBDA(_xlpm.a,_xlpm.b,IF(_xlpm.b<>"",_xlpm.b,_xlpm.a))),_xlpm.elecCol,MATCH(1,(_xlpm.elecYr=_xlpm.yr)*(ISNUMBER(SEARCH(_xlpm.qName,'تاسیسات برقی'!$C$3:$AL$3))),0),_xlpm.elec,IF(_xlpm.shName="تاسیسات برقی",INDEX('تاسیسات برقی'!$C$4:$AL$50,MATCH(_xlpm.chapNum,'تاسیسات برقی'!$A$4:$A$50,0),_xlpm.elecCol),NA()),_xlpm.rahYr,_xlfn.SCAN(0,'[1]راه, راه آهن و باند فرودگاه'!$C$2:$AL$2,_xlfn.LAMBDA(_xlpm.a,_xlpm.b,IF(_xlpm.b<>"",_xlpm.b,_xlpm.a))),_xlpm.rahCol,MATCH(1,(_xlpm.rahYr=_xlpm.yr)*(ISNUMBER(SEARCH(_xlpm.qName,'[1]راه, راه آهن و باند فرودگاه'!$C$3:$AL$3))),0),_xlpm.rah,IF(OR(_xlpm.shName="راه",_xlpm.shName="راه، راه آهن و باند فرودگاه"),INDEX('[1]راه, راه آهن و باند فرودگاه'!$C$4:$AL$50,MATCH(_xlpm.chapNum,'[1]راه, راه آهن و باند فرودگاه'!$A$4:$A$50,0),_xlpm.rahCol),NA()),_xlpm.abYr,_xlfn.SCAN(0,'تجهیزات آب و فاضلاب'!$C$2:$AL$2,_xlfn.LAMBDA(_xlpm.a,_xlpm.b,IF(_xlpm.b<>"",_xlpm.b,_xlpm.a))),_xlpm.abCol,MATCH(1,(_xlpm.abYr=_xlpm.yr)*(ISNUMBER(SEARCH(_xlpm.qName,'تجهیزات آب و فاضلاب'!$C$3:$AL$3))),0),_xlpm.ab,IF(OR(_xlpm.shName="تجهیزات آب و فاضلاب",_xlpm.shName="آب و فاضلاب"),INDEX('تجهیزات آب و فاضلاب'!$C$4:$AL$50,MATCH(_xlpm.chapNum,'تجهیزات آب و فاضلاب'!$A$4:$A$50,0),_xlpm.abCol),NA()),IFERROR(_xlpm.abnie,IFERROR(_xlpm.mech,IFERROR(_xlpm.elec,IFERROR(_xlpm.rah,IFERROR(_xlpm.ab,"یافت نشد"))))))} -> 7848.6 | G7: مکانیک | H7: 7 | I7: 0.1 | J7: {=IF(G7="","",_xlfn.LET(_xlpm.yr,VALUE(RIGHT($R$2,4)),_xlpm.qName,TRIM(SUBSTITUTE(SUBSTITUTE($R$2,RIGHT($R$2,4),""),"سه ماهه","")),_xlpm.chapNum,H7,_xlpm.shName,G7,_xlpm.abnieYr,_xlfn.SCAN(0,ابنیه!$C$2:$AL$2,_xlfn.LAMBDA(_xlpm.a,_xlpm.b,IF(_xlpm.b<>"",_xlpm.b,_xlpm.a))),_xlpm.abnieCol,MATCH(1,(_xlpm.abnieYr=_xlpm.yr)*(ISNUMBER(SEARCH(_xlpm.qName,ابنیه!$C$3:$AL$3))),0),_xlpm.abnie,IF(_xlpm.shName="ابنیه",INDEX(ابنیه!$C$4:$AL$50,MATCH(_xlpm.chapNum,ابنیه!$A$4:$A$50,0),_xlpm.abnieCol),NA()),_xlpm.mechYr,_xlfn.SCAN(0,مکانیک!$C$2:$AL$2,_xlfn.LAMBDA(_xlpm.a,_xlpm.b,IF(_xlpm.b<>"",_xlpm.b,_xlpm.a))),_xlpm.mechCol,MATCH(1,(_xlpm.mechYr=_xlpm.yr)*(ISNUMBER(SEARCH(_xlpm.qName,مکانیک!$C$3:$AL$3))),0),_xlpm.mech,IF(_xlpm.shName="مکانیک",INDEX(مکانیک!$C$4:$AL$50,MATCH(_xlpm.chapNum,مکانیک!$A$4:$A$50,0),_xlpm.mechCol),NA()),_xlpm.elecYr,_xlfn.SCAN(0,'تاسیسات برقی'!$C$2:$AL$2,_xlfn.LAMBDA(_xlpm.a,_xlpm.b,IF(_xlpm.b<>"",_xlpm.b,_xlpm.a))),_xlpm.elecCol,MATCH(1,(_xlpm.elecYr=_xlpm.yr)*(ISNUMBER(SEARCH(_xlpm.qName,'تاسیسات برقی'!$C$3:$AL$3))),0),_xlpm.elec,IF(_xlpm.shName="تاسیسات برقی",INDEX('تاسیسات برقی'!$C$4:$AL$50,MATCH(_xlpm.chapNum,'تاسیسات برقی'!$A$4:$A$50,0),_xlpm.elecCol),NA()),_xlpm.rahYr,_xlfn.SCAN(0,'[1]راه, راه آهن و باند فرودگاه'!$C$2:$AL$2,_xlfn.LAMBDA(_xlpm.a,_xlpm.b,IF(_xlpm.b<>"",_xlpm.b,_xlpm.a))),_xlpm.rahCol,MATCH(1,(_xlpm.rahYr=_xlpm.yr)*(ISNUMBER(SEARCH(_xlpm.qName,'[1]راه, راه آهن و باند فرودگاه'!$C$3:$AL$3))),0),_xlpm.rah,IF(OR(_xlpm.shName="راه",_xlpm.shName="راه، راه آهن و باند فرودگاه"),INDEX('[1]راه, راه آهن و باند فرودگاه'!$C$4:$AL$50,MATCH(_xlpm.chapNum,'[1]راه, راه آهن و باند فرودگاه'!$A$4:$A$50,0),_xlpm.rahCol),NA()),_xlpm.abYr,_xlfn.SCAN(0,'تجهیزات آب و فاضلاب'!$C$2:$AL$2,_xlfn.LAMBDA(_xlpm.a,_xlpm.b,IF(_xlpm.b<>"",_xlpm.b,_xlpm.a))),_xlpm.abCol,MATCH(1,(_xlpm.abYr=_xlpm.yr)*(ISNUMBER(SEARCH(_xlpm.qName,'تجهیزات آب و فاضلاب'!$C$3:$AL$3))),0),_xlpm.ab,IF(OR(_xlpm.shName="تجهیزات آب و فاضلاب",_xlpm.shName="آب و فاضلاب"),INDEX('تجهیزات آب و فاضلاب'!$C$4:$AL$50,MATCH(_xlpm.chapNum,'تجهیزات آب و فاضلاب'!$A$4:$A$50,0),_xlpm.abCol),NA()),IFERROR(_xlpm.abnie,IFERROR(_xlpm.mech,IFERROR(_xlpm.elec,IFERROR(_xlpm.rah,IFERROR(_xlpm.ab,"یافت نشد")))))))} -> 9705.5 | K7: نرخ ارز | L7: {=_xlfn.LET(_xlpm.dateTxt,SUBSTITUTE(SUBSTITUTE(SUBSTITUTE(SUBSTITUTE(SUBSTITUTE(SUBSTITUTE(SUBSTITUTE(SUBSTITUTE(SUBSTITUTE(SUBSTITUTE(K7,"۰","0"),"۱","1"),"۲","2"),"۳","3"),"۴","4"),"۵","5"),"۶","6"),"۷","7"),"۸","8"),"۹","9"),_xlpm.rate,VLOOKUP(_xlpm.dateTxt,'Arz '!A:B,2,FALSE),IFERROR(IF(_xlpm.rate=0,"تعطیل رسمی",IF(_xlpm.rate="","تعطیل رسمی",_xlpm.rate)),"یافت نشد"))} -> یافت نشد | M7: =1-(E7+I7) -> 0.6 | N7: =IFERROR(IF(ISNUMBER(L7),(L7/$Q$2)-1,L7),"یافت نشد") -> یافت نشد
A8: 6 | B8: دریچه فولاد ضد زنگ دستی | C8: ابنیه | D8: 16 | E8: 0.4 | F8: {=_xlfn.LET(_xlpm.yr,VALUE(RIGHT($R$2,4)),_xlpm.qName,TRIM(SUBSTITUTE(SUBSTITUTE($R$2,RIGHT($R$2,4),""),"سه ماهه","")),_xlpm.chapNum,D8,_xlpm.shName,C8,_xlpm.abnieYr,_xlfn.SCAN(0,ابنیه!$C$2:$AL$2,_xlfn.LAMBDA(_xlpm.a,_xlpm.b,IF(_xlpm.b<>"",_xlpm.b,_xlpm.a))),_xlpm.abnieCol,MATCH(1,(_xlpm.abnieYr=_xlpm.yr)*(ISNUMBER(SEARCH(_xlpm.qName,ابنیه!$C$3:$AL$3))),0),_xlpm.abnie,IF(_xlpm.shName="ابنیه",INDEX(ابنیه!$C$4:$AL$50,MATCH(_xlpm.chapNum,ابنیه!$A$4:$A$50,0),_xlpm.abnieCol),NA()),_xlpm.mechYr,_xlfn.SCAN(0,مکانیک!$C$2:$AL$2,_xlfn.LAMBDA(_xlpm.a,_xlpm.b,IF(_xlpm.b<>"",_xlpm.b,_xlpm.a))),_xlpm.mechCol,MATCH(1,(_xlpm.mechYr=_xlpm.yr)*(ISNUMBER(SEARCH(_xlpm.qName,مکانیک!$C$3:$AL$3))),0),_xlpm.mech,IF(_xlpm.shName="مکانیک",INDEX(مکانیک!$C$4:$AL$50,MATCH(_xlpm.chapNum,مکانیک!$A$4:$A$50,0),_xlpm.mechCol),NA()),_xlpm.elecYr,_xlfn.SCAN(0,'تاسیسات برقی'!$C$2:$AL$2,_xlfn.LAMBDA(_xlpm.a,_xlpm.b,IF(_xlpm.b<>"",_xlpm.b,_xlpm.a))),_xlpm.elecCol,MATCH(1,(_xlpm.elecYr=_xlpm.yr)*(ISNUMBER(SEARCH(_xlpm.qName,'تاسیسات برقی'!$C$3:$AL$3))),0),_xlpm.elec,IF(_xlpm.shName="تاسیسات برقی",INDEX('تاسیسات برقی'!$C$4:$AL$50,MATCH(_xlpm.chapNum,'تاسیسات برقی'!$A$4:$A$50,0),_xlpm.elecCol),NA()),_xlpm.rahYr,_xlfn.SCAN(0,'[1]راه, راه آهن و باند فرودگاه'!$C$2:$AL$2,_xlfn.LAMBDA(_xlpm.a,_xlpm.b,IF(_xlpm.b<>"",_xlpm.b,_xlpm.a))),_xlpm.rahCol,MATCH(1,(_xlpm.rahYr=_xlpm.yr)*(ISNUMBER(SEARCH(_xlpm.qName,'[1]راه, راه آهن و باند فرودگاه'!$C$3:$AL$3))),0),_xlpm.rah,IF(OR(_xlpm.shName="راه",_xlpm.shName="راه، راه آهن و باند فرودگاه"),INDEX('[1]راه, راه آهن و باند فرودگاه'!$C$4:$AL$50,MATCH(_xlpm.chapNum,'[1]راه, راه آهن و باند فرودگاه'!$A$4:$A$50,0),_xlpm.rahCol),NA()),_xlpm.abYr,_xlfn.SCAN(0,'تجهیزات آب و فاضلاب'!$C$2:$AL$2,_xlfn.LAMBDA(_xlpm.a,_xlpm.b,IF(_xlpm.b<>"",_xlpm.b,_xlpm.a))),_xlpm.abCol,MATCH(1,(_xlpm.abYr=_xlpm.yr)*(ISNUMBER(SEARCH(_xlpm.qName,'تجهیزات آب و فاضلاب'!$C$3:$AL$3))),0),_xlpm.ab,IF(OR(_xlpm.shName="تجهیزات آب و فاضلاب",_xlpm.shName="آب و فاضلاب"),INDEX('تجهیزات آب و فاضلاب'!$C$4:$AL$50,MATCH(_xlpm.chapNum,'تجهیزات آب و فاضلاب'!$A$4:$A$50,0),_xlpm.abCol),NA()),IFERROR(_xlpm.abnie,IFERROR(_xlpm.mech,IFERROR(_xlpm.elec,IFERROR(_xlpm.rah,IFERROR(_xlpm.ab,"یافت نشد"))))))} -> 7848.6 | G8: مکانیک | H8: 7 | I8: 0.1 | J8: {=IF(G8="","",_xlfn.LET(_xlpm.yr,VALUE(RIGHT($R$2,4)),_xlpm.qName,TRIM(SUBSTITUTE(SUBSTITUTE($R$2,RIGHT($R$2,4),""),"سه ماهه","")),_xlpm.chapNum,H8,_xlpm.shName,G8,_xlpm.abnieYr,_xlfn.SCAN(0,ابنیه!$C$2:$AL$2,_xlfn.LAMBDA(_xlpm.a,_xlpm.b,IF(_xlpm.b<>"",_xlpm.b,_xlpm.a))),_xlpm.abnieCol,MATCH(1,(_xlpm.abnieYr=_xlpm.yr)*(ISNUMBER(SEARCH(_xlpm.qName,ابنیه!$C$3:$AL$3))),0),_xlpm.abnie,IF(_xlpm.shName="ابنیه",INDEX(ابنیه!$C$4:$AL$50,MATCH(_xlpm.chapNum,ابنیه!$A$4:$A$50,0),_xlpm.abnieCol),NA()),_xlpm.mechYr,_xlfn.SCAN(0,مکانیک!$C$2:$AL$2,_xlfn.LAMBDA(_xlpm.a,_xlpm.b,IF(_xlpm.b<>"",_xlpm.b,_xlpm.a))),_xlpm.mechCol,MATCH(1,(_xlpm.mechYr=_xlpm.yr)*(ISNUMBER(SEARCH(_xlpm.qName,مکانیک!$C$3:$AL$3))),0),_xlpm.mech,IF(_xlpm.shName="مکانیک",INDEX(مکانیک!$C$4:$AL$50,MATCH(_xlpm.chapNum,مکانیک!$A$4:$A$50,0),_xlpm.mechCol),NA()),_xlpm.elecYr,_xlfn.SCAN(0,'تاسیسات برقی'!$C$2:$AL$2,_xlfn.LAMBDA(_xlpm.a,_xlpm.b,IF(_xlpm.b<>"",_xlpm.b,_xlpm.a))),_xlpm.elecCol,MATCH(1,(_xlpm.elecYr=_xlpm.yr)*(ISNUMBER(SEARCH(_xlpm.qName,'تاسیسات برقی'!$C$3:$AL$3))),0),_xlpm.elec,IF(_xlpm.shName="تاسیسات برقی",INDEX('تاسیسات برقی'!$C$4:$AL$50,MATCH(_xlpm.chapNum,'تاسیسات برقی'!$A$4:$A$50,0),_xlpm.elecCol),NA()),_xlpm.rahYr,_xlfn.SCAN(0,'[1]راه, راه آهن و باند فرودگاه'!$C$2:$AL$2,_xlfn.LAMBDA(_xlpm.a,_xlpm.b,IF(_xlpm.b<>"",_xlpm.b,_xlpm.a))),_xlpm.rahCol,MATCH(1,(_xlpm.rahYr=_xlpm.yr)*(ISNUMBER(SEARCH(_xlpm.qName,'[1]راه, راه آهن و باند فرودگاه'!$C$3:$AL$3))),0),_xlpm.rah,IF(OR(_xlpm.shName="راه",_xlpm.shName="راه، راه آهن و باند فرودگاه"),INDEX('[1]راه, راه آهن و باند فرودگاه'!$C$4:$AL$50,MATCH(_xlpm.chapNum,'[1]راه, راه آهن و باند فرودگاه'!$A$4:$A$50,0),_xlpm.rahCol),NA()),_xlpm.abYr,_xlfn.SCAN(0,'تجهیزات آب و فاضلاب'!$C$2:$AL$2,_xlfn.LAMBDA(_xlpm.a,_xlpm.b,IF(_xlpm.b<>"",_xlpm.b,_xlpm.a))),_xlpm.abCol,MATCH(1,(_xlpm.abYr=_xlpm.yr)*(ISNUMBER(SEARCH(_xlpm.qName,'تجهیزات آب و فاضلاب'!$C$3:$AL$3))),0),_xlpm.ab,IF(OR(_xlpm.shName="تجهیزات آب و فاضلاب",_xlpm.shName="آب و فاضلاب"),INDEX('تجهیزات آب و فاضلاب'!$C$4:$AL$50,MATCH(_xlpm.chapNum,'تجهیزات آب و فاضلاب'!$A$4:$A$50,0),_xlpm.abCol),NA()),IFERROR(_xlpm.abnie,IFERROR(_xlpm.mech,IFERROR(_xlpm.elec,IFERROR(_xlpm.rah,IFERROR(_xlpm.ab,"یافت نشد")))))))} -> 9705.5 | K8: نرخ ارز | L8: {=_xlfn.LET(_xlpm.dateTxt,SUBSTITUTE(SUBSTITUTE(SUBSTITUTE(SUBSTITUTE(SUBSTITUTE(SUBSTITUTE(SUBSTITUTE(SUBSTITUTE(SUBSTITUTE(SUBSTITUTE(K8,"۰","0"),"۱","1"),"۲","2"),"۳","3"),"۴","4"),"۵","5"),"۶","6"),"۷","7"),"۸","8"),"۹","9"),_xlpm.rate,VLOOKUP(_xlpm.dateTxt,'Arz '!A:B,2,FALSE),IFERROR(IF(_xlpm.rate=0,"تعطیل رسمی",IF(_xlpm.rate="","تعطیل رسمی",_xlpm.rate)),"یافت نشد"))} -> یافت نشد | M8: =1-(E8+I8) -> 0.5 | N8: =IFERROR(IF(ISNUMBER(L8),(L8/$Q$2)-1,L8),"یافت نشد") -> یافت نشد
A9: 7 | B9: دریچه فولادی ضد زنگ با محرک برقی و یا بادی | C9: ابنیه | D9: 16 | E9: 0.25 | F9: {=_xlfn.LET(_xlpm.yr,VALUE(RIGHT($R$2,4)),_xlpm.qName,TRIM(SUBSTITUTE(SUBSTITUTE($R$2,RIGHT($R$2,4),""),"سه ماهه","")),_xlpm.chapNum,D9,_xlpm.shName,C9,_xlpm.abnieYr,_xlfn.SCAN(0,ابنیه!$C$2:$AL$2,_xlfn.LAMBDA(_xlpm.a,_xlpm.b,IF(_xlpm.b<>"",_xlpm.b,_xlpm.a))),_xlpm.abnieCol,MATCH(1,(_xlpm.abnieYr=_xlpm.yr)*(ISNUMBER(SEARCH(_xlpm.qName,ابنیه!$C$3:$AL$3))),0),_xlpm.abnie,IF(_xlpm.shName="ابنیه",INDEX(ابنیه!$C$4:$AL$50,MATCH(_xlpm.chapNum,ابنیه!$A$4:$A$50,0),_xlpm.abnieCol),NA()),_xlpm.mechYr,_xlfn.SCAN(0,مکانیک!$C$2:$AL$2,_xlfn.LAMBDA(_xlpm.a,_xlpm.b,IF(_xlpm.b<>"",_xlpm.b,_xlpm.a))),_xlpm.mechCol,MATCH(1,(_xlpm.mechYr=_xlpm.yr)*(ISNUMBER(SEARCH(_xlpm.qName,مکانیک!$C$3:$AL$3))),0),_xlpm.mech,IF(_xlpm.shName="مکانیک",INDEX(مکانیک!$C$4:$AL$50,MATCH(_xlpm.chapNum,مکانیک!$A$4:$A$50,0),_xlpm.mechCol),NA()),_xlpm.elecYr,_xlfn.SCAN(0,'تاسیسات برقی'!$C$2:$AL$2,_xlfn.LAMBDA(_xlpm.a,_xlpm.b,IF(_xlpm.b<>"",_xlpm.b,_xlpm.a))),_xlpm.elecCol,MATCH(1,(_xlpm.elecYr=_xlpm.yr)*(ISNUMBER(SEARCH(_xlpm.qName,'تاسیسات برقی'!$C$3:$AL$3))),0),_xlpm.elec,IF(_xlpm.shName="تاسیسات برقی",INDEX('تاسیسات برقی'!$C$4:$AL$50,MATCH(_xlpm.chapNum,'تاسیسات برقی'!$A$4:$A$50,0),_xlpm.elecCol),NA()),_xlpm.rahYr,_xlfn.SCAN(0,'[1]راه, راه آهن و باند فرودگاه'!$C$2:$AL$2,_xlfn.LAMBDA(_xlpm.a,_xlpm.b,IF(_xlpm.b<>"",_xlpm.b,_xlpm.a))),_xlpm.rahCol,MATCH(1,(_xlpm.rahYr=_xlpm.yr)*(ISNUMBER(SEARCH(_xlpm.qName,'[1]راه, راه آهن و باند فرودگاه'!$C$3:$AL$3))),0),_xlpm.rah,IF(OR(_xlpm.shName="راه",_xlpm.shName="راه، راه آهن و باند فرودگاه"),INDEX('[1]راه, راه آهن و باند فرودگاه'!$C$4:$AL$50,MATCH(_xlpm.chapNum,'[1]راه, راه آهن و باند فرودگاه'!$A$4:$A$50,0),_xlpm.rahCol),NA()),_xlpm.abYr,_xlfn.SCAN(0,'تجهیزات آب و فاضلاب'!$C$2:$AL$2,_xlfn.LAMBDA(_xlpm.a,_xlpm.b,IF(_xlpm.b<>"",_xlpm.b,_xlpm.a))),_xlpm.abCol,MATCH(1,(_xlpm.abYr=_xlpm.yr)*(ISNUMBER(SEARCH(_xlpm.qName,'تجهیزات آب و فاضلاب'!$C$3:$AL$3))),0),_xlpm.ab,IF(OR(_xlpm.shName="تجهیزات آب و فاضلاب",_xlpm.shName="آب و فاضلاب"),INDEX('تجهیزات آب و فاضلاب'!$C$4:$AL$50,MATCH(_xlpm.chapNum,'تجهیزات آب و فاضلاب'!$A$4:$A$50,0),_xlpm.abCol),NA()),IFERROR(_xlpm.abnie,IFERROR(_xlpm.mech,IFERROR(_xlpm.elec,IFERROR(_xlpm.rah,IFERROR(_xlpm.ab,"یافت نشد"))))))} -> 7848.6 | G9: مکانیک | H9: 7 | I9: 0.1 | J9: {=IF(G9="","",_xlfn.LET(_xlpm.yr,VALUE(RIGHT($R$2,4)),_xlpm.qName,TRIM(SUBSTITUTE(SUBSTITUTE($R$2,RIGHT($R$2,4),""),"سه ماهه","")),_xlpm.chapNum,H9,_xlpm.shName,G9,_xlpm.abnieYr,_xlfn.SCAN(0,ابنیه!$C$2:$AL$2,_xlfn.LAMBDA(_xlpm.a,_xlpm.b,IF(_xlpm.b<>"",_xlpm.b,_xlpm.a))),_xlpm.abnieCol,MATCH(1,(_xlpm.abnieYr=_xlpm.yr)*(ISNUMBER(SEARCH(_xlpm.qName,ابنیه!$C$3:$AL$3))),0),_xlpm.abnie,IF(_xlpm.shName="ابنیه",INDEX(ابنیه!$C$4:$AL$50,MATCH(_xlpm.chapNum,ابنیه!$A$4:$A$50,0),_xlpm.abnieCol),NA()),_xlpm.mechYr,_xlfn.SCAN(0,مکانیک!$C$2:$AL$2,_xlfn.LAMBDA(_xlpm.a,_xlpm.b,IF(_xlpm.b<>"",_xlpm.b,_xlpm.a))),_xlpm.mechCol,MATCH(1,(_xlpm.mechYr=_xlpm.yr)*(ISNUMBER(SEARCH(_xlpm.qName,مکانیک!$C$3:$AL$3))),0),_xlpm.mech,IF(_xlpm.shName="مکانیک",INDEX(مکانیک!$C$4:$AL$50,MATCH(_xlpm.chapNum,مکانیک!$A$4:$A$50,0),_xlpm.mechCol),NA()),_xlpm.elecYr,_xlfn.SCAN(0,'تاسیسات برقی'!$C$2:$AL$2,_xlfn.LAMBDA(_xlpm.a,_xlpm.b,IF(_xlpm.b<>"",_xlpm.b,_xlpm.a))),_xlpm.elecCol,MATCH(1,(_xlpm.elecYr=_xlpm.yr)*(ISNUMBER(SEARCH(_xlpm.qName,'تاسیسات برقی'!$C$3:$AL$3))),0),_xlpm.elec,IF(_xlpm.shName="تاسیسات برقی",INDEX('تاسیسات برقی'!$C$4:$AL$50,MATCH(_xlpm.chapNum,'تاسیسات برقی'!$A$4:$A$50,0),_xlpm.elecCol),NA()),_xlpm.rahYr,_xlfn.SCAN(0,'[1]راه, راه آهن و باند فرودگاه'!$C$2:$AL$2,_xlfn.LAMBDA(_xlpm.a,_xlpm.b,IF(_xlpm.b<>"",_xlpm.b,_xlpm.a))),_xlpm.rahCol,MATCH(1,(_xlpm.rahYr=_xlpm.yr)*(ISNUMBER(SEARCH(_xlpm.qName,'[1]راه, راه آهن و باند فرودگاه'!$C$3:$AL$3))),0),_xlpm.rah,IF(OR(_xlpm.shName="راه",_xlpm.shName="راه، راه آهن و باند فرودگاه"),INDEX('[1]راه, راه آهن و باند فرودگاه'!$C$4:$AL$50,MATCH(_xlpm.chapNum,'[1]راه, راه آهن و باند فرودگاه'!$A$4:$A$50,0),_xlpm.rahCol),NA()),_xlpm.abYr,_xlfn.SCAN(0,'تجهیزات آب و فاضلاب'!$C$2:$AL$2,_xlfn.LAMBDA(_xlpm.a,_xlpm.b,IF(_xlpm.b<>"",_xlpm.b,_xlpm.a))),_xlpm.abCol,MATCH(1,(_xlpm.abYr=_xlpm.yr)*(ISNUMBER(SEARCH(_xlpm.qName,'تجهیزات آب و فاضلاب'!$C$3:$AL$3))),0),_xlpm.ab,IF(OR(_xlpm.shName="تجهیزات آب و فاضلاب",_xlpm.shName="آب و فاضلاب"),INDEX('تجهیزات آب و فاضلاب'!$C$4:$AL$50,MATCH(_xlpm.chapNum,'تجهیزات آب و فاضلاب'!$A$4:$A$50,0),_xlpm.abCol),NA()),IFERROR(_xlpm.abnie,IFERROR(_xlpm.mech,IFERROR(_xlpm.elec,IFERROR(_xlpm.rah,IFERROR(_xlpm.ab,"یافت نشد")))))))} -> 9705.5 | K9: نرخ ارز | L9: {=_xlfn.LET(_xlpm.dateTxt,SUBSTITUTE(SUBSTITUTE(SUBSTITUTE(SUBSTITUTE(SUBSTITUTE(SUBSTITUTE(SUBSTITUTE(SUBSTITUTE(SUBSTITUTE(SUBSTITUTE(K9,"۰","0"),"۱","1"),"۲","2"),"۳","3"),"۴","4"),"۵","5"),"۶","6"),"۷","7"),"۸","8"),"۹","9"),_xlpm.rate,VLOOKUP(_xlpm.dateTxt,'Arz '!A:B,2,FALSE),IFERROR(IF(_xlpm.rate=0,"تعطیل رسمی",IF(_xlpm.rate="","تعطیل رسمی",_xlpm.rate)),"یافت نشد"))} -> یافت نشد | M9: =1-(E9+I9) -> 0.65 | N9: =IFERROR(IF(ISNUMBER(L9),(L9/$Q$2)-1,L9),"یافت نشد") -> یافت نشد
A10: 8 | B10: آشغالگیر دستی فولادی با پوشش | C10: ابنیه | D10: 16 | E10: 1 | F10: {=_xlfn.LET(_xlpm.yr,VALUE(RIGHT($R$2,4)),_xlpm.qName,TRIM(SUBSTITUTE(SUBSTITUTE($R$2,RIGHT($R$2,4),""),"سه ماهه","")),_xlpm.chapNum,D10,_xlpm.shName,C10,_xlpm.abnieYr,_xlfn.SCAN(0,ابنیه!$C$2:$AL$2,_xlfn.LAMBDA(_xlpm.a,_xlpm.b,IF(_xlpm.b<>"",_xlpm.b,_xlpm.a))),_xlpm.abnieCol,MATCH(1,(_xlpm.abnieYr=_xlpm.yr)*(ISNUMBER(SEARCH(_xlpm.qName,ابنیه!$C$3:$AL$3))),0),_xlpm.abnie,IF(_xlpm.shName="ابنیه",INDEX(ابنیه!$C$4:$AL$50,MATCH(_xlpm.chapNum,ابنیه!$A$4:$A$50,0),_xlpm.abnieCol),NA()),_xlpm.mechYr,_xlfn.SCAN(0,مکانیک!$C$2:$AL$2,_xlfn.LAMBDA(_xlpm.a,_xlpm.b,IF(_xlpm.b<>"",_xlpm.b,_xlpm.a))),_xlpm.mechCol,MATCH(1,(_xlpm.mechYr=_xlpm.yr)*(ISNUMBER(SEARCH(_xlpm.qName,مکانیک!$C$3:$AL$3))),0),_xlpm.mech,IF(_xlpm.shName="مکانیک",INDEX(مکانیک!$C$4:$AL$50,MATCH(_xlpm.chapNum,مکانیک!$A$4:$A$50,0),_xlpm.mechCol),NA()),_xlpm.elecYr,_xlfn.SCAN(0,'تاسیسات برقی'!$C$2:$AL$2,_xlfn.LAMBDA(_xlpm.a,_xlpm.b,IF(_xlpm.b<>"",_xlpm.b,_xlpm.a))),_xlpm.elecCol,MATCH(1,(_xlpm.elecYr=_xlpm.yr)*(ISNUMBER(SEARCH(_xlpm.qName,'تاسیسات برقی'!$C$3:$AL$3))),0),_xlpm.elec,IF(_xlpm.shName="تاسیسات برقی",INDEX('تاسیسات برقی'!$C$4:$AL$50,MATCH(_xlpm.chapNum,'تاسیسات برقی'!$A$4:$A$50,0),_xlpm.elecCol),NA()),_xlpm.rahYr,_xlfn.SCAN(0,'[1]راه, راه آهن و باند فرودگاه'!$C$2:$AL$2,_xlfn.LAMBDA(_xlpm.a,_xlpm.b,IF(_xlpm.b<>"",_xlpm.b,_xlpm.a))),_xlpm.rahCol,MATCH(1,(_xlpm.rahYr=_xlpm.yr)*(ISNUMBER(SEARCH(_xlpm.qName,'[1]راه, راه آهن و باند فرودگاه'!$C$3:$AL$3))),0),_xlpm.rah,IF(OR(_xlpm.shName="راه",_xlpm.shName="راه، راه آهن و باند فرودگاه"),INDEX('[1]راه, راه آهن و باند فرودگاه'!$C$4:$AL$50,MATCH(_xlpm.chapNum,'[1]راه, راه آهن و باند فرودگاه'!$A$4:$A$50,0),_xlpm.rahCol),NA()),_xlpm.abYr,_xlfn.SCAN(0,'تجهیزات آب و فاضلاب'!$C$2:$AL$2,_xlfn.LAMBDA(_xlpm.a,_xlpm.b,IF(_xlpm.b<>"",_xlpm.b,_xlpm.a))),_xlpm.abCol,MATCH(1,(_xlpm.abYr=_xlpm.yr)*(ISNUMBER(SEARCH(_xlpm.qName,'تجهیزات آب و فاضلاب'!$C$3:$AL$3))),0),_xlpm.ab,IF(OR(_xlpm.shName="تجهیزات آب و فاضلاب",_xlpm.shName="آب و فاضلاب"),INDEX('تجهیزات آب و فاضلاب'!$C$4:$AL$50,MATCH(_xlpm.chapNum,'تجهیزات آب و فاضلاب'!$A$4:$A$50,0),_xlpm.abCol),NA()),IFERROR(_xlpm.abnie,IFERROR(_xlpm.mech,IFERROR(_xlpm.elec,IFERROR(_xlpm.rah,IFERROR(_xlpm.ab,"یافت نشد"))))))} -> 7848.6 | J10: {=IF(G10="","",_xlfn.LET(_xlpm.yr,VALUE(RIGHT($R$2,4)),_xlpm.qName,TRIM(SUBSTITUTE(SUBSTITUTE($R$2,RIGHT($R$2,4),""),"سه ماهه","")),_xlpm.chapNum,H10,_xlpm.shName,G10,_xlpm.abnieYr,_xlfn.SCAN(0,ابنیه!$C$2:$AL$2,_xlfn.LAMBDA(_xlpm.a,_xlpm.b,IF(_xlpm.b<>"",_xlpm.b,_xlpm.a))),_xlpm.abnieCol,MATCH(1,(_xlpm.abnieYr=_xlpm.yr)*(ISNUMBER(SEARCH(_xlpm.qName,ابنیه!$C$3:$AL$3))),0),_xlpm.abnie,IF(_xlpm.shName="ابنیه",INDEX(ابنیه!$C$4:$AL$50,MATCH(_xlpm.chapNum,ابنیه!$A$4:$A$50,0),_xlpm.abnieCol),NA()),_xlpm.mechYr,_xlfn.SCAN(0,مکانیک!$C$2:$AL$2,_xlfn.LAMBDA(_xlpm.a,_xlpm.b,IF(_xlpm.b<>"",_xlpm.b,_xlpm.a))),_xlpm.mechCol,MATCH(1,(_xlpm.mechYr=_xlpm.yr)*(ISNUMBER(SEARCH(_xlpm.qName,مکانیک!$C$3:$AL$3))),0),_xlpm.mech,IF(_xlpm.shName="مکانیک",INDEX(مکانیک!$C$4:$AL$50,MATCH(_xlpm.chapNum,مکانیک!$A$4:$A$50,0),_xlpm.mechCol),NA()),_xlpm.elecYr,_xlfn.SCAN(0,'تاسیسات برقی'!$C$2:$AL$2,_xlfn.LAMBDA(_xlpm.a,_xlpm.b,IF(_xlpm.b<>"",_xlpm.b,_xlpm.a))),_xlpm.elecCol,MATCH(1,(_xlpm.elecYr=_xlpm.yr)*(ISNUMBER(SEARCH(_xlpm.qName,'تاسیسات برقی'!$C$3:$AL$3))),0),_xlpm.elec,IF(_xlpm.shName="تاسیسات برقی",INDEX('تاسیسات برقی'!$C$4:$AL$50,MATCH(_xlpm.chapNum,'تاسیسات برقی'!$A$4:$A$50,0),_xlpm.elecCol),NA()),_xlpm.rahYr,_xlfn.SCAN(0,'[1]راه, راه آهن و باند فرودگاه'!$C$2:$AL$2,_xlfn.LAMBDA(_xlpm.a,_xlpm.b,IF(_xlpm.b<>"",_xlpm.b,_xlpm.a))),_xlpm.rahCol,MATCH(1,(_xlpm.rahYr=_xlpm.yr)*(ISNUMBER(SEARCH(_xlpm.qName,'[1]راه, راه آهن و باند فرودگاه'!$C$3:$AL$3))),0),_xlpm.rah,IF(OR(_xlpm.shName="راه",_xlpm.shName="راه، راه آهن و باند فرودگاه"),INDEX('[1]راه, راه آهن و باند فرودگاه'!$C$4:$AL$50,MATCH(_xlpm.chapNum,'[1]راه, راه آهن و باند فرودگاه'!$A$4:$A$50,0),_xlpm.rahCol),NA()),_xlpm.abYr,_xlfn.SCAN(0,'تجهیزات آب و فاضلاب'!$C$2:$AL$2,_xlfn.LAMBDA(_xlpm.a,_xlpm.b,IF(_xlpm.b<>"",_xlpm.b,_xlpm.a))),_xlpm.abCol,MATCH(1,(_xlpm.abYr=_xlpm.yr)*(ISNUMBER(SEARCH(_xlpm.qName,'تجهیزات آب و فاضلاب'!$C$3:$AL$3))),0),_xlpm.ab,IF(OR(_xlpm.shName="تجهیزات آب و فاضلاب",_xlpm.shName="آب و فاضلاب"),INDEX('تجهیزات آب و فاضلاب'!$C$4:$AL$50,MATCH(_xlpm.chapNum,'تجهیزات آب و فاضلاب'!$A$4:$A$50,0),_xlpm.abCol),NA()),IFERROR(_xlpm.abnie,IFERROR(_xlpm.mech,IFERROR(_xlpm.elec,IFERROR(_xlpm.rah,IFERROR(_xlpm.ab,"یافت نشد")))))))} | K10: نرخ ارز | L10: {=_xlfn.LET(_xlpm.dateTxt,SUBSTITUTE(SUBSTITUTE(SUBSTITUTE(SUBSTITUTE(SUBSTITUTE(SUBSTITUTE(SUBSTITUTE(SUBSTITUTE(SUBSTITUTE(SUBSTITUTE(K10,"۰","0"),"۱","1"),"۲","2"),"۳","3"),"۴","4"),"۵","5"),"۶","6"),"۷","7"),"۸","8"),"۹","9"),_xlpm.rate,VLOOKUP(_xlpm.dateTxt,'Arz '!A:B,2,FALSE),IFERROR(IF(_xlpm.rate=0,"تعطیل رسمی",IF(_xlpm.rate="","تعطیل رسمی",_xlpm.rate)),"یافت نشد"))} -> یافت نشد | M10: =1-(E10+I10) -> 0 | N10: =IFERROR(IF(ISNUMBER(L10),(L10/$Q$2)-1,L10),"یافت نشد") -> یافت نشد
A11: 9 | B11: آشغالگیر دستی فولاد ضد زنگ | C11: ابنیه | D11: 16 | E11: 0.5 | F11: {=_xlfn.LET(_xlpm.yr,VALUE(RIGHT($R$2,4)),_xlpm.qName,TRIM(SUBSTITUTE(SUBSTITUTE($R$2,RIGHT($R$2,4),""),"سه ماهه","")),_xlpm.chapNum,D11,_xlpm.shName,C11,_xlpm.abnieYr,_xlfn.SCAN(0,ابنیه!$C$2:$AL$2,_xlfn.LAMBDA(_xlpm.a,_xlpm.b,IF(_xlpm.b<>"",_xlpm.b,_xlpm.a))),_xlpm.abnieCol,MATCH(1,(_xlpm.abnieYr=_xlpm.yr)*(ISNUMBER(SEARCH(_xlpm.qName,ابنیه!$C$3:$AL$3))),0),_xlpm.abnie,IF(_xlpm.shName="ابنیه",INDEX(ابنیه!$C$4:$AL$50,MATCH(_xlpm.chapNum,ابنیه!$A$4:$A$50,0),_xlpm.abnieCol),NA()),_xlpm.mechYr,_xlfn.SCAN(0,مکانیک!$C$2:$AL$2,_xlfn.LAMBDA(_xlpm.a,_xlpm.b,IF(_xlpm.b<>"",_xlpm.b,_xlpm.a))),_xlpm.mechCol,MATCH(1,(_xlpm.mechYr=_xlpm.yr)*(ISNUMBER(SEARCH(_xlpm.qName,مکانیک!$C$3:$AL$3))),0),_xlpm.mech,IF(_xlpm.shName="مکانیک",INDEX(مکانیک!$C$4:$AL$50,MATCH(_xlpm.chapNum,مکانیک!$A$4:$A$50,0),_xlpm.mechCol),NA()),_xlpm.elecYr,_xlfn.SCAN(0,'تاسیسات برقی'!$C$2:$AL$2,_xlfn.LAMBDA(_xlpm.a,_xlpm.b,IF(_xlpm.b<>"",_xlpm.b,_xlpm.a))),_xlpm.elecCol,MATCH(1,(_xlpm.elecYr=_xlpm.yr)*(ISNUMBER(SEARCH(_xlpm.qName,'تاسیسات برقی'!$C$3:$AL$3))),0),_xlpm.elec,IF(_xlpm.shName="تاسیسات برقی",INDEX('تاسیسات برقی'!$C$4:$AL$50,MATCH(_xlpm.chapNum,'تاسیسات برقی'!$A$4:$A$50,0),_xlpm.elecCol),NA()),_xlpm.rahYr,_xlfn.SCAN(0,'[1]راه, راه آهن و باند فرودگاه'!$C$2:$AL$2,_xlfn.LAMBDA(_xlpm.a,_xlpm.b,IF(_xlpm.b<>"",_xlpm.b,_xlpm.a))),_xlpm.rahCol,MATCH(1,(_xlpm.rahYr=_xlpm.yr)*(ISNUMBER(SEARCH(_xlpm.qName,'[1]راه, راه آهن و باند فرودگاه'!$C$3:$AL$3))),0),_xlpm.rah,IF(OR(_xlpm.shName="راه",_xlpm.shName="راه، راه آهن و باند فرودگاه"),INDEX('[1]راه, راه آهن و باند فرودگاه'!$C$4:$AL$50,MATCH(_xlpm.chapNum,'[1]راه, راه آهن و باند فرودگاه'!$A$4:$A$50,0),_xlpm.rahCol),NA()),_xlpm.abYr,_xlfn.SCAN(0,'تجهیزات آب و فاضلاب'!$C$2:$AL$2,_xlfn.LAMBDA(_xlpm.a,_xlpm.b,IF(_xlpm.b<>"",_xlpm.b,_xlpm.a))),_xlpm.abCol,MATCH(1,(_xlpm.abYr=_xlpm.yr)*(ISNUMBER(SEARCH(_xlpm.qName,'تجهیزات آب و فاضلاب'!$C$3:$AL$3))),0),_xlpm.ab,IF(OR(_xlpm.shName="تجهیزات آب و فاضلاب",_xlpm.shName="آب و فاضلاب"),INDEX('تجهیزات آب و فاضلاب'!$C$4:$AL$50,MATCH(_xlpm.chapNum,'تجهیزات آب و فاضلاب'!$A$4:$A$50,0),_xlpm.abCol),NA()),IFERROR(_xlpm.abnie,IFERROR(_xlpm.mech,IFERROR(_xlpm.elec,IFERROR(_xlpm.rah,IFERROR(_xlpm.ab,"یافت نشد"))))))} -> 7848.6 | J11: {=IF(G11="","",_xlfn.LET(_xlpm.yr,VALUE(RIGHT($R$2,4)),_xlpm.qName,TRIM(SUBSTITUTE(SUBSTITUTE($R$2,RIGHT($R$2,4),""),"سه ماهه","")),_xlpm.chapNum,H11,_xlpm.shName,G11,_xlpm.abnieYr,_xlfn.SCAN(0,ابنیه!$C$2:$AL$2,_xlfn.LAMBDA(_xlpm.a,_xlpm.b,IF(_xlpm.b<>"",_xlpm.b,_xlpm.a))),_xlpm.abnieCol,MATCH(1,(_xlpm.abnieYr=_xlpm.yr)*(ISNUMBER(SEARCH(_xlpm.qName,ابنیه!$C$3:$AL$3))),0),_xlpm.abnie,IF(_xlpm.shName="ابنیه",INDEX(ابنیه!$C$4:$AL$50,MATCH(_xlpm.chapNum,ابنیه!$A$4:$A$50,0),_xlpm.abnieCol),NA()),_xlpm.mechYr,_xlfn.SCAN(0,مکانیک!$C$2:$AL$2,_xlfn.LAMBDA(_xlpm.a,_xlpm.b,IF(_xlpm.b<>"",_xlpm.b,_xlpm.a))),_xlpm.mechCol,MATCH(1,(_xlpm.mechYr=_xlpm.yr)*(ISNUMBER(SEARCH(_xlpm.qName,مکانیک!$C$3:$AL$3))),0),_xlpm.mech,IF(_xlpm.shName="مکانیک",INDEX(مکانیک!$C$4:$AL$50,MATCH(_xlpm.chapNum,مکانیک!$A$4:$A$50,0),_xlpm.mechCol),NA()),_xlpm.elecYr,_xlfn.SCAN(0,'تاسیسات برقی'!$C$2:$AL$2,_xlfn.LAMBDA(_xlpm.a,_xlpm.b,IF(_xlpm.b<>"",_xlpm.b,_xlpm.a))),_xlpm.elecCol,MATCH(1,(_xlpm.elecYr=_xlpm.yr)*(ISNUMBER(SEARCH(_xlpm.qName,'تاسیسات برقی'!$C$3:$AL$3))),0),_xlpm.elec,IF(_xlpm.shName="تاسیسات برقی",INDEX('تاسیسات برقی'!$C$4:$AL$50,MATCH(_xlpm.chapNum,'تاسیسات برقی'!$A$4:$A$50,0),_xlpm.elecCol),NA()),_xlpm.rahYr,_xlfn.SCAN(0,'[1]راه, راه آهن و باند فرودگاه'!$C$2:$AL$2,_xlfn.LAMBDA(_xlpm.a,_xlpm.b,IF(_xlpm.b<>"",_xlpm.b,_xlpm.a))),_xlpm.rahCol,MATCH(1,(_xlpm.rahYr=_xlpm.yr)*(ISNUMBER(SEARCH(_xlpm.qName,'[1]راه, راه آهن و باند فرودگاه'!$C$3:$AL$3))),0),_xlpm.rah,IF(OR(_xlpm.shName="راه",_xlpm.shName="راه، راه آهن و باند فرودگاه"),INDEX('[1]راه, راه آهن و باند فرودگاه'!$C$4:$AL$50,MATCH(_xlpm.chapNum,'[1]راه, راه آهن و باند فرودگاه'!$A$4:$A$50,0),_xlpm.rahCol),NA()),_xlpm.abYr,_xlfn.SCAN(0,'تجهیزات آب و فاضلاب'!$C$2:$AL$2,_xlfn.LAMBDA(_xlpm.a,_xlpm.b,IF(_xlpm.b<>"",_xlpm.b,_xlpm.a))),_xlpm.abCol,MATCH(1,(_xlpm.abYr=_xlpm.yr)*(ISNUMBER(SEARCH(_xlpm.qName,'تجهیزات آب و فاضلاب'!$C$3:$AL$3))),0),_xlpm.ab,IF(OR(_xlpm.shName="تجهیزات آب و فاضلاب",_xlpm.shName="آب و فاضلاب"),INDEX('تجهیزات آب و فاضلاب'!$C$4:$AL$50,MATCH(_xlpm.chapNum,'تجهیزات آب و فاضلاب'!$A$4:$A$50,0),_xlpm.abCol),NA()),IFERROR(_xlpm.abnie,IFERROR(_xlpm.mech,IFERROR(_xlpm.elec,IFERROR(_xlpm.rah,IFERROR(_xlpm.ab,"یافت نشد")))))))} | K11: نرخ ارز | L11: {=_xlfn.LET(_xlpm.dateTxt,SUBSTITUTE(SUBSTITUTE(SUBSTITUTE(SUBSTITUTE(SUBSTITUTE(SUBSTITUTE(SUBSTITUTE(SUBSTITUTE(SUBSTITUTE(SUBSTITUTE(K11,"۰","0"),"۱","1"),"۲","2"),"۳","3"),"۴","4"),"۵","5"),"۶","6"),"۷","7"),"۸","8"),"۹","9"),_xlpm.rate,VLOOKUP(_xlpm.dateTxt,'Arz '!A:B,2,FALSE),IFERROR(IF(_xlpm.rate=0,"تعطیل رسمی",IF(_xlpm.rate="","تعطیل رسمی",_xlpm.rate)),"یافت نشد"))} -> یافت نشد | M11: =1-(E11+I11) -> 0.5 | N11: =IFERROR(IF(ISNUMBER(L11),(L11/$Q$2)-1,L11),"یافت نشد") -> یافت نشد
